Workbook

Sheet Modul 1
D6: PRAKTIKUM PERANCANGAN SISTEM TERINTEGRASI III
D7: MODUL 3 - Pengendalian Kualitas Secara Statistika
K13: PJ Modul
I14: 13422005 Naufal Vitoperisa Oktora 13422068 Daniel Febrian Parhusip 13422126 Nadya Farah Iresqa
D19: Laboratorium Perencanaan dan Optimasi Sistem Industri
D20: Program Studi Teknik Industri
D21: Fakultas Teknologi Industri
D22: 2025

Sheet Skenario
A1: No | B1: Informasi
A2: 1 | B2: PT PPST Manufacturing memproduksi 4 jenis tripod dengan dua ukuran (tripod kecil dan besar), yaitu Tripod A, B, C, dan D. Dari berbagai macam part yang dibutuhkan untuk membuat tripod, terdapat 3 part yang dibuat sendiri dari bahan baku mentah, yaitu bottom base 2, leg, dan pivot. Untuk part pivot, akan dilakukan pengendalian kualitas pada diameter lubang horizontal. Sampel diambil dengan ukuran banyak. PT PPST Manufacturing ingin melihat kurva OC, ARL, dan kapabilitas dari proses tersebut. PT PPST Manufacturing juga ingin melihat implementasi dari penggunaan peta kendali ini. | E2: Pivot (diameter lubang horizontal)
A3: 2 | B3: Untuk part bottom base 2, akan dilakukan pengendalian kualitas pada diameter half cylinder dari bottom base 2. Sampel diambil dengan ukuran 1 karena waktu proses yang relatif lebih lama.
A4: 3 | B4: Pada tahap perakitan S3A1, perakitan yang menggabungkan S4A1 (assembly bottom base 1 dengan leg dan bottom base 2) dengan S5A2 (assembly guide male dan guide female), akan dihitung jumlah cacat berupa bercak atau goresan yang muncul pada tiap unit S3A1 ketika perakitan berlangsung. Pengendalian kualitas dilakukan per satu unit inspeksi.
A5: 4 | B5: Pada tahap akhir perakitan akan dilakukan inspeksi secara menyeluruh untuk mengecek apakah ada tripod yang rusak (nonconforming).
A6: 5 | B6: Perbedaan dari keempat jenis tripod adalah pada tinggi dari tripod itu sendiri. Oleh karena itu, akan ada perbedaan dimensi panjang pada part Leg di setiap jenis tripod. Pengendalian kualitas secara statistika menggunakan peta kendali diinginkan yang bisa mengakomodasi seluruh jenis tripod. | E6: Bottom base 2 (diameter half cylinder)
A7: 6 | B7: Setelah barang selesai dirakit, akan dilakukan proses pengiriman barang kepada konsumen. Selanjutnya, PT X akan memberikan invoice dan dokumen lain kepada konsumen. Disebabkan oleh penyatuan lini produksi beberapa tripod karena kesamaan alur produksi, beberapa pekerja masih belum terbiasa dengan pembuatan dokumen hasil produksi yang baru sehingga dapat terjadi kesalahan dalam pembuatan dokumen, seperti pencatatan jenis tripod yang salah, invoice yang salah penempatan, dan sebagainya. Oleh karena itu, akan dilakukan pengendalian kualitas untuk dokumen yang akan diberikan kepada konsumen dengan ketentuan unit inspeksi lebih dari satu.
A8: 7 | B8: Disebabkan oleh efisiensi yang berhasil dilakukan pada lini produksi tripod dan tingginya permintaan yang masuk, PT X menerima pesanan pembuatan part XYZ 1 dan XYZ 2. a. Part XYZ 1 adalah part yang perlu diinspeksi dengan teknologi tinggi sehingga ukuran sampel untuk inspeksi hanya satu (pengukuran individual). Dimensi yang diukur adalah panjang. Agar tidak mengecewakan konsumen, peta kendali harus mampu mendeteksi pergeseran kecil.
A9: 8 | B9: b. Dimensi yang ingin dikendalikan kualitasnya untuk part XYZ 2 adalah diameter dalam dan diameter luar secara bersamaan.
E10: Leg (panjang)

Sheet Data Awal
B2: Data Awal | I2: Data untuk Implementasi | S2: Data Awal | V2: Data Awal | Y2: Data Awal | AB2: Data Awal | AK2: Data Awal | AN2: Data Awal | AT2: Data Awal
B3: Diameter Lubang Horizontal part pivot (mm) | I3: Diameter Lubang Horizontal part pivot (mm) | S3: Diameter Half cylinder bottom base 2 (mm) | V3: Jumlah nonconformity assembly S3A1 | Y3: Jumlah nonconforming (cacat) Tripod | AB3: Panjang Leg Tripod (mm) | AK3: Jumlah saltik (typo) pada dokumen (1 inspeksi unit = 1 dokumen) | AN3: Panjang Part XYZ 1 | AT3: Diameter dalam dan luar Part XYZ 2
B4: Sample Number (i) | C4: Observasi | I4: Sample Number (i) | J4: Observasi | P4: Spesifikasi Diameter Lubang Horizontal Tripod | S4: Sample Number (i) | T4: Observasi | V4: Sample Number (i) | W4: Observasi per 1 unit inspeksi | Y4: Sample Number (i) | Z4: Observasi per 50 unit Tripod | AB4: Sample Number (i) | AC4: Jenis Tripod | AD4: Observasi | AH4: Spesifikasi Target Panjang Leg Tripod (mm) | AK4: Sample Number (i) | AL4: Observasi per 100 dokumen | AN4: Sample Number (i) | AO4: Observasi | AQ4: Parameter untuk peta cusum dan EWMA part XYZ 1 | AT4: Sample Number (i) | AU4: Observasi diameter dalam (mm) | AY4: Observasi diameter luar (mm)
B5: 1 | C5: 9.976 | D5: 10.694 | E5: 10.368 | F5: 10.503 | G5: 10.323 | I5: 26 | J5: 10.477 | K5: 10.499 | L5: 10.577 | M5: 10.654 | N5: 10.455 | P5: USL | Q5: 12 | S5: 1 | T5: 3.7664858 | V5: 1 | W5: 5 | Y5: 1 | Z5: 7 | AB5: 1 | AC5: A | AD5: 2.637 | AE5: 2.641 | AF5: 2.639 | AH5: A | AI5: 264 | AK5: 1 | AL5: 12 | AN5: 1 | AO5: 8 | AQ5: K | AR5: 1/2 sigma | AT5: 1 | AU5: 10.036 | AV5: 10.068 | AW5: 10.014 | AX5: 9.963 | AY5: 11.998 | AZ5: 11.885 | BA5: 12.011 | BB5: 11.914
B6: 2 | C6: 10.626 | D6: 10.424 | E6: 11.109 | F6: 1.057 | G6: 10.133 | I6: 27 | J6: 10.299 | K6: 10.321 | L6: 10.343 | M6: 10.266 | N6: 10.543 | P6: LSL | Q6: 10 | S6: 2 | T6: 3.6069998 | V6: 2 | W6: 6 | Y6: 2 | Z6: 15 | AB6: 2 | AC6: A | AD6: 2.639 | AE6: 2.639 | AF6: 2.641 | AH6: B | AI6: 284 | AK6: 2 | AL6: 7 | AN6: 2 | AO6: 9 | AQ6: H | AR6: 5 sigma | AT6: 2 | AU6: 10.045 | AV6: 10.203 | AW6: 10.149 | AX6: 10.199 | AY6: 1.191 | AZ6: 11.784 | BA6: 11.924 | BB6: 11.838
B7: 3 | C7: 10.458 | D7: 10.548 | E7: 10.761 | F7: 10.301 | G7: 10.043 | I7: 28 | J7: 10.532 | K7: 10.643 | L7: 10.221 | M7: 1.021 | N7: 1.041 | S7: 3 | T7: 3.1533437 | V7: 3 | W7: 10 | Y7: 3 | Z7: 7 | AB7: 3 | AC7: A | AD7: 2.638 | AE7: 2.639 | AF7: 2.641 | AH7: C | AI7: 304 | AK7: 3 | AL7: 5 | AN7: 3 | AO7: 1 | AQ7: Lambda | AR7: 0.01 | AT7: 3 | AU7: 9.864 | AV7: 10.257 | AW7: 10.085 | AX7: 10.158 | AY7: 11.866 | AZ7: 12.068 | BA7: 12.063 | BB7: 11.969
B8: 4 | C8: 10.649 | D8: 10.727 | E8: 10.424 | F8: 10.604 | G8: 10.604 | I8: 29 | J8: 10.466 | K8: 10.266 | L8: 10.243 | M8: 10.366 | N8: 1.041 | S8: 4 | T8: 3.8022472 | V8: 4 | W8: 8 | Y8: 4 | Z8: 8 | AB8: 4 | AC8: A | AD8: 2.641 | AE8: 2.639 | AF8: 2.641 | AH8: D | AI8: 324 | AK8: 4 | AL8: 12 | AN8: 4 | AO8: 9 | AQ8: L | AR8: 2.7 | AT8: 4 | AU8: 10.085 | AV8: 10.022 | AW8: 10.063 | AX8: 10.238 | AY8: 11.875 | AZ8: 11.985 | BA8: 12.043 | BB8: 11.688
B9: 5 | C9: 10.581 | D9: 10.918 | E9: 10.402 | F9: 10.481 | G9: 10.795 | I9: 30 | J9: 10.666 | K9: 10.532 | L9: 10.399 | M9: 10.477 | N9: 10.388 | S9: 5 | T9: 3.8057884 | V9: 5 | W9: 8 | Y9: 5 | Z9: 15 | AB9: 5 | AC9: A | AD9: =0.264*10 -> 2.64 | AE9: 2.639 | AF9: =0.264*10 -> 2.64 | AK9: 5 | AL9: 4 | AN9: 5 | AO9: 12 | AQ9: miu0 target | AR9: 1 | AT9: 5 | AU9: 10.445 | AV9: 0.102 | AW9: 10.153 | AX9: 10.097 | AY9: 11.754 | AZ9: 11.888 | BA9: 11.817 | BB9: 12.243
B10: 6 | C10: 10.436 | D10: 10.503 | E10: 10.907 | F10: 10.458 | G10: 9.807 | I10: 31 | J10: 10.343 | K10: 10.588 | L10: 10.277 | M10: 10.388 | N10: 10.399 | S10: 6 | T10: 3.0967304 | V10: 6 | W10: 5 | Y10: 6 | Z10: 9 | AB10: 6 | AC10: B | AD10: 0.284 | AE10: 0.284 | AF10: 2.841 | AK10: 6 | AL10: 3 | AN10: 6 | AO10: 8 | AQ10: sigma target | AR10: 0.1 | AT10: 6 | AU10: 9.993 | AV10: 9.974 | AW10: 10.051 | AX10: 10.434 | AY10: 11.844 | AZ10: 11.979 | BA10: 12.063 | BB10: 11.893
B11: 7 | C11: 10.682 | D11: 10.447 | E11: 10.323 | F11: 10.312 | G11: 10.806 | I11: 32 | J11: 1.051 | K11: 10.421 | L11: 10.221 | M11: 10.555 | N11: 10.555 | S11: 7 | T11: 3.3090724 | V11: 7 | W11: 7 | Y11: 7 | Z11: 9 | AB11: 7 | AC11: B | AD11: 0.284 | AE11: 2.841 | AF11: 0.284 | AK11: 7 | AL11: 12 | AN11: 7 | AO11: 12 | AT11: 7 | AU11: 1.024 | AV11: 10.021 | AW11: 10.297 | AX11: 9.801 | AY11: 11.751 | AZ11: 11.963 | BA11: 11.902 | BB11: 11.883
B12: 8 | C12: 10.357 | D12: 10.481 | E12: 10.447 | F12: 10.469 | G12: 10.638 | I12: 33 | J12: 10.232 | K12: 10.477 | L12: 1.041 | M12: 10.543 | N12: 10.532 | S12: 8 | T12: 3.7744093 | V12: 8 | W12: 12 | Y12: 8 | Z12: 5 | AB12: 8 | AC12: B | AD12: 2.839 | AE12: 0.284 | AF12: 2.839 | AK12: 8 | AL12: 12 | AN12: 8 | AO12: 12 | AT12: 8 | AU12: 10.256 | AV12: 10.139 | AW12: 10.089 | AX12: 10.072 | AY12: 11.962 | AZ12: 11.658 | BA12: 11.757 | BB12: 11.932
B13: 9 | C13: 10.682 | D13: 10.907 | E13: 10.402 | F13: 1.029 | G13: 10.581 | I13: 34 | J13: 10.566 | K13: 10.332 | L13: 10.332 | M13: 10.332 | N13: 10.632 | S13: 9 | T13: 3.6511427 | V13: 9 | W13: 8 | Y13: 9 | Z13: 6 | AB13: 9 | AC13: B | AD13: 2.839 | AE13: 2.841 | AF13: 2.841 | AK13: 9 | AL13: 12 | AN13: 9 | AO13: 9 | AT13: 9 | AU13: 9.983 | AV13: 10.128 | AW13: 10.221 | AX13: 10.043 | AY13: 11.691 | AZ13: 0.121 | BA13: 12.004 | BB13: 0.118
B14: 10 | C14: 10.525 | D14: 10.682 | E14: 10.581 | F14: 1.066 | G14: 10.817 | I14: 35 | J14: 10.343 | K14: 10.455 | L14: 10.588 | M14: 1.041 | N14: 1.021 | S14: 10 | T14: 3.1736182 | V14: 10 | W14: 7 | Y14: 10 | Z14: 11 | AB14: 10 | AC14: B | AD14: 2.839 | AE14: 2.842 | AF14: 0.284 | AK14: 10 | AL14: 5 | AN14: 10 | AO14: 8 | AT14: 10 | AU14: 10.093 | AV14: 10.125 | AW14: 10.116 | AX14: 10.071 | AY14: 11.876 | AZ14: 12.006 | BA14: 12.065 | BB14: 11.847
B15: 11 | C15: 10.795 | D15: 10.424 | E15: 10.638 | F15: 11.109 | G15: 11.109 | I15: 36 | J15: 10.432 | K15: 10.577 | L15: 10.255 | M15: 10.421 | N15: 10.477 | S15: 11 | T15: 3.3752294 | V15: 11 | W15: 5 | Y15: 11 | Z15: 6 | AB15: 11 | AC15: C | AD15: 3.041 | AE15: 3.041 | AF15: 3.039 | AK15: 11 | AL15: 4 | AN15: 11 | AO15: 8 | AT15: 11 | AU15: 10.194 | AV15: 10.329 | AW15: 10.041 | AX15: 10.362 | AY15: 12.067 | AZ15: 11.922 | BA15: 12.123 | BB15: 11.791
B16: 12 | C16: 10.581 | D16: 10.503 | E16: 10.436 | F16: 1.038 | G16: 10.952 | I16: 37 | J16: 10.455 | K16: 1.061 | L16: 10.654 | M16: 10.477 | N16: 10.399 | S16: 12 | T16: 3.7174377 | V16: 12 | W16: 15 | Y16: 12 | Z16: 8 | AB16: 12 | AC16: C | AD16: 3.039 | AE16: 3.041 | AF16: 0.304 | AK16: 12 | AL16: 7 | AN16: 12 | AO16: 1 | AT16: 12 | AU16: 10.195 | AV16: 9.918 | AW16: 10.229 | AX16: 10.141 | AY16: 12.045 | AZ16: 11.985 | BA16: 12.015 | BB16: 11.845
B17: 13 | C17: 10.705 | D17: 10.357 | E17: 10.357 | F17: 10.537 | G17: 10.514 | I17: 38 | J17: 10.455 | K17: 10.455 | L17: 10.432 | M17: 10.299 | N17: 10.232 | S17: 13 | T17: 3.5066225 | V17: 13 | W17: 5 | Y17: 13 | Z17: 5 | AB17: 13 | AC17: C | AD17: 0.304 | AE17: 0.304 | AF17: 3.042 | AK17: 13 | AL17: 9 | AN17: 13 | AO17: 13 | AT17: 13 | AU17: 10.131 | AV17: 0.995 | AW17: 9.815 | AX17: 10.229 | AY17: 11.873 | AZ17: 12.047 | BA17: 11.648 | BB17: 12.033
B18: 14 | C18: 10.413 | D18: 10.335 | E18: 10.469 | F18: 10.424 | G18: 10.559 | I18: 39 | J18: 10.588 | K18: 10.677 | L18: 10.232 | M18: 1.051 | N18: 10.632 | S18: 14 | T18: 3.744536 | V18: 14 | W18: 14 | Y18: 14 | Z18: 5 | AB18: 14 | AC18: C | AD18: 3.041 | AE18: 0.304 | AF18: 3.039 | AK18: 14 | AL18: 12 | AN18: 14 | AO18: 12 | AT18: 14 | AU18: 10.168 | AV18: 9.757 | AW18: 9.969 | AX18: 10.198 | AY18: 1.188 | AZ18: 11.909 | BA18: 11.923 | BB18: 11.895
B19: 15 | C19: 1.011 | D19: 10.604 | E19: 10.514 | F19: 1.057 | G19: 10.503 | I19: 40 | J19: 10.399 | K19: 10.443 | L19: 10.532 | M19: 1.061 | N19: 10.266 | S19: 15 | T19: 3.0840297 | V19: 15 | W19: 11 | Y19: 15 | Z19: 12 | AB19: 15 | AC19: C | AD19: 3.039 | AE19: 3.038 | AF19: 0.304 | AK19: 15 | AL19: 7 | AN19: 15 | AO19: 8 | AT19: 15 | AU19: 10.278 | AV19: 1.033 | AW19: 9.944 | AX19: 10.301 | AY19: 12.037 | AZ19: 11.786 | BA19: 12.062 | BB19: 11.969
B20: 16 | C20: 1.057 | D20: 10.626 | E20: 10.368 | F20: 10.671 | G20: 10.705 | I20: 41 | J20: 10.666 | K20: 10.599 | L20: 10.466 | M20: 10.321 | N20: 10.466 | S20: 16 | T20: 3.6532833 | V20: 16 | W20: 11 | Y20: 16 | Z20: 6 | AB20: 16 | AC20: D | AD20: 3.239 | AE20: 3.239 | AF20: 3.241 | AK20: 16 | AL20: 11 | AN20: 16 | AO20: 11 | AT20: 16 | AU20: 10.025 | AV20: 1.018 | AW20: 10.218 | AX20: 1.004 | AY20: 12.091 | AZ20: 11.915 | BA20: 12.005 | BB20: 11.861
B21: 17 | C21: 10.727 | D21: 10.458 | E21: 9.706 | F21: 10.346 | G21: 10.604 | I21: 42 | J21: 10.555 | K21: 10.288 | L21: 10.466 | M21: 10.421 | N21: 10.266 | S21: 17 | T21: 3.3985718 | V21: 17 | W21: 5 | Y21: 17 | Z21: 13 | AB21: 17 | AC21: D | AD21: 3.241 | AE21: 3.242 | AF21: 3.241 | AK21: 17 | AL21: 8 | AN21: 17 | AO21: 7 | AT21: 17 | AU21: 10.082 | AV21: 10.245 | AW21: 9.965 | AX21: 10.063 | AY21: 11.618 | AZ21: 12.058 | BA21: 11.795 | BB21: 0.12
B22: 18 | C22: 10.705 | D22: 11.053 | E22: 10.548 | F22: 10.346 | G22: 9.886 | I22: 43 | J22: 10.232 | K22: 10.332 | L22: 10.377 | M22: 10.421 | N22: 10.266 | S22: 18 | T22: 3.4784714 | V22: 18 | W22: 7 | Y22: 18 | Z22: 5 | AB22: 18 | AC22: D | AD22: 3.238 | AE22: 3.239 | AF22: 0.324 | AK22: 18 | AL22: 5 | AN22: 18 | AO22: 9 | AT22: 18 | AU22: 10.304 | AV22: 9.798 | AW22: 10.145 | AX22: 10.342 | AY22: 0.121 | AZ22: 11.853 | BA22: 1.221 | BB22: 11.761
... B24: 20 | C24: 10.806 | D24: 10.772 | E24: 1.075 | F24: 10.503 | G24: 10.896 | I24: 45 | J24: 10.388 | K24: 10.421 | L24: 1.061 | M24: 10.221 | N24: 10.288 | S24: 20 | T24: 3.4005051 | V24: 20 | W24: 5 | Y24: 20 | Z24: 10 | AB24: 20 | AC24: D | AD24: 0.324 | AE24: 0.324 | AF24: 3.241 | AK24: 20 | AL24: 11 | AN24: 20 | AO24: 1 | AT24: 20 | AU24: 10.013 | AV24: 10.293 | AW24: 10.101 | AX24: 9.977 | AY24: 12.006 | AZ24: 11.744 | BA24: 11.583 | BB24: 12.022
B25: 21 | C25: 10.279 | D25: 10.716 | E25: 1.057 | F25: 10.705 | G25: 10.335 | I25: 46 | J25: 10.621 | K25: 10.288 | L25: 10.399 | M25: 10.466 | N25: 10.343 | S25: 21 | T25: 3.4304236 | V25: 21 | W25: 6 | Y25: 21 | Z25: 7 | AK25: 21 | AL25: 7 | AN25: 21 | AO25: 11
B26: 22 | C26: 1.075 | D26: 10.593 | E26: 10.402 | F26: 1.038 | G26: 9.886 | I26: 47 | J26: 10.677 | K26: 10.443 | L26: 10.588 | M26: 10.366 | N26: 10.421 | S26: 22 | T26: 3.5846108 | V26: 22 | W26: 15 | Y26: 22 | Z26: 8 | AK26: 22 | AL26: 14 | AN26: 22 | AO26: 7
B27: 23 | C27: 11.776 | D27: 10.469 | E27: 1095618.2 | F27: 1076273.7 | G27: 1079306 | I27: 48 | J27: 10.666 | K27: 10.366 | L27: 10.343 | M27: 1.021 | N27: 10.566 | S27: 23 | T27: 3.6765189 | V27: 23 | W27: 6 | Y27: 23 | Z27: 14 | AK27: 23 | AL27: 8 | AN27: 23 | AO27: 11
B28: 24 | C28: 10.705 | D28: 10.761 | E28: 10.436 | F28: 10.548 | G28: 9.897 | I28: 49 | J28: 1.041 | K28: 10.677 | L28: 10.321 | M28: 10.588 | N28: 10.499 | S28: 24 | T28: 3.5462192 | V28: 24 | W28: 12 | Y28: 24 | Z28: 7 | AK28: 24 | AL28: 12 | AN28: 24 | AO28: 1
B29: 25 | C29: 10.245 | D29: 10.525 | E29: 10.436 | F29: 10.525 | G29: 10.346 | I29: 50 | J29: 10.443 | K29: 1.031 | L29: 10.377 | M29: 10.688 | N29: 10.477 | S29: 25 | T29: 3.2133604 | V29: 25 | W29: 8 | Y29: 25 | Z29: 10 | AK29: 25 | AL29: 15 | AN29: 25 | AO29: 9
AN30: 26 | AO30: 9
AN31: 27 | AO31: 7
AN32: 28 | AO32: 6
AN33: 29 | AO33: 9
AN34: 30 | AO34: 7

Sheet Tabel Faktor
A1: n | B1: A | C1: A2 | D1: A3 | E1: c4 | F1: 1/c4 | G1: B3 | H1: B4 | I1: B5 | J1: B6 | K1: d2 | L1: 1/d2 | M1: d_3 | N1: D1 | O1: D2 | P1: D3 | Q1: D4
A2: 2 | B2: 2.121 | C2: 1.88 | D2: 2.659 | E2: 0.7979 | F2: 1.2533 | G2: 0 | H2: 3.267 | I2: 0 | J2: 2.606 | K2: 1.128 | L2: 0.8865 | M2: 0.853 | N2: 0 | O2: 3.686 | P2: 0 | Q2: 3.267
A3: 3 | B3: 1.732 | C3: 1.023 | D3: 1.954 | E3: 0.8862 | F3: 1.1284 | G3: 0 | H3: 2.568 | I3: 0 | J3: 2.276 | K3: 1.693 | L3: 0.5907 | M3: 0.888 | N3: 0 | O3: 4.358 | P3: 0 | Q3: 2.574
A4: 4 | B4: 1.5 | C4: 0.729 | D4: 1.628 | E4: 0.9213 | F4: 1.0854 | G4: 0 | H4: 2.266 | I4: 0 | J4: 2.088 | K4: 2.059 | L4: 0.4857 | M4: 0.88 | N4: 0 | O4: 4.698 | P4: 0 | Q4: 2.282
A5: 5 | B5: 1.342 | C5: 0.577 | D5: 1.427 | E5: 0.94 | F5: 1.0638 | G5: 0 | H5: 2.089 | I5: 0 | J5: 1.964 | K5: 2.326 | L5: 0.4299 | M5: 0.864 | N5: 0 | O5: 4.918 | P5: 0 | Q5: 2.114
A6: 6 | B6: 1.225 | C6: 0.483 | D6: 1.287 | E6: 0.9515 | F6: 1.051 | G6: 0.03 | H6: 1.97 | I6: 0.029 | J6: 1.874 | K6: 2.534 | L6: 0.3946 | M6: 0.848 | N6: 0 | O6: 5.078 | P6: 0 | Q6: 2.004
A7: 7 | B7: 1.134 | C7: 0.419 | D7: 1.182 | E7: 0.9594 | F7: 1.0423 | G7: 0.118 | H7: 1.882 | I7: 0.113 | J7: 1.806 | K7: 2.704 | L7: 0.3698 | M7: 0.833 | N7: 0.204 | O7: 5.204 | P7: 0.076 | Q7: 1.924
A8: 8 | B8: 1.061 | C8: 0.373 | D8: 1.099 | E8: 0.965 | F8: 1.0363 | G8: 0.185 | H8: 1.815 | I8: 0.179 | J8: 1.751 | K8: 2.847 | L8: 0.3512 | M8: 0.82 | N8: 0.388 | O8: 5.306 | P8: 0.136 | Q8: 1.864
A9: 9 | B9: 1 | C9: 0.337 | D9: 1.032 | E9: 0.9693 | F9: 1.0317 | G9: 0.239 | H9: 1.761 | I9: 0.232 | J9: 1.707 | K9: 2.97 | L9: 0.3367 | M9: 0.808 | N9: 0.547 | O9: 5.393 | P9: 0.184 | Q9: 1.816
A10: 10 | B10: 0.949 | C10: 0.308 | D10: 0.975 | E10: 0.9727 | F10: 1.0281 | G10: 0.284 | H10: 1.716 | I10: 0.276 | J10: 1.669 | K10: 3.078 | L10: 0.3249 | M10: 0.797 | N10: 0.687 | O10: 5.469 | P10: 0.223 | Q10: 1.777
A11: 11 | B11: 0.905 | C11: 0.285 | D11: 0.927 | E11: 0.9754 | F11: 1.0252 | G11: 0.321 | H11: 1.679 | I11: 0.313 | J11: 1.637 | K11: 3.173 | L11: 0.3152 | M11: 0.787 | N11: 0.811 | O11: 5.535 | P11: 0.256 | Q11: 1.744
A12: 12 | B12: 0.866 | C12: 0.266 | D12: 0.886 | E12: 0.9776 | F12: 1.0229 | G12: 0.354 | H12: 1.646 | I12: 0.346 | J12: 1.61 | K12: 3.258 | L12: 0.3069 | M12: 0.778 | N12: 0.922 | O12: 5.594 | P12: 0.283 | Q12: 1.717
A13: 13 | B13: 0.832 | C13: 0.249 | D13: 0.85 | E13: 0.9794 | F13: 1.021 | G13: 0.382 | H13: 1.618 | I13: 0.374 | J13: 1.585 | K13: 3.336 | L13: 0.2998 | M13: 0.77 | N13: 1.025 | O13: 5.647 | P13: 0.307 | Q13: 1.693
... A25: 25 | B25: 0.6 | C25: 0.153 | D25: 0.606 | E25: 0.9896 | F25: 1.0105 | G25: 0.565 | H25: 1.435 | I25: 0.559 | J25: 1.42 | K25: 3.931 | L25: 0.2544 | M25: 0.708 | N25: 1.806 | O25: 6.056 | P25: 0.459 | Q25: 1.541

Sheet Instruksi
B1: Instructions
B2: Worksheet specific notes
B4: Summary
B5: Lembar kerja ini dibuat untuk mengakomodasi pengolahan data PPST III 2025/2025 Modul 3 - Pengendalian Kualitas Secara Statistika. Seluruh data yang diperlukan tersedia pada lembar kerja ini.
B6: Keluaran dari lembar kerja ini adalah peta kendali, kurva OC, ARL, dan kapabilitas proses.
B8: Formatting guide
B10: Dalam lembar kerja ini, digunakan konvensi penulisan sebagai berikut.
B12: Cells | C12: Sel yang telah dikalkulasikan yang tidak boleh diubah secara manual
C13: Data mentah yang digunakan model
C14: Instruksi, catatan, atau informasi kontekstual lainnya
B16: Tabs | C16: Analysis sheets
C17: Raw data sheets

Sheet Pemilihan Peta Kendali
A1: Part | B1: Peta Kendali
A2: Pivot | E2: xbar-R atau xbar-s
A3: Bottom Base 2 | E3: MR
A4: Pan Assembly | E4: p atau np
A5: Tripod | E5: c
A6: Leg | E6: u
A7: Dokumen | E7: cusum atau EWMA
A8: XYZ 1 | E8: Short Production Run xbar-R
A9: XYZ 2 | E9: T^2

Sheet Peta Kendali xbar-R
B2: Part | C2: Pivot (Diameter Lubang Horizontal)
B3: Iterasi 1 | Q3: Iterasi 2
B4: Pemeriksaan Kondisi Abnormalitas Peta R | I4: Pemeriksaan Kondisi Abnormalitas Peta xbar | Q4: Pemeriksaan Kondisi Abnormalitas Peta R | X4: Pemeriksaan Kondisi Abnormalitas Peta xbar
B5: Run | I5: Run | Q5: Run | X5: Run
B6: Trend | I6: Trend | Q6: Trend | X6: Trend
B7: Pengulangan Secara Periodik | I7: Pengulangan Secara Periodik | Q7: Pengulangan Secara Periodik | X7: Pengulangan Secara Periodik
B8: Hugging pada garis tengah | I8: Hugging pada garis tengah | Q8: Hugging pada garis tengah | X8: Hugging pada garis tengah
B9: Hugging dekat garis batas kendali | I9: Hugging dekat garis batas kendali | Q9: Hugging dekat garis batas kendali | X9: Hugging dekat garis batas kendali
B27: Peta xbar-R | Q27: Peta xbar-R
B29: Parameter Peta Kendali | C29: m | D29: 50 | Q29: Parameter Peta Kendali | R29: m | S29: 46
C30: n | D30: 5 | R30: n | S30: 5
C31: xbarbar | D31: 10.491992 | R31: xbarbar | S31: 10.485874
C32: Rbar | D32: 0.46806 | R32: Rbar | S32: 0.40887
C33: BKA R | D33: 0.989479 | R33: BKA R | S33: 0.86435
C34: BKB R | D34: 0 | R34: BKB R | S34: 0
C35: BKA Xbar | D35: 10.762063 | R35: BKA Xbar | S35: 10.721792
C36: BKB Xbar | D36: 10.221921 | R36: BKB Xbar | S36: 10.249956
C37: A2 | D37: =INDEX('Tabel Faktor'!$A$1:$Q$25,MATCH(D30,'Tabel Faktor'!$A$1:$A$25,0),MATCH(C37,'Tabel Faktor'!$A$1:$Q$1,0)) -> 0.577 | R37: A2 | S37: {=D37:D39} -> 0.577
C38: D4 | D38: {=INDEX('Tabel Faktor'!$A$1:$Q$25,MATCH(D30,'Tabel Faktor'!$A$1:$A$25,0),MATCH(C38,'Tabel Faktor'!$A$1:$Q$1,0))} -> 2.114 | R38: D4 | S38: 2.114
C39: D3 | D39: {=INDEX('Tabel Faktor'!$A$1:$Q$25,MATCH(D30,'Tabel Faktor'!$A$1:$A$25,0),MATCH(C39,'Tabel Faktor'!$A$1:$Q$1,0))} -> 0 | R39: D3 | S39: 0
B41: Sample Number (i) | C41: Observasi | H41: Rata-rata (xi bar) | I41: Range (Ri) | J41: GT R | K41: BKA R | L41: BKB R | M41: GT xbar | N41: BKA xbar | O41: BKB xbar | Q41: Sample Number (i) | R41: Observasi | W41: Rata-rata (xi bar) | X41: Range (Ri) | Y41: GT R | Z41: BKA R | AA41: BKB R | AB41: GT xbar | AC41: BKA xbar | AD41: BKB xbar
B42: 1 | C42: 9.976 | D42: 10.694 | E42: 10.368 | F42: 10.503 | G42: 10.323 | H42: 10.3728 | I42: 0.718 | J42: 0.46806 | K42: 0.989479 | L42: 0 | M42: 10.491992 | N42: 10.762063 | O42: 10.221921 | Q42: 1 | R42: 9.976 | S42: 10.694 | T42: 10.368 | U42: 10.503 | V42: 10.323 | W42: 10.3728 | X42: 0.718 | Y42: 0.40887 | Z42: 0.86435 | AA42: 0 | AB42: 10.485874 | AC42: 10.721792 | AD42: 10.249956
B43: 2 | C43: 10.626 | D43: 10.424 | E43: 11.109 | F43: 10.57 | G43: 10.133 | H43: 10.5724 | I43: 0.976 | J43: 0.46806 | K43: 0.989479 | L43: 0 | M43: 10.491992 | N43: 10.762063 | O43: 10.221921 | Q43: 2 | R43: 10.626 | S43: 10.424 | T43: 11.109 | U43: 10.57 | V43: 10.133 | W43: 10.5724 | X43: 0.976 | Y43: 0.40887 | Z43: 0.86435 | AA43: 0 | AB43: 10.485874 | AC43: 10.721792 | AD43: 10.249956
B44: 3 | C44: 10.458 | D44: 10.548 | E44: 10.761 | F44: 10.301 | G44: 10.043 | H44: 10.4222 | I44: 0.718 | J44: 0.46806 | K44: 0.989479 | L44: 0 | M44: 10.491992 | N44: 10.762063 | O44: 10.221921 | Q44: 3 | R44: 10.458 | S44: 10.548 | T44: 10.761 | U44: 10.301 | V44: 10.043 | W44: 10.4222 | X44: 0.718 | Y44: 0.40887 | Z44: 0.86435 | AA44: 0 | AB44: 10.485874 | AC44: 10.721792 | AD44: 10.249956
B45: 4 | C45: 10.649 | D45: 10.727 | E45: 10.424 | F45: 10.604 | G45: 10.604 | H45: 10.6016 | I45: 0.303 | J45: 0.46806 | K45: 0.989479 | L45: 0 | M45: 10.491992 | N45: 10.762063 | O45: 10.221921 | Q45: 4 | R45: 10.649 | S45: 10.727 | T45: 10.424 | U45: 10.604 | V45: 10.604 | W45: 10.6016 | X45: 0.303 | Y45: 0.40887 | Z45: 0.86435 | AA45: 0 | AB45: 10.485874 | AC45: 10.721792 | AD45: 10.249956
B46: 5 | C46: 10.581 | D46: 10.918 | E46: 10.402 | F46: 10.481 | G46: 10.795 | H46: 10.6354 | I46: 0.516 | J46: 0.46806 | K46: 0.989479 | L46: 0 | M46: 10.491992 | N46: 10.762063 | O46: 10.221921 | Q46: 5 | R46: 10.581 | S46: 10.918 | T46: 10.402 | U46: 10.481 | V46: 10.795 | W46: 10.6354 | X46: 0.516 | Y46: 0.40887 | Z46: 0.86435 | AA46: 0 | AB46: 10.485874 | AC46: 10.721792 | AD46: 10.249956
B47: 6 | C47: 10.436 | D47: 10.503 | E47: 10.907 | F47: 10.458 | G47: 9.807 | H47: 10.4222 | I47: 1.1 | J47: 0.46806 | K47: 0.989479 | L47: 0 | M47: 10.491992 | N47: 10.762063 | O47: 10.221921 | Q47: 7 | R47: 10.682 | S47: 10.447 | T47: 10.323 | U47: 10.312 | V47: 10.806 | W47: 10.514 | X47: 0.494 | Y47: 0.40887 | Z47: 0.86435 | AA47: 0 | AB47: 10.485874 | AC47: 10.721792 | AD47: 10.249956
B48: 7 | C48: 10.682 | D48: 10.447 | E48: 10.323 | F48: 10.312 | G48: 10.806 | H48: 10.514 | I48: 0.494 | J48: 0.46806 | K48: 0.989479 | L48: 0 | M48: 10.491992 | N48: 10.762063 | O48: 10.221921 | Q48: 8 | R48: 10.357 | S48: 10.481 | T48: 10.447 | U48: 10.469 | V48: 10.638 | W48: 10.4784 | X48: 0.281 | Y48: 0.40887 | Z48: 0.86435 | AA48: 0 | AB48: 10.485874 | AC48: 10.721792 | AD48: 10.249956
B49: 8 | C49: 10.357 | D49: 10.481 | E49: 10.447 | F49: 10.469 | G49: 10.638 | H49: 10.4784 | I49: 0.281 | J49: 0.46806 | K49: 0.989479 | L49: 0 | M49: 10.491992 | N49: 10.762063 | O49: 10.221921 | Q49: 9 | R49: 10.682 | S49: 10.907 | T49: 10.402 | U49: 10.29 | V49: 10.581 | W49: 10.5724 | X49: 0.617 | Y49: 0.40887 | Z49: 0.86435 | AA49: 0 | AB49: 10.485874 | AC49: 10.721792 | AD49: 10.249956
B50: 9 | C50: 10.682 | D50: 10.907 | E50: 10.402 | F50: 10.29 | G50: 10.581 | H50: 10.5724 | I50: 0.617 | J50: 0.46806 | K50: 0.989479 | L50: 0 | M50: 10.491992 | N50: 10.762063 | O50: 10.221921 | Q50: 10 | R50: 10.525 | S50: 10.682 | T50: 10.581 | U50: 10.66 | V50: 10.817 | W50: 10.653 | X50: 0.292 | Y50: 0.40887 | Z50: 0.86435 | AA50: 0 | AB50: 10.485874 | AC50: 10.721792 | AD50: 10.249956
B51: 10 | C51: 10.525 | D51: 10.682 | E51: 10.581 | F51: 10.66 | G51: 10.817 | H51: 10.653 | I51: 0.292 | J51: 0.46806 | K51: 0.989479 | L51: 0 | M51: 10.491992 | N51: 10.762063 | O51: 10.221921 | Q51: 11 | R51: 10.795 | S51: 10.424 | T51: 10.638 | U51: 11.109 | V51: 11.109 | W51: 10.815 | X51: 0.685 | Y51: 0.40887 | Z51: 0.86435 | AA51: 0 | AB51: 10.485874 | AC51: 10.721792 | AD51: 10.249956
B52: 11 | C52: 10.795 | D52: 10.424 | E52: 10.638 | F52: 11.109 | G52: 11.109 | H52: 10.815 | I52: 0.685 | J52: 0.46806 | K52: 0.989479 | L52: 0 | M52: 10.491992 | N52: 10.762063 | O52: 10.221921 | Q52: 12 | R52: 10.581 | S52: 10.503 | T52: 10.436 | U52: 10.38 | V52: 10.952 | W52: 10.5704 | X52: 0.572 | Y52: 0.40887 | Z52: 0.86435 | AA52: 0 | AB52: 10.485874 | AC52: 10.721792 | AD52: 10.249956
B53: 12 | C53: 10.581 | D53: 10.503 | E53: 10.436 | F53: 10.38 | G53: 10.952 | H53: 10.5704 | I53: 0.572 | J53: 0.46806 | K53: 0.989479 | L53: 0 | M53: 10.491992 | N53: 10.762063 | O53: 10.221921 | Q53: 13 | R53: 10.705 | S53: 10.357 | T53: 10.357 | U53: 10.537 | V53: 10.514 | W53: 10.494 | X53: 0.348 | Y53: 0.40887 | Z53: 0.86435 | AA53: 0 | AB53: 10.485874 | AC53: 10.721792 | AD53: 10.249956
... B87: 46 | C87: 10.621 | D87: 10.288 | E87: 10.399 | F87: 10.466 | G87: 10.343 | H87: 10.4234 | I87: 0.333 | J87: 0.46806 | K87: 0.989479 | L87: 0 | M87: 10.491992 | N87: 10.762063 | O87: 10.221921 | Q87: 50 | R87: 10.443 | S87: 10.31 | T87: 10.377 | U87: 10.688 | V87: 10.477 | W87: 10.459 | X87: 0.378 | Y87: 0.40887 | Z87: 0.86435 | AA87: 0 | AB87: 10.485874 | AC87: 10.721792 | AD87: 10.249956
B88: 47 | C88: 10.677 | D88: 10.443 | E88: 10.588 | F88: 10.366 | G88: 10.421 | H88: 10.499 | I88: 0.311 | J88: 0.46806 | K88: 0.989479 | L88: 0 | M88: 10.491992 | N88: 10.762063 | O88: 10.221921
B89: 48 | C89: 10.666 | D89: 10.366 | E89: 10.343 | F89: 10.21 | G89: 10.566 | H89: 10.4302 | I89: 0.456 | J89: 0.46806 | K89: 0.989479 | L89: 0 | M89: 10.491992 | N89: 10.762063 | O89: 10.221921
B90: 49 | C90: 10.41 | D90: 10.677 | E90: 10.321 | F90: 10.588 | G90: 10.499 | H90: 10.499 | I90: 0.356 | J90: 0.46806 | K90: 0.989479 | L90: 0 | M90: 10.491992 | N90: 10.762063 | O90: 10.221921
B91: 50 | C91: 10.443 | D91: 10.31 | E91: 10.377 | F91: 10.688 | G91: 10.477 | H91: 10.459 | I91: 0.378 | J91: 0.46806 | K91: 0.989479 | L91: 0 | M91: 10.491992 | N91: 10.762063 | O91: 10.221921

Sheet Peta Kendali xbar-s
B2: Part | C2: Pivot (Diameter Lubang Horizontal) | R2: Part
B3: Iterasi 1 | R3: Iterasi 2
B4: Pemeriksaan Kondisi Abnormalitas Peta s | I4: Pemeriksaan Kondisi Abnormalitas Peta xbar | R4: Pemeriksaan Kondisi Abnormalitas Peta s | Y4: Pemeriksaan Kondisi Abnormalitas Peta xbar
B5: Run | I5: Run | R5: Run | Y5: Run
B6: Trend | I6: Trend | R6: Trend | Y6: Trend
B7: Pengulangan Secara Periodik | I7: Pengulangan Secara Periodik | R7: Pengulangan Secara Periodik | Y7: Pengulangan Secara Periodik
B8: Hugging pada garis tengah | I8: Hugging pada garis tengah | R8: Hugging pada garis tengah | Y8: Hugging pada garis tengah
B9: Hugging dekat garis batas kendali | I9: Hugging dekat garis batas kendali | R9: Hugging dekat garis batas kendali | Y9: Hugging dekat garis batas kendali
B27: Peta xbar-s | R27: Peta xbar-s
B29: Parameter Peta Kendali | C29: m | D29: 50 | R29: Parameter Peta Kendali | S29: 46
C30: n | D30: 5 | S30: 5
C31: xbarbar | D31: 10.491992 | S31: 10.485874
C32: sbar | D32: 0.184341 | S32: 0.163024
C33: BKA s | D33: 0.385088 | S33: 0.340556
C34: BKB s | D34: 0 | S34: 0
C35: BKA Xbar | D35: 10.755046 | S35: 10.718509
C36: BKB Xbar | D36: 10.228938 | S36: 10.253239
C37: A3 | D37: =INDEX('Tabel Faktor'!$A$1:$Q$25,MATCH(D30,'Tabel Faktor'!$A$1:$A$25,0),MATCH(C37,'Tabel Faktor'!$A$1:$Q$1,0)) -> 1.427 | S37: A3 | T37: 1.427
C38: B4 | D38: {=INDEX('Tabel Faktor'!$A$1:$Q$25,MATCH(D30,'Tabel Faktor'!$A$1:$A$25,0),MATCH(C38,'Tabel Faktor'!$A$1:$Q$1,0))} -> 2.089 | S38: B4 | T38: 2.089
C39: B3 | D39: {=INDEX('Tabel Faktor'!$A$1:$Q$25,MATCH(D30,'Tabel Faktor'!$A$1:$A$25,0),MATCH(C39,'Tabel Faktor'!$A$1:$Q$1,0))} -> 0 | S39: B3 | T39: 0
B41: Sample Number (i) | C41: Observasi | H41: Rata-rata (xi bar) | I41: Standar Deviasi (si) | J41: GT s | K41: BKA s | L41: BKB s | M41: GT xbar | N41: BKA xbar | O41: BKB xbar | R41: Sample Number (i) | S41: Observasi | X41: Rata-rata (xi bar) | Y41: Standar Deviasi (si) | Z41: GT s | AA41: BKA s | AB41: BKB s | AC41: GT xbar | AD41: BKA xbar | AE41: BKB xbar
B42: 1 | C42: 9.976 | D42: 10.694 | E42: 10.368 | F42: 10.503 | G42: 10.323 | H42: 10.3728 | I42: 0.26461 | J42: 0.184341 | K42: 0.385088 | L42: 0 | M42: 10.491992 | N42: 10.755046 | O42: 10.228938 | Q42: 1 | R42: 9.976 | S42: 10.694 | T42: 10.368 | U42: 10.503 | V42: 10.323 | W42: 10.3728 | X42: 0.26461 | Y42: 0.163024 | Z42: 0.340556 | AA42: 0 | AB42: 10.485874 | AC42: 10.718509 | AD42: 10.253239 | AE42: =$T$36 -> 0
B43: 2 | C43: 10.626 | D43: 10.424 | E43: 11.109 | F43: 10.57 | G43: 10.133 | H43: 10.5724 | I43: 0.355638 | J43: 0.184341 | K43: 0.385088 | L43: 0 | M43: 10.491992 | N43: 10.755046 | O43: 10.228938 | Q43: 2 | R43: 10.626 | S43: 10.424 | T43: 11.109 | U43: 10.57 | V43: 10.133 | W43: 10.5724 | X43: 0.355638 | Y43: 0.163024 | Z43: 0.340556 | AA43: 0 | AB43: 10.485874 | AC43: 10.718509 | AD43: 10.253239 | AE43: =$T$36 -> 0
B44: 3 | C44: 10.458 | D44: 10.548 | E44: 10.761 | F44: 10.301 | G44: 10.043 | H44: 10.4222 | I44: 0.269432 | J44: 0.184341 | K44: 0.385088 | L44: 0 | M44: 10.491992 | N44: 10.755046 | O44: 10.228938 | Q44: 3 | R44: 10.458 | S44: 10.548 | T44: 10.761 | U44: 10.301 | V44: 10.043 | W44: 10.4222 | X44: 0.269432 | Y44: 0.163024 | Z44: 0.340556 | AA44: 0 | AB44: 10.485874 | AC44: 10.718509 | AD44: 10.253239 | AE44: =$T$36 -> 0
B45: 4 | C45: 10.649 | D45: 10.727 | E45: 10.424 | F45: 10.604 | G45: 10.604 | H45: 10.6016 | I45: 0.111271 | J45: 0.184341 | K45: 0.385088 | L45: 0 | M45: 10.491992 | N45: 10.755046 | O45: 10.228938 | Q45: 4 | R45: 10.649 | S45: 10.727 | T45: 10.424 | U45: 10.604 | V45: 10.604 | W45: 10.6016 | X45: 0.111271 | Y45: 0.163024 | Z45: 0.340556 | AA45: 0 | AB45: 10.485874 | AC45: 10.718509 | AD45: 10.253239 | AE45: =$T$36 -> 0
B46: 5 | C46: 10.581 | D46: 10.918 | E46: 10.402 | F46: 10.481 | G46: 10.795 | H46: 10.6354 | I46: 0.215991 | J46: 0.184341 | K46: 0.385088 | L46: 0 | M46: 10.491992 | N46: 10.755046 | O46: 10.228938 | Q46: 5 | R46: 10.581 | S46: 10.918 | T46: 10.402 | U46: 10.481 | V46: 10.795 | W46: 10.6354 | X46: 0.215991 | Y46: 0.163024 | Z46: 0.340556 | AA46: 0 | AB46: 10.485874 | AC46: 10.718509 | AD46: 10.253239 | AE46: =$T$36 -> 0
B47: 6 | C47: 10.436 | D47: 10.503 | E47: 10.907 | F47: 10.458 | G47: 9.807 | H47: 10.4222 | I47: 0.394177 | J47: 0.184341 | K47: 0.385088 | L47: 0 | M47: 10.491992 | N47: 10.755046 | O47: 10.228938 | Q47: 7 | R47: 10.682 | S47: 10.447 | T47: 10.323 | U47: 10.312 | V47: 10.806 | W47: 10.514 | X47: 0.220942 | Y47: 0.163024 | Z47: 0.340556 | AA47: 0 | AB47: 10.485874 | AC47: 10.718509 | AD47: 10.253239 | AE47: =$T$36 -> 0
B48: 7 | C48: 10.682 | D48: 10.447 | E48: 10.323 | F48: 10.312 | G48: 10.806 | H48: 10.514 | I48: 0.220942 | J48: 0.184341 | K48: 0.385088 | L48: 0 | M48: 10.491992 | N48: 10.755046 | O48: 10.228938 | Q48: 8 | R48: 10.357 | S48: 10.481 | T48: 10.447 | U48: 10.469 | V48: 10.638 | W48: 10.4784 | X48: 0.101601 | Y48: 0.163024 | Z48: 0.340556 | AA48: 0 | AB48: 10.485874 | AC48: 10.718509 | AD48: 10.253239 | AE48: =$T$36 -> 0
B49: 8 | C49: 10.357 | D49: 10.481 | E49: 10.447 | F49: 10.469 | G49: 10.638 | H49: 10.4784 | I49: 0.101601 | J49: 0.184341 | K49: 0.385088 | L49: 0 | M49: 10.491992 | N49: 10.755046 | O49: 10.228938 | Q49: 9 | R49: 10.682 | S49: 10.907 | T49: 10.402 | U49: 10.29 | V49: 10.581 | W49: 10.5724 | X49: 0.241262 | Y49: 0.163024 | Z49: 0.340556 | AA49: 0 | AB49: 10.485874 | AC49: 10.718509 | AD49: 10.253239 | AE49: =$T$36 -> 0
B50: 9 | C50: 10.682 | D50: 10.907 | E50: 10.402 | F50: 10.29 | G50: 10.581 | H50: 10.5724 | I50: 0.241262 | J50: 0.184341 | K50: 0.385088 | L50: 0 | M50: 10.491992 | N50: 10.755046 | O50: 10.228938 | Q50: 10 | R50: 10.525 | S50: 10.682 | T50: 10.581 | U50: 10.66 | V50: 10.817 | W50: 10.653 | X50: 0.111079 | Y50: 0.163024 | Z50: 0.340556 | AA50: 0 | AB50: 10.485874 | AC50: 10.718509 | AD50: 10.253239 | AE50: =$T$36 -> 0
B51: 10 | C51: 10.525 | D51: 10.682 | E51: 10.581 | F51: 10.66 | G51: 10.817 | H51: 10.653 | I51: 0.111079 | J51: 0.184341 | K51: 0.385088 | L51: 0 | M51: 10.491992 | N51: 10.755046 | O51: 10.228938 | Q51: 11 | R51: 10.795 | S51: 10.424 | T51: 10.638 | U51: 11.109 | V51: 11.109 | W51: 10.815 | X51: 0.298949 | Y51: 0.163024 | Z51: 0.340556 | AA51: 0 | AB51: 10.485874 | AC51: 10.718509 | AD51: 10.253239 | AE51: =$T$36 -> 0
B52: 11 | C52: 10.795 | D52: 10.424 | E52: 10.638 | F52: 11.109 | G52: 11.109 | H52: 10.815 | I52: 0.298949 | J52: 0.184341 | K52: 0.385088 | L52: 0 | M52: 10.491992 | N52: 10.755046 | O52: 10.228938 | Q52: 12 | R52: 10.581 | S52: 10.503 | T52: 10.436 | U52: 10.38 | V52: 10.952 | W52: 10.5704 | X52: 0.226158 | Y52: 0.163024 | Z52: 0.340556 | AA52: 0 | AB52: 10.485874 | AC52: 10.718509 | AD52: 10.253239 | AE52: =$T$36 -> 0
B53: 12 | C53: 10.581 | D53: 10.503 | E53: 10.436 | F53: 10.38 | G53: 10.952 | H53: 10.5704 | I53: 0.226158 | J53: 0.184341 | K53: 0.385088 | L53: 0 | M53: 10.491992 | N53: 10.755046 | O53: 10.228938 | Q53: 13 | R53: 10.705 | S53: 10.357 | T53: 10.357 | U53: 10.537 | V53: 10.514 | W53: 10.494 | X53: 0.145179 | Y53: 0.163024 | Z53: 0.340556 | AA53: 0 | AB53: 10.485874 | AC53: 10.718509 | AD53: 10.253239 | AE53: =$T$36 -> 0
... B65: 24 | C65: 10.705 | D65: 10.761 | E65: 10.436 | F65: 10.548 | G65: 9.897 | H65: 10.4694 | I65: 0.344773 | J65: 0.184341 | K65: 0.385088 | L65: 0 | M65: 10.491992 | N65: 10.755046 | O65: 10.228938 | Q65: 28 | R65: 10.532 | S65: 10.643 | T65: 10.221 | U65: 10.21 | V65: 10.41 | W65: 10.4032 | X65: 0.190173 | Y65: 0.163024 | Z65: 0.340556 | AA65: 0 | AB65: 10.485874 | AC65: 10.718509 | AD65: 10.253239 | AE65: =$T$36 -> 0
B66: 25 | C66: 10.245 | D66: 10.525 | E66: 10.436 | F66: 10.525 | G66: 10.346 | H66: 10.4154 | I66: 0.120728 | J66: 0.184341 | K66: 0.385088 | L66: 0 | M66: 10.491992 | N66: 10.755046 | O66: 10.228938 | Q66: 29 | R66: 10.466 | S66: 10.266 | T66: 10.243 | U66: 10.366 | V66: 10.41 | W66: 10.3502 | X66: 0.094627 | Y66: 0.163024 | Z66: 0.340556 | AA66: 0 | AB66: 10.485874 | AC66: 10.718509 | AD66: 10.253239
B67: 26 | C67: 10.477 | D67: 10.499 | E67: 10.577 | F67: 10.654 | G67: 10.455 | H67: 10.5324 | I67: 0.082084 | J67: 0.184341 | K67: 0.385088 | L67: 0 | M67: 10.491992 | N67: 10.755046 | O67: 10.228938 | Q67: 30 | R67: 10.666 | S67: 10.532 | T67: 10.399 | U67: 10.477 | V67: 10.388 | W67: 10.4924 | X67: 0.11354 | Y67: 0.163024 | Z67: 0.340556 | AA67: 0 | AB67: 10.485874 | AC67: 10.718509 | AD67: 10.253239
B68: 27 | C68: 10.299 | D68: 10.321 | E68: 10.343 | F68: 10.266 | G68: 10.543 | H68: 10.3544 | I68: 0.109201 | J68: 0.184341 | K68: 0.385088 | L68: 0 | M68: 10.491992 | N68: 10.755046 | O68: 10.228938 | Q68: 31 | R68: 10.343 | S68: 10.588 | T68: 10.277 | U68: 10.388 | V68: 10.399 | W68: 10.399 | X68: 0.116041 | Y68: 0.163024 | Z68: 0.340556 | AA68: 0 | AB68: 10.485874 | AC68: 10.718509 | AD68: 10.253239
B69: 28 | C69: 10.532 | D69: 10.643 | E69: 10.221 | F69: 10.21 | G69: 10.41 | H69: 10.4032 | I69: 0.190173 | J69: 0.184341 | K69: 0.385088 | L69: 0 | M69: 10.491992 | N69: 10.755046 | O69: 10.228938 | Q69: 32 | R69: 10.51 | S69: 10.421 | T69: 10.221 | U69: 10.555 | V69: 10.555 | W69: 10.4524 | X69: 0.140449 | Y69: 0.163024 | Z69: 0.340556 | AA69: 0 | AB69: 10.485874 | AC69: 10.718509 | AD69: 10.253239
B70: 29 | C70: 10.466 | D70: 10.266 | E70: 10.243 | F70: 10.366 | G70: 10.41 | H70: 10.3502 | I70: 0.094627 | J70: 0.184341 | K70: 0.385088 | L70: 0 | M70: 10.491992 | N70: 10.755046 | O70: 10.228938 | Q70: 33 | R70: 10.232 | S70: 10.477 | T70: 10.41 | U70: 10.543 | V70: 10.532 | W70: 10.4388 | X70: 0.127081 | Y70: 0.163024 | Z70: 0.340556 | AA70: 0 | AB70: 10.485874 | AC70: 10.718509 | AD70: 10.253239
B71: 30 | C71: 10.666 | D71: 10.532 | E71: 10.399 | F71: 10.477 | G71: 10.388 | H71: 10.4924 | I71: 0.11354 | J71: 0.184341 | K71: 0.385088 | L71: 0 | M71: 10.491992 | N71: 10.755046 | O71: 10.228938 | Q71: 34 | R71: 10.566 | S71: 10.332 | T71: 10.332 | U71: 10.332 | V71: 10.632 | W71: 10.4388 | X71: 0.148092 | Y71: 0.163024 | Z71: 0.340556 | AA71: 0 | AB71: 10.485874 | AC71: 10.718509 | AD71: 10.253239
...

Sheet OC Curve ARL xbar-R
B2: Pivot - Diameter Lubang Horizontal (mm)
B4: OC Curve dan ARL
B6: Parameter kurva OC | C6: R | D6: 0.40887
C7: d2 | D7: =INDEX('Tabel Faktor'!$A$1:$Q$25,MATCH(D10,'Tabel Faktor'!$A$1:$A$25,0),MATCH(C7,'Tabel Faktor'!$A$1:$Q$1,0)) -> 2.326
C8: sigma | D8: =D6/D7 -> 0.17578246
C9: L | D9: 3
C10: n | D10: 5
B12: ksigma | C12: k | D12: Beta | E12: ARL
B13: 0 | C13: =B13/$D$8 -> 0 | D13: =_xlfn.NORM.S.DIST($D$9-C13*SQRT($D$10),TRUE())-_xlfn.NORM.S.DIST(-$D$9-C13*SQRT($D$10),TRUE()) -> 0.9973002 | E13: =1/(1-D13) -> 370.39835
B14: 0.01 | C14: =B14/$D$8 -> 0.056888498 | D14: =_xlfn.NORM.S.DIST($D$9-C14*SQRT($D$10),TRUE())-_xlfn.NORM.S.DIST(-$D$9-C14*SQRT($D$10),TRUE()) -> 0.99708332 | E14: =1/(1-D14) -> 342.85562
B15: 0.02 | C15: =B15/$D$8 -> 0.113777 | D15: =_xlfn.NORM.S.DIST($D$9-C15*SQRT($D$10),TRUE())-_xlfn.NORM.S.DIST(-$D$9-C15*SQRT($D$10),TRUE()) -> 0.99641173 | E15: =1/(1-D15) -> 278.6856
B16: 0.03 | C16: =B16/$D$8 -> 0.17066549 | D16: =_xlfn.NORM.S.DIST($D$9-C16*SQRT($D$10),TRUE())-_xlfn.NORM.S.DIST(-$D$9-C16*SQRT($D$10),TRUE()) -> 0.99522229 | E16: =1/(1-D16) -> 209.30518
B17: 0.04 | C17: =B17/$D$8 -> 0.22755399 | D17: =_xlfn.NORM.S.DIST($D$9-C17*SQRT($D$10),TRUE())-_xlfn.NORM.S.DIST(-$D$9-C17*SQRT($D$10),TRUE()) -> 0.99340886 | E17: =1/(1-D17) -> 151.71893
B18: 0.05 | C18: =B18/$D$8 -> 0.28444249 | D18: =_xlfn.NORM.S.DIST($D$9-C18*SQRT($D$10),TRUE())-_xlfn.NORM.S.DIST(-$D$9-C18*SQRT($D$10),TRUE()) -> 0.99082136 | E18: =1/(1-D18) -> 108.94861
B19: 0.06 | C19: =B19/$D$8 -> 0.34133099 | D19: =_xlfn.NORM.S.DIST($D$9-C19*SQRT($D$10),TRUE())-_xlfn.NORM.S.DIST(-$D$9-C19*SQRT($D$10),TRUE()) -> 0.98726514 | E19: =1/(1-D19) -> 78.524647
B20: 0.07 | C20: =B20/$D$8 -> 0.39821948 | D20: =_xlfn.NORM.S.DIST($D$9-C20*SQRT($D$10),TRUE())-_xlfn.NORM.S.DIST(-$D$9-C20*SQRT($D$10),TRUE()) -> 0.98250158 | E20: =1/(1-D20) -> 57.148023
B21: 0.08 | C21: =B21/$D$8 -> 0.45510798 | D21: =_xlfn.NORM.S.DIST($D$9-C21*SQRT($D$10),TRUE())-_xlfn.NORM.S.DIST(-$D$9-C21*SQRT($D$10),TRUE()) -> 0.97625044 | E21: =1/(1-D21) -> 42.106035
B22: 0.09 | C22: =B22/$D$8 -> 0.51199648 | D22: =_xlfn.NORM.S.DIST($D$9-C22*SQRT($D$10),TRUE())-_xlfn.NORM.S.DIST(-$D$9-C22*SQRT($D$10),TRUE()) -> 0.96819496 | E22: =1/(1-D22) -> 31.441554
B23: 0.1 | C23: =B23/$D$8 -> 0.56888498 | D23: =_xlfn.NORM.S.DIST($D$9-C23*SQRT($D$10),TRUE())-_xlfn.NORM.S.DIST(-$D$9-C23*SQRT($D$10),TRUE()) -> 0.95799033 | E23: =1/(1-D23) -> 23.804046
B24: 0.11 | C24: =B24/$D$8 -> 0.62577347 | D24: =_xlfn.NORM.S.DIST($D$9-C24*SQRT($D$10),TRUE())-_xlfn.NORM.S.DIST(-$D$9-C24*SQRT($D$10),TRUE()) -> 0.94527598 | E24: =1/(1-D24) -> 18.273511
... B57: 1 | C57: =B57/$D$8 -> 5.6888498 | D57: =_xlfn.NORM.S.DIST($D$9-C57*SQRT($D$10),TRUE())-_xlfn.NORM.S.DIST(-$D$9-C57*SQRT($D$10),TRUE()) -> 1.2309661e-22 | E57: =1/(1-D57) -> 1

Sheet Kapabilitas Proses xbar-R
B2: Pivot - Diameter Lubang Horizontal (mm)
B3: Cp=1.3161, Cpk=0.6908, %Cacat=1.9111%. Proses capable (Cp>1) namun tidak centered.
B19: Kapabilitas Proses
B21: Parameter Proses | C21: Mean | D21: 10.485874
C22: R | D22: 0.40887
C23: n | D23: 5
C24: d2 | D24: {=INDEX('Tabel Faktor'!$A$1:$Q$25,MATCH(D23,'Tabel Faktor'!$A$1:$A$25,0),MATCH(C24,'Tabel Faktor'!$A$1:$Q$1,0))} -> 2.326
C25: sigma | D25: =D22/D24 -> 0.17578246
B26: Spesifikasi | C26: USL | D26: 12
C27: LSL | D27: 10
C28: Sigma | D28: =(D29-D27)/3 -> 0.33333333
C29: Mean | D29: =AVERAGE(D26:D27) -> 11
B30: Kapabilitas Proses | C30: Cp | D30: =(D26-D27)/(6*D25) -> 1.8962833
C31: Cpl | D31: =(D21-D27)/(3*D25) -> 0.92135473
C32: Cpu | D32: =(D26-D21)/(3*D25) -> 2.8712118
C33: Cpk | D33: =MIN(D31:D32) -> 0.92135473
C34: Persentase Cacat | D34: =1-(_xlfn.NORM.DIST(D26,D21,D25,TRUE())-_xlfn.NORM.DIST(D27,D21,D25,TRUE())) -> 0.0028543154
B35: z | C35: x proses | D35: f(x) proses | E35: x spesifikasi | F35: f(x) spesifikasi | G35: USL | H35: LSL
B36: -3 | C36: =$D$21+B36*$D$25 -> 9.9585266 | D36: =_xlfn.NORM.DIST($D$21+B36*$D$25,$D$21,$D$25,FALSE()) -> 0.02521212 | E36: =$D$29+B36*$D$28 -> 10 | F36: =_xlfn.NORM.DIST(E36,$D$29,$D$28,TRUE()) -> 0.001349898 | G36: =$D$26 -> 12 | H36: =$D$27 -> 10
B37: =B36+0.03 -> -2.97 | C37: =$D$21+B37*$D$25 -> 9.9638001 | D37: =_xlfn.NORM.DIST($D$21+B37*$D$25,$D$21,$D$25,FALSE()) -> 0.027574042 | E37: =$D$29+B37*$D$28 -> 10.01 | F37: =_xlfn.NORM.DIST(E37,$D$29,$D$28,TRUE()) -> 0.0014889987 | G37: =$D$26 -> 12 | H37: =$D$27 -> 10
B38: =B37+0.03 -> -2.94 | C38: =$D$21+B38*$D$25 -> 9.9690736 | D38: =_xlfn.NORM.DIST($D$21+B38*$D$25,$D$21,$D$25,FALSE()) -> 0.030130105 | E38: =$D$29+B38*$D$28 -> 10.02 | F38: =_xlfn.NORM.DIST(E38,$D$29,$D$28,TRUE()) -> 0.0016410612 | G38: =$D$26 -> 12 | H38: =$D$27 -> 10
B39: =B38+0.03 -> -2.91 | C39: =$D$21+B39*$D$25 -> 9.974347 | D39: =_xlfn.NORM.DIST($D$21+B39*$D$25,$D$21,$D$25,FALSE()) -> 0.032893492 | E39: =$D$29+B39*$D$28 -> 10.03 | F39: =_xlfn.NORM.DIST(E39,$D$29,$D$28,TRUE()) -> 0.0018071438 | G39: =$D$26 -> 12 | H39: =$D$27 -> 10
B40: =B39+0.03 -> -2.88 | C40: =$D$21+B40*$D$25 -> 9.9796205 | D40: =_xlfn.NORM.DIST($D$21+B40*$D$25,$D$21,$D$25,FALSE()) -> 0.035878019 | E40: =$D$29+B40*$D$28 -> 10.04 | F40: =_xlfn.NORM.DIST(E40,$D$29,$D$28,TRUE()) -> 0.0019883759 | G40: =$D$26 -> 12 | H40: =$D$27 -> 10
B41: =B40+0.03 -> -2.85 | C41: =$D$21+B41*$D$25 -> 9.984894 | D41: =_xlfn.NORM.DIST($D$21+B41*$D$25,$D$21,$D$25,FALSE()) -> 0.039098137 | E41: =$D$29+B41*$D$28 -> 10.05 | F41: =_xlfn.NORM.DIST(E41,$D$29,$D$28,TRUE()) -> 0.0021859615 | G41: =$D$26 -> 12 | H41: =$D$27 -> 10
B42: =B41+0.03 -> -2.82 | C42: =$D$21+B42*$D$25 -> 9.9901675 | D42: =_xlfn.NORM.DIST($D$21+B42*$D$25,$D$21,$D$25,FALSE()) -> 0.042568938 | E42: =$D$29+B42*$D$28 -> 10.06 | F42: =_xlfn.NORM.DIST(E42,$D$29,$D$28,TRUE()) -> 0.0024011825 | G42: =$D$26 -> 12 | H42: =$D$27 -> 10
B43: =B42+0.03 -> -2.79 | C43: =$D$21+B43*$D$25 -> 9.9954409 | D43: =_xlfn.NORM.DIST($D$21+B43*$D$25,$D$21,$D$25,FALSE()) -> 0.046306152 | E43: =$D$29+B43*$D$28 -> 10.07 | F43: =_xlfn.NORM.DIST(E43,$D$29,$D$28,TRUE()) -> 0.0026354021 | G43: =$D$26 -> 12 | H43: =$D$27 -> 10
B44: =B43+0.03 -> -2.76 | C44: =$D$21+B44*$D$25 -> 10.000714 | D44: =_xlfn.NORM.DIST($D$21+B44*$D$25,$D$21,$D$25,FALSE()) -> 0.05032615 | E44: =$D$29+B44*$D$28 -> 10.08 | F44: =_xlfn.NORM.DIST(E44,$D$29,$D$28,TRUE()) -> 0.0028900681 | G44: =$D$26 -> 12 | H44: =$D$27 -> 10
B45: =B44+0.03 -> -2.73 | C45: =$D$21+B45*$D$25 -> 10.005988 | D45: =_xlfn.NORM.DIST($D$21+B45*$D$25,$D$21,$D$25,FALSE()) -> 0.054645935 | E45: =$D$29+B45*$D$28 -> 10.09 | F45: =_xlfn.NORM.DIST(E45,$D$29,$D$28,TRUE()) -> 0.0031667163 | G45: =$D$26 -> 12 | H45: =$D$27 -> 10
B46: =B45+0.03 -> -2.7 | C46: =$D$21+B46*$D$25 -> 10.011261 | D46: =_xlfn.NORM.DIST($D$21+B46*$D$25,$D$21,$D$25,FALSE()) -> 0.059283132 | E46: =$D$29+B46*$D$28 -> 10.1 | F46: =_xlfn.NORM.DIST(E46,$D$29,$D$28,TRUE()) -> 0.0034669738 | G46: =$D$26 -> 12 | H46: =$D$27 -> 10
B47: =B46+0.03 -> -2.67 | C47: =$D$21+B47*$D$25 -> 10.016535 | D47: =_xlfn.NORM.DIST($D$21+B47*$D$25,$D$21,$D$25,FALSE()) -> 0.064255982 | E47: =$D$29+B47*$D$28 -> 10.11 | F47: =_xlfn.NORM.DIST(E47,$D$29,$D$28,TRUE()) -> 0.0037925623 | G47: =$D$26 -> 12 | H47: =$D$27 -> 10
B48: =B47+0.03 -> -2.64 | C48: =$D$21+B48*$D$25 -> 10.021808 | D48: =_xlfn.NORM.DIST($D$21+B48*$D$25,$D$21,$D$25,FALSE()) -> 0.069583316 | E48: =$D$29+B48*$D$28 -> 10.12 | F48: =_xlfn.NORM.DIST(E48,$D$29,$D$28,TRUE()) -> 0.0041453014 | G48: =$D$26 -> 12 | H48: =$D$27 -> 10
... B236: =B235+0.03 -> 3 | C236: =$D$21+B236*$D$25 -> 11.013221 | D236: =_xlfn.NORM.DIST($D$21+B236*$D$25,$D$21,$D$25,FALSE()) -> 0.02521212 | E236: =$D$29+B236*$D$28 -> 12 | F236: =_xlfn.NORM.DIST(E236,$D$29,$D$28,TRUE()) -> 0.9986501 | G236: =$D$26 -> 12 | H236: =$D$27 -> 10

Sheet Implementasi xbar-R
B2: Pivot - Implementasi Fase II (Samples 26-50, xbar-S chart)
B3: Kesimpulan
B5: xbarbar | C5: 10.485874
B6: sbar | C6: 0.163024
B7: sigma | C7: 0.173429
B8: BKA s | C8: 0.340556
B9: BKB s | C9: 0
B10: BKA xbar | C10: 10.718509
B11: BKB xbar | C11: 10.253239
B13: Sample | C13: Obs1 | D13: Obs2 | E13: Obs3 | F13: Obs4 | G13: Obs5 | H13: xbar_i | I13: s_i | J13: Status x | K13: Status s
B14: 26 | C14: 10.477 | D14: 10.499 | E14: 10.577 | F14: 10.654 | G14: 10.455 | H14: 10.5324 | I14: 0.082084 | J14: In Control | K14: In Control
B15: 27 | C15: 10.299 | D15: 10.321 | E15: 10.343 | F15: 10.266 | G15: 10.543 | H15: 10.3544 | I15: 0.109201 | J15: In Control | K15: In Control
B16: 28 | C16: 10.532 | D16: 10.643 | E16: 10.221 | F16: 10.21 | G16: 10.41 | H16: 10.4032 | I16: 0.190173 | J16: In Control | K16: In Control
B17: 29 | C17: 10.466 | D17: 10.266 | E17: 10.243 | F17: 10.366 | G17: 10.41 | H17: 10.3502 | I17: 0.094627 | J17: In Control | K17: In Control
B18: 30 | C18: 10.666 | D18: 10.532 | E18: 10.399 | F18: 10.477 | G18: 10.388 | H18: 10.4924 | I18: 0.11354 | J18: In Control | K18: In Control
B19: 31 | C19: 10.343 | D19: 10.588 | E19: 10.277 | F19: 10.388 | G19: 10.399 | H19: 10.399 | I19: 0.116041 | J19: In Control | K19: In Control
B20: 32 | C20: 10.51 | D20: 10.421 | E20: 10.221 | F20: 10.555 | G20: 10.555 | H20: 10.4524 | I20: 0.140449 | J20: In Control | K20: In Control
B21: 33
B23: 35 | C23: 10.343 | D23: 10.455 | E23: 10.588 | F23: 10.41 | G23: 10.21 | H23: 10.4012 | I23: 0.139473 | J23: In Control | K23: In Control
C24: 10.432 | D24: 10.577 | E24: 10.255 | F24: 10.421 | G24: 10.477 | H24: 10.4324 | I24: 0.116725 | J24: In Control | K24: In Control
C25: 10.455 | D25: 10.61 | E25: 10.654 | F25: 10.477 | G25: 10.399 | H25: 10.519 | I25: 0.108127 | J25: In Control | K25: In Control
C26: 10.455 | D26: 10.455 | E26: 10.432 | F26: 10.299 | G26: 10.232 | H26: 10.3746 | I26: 0.102802 | J26: In Control | K26: In Control
C27: 10.588 | D27: 10.677 | E27: 10.232 | F27: 10.51 | G27: 10.632 | H27: 10.5278 | I27: 0.176463 | J27: In Control | K27: In Control
C28: 10.399 | D28: 10.443 | E28: 10.532 | F28: 10.61 | G28: 10.266 | H28: 10.45 | I28: 0.131177 | J28: In Control | K28: In Control
C29: 10.666 | D29: 10.599 | E29: 10.466 | F29: 10.321 | G29: 10.466 | H29: 10.5036 | I29: 0.133833 | J29: In Control | K29: In Control
C30: 10.555 | D30: 10.288 | E30: 10.466 | F30: 10.421 | G30: 10.266 | H30: 10.3992 | I30: 0.121777 | J30: In Control | K30: In Control
B31: 43 | C31: 10.232 | D31: 10.332 | E31: 10.377 | F31: 10.421 | G31: 10.266 | H31: 10.3256 | I31: 0.077616 | J31: In Control | K31: In Control
B32: 44 | C32: 10.688 | H32: 10.5592 | I32: 0.098728 | J32: In Control | K32: In Control | L32: BKB R | M32: GT xbar | N32: BKA xbar | O32: BKB xbar
B33: 45 | C33: 10.388 | D33: 10.421 | E33: 10.61 | F33: 10.221 | G33: 10.288 | H33: 10.3856 | I33: 0.14852 | J33: In Control | K33: In Control | L33: =$D$28 -> 10.443 | M33: =$D$25 -> 10.61 | N33: =$D$29 -> 10.599 | O33: =$D$30 -> 10.288
B34: 46 | C34: 10.621 | D34: 10.288 | E34: 10.399 | F34: 10.466 | G34: 10.343 | H34: 10.4234 | I34: 0.128698 | J34: In Control | K34: In Control | L34: =$D$28 -> 10.443 | M34: =$D$25 -> 10.61 | N34: =$D$29 -> 10.599 | O34: =$D$30 -> 10.288
B35: 47 | C35: 10.677 | D35: 10.443 | E35: 10.588 | F35: 10.366 | G35: 10.421 | H35: 10.499 | I35: 0.128952 | J35: In Control | K35: In Control | L35: =$D$28 -> 10.443 | M35: =$D$25 -> 10.61 | N35: =$D$29 -> 10.599 | O35: =$D$30 -> 10.288
B36: 48 | C36: 10.666 | D36: 10.366 | E36: 10.343 | F36: 10.21 | G36: 10.566 | H36: 10.4302 | I36: 0.183205 | J36: In Control | K36: In Control | L36: =$D$28 -> 10.443 | M36: =$D$25 -> 10.61 | N36: =$D$29 -> 10.599 | O36: =$D$30 -> 10.288
B37: 49 | C37: 10.41 | D37: 10.677 | E37: 10.321 | F37: 10.588 | G37: 10.499 | H37: 10.499 | I37: 0.140721 | J37: In Control | K37: In Control | L37: =$D$28 -> 10.443 | M37: =$D$25 -> 10.61 | N37: =$D$29 -> 10.599 | O37: =$D$30 -> 10.288
B38: 50 | C38: 10.443 | D38: 10.31 | E38: 10.377 | F38: 10.688 | G38: 10.477 | H38: 10.459 | I38: 0.143131 | J38: In Control | K38: In Control | L38: =$D$28 -> 10.443 | M38: =$D$25 -> 10.61 | N38: =$D$29 -> 10.599 | O38: =$D$30 -> 10.288
B39: 32 | C39: 10.51 | D39: 10.421 | E39: 10.221 | F39: 10.555 | G39: 10.555 | H39: =AVERAGE(C39:G39) -> 10.4524 | I39: =MAX(C39:G39)-MIN(C39:G39) -> 0.334 | J39: =$D$26 -> 10.455 | K39: =$D$27 -> 10.677 | L39: =$D$28 -> 10.443 | M39: =$D$25 -> 10.61 | N39: =$D$29 -> 10.599 | O39: =$D$30 -> 10.288
B40: 33 | C40: 10.232 | D40: 10.477 | E40: 10.41 | F40: 10.543 | G40: 10.532 | H40: =AVERAGE(C40:G40) -> 10.4388 | I40: =MAX(C40:G40)-MIN(C40:G40) -> 0.311 | J40: =$D$26 -> 10.455 | K40: =$D$27 -> 10.677 | L40: =$D$28 -> 10.443 | M40: =$D$25 -> 10.61 | N40: =$D$29 -> 10.599 | O40: =$D$30 -> 10.288
B41: 34 | C41: 10.566 | D41: 10.332 | E41: 10.332 | F41: 10.332 | G41: 10.632 | H41: =AVERAGE(C41:G41) -> 10.4388 | I41: =MAX(C41:G41)-MIN(C41:G41) -> 0.3 | J41: =$D$26 -> 10.455 | K41: =$D$27 -> 10.677 | L41: =$D$28 -> 10.443 | M41: =$D$25 -> 10.61 | N41: =$D$29 -> 10.599 | O41: =$D$30 -> 10.288
B42: 35 | C42: 10.343 | D42: 10.455 | E42: 10.588 | F42: 10.41 | G42: 10.21 | H42: =AVERAGE(C42:G42) -> 10.4012 | I42: =MAX(C42:G42)-MIN(C42:G42) -> 0.378 | J42: =$D$26 -> 10.455 | K42: =$D$27 -> 10.677 | L42: =$D$28 -> 10.443 | M42: =$D$25 -> 10.61 | N42: =$D$29 -> 10.599 | O42: =$D$30 -> 10.288
B43: 36 | C43: 10.432 | D43: 10.577 | E43: 10.255 | F43: 10.421 | G43: 10.477 | H43: =AVERAGE(C43:G43) -> 10.4324 | I43: =MAX(C43:G43)-MIN(C43:G43) -> 0.322 | J43: =$D$26 -> 10.455 | K43: =$D$27 -> 10.677 | L43: =$D$28 -> 10.443 | M43: =$D$25 -> 10.61 | N43: =$D$29 -> 10.599 | O43: =$D$30 -> 10.288
B44: 37 | C44: 10.455 | D44: 10.61 | E44: 10.654 | F44: 10.477 | G44: 10.399 | H44: =AVERAGE(C44:G44) -> 10.519 | I44: =MAX(C44:G44)-MIN(C44:G44) -> 0.255 | J44: =$D$26 -> 10.455 | K44: =$D$27 -> 10.677 | L44: =$D$28 -> 10.443 | M44: =$D$25 -> 10.61 | N44: =$D$29 -> 10.599 | O44: =$D$30 -> 10.288
...

Sheet Peta Kendali MR
B2: Bottom Base 2 (Diameter Half Cylinder)
B3: Iterasi 1
B4: Pemeriksaan Kondisi Abnormalitas Peta MR | G4: Pemeriksaan Kondisi Abnormalitas Peta xindv
B5: Run | G5: Run
B6: Trend | G6: Trend
B7: Pengulangan Secara Periodik | G7: Pengulangan Secara Periodik
B8: Hugging pada garis tengah | G8: Hugging pada garis tengah
B9: Hugging dekat garis batas kendali | G9: Hugging dekat garis batas kendali
B27: Peta xindv-MR
B29: Parameter Peta Kendali | C29: m | D29: 25
C30: n | D30: 2
C31: xbar | D31: =AVERAGE(C42:C66) -> 3.4969608
C32: MRbar | D32: =AVERAGE(E43:E66) -> 0.27613221
C33: BKA MR | D33: =D38*D32 -> 0.90212392
C34: BKB MR | D34: =D39*D32 -> 0
C35: BKA xindv | D35: =D31+(3*D32/D37) -> 4.231355
C36: BKB xindv | D36: =D31-(3*D32/D37) -> 2.7625666
C37: d2 | D37: {=INDEX('Tabel Faktor'!$A$1:$Q$25,MATCH(D30,'Tabel Faktor'!$A$1:$A$25,0),MATCH(C37,'Tabel Faktor'!$A$1:$Q$1,0))} -> 1.128
C38: D4 | D38: {=INDEX('Tabel Faktor'!$A$1:$Q$25,MATCH(D30,'Tabel Faktor'!$A$1:$A$25,0),MATCH(C38,'Tabel Faktor'!$A$1:$Q$1,0))} -> 3.267
C39: D3 | D39: {=INDEX('Tabel Faktor'!$A$1:$Q$25,MATCH(D30,'Tabel Faktor'!$A$1:$A$25,0),MATCH(C39,'Tabel Faktor'!$A$1:$Q$1,0))} -> 0
B41: Sample Number (i) | C41: Observasi | D41: x individual | E41: MR | F41: GT MR | G41: BKA MR | H41: BKB MR | I41: GT xindv | J41: BKA xindv | K41: BKB xindv | L41: 1/2 UCLx | M41: 1/2 LCLx
B42: 1 | C42: 3.766486 | D42: =C42 -> 3.766486 | F42: =$D$32 -> 0.27613221 | G42: =$D$33 -> 0.90212392 | H42: =$D$34 -> 0 | I42: =$D$31 -> 3.4969608 | J42: =$D$35 -> 4.231355 | K42: =$D$36 -> 2.7625666 | L42: =I42+(J42-I42)/2 -> 3.8641579 | M42: =I42-(I42-K42)/2 -> 3.1297637
B43: 2 | C43: 3.607 | D43: =C43 -> 3.607 | E43: 0.159486 | F43: =$D$32 -> 0.27613221 | G43: =$D$33 -> 0.90212392 | H43: =$D$34 -> 0 | I43: =$D$31 -> 3.4969608 | J43: =$D$35 -> 4.231355 | K43: =$D$36 -> 2.7625666 | L43: =L42 -> 3.8641579 | M43: =M42 -> 3.1297637
B44: 3 | C44: 3.153344 | D44: =C44 -> 3.153344 | E44: 0.453656 | F44: =$D$32 -> 0.27613221 | G44: =$D$33 -> 0.90212392 | H44: =$D$34 -> 0 | I44: =$D$31 -> 3.4969608 | J44: =$D$35 -> 4.231355 | K44: =$D$36 -> 2.7625666 | L44: =L43 -> 3.8641579 | M44: =M43 -> 3.1297637
B45: 4 | C45: 3.802247 | D45: =C45 -> 3.802247 | E45: 0.648904 | F45: =$D$32 -> 0.27613221 | G45: =$D$33 -> 0.90212392 | H45: =$D$34 -> 0 | I45: =$D$31 -> 3.4969608 | J45: =$D$35 -> 4.231355 | K45: =$D$36 -> 2.7625666 | L45: =L44 -> 3.8641579 | M45: =M44 -> 3.1297637
B46: 5 | C46: 3.805788 | D46: =C46 -> 3.805788 | E46: 0.003541 | F46: =$D$32 -> 0.27613221 | G46: =$D$33 -> 0.90212392 | H46: =$D$34 -> 0 | I46: =$D$31 -> 3.4969608 | J46: =$D$35 -> 4.231355 | K46: =$D$36 -> 2.7625666 | L46: =L45 -> 3.8641579 | M46: =M45 -> 3.1297637
B47: 6 | C47: 3.09673 | D47: =C47 -> 3.09673 | E47: 0.709058 | F47: =$D$32 -> 0.27613221 | G47: =$D$33 -> 0.90212392 | H47: =$D$34 -> 0 | I47: =$D$31 -> 3.4969608 | J47: =$D$35 -> 4.231355 | K47: =$D$36 -> 2.7625666 | L47: =L46 -> 3.8641579 | M47: =M46 -> 3.1297637
B48: 7 | C48: 3.309072 | D48: =C48 -> 3.309072 | E48: 0.212342 | F48: =$D$32 -> 0.27613221 | G48: =$D$33 -> 0.90212392 | H48: =$D$34 -> 0 | I48: =$D$31 -> 3.4969608 | J48: =$D$35 -> 4.231355 | K48: =$D$36 -> 2.7625666 | L48: =L47 -> 3.8641579 | M48: =M47 -> 3.1297637
B49: 8 | C49: 3.774409 | D49: =C49 -> 3.774409 | E49: 0.465337 | F49: =$D$32 -> 0.27613221 | G49: =$D$33 -> 0.90212392 | H49: =$D$34 -> 0 | I49: =$D$31 -> 3.4969608 | J49: =$D$35 -> 4.231355 | K49: =$D$36 -> 2.7625666 | L49: =L48 -> 3.8641579 | M49: =M48 -> 3.1297637
B50: 9 | C50: 3.651143 | D50: =C50 -> 3.651143 | E50: 0.123267 | F50: =$D$32 -> 0.27613221 | G50: =$D$33 -> 0.90212392 | H50: =$D$34 -> 0 | I50: =$D$31 -> 3.4969608 | J50: =$D$35 -> 4.231355 | K50: =$D$36 -> 2.7625666 | L50: =L49 -> 3.8641579 | M50: =M49 -> 3.1297637
B51: 10 | C51: 3.173618 | D51: =C51 -> 3.173618 | E51: 0.477524 | F51: =$D$32 -> 0.27613221 | G51: =$D$33 -> 0.90212392 | H51: =$D$34 -> 0 | I51: =$D$31 -> 3.4969608 | J51: =$D$35 -> 4.231355 | K51: =$D$36 -> 2.7625666 | L51: =L50 -> 3.8641579 | M51: =M50 -> 3.1297637
B52: 11 | C52: 3.37523 | D52: =C52 -> 3.37523 | E52: 0.201611 | F52: =$D$32 -> 0.27613221 | G52: =$D$33 -> 0.90212392 | H52: =$D$34 -> 0 | I52: =$D$31 -> 3.4969608 | J52: =$D$35 -> 4.231355 | K52: =$D$36 -> 2.7625666 | L52: =L51 -> 3.8641579 | M52: =M51 -> 3.1297637
B53: 12 | C53: 3.717438 | D53: =C53 -> 3.717438 | E53: 0.342208 | F53: =$D$32 -> 0.27613221 | G53: =$D$33 -> 0.90212392 | H53: =$D$34 -> 0 | I53: =$D$31 -> 3.4969608 | J53: =$D$35 -> 4.231355 | K53: =$D$36 -> 2.7625666 | L53: =L52 -> 3.8641579 | M53: =M52 -> 3.1297637
B54: 13 | C54: 3.506622 | D54: =C54 -> 3.506622 | E54: 0.210815 | F54: =$D$32 -> 0.27613221 | G54: =$D$33 -> 0.90212392 | H54: =$D$34 -> 0 | I54: =$D$31 -> 3.4969608 | J54: =$D$35 -> 4.231355 | K54: =$D$36 -> 2.7625666 | L54: =L53 -> 3.8641579 | M54: =M53 -> 3.1297637
... B66: 25 | C66: 3.21336 | D66: =C66 -> 3.21336 | E66: 0.332859 | F66: =$D$32 -> 0.27613221 | G66: =$D$33 -> 0.90212392 | H66: =$D$34 -> 0 | I66: =$D$31 -> 3.4969608 | J66: =$D$35 -> 4.231355 | K66: =$D$36 -> 2.7625666 | L66: =L65 -> 3.8641579 | M66: =M65 -> 3.1297637

Sheet Peta Kendali p dan np
B2: Tripod (Jumlah Nonconforming per 50 unit)
B4: Pemeriksaan Kondisi Abnormalitas Peta p | G4: Pemeriksaan Kondisi Abnormalitas Peta np
B5: Run | G5: Run
B6: Trend | G6: Trend
B7: Pengulangan Secara Periodik | G7: Pengulangan Secara Periodik
B8: Hugging pada garis tengah | G8: Hugging pada garis tengah
B9: Hugging dekat garis batas kendali | G9: Hugging dekat garis batas kendali
B27: Peta p dan np
B29: Parameter Peta Kendali | C29: m | D29: 25
C30: n | D30: 50
C31: pbar | D31: 0.172
C32: npbar | D32: 8.6
C33: BKA p | D33: 0.332109
C34: BKB p | D34: 0.011891
C35: BKA np | D35: 16.605448
C36: BKB np | D36: 0.594552
B38: Sample Number (i) | C38: Jumlah Item Cacat | D38: Fraksi Item Cacat (p) | E38: Jumlah Item Cacat (np) | F38: GT p | G38: BKA p | H38: BKB p | I38: GT np | J38: BKA np | K38: BKB np
B39: 1 | C39: 7 | D39: 0.14 | E39: 7 | F39: 0.172 | G39: 0.332109 | H39: 0.011891 | I39: 8.6 | J39: 16.605448 | K39: 0.594552
B40: 2 | C40: 15 | D40: 0.3 | E40: 15 | F40: 0.172 | G40: 0.332109 | H40: 0.011891 | I40: 8.6 | J40: 16.605448 | K40: 0.594552
B41: 3 | C41: 7 | D41: 0.14 | E41: 7 | F41: 0.172 | G41: 0.332109 | H41: 0.011891 | I41: 8.6 | J41: 16.605448 | K41: 0.594552
B42: 4 | C42: 8 | D42: 0.16 | E42: 8 | F42: 0.172 | G42: 0.332109 | H42: 0.011891 | I42: 8.6 | J42: 16.605448 | K42: 0.594552
B43: 5 | C43: 15 | D43: 0.3 | E43: 15 | F43: 0.172 | G43: 0.332109 | H43: 0.011891 | I43: 8.6 | J43: 16.605448 | K43: 0.594552
B44: 6 | C44: 9 | D44: 0.18 | E44: 9 | F44: 0.172 | G44: 0.332109 | H44: 0.011891 | I44: 8.6 | J44: 16.605448 | K44: 0.594552
B45: 7 | C45: 9 | D45: 0.18 | E45: 9 | F45: 0.172 | G45: 0.332109 | H45: 0.011891 | I45: 8.6 | J45: 16.605448 | K45: 0.594552
B46: 8 | C46: 5 | D46: 0.1 | E46: 5 | F46: 0.172 | G46: 0.332109 | H46: 0.011891 | I46: 8.6 | J46: 16.605448 | K46: 0.594552
B47: 9 | C47: 6 | D47: 0.12 | E47: 6 | F47: 0.172 | G47: 0.332109 | H47: 0.011891 | I47: 8.6 | J47: 16.605448 | K47: 0.594552
B48: 10 | C48: 11 | D48: 0.22 | E48: 11 | F48: 0.172 | G48: 0.332109 | H48: 0.011891 | I48: 8.6 | J48: 16.605448 | K48: 0.594552
B49: 11 | C49: 6 | D49: 0.12 | E49: 6 | F49: 0.172 | G49: 0.332109 | H49: 0.011891 | I49: 8.6 | J49: 16.605448 | K49: 0.594552
B50: 12 | C50: 8 | D50: 0.16 | E50: 8 | F50: 0.172 | G50: 0.332109 | H50: 0.011891 | I50: 8.6 | J50: 16.605448 | K50: 0.594552
... B63: 25 | C63: 10 | D63: 0.2 | E63: 10 | F63: 0.172 | G63: 0.332109 | H63: 0.011891 | I63: 8.6 | J63: 16.605448 | K63: 0.594552

Sheet Peta Kendali c
B2: Pan Assembly S3A1 (Jumlah Nonconformity)
B3: Iterasi 1
B4: Pemeriksaan Kondisi Abnormalitas Peta c
B5: Run
B6: Trend
B7: Pengulangan Secara Periodik
B8: Hugging pada garis tengah
B9: Hugging dekat garis batas kendali
B27: Peta c
B29: Parameter Peta Kendali | C29: m | D29: 25
C30: n | D30: 1
C31: cbar | D31: 8.64
C32: BKA c | D32: 17.458163
C33: BKB c | D33: 0
B35: Sample Number (i) | C35: Jumlah Cacat (c) | D35: GT c | E35: BKA c | F35: BKB c
B36: 1 | C36: 5 | D36: =$D$31 -> 8.64 | E36: =$D$32 -> 17.458163 | F36: =$D$33 -> 0
B37: 2 | C37: 6 | D37: =$D$31 -> 8.64 | E37: =$D$32 -> 17.458163 | F37: =$D$33 -> 0
B38: 3 | C38: 10 | D38: =$D$31 -> 8.64 | E38: =$D$32 -> 17.458163 | F38: =$D$33 -> 0
B39: 4 | C39: 8 | D39: =$D$31 -> 8.64 | E39: =$D$32 -> 17.458163 | F39: =$D$33 -> 0
B40: 5 | C40: 8 | D40: =$D$31 -> 8.64 | E40: =$D$32 -> 17.458163 | F40: =$D$33 -> 0
B41: 6 | C41: 5 | D41: =$D$31 -> 8.64 | E41: =$D$32 -> 17.458163 | F41: =$D$33 -> 0
B42: 7 | C42: 7 | D42: =$D$31 -> 8.64 | E42: =$D$32 -> 17.458163 | F42: =$D$33 -> 0
B43: 8 | C43: 12 | D43: =$D$31 -> 8.64 | E43: =$D$32 -> 17.458163 | F43: =$D$33 -> 0
B44: 9 | C44: 8 | D44: =$D$31 -> 8.64 | E44: =$D$32 -> 17.458163 | F44: =$D$33 -> 0
B45: 10 | C45: 7 | D45: =$D$31 -> 8.64 | E45: =$D$32 -> 17.458163 | F45: =$D$33 -> 0
B46: 11 | C46: 5 | D46: =$D$31 -> 8.64 | E46: =$D$32 -> 17.458163 | F46: =$D$33 -> 0
B47: 12 | C47: 15 | D47: =$D$31 -> 8.64 | E47: =$D$32 -> 17.458163 | F47: =$D$33 -> 0
... B60: 25 | C60: 8 | D60: =$D$31 -> 8.64 | E60: =$D$32 -> 17.458163 | F60: =$D$33 -> 0

Sheet Peta Kendali u
B2: Dokumen (Jumlah Saltik/Typo per 100 dokumen)
B3: Iterasi 1
B4: Pemeriksaan Kondisi Abnormalitas Peta u
B5: Run
B6: Trend
B7: Pengulangan Secara Periodik
B8: Hugging pada garis tengah
B9: Hugging dekat garis batas kendali
B27: Peta u
B29: Parameter Peta Kendali | C29: m | D29: 25
C30: n | D30: 100
C31: ubar | D31: 0.0904
C32: BKA u | D32: 0.1806
C33: BKB u | D33: 0.0002
