Workbook

Sheet Cover
A2: PRAKTIKUM PERANCANGAN SISTEM TERINTEGRASI I
A4: LEMBAR RENCANA PROSES (LRP)
F15: Disusun Oleh
E16: Kelompok (19)
E17: Nama | G17: NIM
E18: Diva Alifia Ayala | G18: 13423105
E19: Chindy Herpati | G19: 13423121
E20: I Made Gede Yoga S. | G20: 13423124
E21: Ghaida Tsurayya | G21: 13423128
E22: Yoel Salvador | G22: 13423135
E23: M. Yasin Nurfadlilah | G23: 13423136
E24: Ikrom Nur Khanyfah | G24: 13423140
E25: Ega Mizuar | G25: 13423150
A29: PROGRAM STUDI TEKNIK INDUSTRI
A31: INSTITUT TEKNOLOGI BANDUNG
A33: 2024

Sheet Stripper
A1: LEMBAR RENCANA PROSES | K1: GAMBAR PART
A3: No . | B3: 1.3 | E3: Halaman ke-
A4: No . Part | B4: 1.3 | E4: File Gambar
A5: Nama Part | B5: Stripper | E5: Material | F5: SS41
E6: Ukuran | F6: Panjang | G6: 80 | I6: mm
A7: Dibuat oleh | B7: Kelompok 19 | F7: Lebar/Diameter | G7: 60 | I7: mm
A8: Tanggal | B8: 14 Desember 2024 | F8: Tinggi | G8: 10 | I8: mm
A10: No. Proses | B10: Urutan Operasi | C10: Stasiun Kerja | D10: Setup | F10: Tools | G10: Waktu Setup (detik) | H10: Waktu Proses (detik) | I10: Waktu Total (detik) | K10: berat = 0.08 lbs
D11: n | E11: alat bantu
A12: 1 | B12: Slot Milling (L = 39mm, d = 4mm, w = 14mm) Center Slot 2x | C12: CNC Milling | E12: Standard Vise | F12: HSS Milling Tools | G12: 194.04 | H12: ='Perhitungan LRP (Stripper)'!L7 -> 4.7428571 | I12: =G12+H12 -> 198.78286
A13: 3 | B13: Drilling (D = 4mm, d = 5mm) (Top Side) (Right) 2x | C13: CNC Milling | E13: Standard Vise | F13: HSS Center Drill | G13: =180+(4.68/5)*0.2 -> 180.1872 | H13: ='Perhitungan LRP (Stripper)'!J25 -> 0.28571429 | I13: =G13+H13 -> 180.47291
A14: 5 | B14: Drilling (D = 4mm, d = 5mm) (Top Side) (Left) 2x | C14: CNC Milling | E14: Standard Vise | F14: HSS Center Drill | G14: =180+(4.68/5)*0.2 -> 180.1872 | H14: ='Perhitungan LRP (Stripper)'!J26 -> 0.28571429 | I14: =G14+H14 -> 180.47291
A15: 7 | B15: Slot Milling (L = 10mm, d = 4mm, w = 10mm) Right 2x | C15: CNC Milling | E15: Standard Vise | F15: HSS Milling Tools | G15: 194.04 | H15: ='Perhitungan LRP (Stripper)'!L9 -> 1.4285714 | I15: =G15+H15 -> 195.46857
A16: 9 | B16: Slot Milling (L = 10mm, d = 4mm, w = 10mm) Left 2x | C16: CNC Milling | E16: Standard Vise | F16: HSS Milling Tools | G16: 194.04 | H16: ='Perhitungan LRP (Stripper)'!L9 -> 1.4285714 | I16: =G16+H16 -> 195.46857 | W16: .
A17: 11 | B17: Drilling (D = 6.60mm, d = 5mm) Right 2x | C17: CNC Milling | E17: Standard Vise | F17: HSS Center Drill | G17: =180+(4.68/5)*0.2 -> 180.1872 | H17: ='Perhitungan LRP (Stripper)'!J27 -> 0.28571429 | I17: =G17+H17 -> 180.47291
A18: 13 | B18: Drilling (D = 6.60mm, d = 5mm) Left2x | C18: CNC Milling | E18: Standard Vise | F18: HSS Center Drill | G18: =180+(4.68/5)*0.2 -> 180.1872 | H18: ='Perhitungan LRP (Stripper)'!J28 -> 0.28571429 | I18: =G18+H18 -> 180.47291
A19: 15 | B19: Shell-End Milling Roughing (L = 38mm, d = 2mm, w = 8mm) Center | C19: CNC Milling | E19: Standard Vise | F19: HSS Milling Tools | G19: 194.04 | H19: ='Perhitungan LRP (Stripper)'!L11 -> 2.3142857 | I19: =G19+H19 -> 196.35429
A20: 16 | B20: Shell-End Milling Roughing (L = 38mm, d = 2mm, w = 8mm) Center | C20: CNC Milling | E20: Standard Vise | F20: HSS Milling Tools | G20: 194.04 | H20: ='Perhitungan LRP (Stripper)'!L11 -> 2.3142857 | I20: =G20+H20 -> 196.35429
A21: 17 | B21: Shell-End Milling Roughing (L = 38mm, d = 2mm, w = 8mm) Center | C21: CNC Milling | E21: Standard Vise | F21: HSS Milling Tools | G21: 194.04 | H21: ='Perhitungan LRP (Stripper)'!L12 -> 2.3142857 | I21: =G21+H21 -> 196.35429
A22: 18 | B22: Shell-End Milling Roughing (L = 38mm, d = 2mm, w = 8mm) Center | C22: CNC Milling | E22: Standard Vise | F22: HSS Milling Tools | G22: 194.04 | H22: ='Perhitungan LRP (Stripper)'!L13 -> 2.3142857 | I22: =G22+H22 -> 196.35429
A23: 19 | B23: Shell-End Milling Roughing (L = 38mm, d = 2mm, w = 6mm) Center | C23: CNC Milling | E23: Standard Vise | F23: HSS Milling Tools | G23: 194.04 | H23: ='Perhitungan LRP (Stripper)'!L14 -> 2.3142857 | I23: =G23+H23 -> 196.35429
A24: 20 | B24: Inspeksi | C24: Bangku Kerja | E24: Jangka Sorong | F24: Jangka Sorong | G24: 0 | H24: 180 | I24: =G24+H24 -> 180
H32: Total | I32: =SUM(I12:I24) -> 2473.3831
B38: Raw Material | F38: Produk akhir yang diinginkan
B53: Ilustrasi urutan operasi berdasarkan LRP

Sheet Perhitungan LRP (Stripper)
A1: PERHITUNGAN LEMBAR RENCANA PROSES
A5: MILLING
A6: No. Proses | B6: Nama Proses | C6: D (mm) | D6: d (mm) | E6: L (mm) | F6: v (mm/min) | G6: N (rev/min) | H6: fr (mm/min) | I6: w (mm) | J6: A (mm) | K6: Tm (min) | L6: Tm (sekon) | M6: MRR (mm3/min) | N6: Volume Awal (mm3) | O6: Scrap | P6: %Scrap | Q6: Volume Akhir (mm3)
A7: 1 | B7: Slot Milling (L = 39mm, d = 4mm, w = 14mm) Center Slot 2x | C7: 5 | D7: 4 | E7: 39 | F7: 8500 | G7: =F7/(3.14*C7) -> 541.40127 | H7: 1050 | I7: 14 | J7: 2.5 | K7: =((E7 + J7)/H7)*2 -> 0.079047619 | L7: =K7*60 -> 4.7428571 | M7: =I7*D7*H7 -> 58800 | N7: 48000 | O7: =C7*D7*E7*2 -> 1560 | P7: =(O7/N7)*100% -> 0.0325 | Q7: =N7-O7 -> 46440
A8: 2 | B8: Slot Milling (L = 10mm, d = 4mm, w = 10mm) Right 2x | C8: 5 | D8: 4 | E8: 10 | F8: 8500 | G8: =F8/(3.14*C8) -> 541.40127 | H8: 1050 | I8: 10 | J8: 2.5 | K8: =((E8 + J8)/H8)*2 -> 0.023809524 | L8: =K8*60 -> 1.4285714 | M8: =I8*D8*H8 -> 42000 | N8: =Q7 -> 46440 | O8: =C8*D8*E8*2 -> 400 | P8: =(O8/N8)*100% -> 0.0086132644 | Q8: =N8-O8 -> 46040
A9: 3 | B9: Slot Milling (L = 10mm, d = 4mm, w = 10mm) Left 2x | C9: 5 | D9: 4 | E9: 10 | F9: 8500 | G9: =F9/(3.14*C9) -> 541.40127 | H9: 1050 | I9: 10 | J9: 2.5 | K9: =((E9 + J9)/H9)*2 -> 0.023809524 | L9: =K9*60 -> 1.4285714 | M9: =I9*D9*H9 -> 42000 | N9: =Q8 -> 46040 | O9: =C9*D9*E9*2 -> 400 | P9: =(O9/N9)*100% -> 0.0086880973 | Q9: =N9-O9 -> 45640
A10: 4 | B10: Shell-End Milling Roughing (L = 38mm, d = 2mm, w = 8mm) Center | C10: 5 | D10: 2 | E10: 38 | F10: 8500 | G10: =F10/(3.14*C10) -> 541.40127 | H10: 1050 | I10: 8 | J10: 2.5 | K10: =((E10 + J10)/H10) -> 0.038571429 | L10: =K10*60 -> 2.3142857 | M10: =I10*D10*H10 -> 16800 | N10: =Q9 -> 45640 | O10: =C10*D10*E10 -> 380 | P10: =(O10/N10)*100% -> 0.0083260298 | Q10: =N10-O10 -> 45260
A11: 5 | B11: Shell-End Milling Roughing (L = 38mm, d = 2mm, w = 8mm) Center | C11: 5 | D11: 2 | E11: 38 | F11: 8500 | G11: =F11/(3.14*C11) -> 541.40127 | H11: 1050 | I11: 8 | J11: 2.5 | K11: =((E11 + J11)/H11) -> 0.038571429 | L11: =K11*60 -> 2.3142857 | M11: =I11*D11*H11 -> 16800 | N11: =Q10 -> 45260 | O11: =C11*D11*E11 -> 380 | P11: =(O11/N11)*100% -> 0.0083959346 | Q11: =N11-O11 -> 44880
A12: 6 | B12: Shell-End Milling Roughing (L = 38mm, d = 2mm, w = 8mm) Center | C12: 5 | D12: 2 | E12: 38 | F12: 8500 | G12: =F12/(3.14*C12) -> 541.40127 | H12: 1050 | I12: 8 | J12: 2.5 | K12: =((E12 + J12)/H12) -> 0.038571429 | L12: =K12*60 -> 2.3142857 | M12: =I12*D12*H12 -> 16800 | N12: =Q11 -> 44880 | O12: =C12*D12*E12 -> 380 | P12: =(O12/N12)*100% -> 0.0084670232 | Q12: =N12-O12 -> 44500
A13: 7 | B13: Shell-End Milling Roughing (L = 38mm, d = 2mm, w = 8mm) Center | C13: 5 | D13: 2 | E13: 38 | F13: 8500 | G13: =F13/(3.14*C13) -> 541.40127 | H13: 1050 | I13: 8 | J13: 2.5 | K13: =((E13 + J13)/H13) -> 0.038571429 | L13: =K13*60 -> 2.3142857 | M13: =I13*D13*H13 -> 16800 | N13: =Q12 -> 44500 | O13: =C13*D13*E13 -> 380 | P13: =(O13/N13)*100% -> 0.0085393258 | Q13: =N13-O13 -> 44120
A14: 8 | B14: Shell-End Milling Roughing (L = 38mm, d = 2mm, w = 6mm) Center | C14: 5 | D14: 2 | E14: 38 | F14: 8500 | G14: =F14/(3.14*C14) -> 541.40127 | H14: 1050 | I14: 6 | J14: 2.5 | K14: =((E14 + J14)/H14) -> 0.038571429 | L14: =K14*60 -> 2.3142857 | M14: =I14*D14*H14 -> 12600 | N14: =Q13 -> 44120 | O14: =C14*D14*E14 -> 380 | P14: =(O14/N14)*100% -> 0.008612874 | Q14: =N14-O14 -> 43740
A17: TURNING
A18: No. Proses | B18: Nama Proses | C18: Do (mm) | D18: Df (mm) | E18: d (mm) | F18: d maks (mm) | G18: L (mm) | H18: f (mm/rev) | I18: v (mm/min) | J18: N (rev/min) | K18: fr (mm/min) | L18: Tm (min) | M18: Tm (sekon) | N18: MRR (mm3/min) | O18: Volume Awal (mm3) | P18: Scrap | Q18: % Scrap | R18: Volume Akhir (mm3)
A23: DRILLING (TERMASUK TAPPING DAN BORING)
A24: No. Proses | B24: Nama Proses | C24: D (mm) | D24: d (mm) | E24: f (mm/rev) | F24: v(mm/min) | G24: N (rev/min) | H24: fr (mm/min) | I24: Tm (min) | J24: Tm (sekon) | K24: MRR (mm3/min) | L24: Volume Awal (mm3) | M24: Scrap | N24: % Scrap | O24: Volume Akhir (mm3)
A25: 1 | B25: Drilling (D = 4mm, d = 5mm) (Top Side) (Right) 2x | C25: 4 | D25: 5 | E25: 0.04 | F25: 500 | G25: =H25/E25 -> 26250 | H25: 1050 | I25: =D25/H25 -> 0.0047619048 | J25: =I25*60 -> 0.28571429 | K25: =(3.14*(C25*C25)*H25)/4 -> 13188 | L25: =Q14 -> 43740 | M25: =3.14159*(C25/2)^2*D25 -> 62.8318 | N25: =(M25/L25)*100% -> 0.0014364838 | O25: =L25-M25 -> 43677.168
A26: 2 | B26: Drilling (D = 4mm, d = 5mm) (Top Side) (Left) 2x | C26: 4 | D26: 5 | E26: 0.04 | F26: 500 | G26: =H26/E26 -> 26250 | H26: 1050 | I26: =D26/H26 -> 0.0047619048 | J26: =I26*60 -> 0.28571429 | K26: =(3.14*(C26*C26)*H26)/4 -> 13188 | L26: =O25 -> 43677.168 | M26: =3.14159*(C26/2)^2*D26 -> 62.8318 | N26: =(M26/L26)*100% -> 0.0014385502 | O26: =L26-M26 -> 43614.336
A27: 3 | B27: Drilling (D = 6.60mm, d = 5mm) Right 2x | C27: 6.6 | D27: 5 | E27: 0.04 | F27: 500 | G27: =H27/E27 -> 26250 | H27: 1050 | I27: =D27/H27 -> 0.0047619048 | J27: =I27*60 -> 0.28571429 | K27: =(3.14*(C27*C27)*H27)/4 -> 35904.33 | L27: =O26 -> 43614.336 | M27: =3.14159*(C27/2)^2*D27 -> 171.05958 | N27: =(M27/L27)*100% -> 0.0039220951 | O27: =L27-M27 -> 43443.277
A28: 5 | B28: Drilling (D = 6.60mm, d = 5mm) Left2x | C28: 6.6 | D28: 5 | E28: 0.04 | F28: 500 | G28: =H28/E28 -> 26250 | H28: 1050 | I28: =D28/H28 -> 0.0047619048 | J28: =I28*60 -> 0.28571429 | K28: =(3.14*(C28*C28)*H28)/4 -> 35904.33 | L28: =O27 -> 43443.277 | M28: =3.14159*(C28/2)^2*D28 -> 171.05958 | N28: =(M28/L28)*100% -> 0.0039375385 | O28: =L28-M28 -> 43272.217
A30: PRESSING (BLANKING, PUNCHING, EMBOSS, DEBOSS)
A31: No. Proses | B31: Nama Proses | C31: TS(MPa) | D31: t (mm) | E31: L (mm) | F31: Volume Awal (mm3) | G31: SPM | H31: Tm (min) | I31: Tm (s) | J31: Scrap | K31: %Scrap | L31: Volume Akhir (mm3)
P34: =POWER(3,2) -> 9
A36: PRESSING (BENDING)
A37: No. Proses | B37: Nama Proses | C37: Kbf | D37: w (mm) | E37: TS (Mpa) | F37: t (mm) | G37: D (mm) | H37: F (N) | I37: SPM | J37: Tm (min) | K37: Tm (s) | L37: Scrap (mm3)
A41: CUTTING (TERMASUK CHAMFERING LINEAR)
A42: No. Proses | B42: Nama Proses | C42: A (mm) | D42: t (mm) | E42: θ | F42: Volume Awal | G42: Scrap | H42: % Scrap | I42: Volume Akhir (mm3)
A47: LANGKAH MEMBACA REFERENSI KALPAKJIAN - MILLING
A50: 1. Operasi yang ingin digunakan?
A52: 2. Untuk operasi tersebut, perhatikan diameter tools (maximum width of cut) yang digunakan -> untuk pengulangan proses
A54: 3. Proses roughing atau finishing? Ingat semua milling harus ada proses finishing (kecuali dinyatakan sebaliknya).
A56: 4. Untuk operasi tersebut, perhatikan maksimum depth of cut -> untuk pengulangan proses
A58: 5. Material apa yang digunakan? Untuk stainless steel, gunakan 'Carbon steel up to 63 kgf/mm2'
A60: 6. Lihat cutting speed dan feed rate yang direkomendasikan.
A86: LANGKAH MEMBACA REFERENSI KALPAKJIAN - DRILLING
A88: 1. Berapa diameter drilling yang diinginkan?
A90: 2. Material apa yang digunakan?
A92: 3. Lihat cutting speed dan feed yang direkomendasikan (feed, bukan feed rate)
A93: (cutting speed > feed)
... A130: 4. Lihat cutting speed yang direkomendasikan

Sheet Upper Base
A1: LEMBAR RENCANA PROSES | K1: GAMBAR PART
A3: No . | B3: 2.1 | E3: Halaman ke-
A4: No . Part | B4: 2.1 | E4: File Gambar
A5: Nama Part | B5: Upper Base Plate | E5: Material | F5: SS41
E6: Ukuran | F6: Panjang | G6: 150 | I6: mm
A7: Dibuat oleh | B7: Kelompok 19 | F7: Lebar/Diameter | G7: 60 | I7: mm
A8: Tanggal | B8: 45626 | F8: Tinggi | G8: 25 | I8: mm
A10: No. Proses | B10: Urutan Operasi | C10: Stasiun Kerja | D10: Setup | F10: Tools | G10: Waktu Setup (detik) | H10: Waktu Proses (detik) | I10: Waktu Total (detik)
D11: n | E11: alat bantu
A12: 1 | B12: Slot Milling (L = 15mm, d = 5mm, w = 15mm) (Top SIde) (Right) | C12: CNC Milling | E12: Standar Vise | F12: HSS Milling Tools | G12: =(180)+((4.68/5)*0.25)*60 -> 194.04 | H12: ='Perhitungan LRP (Upper Base Pla'!L7 -> 1 | I12: =G12+H12 -> 195.04
A13: 2 | B13: Slot Milling (L = 15mm, d = 5mm, w = 15mm) (Top SIde) (Right) | C13: CNC Milling | E13: Standar Vise | F13: HSS Milling Tools | G13: =(180)+((4.68/5)*0.25)*60 -> 194.04 | H13: ='Perhitungan LRP (Upper Base Pla'!L8 -> 1 | I13: =G13+H13 -> 195.04
A14: 3 | B14: Slot Milling (L = 15mm, d = 1mm, w = 15mm) (Top SIde) (Right) | C14: CNC Milling | E14: Standar Vise | F14: HSS Milling Tools | G14: =(180)+((4.68/5)*0.25)*60 -> 194.04 | H14: ='Perhitungan LRP (Upper Base Pla'!L9 -> 1 | I14: =G14+H14 -> 195.04
A15: 4 | B15: Slot Milling (L = 4.50mm, d = 5mm, w = 4.50mm) (Top Side) (Right)2x | C15: CNC Milling | E15: Standar Vise | F15: HSS Milling Tools | G15: =(180)+((4.68/5)*0.25)*60 -> 194.04 | H15: ='Perhitungan LRP (Upper Base Pla'!L10 -> 0.8 | I15: =G15+H15 -> 194.84
A16: 6 | B16: Slot Milling (L = 4.50mm, d = 5mm, w = 4.50mm) (Top Side) (Right)2x | C16: CNC Milling | E16: Standar Vise | F16: HSS Milling Tools | G16: =(180)+((4.68/5)*0.25)*60 -> 194.04 | H16: ='Perhitungan LRP (Upper Base Pla'!L11 -> 0.8 | I16: =G16+H16 -> 194.84
A17: 8 | B17: Slot Milling (L = 4.50mm, d = 1mm, w = 4.50mm) (Top Side) (Right) 2x | C17: CNC Milling | E17: Standar Vise | F17: HSS Milling Tools | G17: =(180)+((4.68/5)*0.25)*60 -> 194.04 | H17: ='Perhitungan LRP (Upper Base Pla'!L12 -> 0.8 | I17: =G17+H17 -> 194.84
A18: 10 | B18: Slot Milling (L= 15mm, d = 5mm, w = 15mm) Center 3x | C18: CNC Milling | E18: Standar Vise | F18: HSS Milling Tools | G18: =(180)+((4.68/5)*0.25)*60 -> 194.04 | H18: ='Perhitungan LRP (Upper Base Pla'!L13 -> 3 | I18: =G18+H18 -> 197.04
A19: 14 | B19: Slot Milling (L= 15mm, d = 0.5mm, w = 15mm) Center | C19: CNC Milling | E19: Standar Vise | F19: HSS Milling Tools | G19: =(180)+((4.68/5)*0.25)*60 -> 194.04 | H19: ='Perhitungan LRP (Upper Base Pla'!L14 -> 1 | I19: =G19+H19 -> 195.04
A20: 15 | B20: Drilling (D = 4mm, d = 8mm) Center 2x | C20: CNC Milling | E20: Standar Vise | F20: HSS Center Drill | G20: =180 + (4.68/5)*0.2 -> 180.1872 | H20: ='Perhitungan LRP (Upper Base Pla'!J28 -> 0.91428571 | I20: =G20+H20 -> 181.10149
A21: 17 | B21: Drilling (D = 4mm, d = 7.5mm) Center 2x | C21: CNC Milling | E21: Standar Vise | F21: HSS Center Drill | G21: =180 + (4.68/5)*0.2 -> 180.1872 | H21: ='Perhitungan LRP (Upper Base Pla'!J29 -> 0.85714286 | I21: =G21+H21 -> 181.04434
A22: 19 | B22: Drilling (D = 9mm, d = 8mm) Center 3x | C22: CNC Milling | E22: Standar Vise | F22: HSS Center Drill | G22: =180 + (4.68/5)*0.2 -> 180.1872 | H22: ='Perhitungan LRP (Upper Base Pla'!J30 -> 1.3714286 | I22: =G22+H22 -> 181.55863
A23: 22 | B23: Drilling (D = 9mm, d = 1mm) Center | C23: CNC Milling | E23: Standar Vise | F23: HSS Center Drill | G23: =180 + (4.68/5)*0.2 -> 180.1872 | H23: ='Perhitungan LRP (Upper Base Pla'!J31 -> 0.057142857 | I23: =G23+H23 -> 180.24434
A24: 23 | B24: Slot Milling (L = 14mm, d = 5mm, w = 14mm) (Top Side) (Right) 5x | C24: CNC Milling | E24: Standar Vise | F24: HSS Milling Tools | G24: =(180)+((4.68/5)*0.25)*60 -> 194.04 | H24: ='Perhitungan LRP (Upper Base Pla'!L15 -> 4.7142857 | I24: =G24+H24 -> 198.75429
A25: 28 | B25: Slot Milling (L = 4,10mm, d = 5mm, w=4.10) (Top Side) (Right) 5x | C25: CNC Milling | E25: Standar Vise | F25: HSS Milling Tools | G25: =(180)+((4.68/5)*0.25)*60 -> 194.04 | H25: ='Perhitungan LRP (Upper Base Pla'!L16 -> 1.8857143 | I25: =G25+H25 -> 195.92571
A26: 33 | B26: Slot Milling (L = 4,10mm, d = 5mm, w=4.10) (Top Side) (Right) 5x | C26: CNC Milling | E26: Standar Vise | F26: HSS Milling Tools | G26: =(180)+((4.68/5)*0.25)*60 -> 194.04 | H26: ='Perhitungan LRP (Upper Base Pla'!L17 -> 1.8857143 | I26: =G26+H26 -> 195.92571
A27: 38 | B27: Drilling (D = 6.10mm, d = 8mm) Center 2x | C27: CNC Milling | E27: Standar Vise | F27: HSS Center Drill | G27: =180 + (4.68/5)*0.2 -> 180.1872 | H27: ='Perhitungan LRP (Upper Base Pla'!J32 -> 0.91428571 | I27: =G27+H27 -> 181.10149
A28: 40 | B28: Drilling (D = 6.10mm, d = 7.5mm) Center 2x | C28: CNC Milling | E28: Standar Vise | F28: HSS Center Drill | G28: =180 + (4.68/5)*0.2 -> 180.1872 | H28: ='Perhitungan LRP (Upper Base Pla'!J33 -> 0.85714286 | I28: =G28+H28 -> 181.04434
A29: 41 | B29: Inspeksi | C29: Meja Kerja | E29: Jangka Sorong | F29: jangka Sorong | G29: 0 | H29: 180 | I29: =G29+H29 -> 180
H32: Total | I32: =SUM(I12:I29) -> 3418.4203
B38: Raw Material | F38: Produk akhir yang diinginkan
B51: Ilustrasi urutan operasi berdasarkan LRP

Sheet Perhitungan LRP (Upper Base Pla
A1: PERHITUNGAN LEMBAR RENCANA PROSES
A5: MILLING
A6: No. Proses | B6: Nama Proses | C6: D (mm) | D6: d (mm) | E6: L (mm) | F6: v (mm/min) | G6: N (rev/min) | H6: fr (mm/min) | I6: w (mm) | J6: A (mm) | K6: Tm (min) | L6: Tm (sekon) | M6: MRR (mm3/min) | N6: Volume Awal (mm3) | O6: Scrap | P6: %Scrap | Q6: Volume Akhir (mm3)
A7: 1 | B7: Slot Milling (L = 15mm, d = 5mm, w = 15mm) (Top SIde) (Right) | C7: 5 | D7: 5 | E7: 15 | F7: 8500 | G7: 541.12681 | H7: 1050 | I7: 15 | J7: 2.5 | K7: =((E7 + J7)/H7) -> 0.016666667 | L7: =K7*60 -> 1 | M7: =I7*D7*H7 -> 78750 | N7: 48000 | O7: =C7*D7*E7*2 -> 750 | P7: =(O7/N7)*100% -> 0.015625 | Q7: =N7-O7 -> 47250
A8: 2 | B8: Slot Milling (L = 15mm, d = 5mm, w = 15mm) (Top SIde) (Right) | C8: 5 | D8: 5 | E8: 15 | F8: 8500 | G8: 541.12681 | H8: 1050 | I8: 15 | J8: 2.5 | K8: =((E8 + J8)/H8) -> 0.016666667 | L8: =K8*60 -> 1 | M8: =I8*D8*H8 -> 78750 | N8: =Q7 -> 47250 | O8: =C8*D8*E8*2 -> 750 | P8: =(O8/N8)*100% -> 0.015873016 | Q8: =N8-O8 -> 46500
A9: 3 | B9: Slot Milling (L = 15mm, d = 1mm, w = 15mm) (Top SIde) (Right) | C9: 5 | D9: 1 | E9: 15 | F9: 8500 | G9: 541.12681 | H9: 1050 | I9: 15 | J9: 2.5 | K9: =((E9 + J9)/H9) -> 0.016666667 | L9: =K9*60 -> 1 | M9: =I9*D9*H9 -> 15750 | N9: =Q8 -> 46500 | O9: =C9*D9*E9*2 -> 150 | P9: =(O9/N9)*100% -> 0.0032258065 | Q9: =N9-O9 -> 46350
A10: 4 | B10: Slot Milling (L = 4.50mm, d = 5mm, w = 4.50mm) (Top Side) (Right)2x | C10: 5 | D10: 5 | E10: 4.5 | F10: 8500 | G10: 541.12681 | H10: 1050 | I10: 4.5 | J10: 2.5 | K10: =((E10 + J10)/H10)*2 -> 0.013333333 | L10: =K10*60 -> 0.8 | M10: =I10*D10*H10 -> 23625 | N10: =Q9 -> 46350 | O10: =C10*D10*E10*2 -> 225 | P10: =(O10/N10)*100% -> 0.0048543689 | Q10: =N10-O10 -> 46125
A11: 5 | B11: Slot Milling (L = 4.50mm, d = 5mm, w = 4.50mm) (Top Side) (Right)2x | C11: 5 | D11: 5 | E11: 4.5 | F11: 8500 | G11: 541.12681 | H11: 1050 | I11: 4.5 | J11: 2.5 | K11: =((E11 + J11)/H11)*2 -> 0.013333333 | L11: =K11*60 -> 0.8 | M11: =I11*D11*H11 -> 23625 | N11: =Q10 -> 46125 | O11: =C11*D11*E11*2 -> 225 | P11: =(O11/N11)*100% -> 0.0048780488 | Q11: =N11-O11 -> 45900
A12: 6 | B12: Slot Milling (L = 4.50mm, d = 1mm, w = 4.50mm) (Top Side) (Right) 2x | C12: 5 | D12: 1 | E12: 4.5 | F12: 8500 | G12: 541.12681 | H12: 1050 | I12: 4.5 | J12: 2.5 | K12: =((E12 + J12)/H12)*2 -> 0.013333333 | L12: =K12*60 -> 0.8 | M12: =I12*D12*H12 -> 4725 | N12: =Q11 -> 45900 | O12: =C12*D12*E12*2 -> 45 | P12: =(O12/N12)*100% -> 0.00098039216 | Q12: =N12-O12 -> 45855
A13: 7 | B13: Slot Milling (L= 15mm, d = 5mm, w = 15mm) Center 3x | C13: 5 | D13: 5 | E13: 15 | F13: 8500 | G13: 541.12681 | H13: 1050 | I13: 15 | J13: 2.5 | K13: =((E13 + J13)/H13)*3 -> 0.05 | L13: =K13*60 -> 3 | M13: =I13*D13*H13 -> 78750 | N13: =Q12 -> 45855 | O13: =C13*D13*E13*2 -> 750 | P13: =(O13/N13)*100% -> 0.016355904 | Q13: =N13-O13 -> 45105
A14: 8 | B14: Slot Milling (L= 15mm, d = 0.5mm, w = 15mm) Center | C14: 5 | D14: 0.5 | E14: 15 | F14: 8500 | G14: 541.12681 | H14: 1050 | I14: 15 | J14: 2.5 | K14: =((E14 + J14)/H14) -> 0.016666667 | L14: =K14*60 -> 1 | M14: =I14*D14*H14 -> 7875 | N14: =Q13 -> 45105 | O14: =C14*D14*E14*2 -> 75 | P14: =(O14/N14)*100% -> 0.0016627868 | Q14: =N14-O14 -> 45030
A15: 9 | B15: Slot Milling (L = 14mm, d = 5mm, w = 14mm) (Top Side) (Right) 5x | C15: 5 | D15: 5 | E15: 14 | F15: 8500 | G15: 541.12681 | H15: 1050 | I15: 14 | J15: 2.5 | K15: =((E15 + J15)/H15)*5 -> 0.078571429 | L15: =K15*60 -> 4.7142857 | M15: =I15*D15*H15 -> 73500 | N15: =Q14 -> 45030 | O15: =C15*D15*E15*2 -> 700 | P15: =(O15/N15)*100% -> 0.015545192 | Q15: =N15-O15 -> 44330
A16: 10 | B16: Slot Milling (L = 4,10mm, d = 5mm, w=4.10) (Top Side) (Right) 5x | C16: 5 | D16: 5 | E16: 4.1 | F16: 8500 | G16: 541.12681 | H16: 1050 | I16: 4.1 | J16: 2.5 | K16: =((E16 + J16)/H16)*5 -> 0.031428571 | L16: =K16*60 -> 1.8857143 | M16: =I16*D16*H16 -> 21525 | N16: =Q15 -> 44330 | O16: =C16*D16*E16*2 -> 205 | P16: =(O16/N16)*100% -> 0.0046244078 | Q16: =N16-O16 -> 44125
A17: 11 | B17: Slot Milling (L = 4,10mm, d = 5mm, w=4.10) (Top Side) (Right) 5x | C17: 5 | D17: 5 | E17: 4.1 | F17: 8500 | G17: 541.12681 | H17: 1050 | I17: 4.1 | J17: 2.5 | K17: =((E17 + J17)/H17)*5 -> 0.031428571 | L17: =K17*60 -> 1.8857143 | M17: =I17*D17*H17 -> 21525 | N17: =Q16 -> 44125 | O17: =C17*D17*E17*2 -> 205 | P17: =(O17/N17)*100% -> 0.0046458924 | Q17: =N17-O17 -> 43920
A20: TURNING
A21: No. Proses | B21: Nama Proses | C21: Do (mm) | D21: Df (mm) | E21: d (mm) | F21: d maks (mm) | G21: L (mm) | H21: f (mm/rev) | I21: v (mm/min) | J21: N (rev/min) | K21: fr (mm/min) | L21: Tm (min) | M21: Tm (sekon) | N21: MRR (mm3/min) | O21: Volume Awal (mm3) | P21: Scrap | Q21: % Scrap | R21: Volume Akhir (mm3)
A26: DRILLING (TERMASUK TAPPING DAN BORING)
A27: No. Proses | B27: Nama Proses | C27: D (mm) | D27: d (mm) | E27: f (mm/rev) | F27: v(mm/min) | G27: N (rev/min) | H27: fr (mm/min) | I27: Tm (min) | J27: Tm (sekon) | K27: MRR (mm3/min) | L27: Volume Awal (mm3) | M27: Scrap | N27: % Scrap | O27: Volume Akhir (mm3)
A28: 1 | B28: Drilling (D = 4mm, d = 8mm) Center 2x | C28: 4 | D28: 8 | E28: 0.04 | F28: 500 | G28: =H28/E28 -> 26250 | H28: 1050 | I28: =(D28/H28)*2 -> 0.015238095 | J28: =I28*60 -> 0.91428571 | K28: =(3.14*(C28*C28)*H28)/4 -> 13188 | L28: =Q17 -> 43920 | M28: =3.14159*(C28/2)^2*D28 -> 100.53088 | N28: =(M28/L28)*100% -> 0.0022889545 | O28: =L28-M28 -> 43819.469
A29: 2 | B29: Drilling (D = 4mm, d = 7.5mm) Center 2x | C29: 4 | D29: 7.5 | E29: 0.04 | F29: 500 | G29: =H29/E29 -> 26250 | H29: 1050 | I29: =(D29/H29)*2 -> 0.014285714 | J29: =I29*60 -> 0.85714286 | K29: =(3.14*(C29*C29)*H29)/4 -> 13188 | L29: =O28 -> 43819.469 | M29: =3.14159*(C29/2)^2*D29 -> 94.2477 | N29: =(M29/L29)*100% -> 0.0021508179 | O29: =L29-M29 -> 43725.221
A30: 3 | B30: Drilling (D = 9mm, d = 8mm) Center 3x | C30: 9 | D30: 8 | E30: 0.04 | F30: 500 | G30: =H30/E30 -> 26250 | H30: 1050 | I30: =(D30/H30)*3 -> 0.022857143 | J30: =I30*60 -> 1.3714286 | K30: =(3.14*(C30*C30)*H30)/4 -> 66764.25 | L30: =O29 -> 43725.221 | M30: =3.14159*(C30/2)^2*D30 -> 508.93758 | N30: =(M30/L30)*100% -> 0.011639451 | O30: =L30-M30 -> 43216.284
A31: 4 | B31: Drilling (D = 9mm, d = 1mm) Center | C31: 9 | D31: 1 | E31: 0.04 | F31: 500 | G31: =H31/E31 -> 26250 | H31: 1050 | I31: =(D31/H31) -> 0.00095238095 | J31: =I31*60 -> 0.057142857 | K31: =(3.14*(C31*C31)*H31)/4 -> 66764.25 | L31: =O30 -> 43216.284 | M31: =3.14159*(C31/2)^2*D31 -> 63.617198 | N31: =(M31/L31)*100% -> 0.0014720654 | O31: =L31-M31 -> 43152.667
A32: 5 | B32: Drilling (D = 6.10mm, d = 8mm) Center 2x | C32: 6.1 | D32: 8 | E32: 0.04 | F32: 500 | G32: =H32/E32 -> 26250 | H32: 1050 | I32: =(D32/H32)*2 -> 0.015238095 | J32: =I32*60 -> 0.91428571 | K32: =(3.14*(C32*C32)*H32)/4 -> 30670.342 | L32: =O31 -> 43152.667 | M32: =3.14159*(C32/2)^2*D32 -> 233.79713 | N32: =(M32/L32)*100% -> 0.0054179068 | O32: =L32-M32 -> 42918.87
A33: 7 | B33: Drilling (D = 6.10mm, d = 7.5mm) Center 2x | C33: 6.1 | D33: 7.5 | E33: 0.04 | F33: 500 | G33: =H33/E33 -> 26250 | H33: 1050 | I33: =(D33/H33)*2 -> 0.014285714 | J33: =I33*60 -> 0.85714286 | K33: =(3.14*(C33*C33)*H33)/4 -> 30670.342 | L33: =O32 -> 42918.87 | M33: =3.14159*(C33/2)^2*D33 -> 219.18481 | N33: =(M33/L33)*100% -> 0.0051069567 | O33: =L33-M33 -> 42699.685
A35: PRESSING (BLANKING, PUNCHING, EMBOSS, DEBOSS)
A36: No. Proses | B36: Nama Proses | C36: TS(MPa) | D36: t (mm) | E36: L (mm) | F36: Volume Awal (mm3) | G36: SPM | H36: Tm (min) | I36: Tm (s) | J36: Scrap | K36: %Scrap | L36: Volume Akhir (mm3)
A37: 2
A41: PRESSING (BENDING)
A42: No. Proses | B42: Nama Proses | C42: Kbf | D42: w (mm) | E42: TS (Mpa) | F42: t (mm) | G42: D (mm) | H42: F (N) | I42: SPM | J42: Tm (min) | K42: Tm (s) | L42: Scrap (mm3)
A46: CUTTING (TERMASUK CHAMFERING LINEAR)
A47: No. Proses | B47: Nama Proses | C47: A (mm) | D47: t (mm) | E47: θ | F47: Volume Awal | G47: Scrap | H47: % Scrap | I47: Volume Akhir (mm3)
A48: 5
A52: LANGKAH MEMBACA REFERENSI KALPAKJIAN - MILLING
A55: 1. Operasi yang ingin digunakan?
A57: 2. Untuk operasi tersebut, perhatikan diameter tools (maximum width of cut) yang digunakan -> untuk pengulangan proses
A59: 3. Proses roughing atau finishing? Ingat semua milling harus ada proses finishing (kecuali dinyatakan sebaliknya).
A61: 4. Untuk operasi tersebut, perhatikan maksimum depth of cut -> untuk pengulangan proses
A63: 5. Material apa yang digunakan? Untuk stainless steel, gunakan 'Carbon steel up to 63 kgf/mm2'
A65: 6. Lihat cutting speed dan feed rate yang direkomendasikan.
A91: LANGKAH MEMBACA REFERENSI KALPAKJIAN - DRILLING
...

Sheet Blank Punch
A1: LEMBAR RENCANA PROSES | K1: GAMBAR PART
A3: No . | B3: 2.3 | E3: Halaman ke-
A4: No . Part | B4: 2.3 | E4: File Gambar
A5: Nama Part | B5: Blank Punch | E5: Material | F5: SKD11
E6: Ukuran | F6: Panjang | G6: 39 | I6: mm
A7: Dibuat oleh | B7: Kelompok 19 | F7: Lebar/Diameter | G7: 14 | I7: mm
A8: Tanggal | B8: 19 Desember 2024 | F8: Tinggi | G8: 30 | I8: mm
A10: No. Proses | B10: Urutan Operasi | C10: Stasiun Kerja | D10: Setup | F10: Tools | G10: Waktu Setup (detik) | H10: Waktu Proses (detik) | I10: Waktu Total (detik)
D11: n | E11: alat bantu
A12: 1 | B12: Drilling (D = 4mm, d = 8mm) Right Side 5x | C12: CNC Milling | E12: Standard Vise | F12: HSS Center Drill | G12: =180 + (4.68/5)*0.2 -> 180.1872 | H12: ='Perhitungan LRP (Blank Punch)'!J19 -> 2.2857143 | I12: =G12+H12 -> 182.47291
A13: 2 | B13: Drilling (D = 4mm, d = 8mm) Left Side 5x | C13: CNC Milling | E13: Standard Vise | F13: HSS Center Drill | G13: =180 + (4.68/5)*0.2 -> 180.1872 | H13: ='Perhitungan LRP (Blank Punch)'!J20 -> 2.2857143 | I13: =G13+H13 -> 182.47291
A14: 3 | B14: Drilling (D = 8mm, d = 8mm) Center 2x | C14: CNC Milling | E14: Standard Vise | F14: HSS Center Drill | G14: =180 + (4.68/5)*0.2 -> 180.1872 | H14: ='Perhitungan LRP (Blank Punch)'!J21 -> 0.91428571 | I14: =G14+H14 -> 181.10149
A15: 4 | B15: Shell-end Milling Finishing (D = 14mm, d = 5mm) All Side 6x | C15: CNC Milling | E15: Standard Vise | F15: HSS Milling Tools | G15: =(180)+((4.68/5)*0.25)*60 -> 194.04 | H15: ='Perhitungan LRP (Blank Punch)'!L7 -> 2.1142857 | I15: =G15+H15 -> 196.15429
A16: 5 | B16: Inspeksi | C16: Meja Kerja | E16: Jangka Sorong | F16: Jangka Sorong | G16: 0 | H16: 180 | I16: =G16+H16 -> 180
H32: Total | I32: =sum(I12:I16) -> 922.2016
B38: Raw Material | F38: Produk akhir yang diinginkan
B53: Ilustrasi urutan operasi berdasarkan LRP

Sheet Perhitungan LRP (Blank Punch)
A1: PERHITUNGAN LEMBAR RENCANA PROSES | T1: DRILLING | AE1: TURNING
A5: MILLING
A6: No. Proses | B6: Nama Proses | C6: D (mm) | D6: d (mm) | E6: L (mm) | F6: v (mm/min) | G6: N (rev/min) | H6: fr (mm/min) | I6: w (mm) | J6: A (mm) | K6: Tm (min) | L6: Tm (sekon) | M6: MRR (mm3/min) | N6: Volume Awal (mm3) | O6: Scrap | P6: %Scrap | Q6: Volume Akhir (mm3)
A7: 4 | B7: Shell-end Milling Finishing (D = 14mm, d = 5mm) All Side 6x | C7: 14 | D7: 5 | E7: 30 | F7: 8500 | G7: =F7/3.14*C7 -> 37898.089 | H7: 1050 | I7: 14 | J7: 7 | K7: =(E7+J7)/H7 -> 0.035238095 | L7: =K7*60 -> 2.1142857 | M7: =I7*D7*H7 -> 73500 | N7: =O21 -> 15776.815 | O7: =C7*D7*E7*6 -> 12600 | P7: =(O7/N7)*100% -> 0.7986403 | Q7: =N7-O7 -> 3176.8147
A11: TURNING
A12: No. Proses | B12: Nama Proses | C12: Do (mm) | D12: Df (mm) | E12: d (mm) | F12: d maks (mm) | G12: L (mm) | H12: f (mm/rev) | I12: v (mm/min) | J12: N (rev/min) | K12: fr (mm/min) | L12: Tm (min) | M12: Tm (sekon) | N12: MRR (mm3/min) | O12: Volume Awal (mm3) | P12: Scrap | Q12: % Scrap | R12: Volume Akhir (mm3)
A17: DRILLING (TERMASUK TAPPING DAN BORING)
A18: No. Proses | B18: Nama Proses | C18: D (mm) | D18: d (mm) | E18: f (mm/rev) | F18: v(mm/min) | G18: N (rev/min) | H18: fr (mm/min) | I18: Tm (min) | J18: Tm (sekon) | K18: MRR (mm3/min) | L18: Volume Awal (mm3) | M18: Scrap | N18: % Scrap | O18: Volume Akhir (mm3)
A19: 1 | B19: Drilling (D = 4mm, d = 8mm) Right Side 5x | C19: 4 | D19: 8 | E19: 0.04 | F19: 500 | G19: =H19/E19 -> 26250 | H19: 1050 | I19: =(D19/H19)*5 -> 0.038095238 | J19: =I19*60 -> 2.2857143 | K19: =(3.14*(C19*C19)*H19)/4 -> 13188 | L19: 16380 | M19: =3.14159*(C19/2)^2*D19 -> 100.53088 | N19: =(M19/L19)*100% -> 0.0061374164 | O19: =L19-M19 -> 16279.469
A20: 2 | B20: Drilling (D = 4mm, d = 8mm) Left Side 5x | C20: 4 | D20: 8 | E20: 0.04 | F20: 500 | G20: =H20/E20 -> 26250 | H20: 1050 | I20: =(D20/H20)*5 -> 0.038095238 | J20: =I20*60 -> 2.2857143 | K20: =(3.14*(C20*C20)*H20)/4 -> 13188 | L20: =O19 -> 16279.469 | M20: =3.14159*(C20/2)^2*D20 -> 100.53088 | N20: =(M20/L20)*100% -> 0.0061753169 | O20: =L20-M20 -> 16178.938
A21: 3 | B21: Drilling (D = 8mm, d = 8mm) Center 2x | C21: 8 | D21: 8 | E21: 0.04 | F21: 500 | G21: =H21/E21 -> 26250 | H21: 1050 | I21: =(D21/H21)*2 -> 0.015238095 | J21: =I21*60 -> 0.91428571 | K21: =(3.14*(C21*C21)*H21)/4 -> 52752 | L21: =O20 -> 16178.938 | M21: =3.14159*((C21/2)^2)*D21 -> 402.12352 | N21: =(M21/L21)*100% -> 0.024854753 | O21: =L21-M21 -> 15776.815
A24: PRESSING (BLANKING, PUNCHING, EMBOSS, DEBOSS)
A25: No. Proses | B25: Nama Proses | C25: TS(MPa) | D25: t (mm) | E25: L (mm) | F25: Volume Awal (mm3) | G25: SPM | H25: Tm (min) | I25: Tm (s) | J25: Scrap | K25: %Scrap | L25: Volume Akhir (mm3) | T25: MILLING | AE25: BENDING
A26: 2
P28: =POWER(3,2) -> 9
A30: PRESSING (BENDING)
A31: No. Proses | B31: Nama Proses | C31: Kbf | D31: w (mm) | E31: TS (Mpa) | F31: t (mm) | G31: D (mm) | H31: F (N) | I31: SPM | J31: Tm (min) | K31: Tm (s) | L31: Scrap (mm3)
A35: CUTTING (TERMASUK CHAMFERING LINEAR)
A36: No. Proses | B36: Nama Proses | C36: A (mm) | D36: t (mm) | E36: θ | F36: Volume Awal | G36: Scrap | H36: % Scrap | I36: Volume Akhir (mm3)
A37: 5
A41: LANGKAH MEMBACA REFERENSI KALPAKJIAN - MILLING
A44: 1. Operasi yang ingin digunakan?
A46: 2. Untuk operasi tersebut, perhatikan diameter tools (maximum width of cut) yang digunakan -> untuk pengulangan proses
A48: 3. Proses roughing atau finishing? Ingat semua milling harus ada proses finishing (kecuali dinyatakan sebaliknya).
A50: 4. Untuk operasi tersebut, perhatikan maksimum depth of cut -> untuk pengulangan proses
A52: 5. Material apa yang digunakan? Untuk stainless steel, gunakan 'Carbon steel up to 63 kgf/mm2'
A54: 6. Lihat cutting speed dan feed rate yang direkomendasikan.
U62: PUNCHING/BLANKING
A80: LANGKAH MEMBACA REFERENSI KALPAKJIAN - DRILLING
A82: 1. Berapa diameter drilling yang diinginkan?
A84: 2. Material apa yang digunakan?
A86: 3. Lihat cutting speed dan feed yang direkomendasikan (feed, bukan feed rate)
A87: (cutting speed > feed)
A89: 4. Gunakan interpolasi apabila diperlukan (misal: ketika diameter drill 8 mm)
A91: 5. Lihat cooling/lubricant agents yang direkomendasikan bila diperlukan
A117: LANGKAH MEMBACA REFERENSI KALPAKJIAN - TURNING
A118: 1. Berapa feed yang ingin digunakan? (Pertimbangkan trade off-nya)
A120: 2. Material apa yang digunakan?
A122: 3. Cutting tool apa yang digunakan? (Pertimbangkan trade off HSS dan TCT)
A124: 4. Lihat cutting speed yang direkomendasikan
