Workbook
Name No: 1

Sheet Data
B1: PT PPST Manufacturing
B3: Facility detail
B4: Facility Length | D4: 30 | E4: Area | F4: %Utilized
B5: Facility Width | D5: 35 | E5: =D4*D5 -> 1050 | F5: =SUM(M12:M23)/E5 -> 0.69871467
B6: Number of Departments | D6: 12
B7: Number of Restricted Areas | D7: 0
H8: 0 = Existing | K8: 0 = Movable
B9: Department detail | H9: 1 = New | K9: 1 = Fixed
B10: No | C10: Department's Name | D10: Length | E10: Width | F10: Load/Unload Point | H10: New? | I10: Coordinate | K10: Fixed? | L10: Label | M10: Area | N10: Color | O10: Sequ-ence
F11: x-offset | G11: y-offset | I11: x-center | J11: y-center
B12: 1 | C12: Receiving | D12: 8.24 | E12: 8.24 | F12: 0 | G12: 0 | H12: 0 | I12: 4.12 | J12: 4.12 | K12: 1 | L12: R | M12: 67.8976 | N12: bisque
B13: 2 | C13: Gudang Bahan Baku Utana | D13: 7.71 | E13: 6.97 | F13: 0 | G13: 0 | H13: 1 | K13: 0 | L13: GBBU | M13: 53.7387 | N13: darkorange | O13: 1
B14: 3 | C14: Gudang Bahan Baku Pembantu | D14: 5.89 | E14: 10.12 | F14: 0 | G14: 0 | H14: 1 | K14: 0 | L14: GBBP | M14: 59.6068 | N14: forestgreen | O14: 2
B15: 4 | C15: Mesin Drilling | D15: 6.912 | E15: 6.22 | F15: 0 | G15: 0 | H15: 1 | K15: 0 | L15: DRL | M15: 42.99264 | N15: slategray | O15: 3
B16: 5 | C16: Mesin Injection Molding | D16: 6.687 | E16: 6.24 | F16: 0 | G16: 0 | H16: 1 | K16: 0 | L16: INJ | M16: 41.72688 | N16: gold | O16: 4
B17: 6 | C17: Mesin Milling | D17: 29.01 | E17: 6.5 | F17: 0 | G17: 0 | H17: 1 | K17: 0 | L17: MIL | M17: 188.565 | N17: turquoise | O17: 5
B18: 7 | C18: Mesin Turning | D18: 7.84 | E18: 6.492 | F18: 0 | G18: 0 | H18: 1 | K18: 0 | L18: TUR | M18: 50.89728 | N18: navy | O18: 6
B19: 8 | C19: Kerja Bangku | D19: 12.85 | E19: 6.2 | F19: 0 | G19: 0 | H19: 1 | K19: 0 | L19: KRJ | M19: 79.67 | N19: lavender | O19: 7
B20: 9 | C20: Bench Perakitan | D20: 7.15 | E20: 6.25 | F20: 0 | G20: 0 | H20: 1 | K20: 0 | L20: RKT | M20: 44.6875 | N20: coral | O20: 8
B21: 10 | C21: Bench Pengemasan | D21: 7.9 | E21: 6.17 | F21: 0 | G21: 0 | H21: 1 | K21: 0 | L21: PGM | M21: 48.743 | N21: mediumvioletred | O21: 9
B22: 11 | C22: Warehousing | D22: 5.25 | E22: 5.25 | F22: 0 | G22: 0 | H22: 1 | K22: 0 | L22: WRH | M22: 27.5625 | N22: khaki | O22: 10
B23: 12 | C23: Shipping | D23: 5.25 | E23: 5.25 | F23: 0 | G23: 0 | H23: 0 | I23: 10.865 | J23: 2.625 | K23: 1 | L23: SHP | M23: 27.5625 | N23: deepskyblue
B25: Restricted area detail
B26: No | C26: Restricted Area's Name | D26: Length | E26: Width | F26: Coordinate | H26: Label | I26: Area | J26: Color
F27: x-center | G27: y-center
B29: Flow Matrix
C30: To | D30: 1 | E30: 2 | F30: 3 | G30: 4 | H30: 5 | I30: 6 | J30: 7 | K30: 8 | L30: 9 | M30: 10 | N30: 11 | O30: 12
B31: From | C31: 1 | D31: 0 | E31: 1 | F31: 1 | G31: 0 | H31: 0 | I31: 0 | J31: 0 | K31: 0 | L31: 0 | M31: 0 | N31: 0 | O31: 0
C32: 2 | D32: 0 | E32: 0 | F32: 0 | G32: 0 | H32: 0 | I32: 0 | J32: 0 | K32: 2 | L32: 0 | M32: 0 | N32: 0 | O32: 0
C33: 3 | D33: 0 | E33: 0 | F33: 0 | G33: 0 | H33: 0 | I33: 0 | J33: 0 | K33: 5 | L33: 0 | M33: 0 | N33: 0 | O33: 0
C34: 4 | D34: 0 | E34: 0 | F34: 0 | G34: 0 | H34: 0 | I34: 0 | J34: 0 | K34: 1 | L34: 0 | M34: 0 | N34: 0 | O34: 0
C35: 5 | D35: 0 | E35: 0 | F35: 0 | G35: 0 | H35: 0 | I35: 1 | J35: 0 | K35: 1 | L35: 0 | M35: 0 | N35: 0 | O35: 0
C36: 6 | D36: 0 | E36: 0 | F36: 0 | G36: 0 | H36: 1 | I36: 0 | J36: 0 | K36: 2 | L36: 0 | M36: 0 | N36: 0 | O36: 0
C37: 7 | D37: 0 | E37: 0 | F37: 0 | G37: 0 | H37: 2 | I37: 1 | J37: 0 | K37: 1 | L37: 0 | M37: 0 | N37: 0 | O37: 0
C38: 8 | D38: 0 | E38: 0 | F38: 0 | G38: 1 | H38: 1 | I38: 1 | J38: 8 | K38: 0 | L38: 2 | M38: 0 | N38: 0 | O38: 0
C39: 9 | D39: 0 | E39: 0 | F39: 0 | G39: 0 | H39: 0 | I39: 0 | J39: 0 | K39: 0 | L39: 0 | M39: 3 | N39: 0 | O39: 0
C40: 10 | D40: 0 | E40: 0 | F40: 0 | G40: 0 | H40: 0 | I40: 0 | J40: 0 | K40: 0 | L40: 0 | M40: 0 | N40: 3 | O40: 0
C41: 11 | D41: 0 | E41: 0 | F41: 0 | G41: 0 | H41: 0 | I41: 0 | J41: 0 | K41: 0 | L41: 0 | M41: 0 | N41: 0 | O41: 1
C42: 12 | D42: 0 | E42: 0 | F42: 0 | G42: 0 | H42: 0 | I42: 0 | J42: 0 | K42: 0 | L42: 0 | M42: 0 | N42: 0 | O42: 0
B44: Cost Matrix
...

Sheet Result
C3: 1 | D3: 2 | E3: 3 | F3: 4 | G3: 5 | H3: 6 | I3: 7 | J3: 8 | K3: 9 | L3: 10 | M3: 11 | N3: 12
B4: x | C4: 4.12 | D4: 4.12 | E4: 11.185 | F4: 4.163 | G4: 4.2755 | H4: 17.38 | I4: 10.865 | J4: 23.73 | K4: 30.78 | L4: 30.78 | M4: 23.255 | N4: 10.865
B5: y | C5: 4.12 | D5: 11.725 | E5: 10.31 | F5: 18.32 | G5: 24.55 | H5: 15.495 | I5: 19.29 | J5: 18.32 | K5: 9.295 | L5: 3.085 | M5: 2.625 | N5: 2.625
B6: x_in | C6: 4.12 | D6: 4.12 | E6: 11.185 | F6: 4.163 | G6: 4.2755 | H6: 17.38 | I6: 10.865 | J6: 23.73 | K6: 30.78 | L6: 30.78 | M6: 23.255 | N6: 10.865
B7: y_in | C7: 4.12 | D7: 11.725 | E7: 10.31 | F7: 18.32 | G7: 24.55 | H7: 15.495 | I7: 19.29 | J7: 18.32 | K7: 9.295 | L7: 3.085 | M7: 2.625 | N7: 2.625
B8: H_bound | C8: 4.12 | D8: 3.855 | E8: 2.945 | F8: 3.456 | G8: 3.3435 | H8: 3.25 | I8: 3.246 | J8: 3.1 | K8: 3.575 | L8: 3.95 | M8: 2.625 | N8: 2.625
B9: V_bound | C9: 4.12 | D9: 3.485 | E9: 5.06 | F9: 3.11 | G9: 3.12 | H9: 14.505 | I9: 3.92 | J9: 6.425 | K9: 3.125 | L9: 3.085 | M9: 2.625 | N9: 2.625
C11: decision variable
A12: m | B12: Label | C12: x | D12: y | E12: x_in | F12: y_in | G12: H_bound | H12: V_bound
A13: 1 | B13: =Data!L12 -> R | C13: {=TRANSPOSE(C4:N9)} -> 4.12 | D13: 4.12 | E13: 4.12 | F13: 4.12 | G13: 4.12 | H13: 4.12
A14: 2 | B14: =Data!L13 -> GBBU | C14: 4.12 | D14: 11.725 | E14: 4.12 | F14: 11.725 | G14: 3.855 | H14: 3.485
A15: 3 | B15: =Data!L14 -> GBBP | C15: 11.185 | D15: 10.31 | E15: 11.185 | F15: 10.31 | G15: 2.945 | H15: 5.06
A16: 4 | B16: =Data!L15 -> DRL | C16: 4.163 | D16: 18.32 | E16: 4.163 | F16: 18.32 | G16: 3.456 | H16: 3.11
A17: 5 | B17: =Data!L16 -> INJ | C17: 4.2755 | D17: 24.55 | E17: 4.2755 | F17: 24.55 | G17: 3.3435 | H17: 3.12
A18: 6 | B18: =Data!L17 -> MIL | C18: 17.38 | D18: 15.495 | E18: 17.38 | F18: 15.495 | G18: 3.25 | H18: 14.505
A19: 7 | B19: =Data!L18 -> TUR | C19: 10.865 | D19: 19.29 | E19: 10.865 | F19: 19.29 | G19: 3.246 | H19: 3.92
A20: 8 | B20: =Data!L19 -> KRJ | C20: 23.73 | D20: 18.32 | E20: 23.73 | F20: 18.32 | G20: 3.1 | H20: 6.425
A21: 9 | B21: =Data!L20 -> RKT | C21: 30.78 | D21: 9.295 | E21: 30.78 | F21: 9.295 | G21: 3.575 | H21: 3.125
A22: 10 | B22: =Data!L21 -> PGM | C22: 30.78 | D22: 3.085 | E22: 30.78 | F22: 3.085 | G22: 3.95 | H22: 3.085
A23: 11 | B23: =Data!L22 -> WRH | C23: 23.255 | D23: 2.625 | E23: 23.255 | F23: 2.625 | G23: 2.625 | H23: 2.625
A24: 12 | B24: =Data!L23 -> SHP | C24: 10.865 | D24: 2.625 | E24: 10.865 | F24: 2.625 | G24: 2.625 | H24: 2.625
A27: dXmn | B27: n | C27: 1 | D27: 2 | E27: 3 | F27: 4 | G27: 5 | H27: 6 | I27: 7 | J27: 8 | K27: 9 | L27: 10 | M27: 11 | N27: 12
A28: m | B28: 1 | C28: =ABS(VLOOKUP($B28,$A$13:$AG$24,5,FALSE)-VLOOKUP(C$27,$A$13:$AG$24,5,FALSE)) -> 0 | D28: =ABS(VLOOKUP($B28,$A$13:$AG$24,5,FALSE)-VLOOKUP(D$27,$A$13:$AG$24,5,FALSE)) -> 0 | E28: =ABS(VLOOKUP($B28,$A$13:$AG$24,5,FALSE)-VLOOKUP(E$27,$A$13:$AG$24,5,FALSE)) -> 7.065 | F28: =ABS(VLOOKUP($B28,$A$13:$AG$24,5,FALSE)-VLOOKUP(F$27,$A$13:$AG$24,5,FALSE)) -> 0.043 | G28: =ABS(VLOOKUP($B28,$A$13:$AG$24,5,FALSE)-VLOOKUP(G$27,$A$13:$AG$24,5,FALSE)) -> 0.1555 | H28: =ABS(VLOOKUP($B28,$A$13:$AG$24,5,FALSE)-VLOOKUP(H$27,$A$13:$AG$24,5,FALSE)) -> 13.26 | I28: =ABS(VLOOKUP($B28,$A$13:$AG$24,5,FALSE)-VLOOKUP(I$27,$A$13:$AG$24,5,FALSE)) -> 6.745 | J28: =ABS(VLOOKUP($B28,$A$13:$AG$24,5,FALSE)-VLOOKUP(J$27,$A$13:$AG$24,5,FALSE)) -> 19.61 | ... N28: =ABS(VLOOKUP($B28,$A$13:$AG$24,5,FALSE)-VLOOKUP(N$27,$A$13:$AG$24,5,FALSE)) -> 6.745
B29: 2 | C29: =ABS(VLOOKUP($B29,$A$13:$AG$24,5,FALSE)-VLOOKUP(C$27,$A$13:$AG$24,5,FALSE)) -> 0 | D29: =ABS(VLOOKUP($B29,$A$13:$AG$24,5,FALSE)-VLOOKUP(D$27,$A$13:$AG$24,5,FALSE)) -> 0 | E29: =ABS(VLOOKUP($B29,$A$13:$AG$24,5,FALSE)-VLOOKUP(E$27,$A$13:$AG$24,5,FALSE)) -> 7.065 | F29: =ABS(VLOOKUP($B29,$A$13:$AG$24,5,FALSE)-VLOOKUP(F$27,$A$13:$AG$24,5,FALSE)) -> 0.043 | G29: =ABS(VLOOKUP($B29,$A$13:$AG$24,5,FALSE)-VLOOKUP(G$27,$A$13:$AG$24,5,FALSE)) -> 0.1555 | H29: =ABS(VLOOKUP($B29,$A$13:$AG$24,5,FALSE)-VLOOKUP(H$27,$A$13:$AG$24,5,FALSE)) -> 13.26 | I29: =ABS(VLOOKUP($B29,$A$13:$AG$24,5,FALSE)-VLOOKUP(I$27,$A$13:$AG$24,5,FALSE)) -> 6.745 | J29: =ABS(VLOOKUP($B29,$A$13:$AG$24,5,FALSE)-VLOOKUP(J$27,$A$13:$AG$24,5,FALSE)) -> 19.61 | ... N29: =ABS(VLOOKUP($B29,$A$13:$AG$24,5,FALSE)-VLOOKUP(N$27,$A$13:$AG$24,5,FALSE)) -> 6.745
B30: 3 | C30: =ABS(VLOOKUP($B30,$A$13:$AG$24,5,FALSE)-VLOOKUP(C$27,$A$13:$AG$24,5,FALSE)) -> 7.065 | D30: =ABS(VLOOKUP($B30,$A$13:$AG$24,5,FALSE)-VLOOKUP(D$27,$A$13:$AG$24,5,FALSE)) -> 7.065 | E30: =ABS(VLOOKUP($B30,$A$13:$AG$24,5,FALSE)-VLOOKUP(E$27,$A$13:$AG$24,5,FALSE)) -> 0 | F30: =ABS(VLOOKUP($B30,$A$13:$AG$24,5,FALSE)-VLOOKUP(F$27,$A$13:$AG$24,5,FALSE)) -> 7.022 | G30: =ABS(VLOOKUP($B30,$A$13:$AG$24,5,FALSE)-VLOOKUP(G$27,$A$13:$AG$24,5,FALSE)) -> 6.9095 | H30: =ABS(VLOOKUP($B30,$A$13:$AG$24,5,FALSE)-VLOOKUP(H$27,$A$13:$AG$24,5,FALSE)) -> 6.195 | I30: =ABS(VLOOKUP($B30,$A$13:$AG$24,5,FALSE)-VLOOKUP(I$27,$A$13:$AG$24,5,FALSE)) -> 0.32 | J30: =ABS(VLOOKUP($B30,$A$13:$AG$24,5,FALSE)-VLOOKUP(J$27,$A$13:$AG$24,5,FALSE)) -> 12.545 | ... N30: =ABS(VLOOKUP($B30,$A$13:$AG$24,5,FALSE)-VLOOKUP(N$27,$A$13:$AG$24,5,FALSE)) -> 0.32
B31: 4 | C31: =ABS(VLOOKUP($B31,$A$13:$AG$24,5,FALSE)-VLOOKUP(C$27,$A$13:$AG$24,5,FALSE)) -> 0.043 | D31: =ABS(VLOOKUP($B31,$A$13:$AG$24,5,FALSE)-VLOOKUP(D$27,$A$13:$AG$24,5,FALSE)) -> 0.043 | E31: =ABS(VLOOKUP($B31,$A$13:$AG$24,5,FALSE)-VLOOKUP(E$27,$A$13:$AG$24,5,FALSE)) -> 7.022 | F31: =ABS(VLOOKUP($B31,$A$13:$AG$24,5,FALSE)-VLOOKUP(F$27,$A$13:$AG$24,5,FALSE)) -> 0 | G31: =ABS(VLOOKUP($B31,$A$13:$AG$24,5,FALSE)-VLOOKUP(G$27,$A$13:$AG$24,5,FALSE)) -> 0.1125 | H31: =ABS(VLOOKUP($B31,$A$13:$AG$24,5,FALSE)-VLOOKUP(H$27,$A$13:$AG$24,5,FALSE)) -> 13.217 | I31: =ABS(VLOOKUP($B31,$A$13:$AG$24,5,FALSE)-VLOOKUP(I$27,$A$13:$AG$24,5,FALSE)) -> 6.702 | J31: =ABS(VLOOKUP($B31,$A$13:$AG$24,5,FALSE)-VLOOKUP(J$27,$A$13:$AG$24,5,FALSE)) -> 19.567 | ... N31: =ABS(VLOOKUP($B31,$A$13:$AG$24,5,FALSE)-VLOOKUP(N$27,$A$13:$AG$24,5,FALSE)) -> 6.702
B32: 5 | C32: =ABS(VLOOKUP($B32,$A$13:$AG$24,5,FALSE)-VLOOKUP(C$27,$A$13:$AG$24,5,FALSE)) -> 0.1555 | D32: =ABS(VLOOKUP($B32,$A$13:$AG$24,5,FALSE)-VLOOKUP(D$27,$A$13:$AG$24,5,FALSE)) -> 0.1555 | E32: =ABS(VLOOKUP($B32,$A$13:$AG$24,5,FALSE)-VLOOKUP(E$27,$A$13:$AG$24,5,FALSE)) -> 6.9095 | F32: =ABS(VLOOKUP($B32,$A$13:$AG$24,5,FALSE)-VLOOKUP(F$27,$A$13:$AG$24,5,FALSE)) -> 0.1125 | G32: =ABS(VLOOKUP($B32,$A$13:$AG$24,5,FALSE)-VLOOKUP(G$27,$A$13:$AG$24,5,FALSE)) -> 0 | H32: =ABS(VLOOKUP($B32,$A$13:$AG$24,5,FALSE)-VLOOKUP(H$27,$A$13:$AG$24,5,FALSE)) -> 13.1045 | I32: =ABS(VLOOKUP($B32,$A$13:$AG$24,5,FALSE)-VLOOKUP(I$27,$A$13:$AG$24,5,FALSE)) -> 6.5895 | J32: =ABS(VLOOKUP($B32,$A$13:$AG$24,5,FALSE)-VLOOKUP(J$27,$A$13:$AG$24,5,FALSE)) -> 19.4545 | ... N32: =ABS(VLOOKUP($B32,$A$13:$AG$24,5,FALSE)-VLOOKUP(N$27,$A$13:$AG$24,5,FALSE)) -> 6.5895
B33: 6 | C33: =ABS(VLOOKUP($B33,$A$13:$AG$24,5,FALSE)-VLOOKUP(C$27,$A$13:$AG$24,5,FALSE)) -> 13.26 | D33: =ABS(VLOOKUP($B33,$A$13:$AG$24,5,FALSE)-VLOOKUP(D$27,$A$13:$AG$24,5,FALSE)) -> 13.26 | E33: =ABS(VLOOKUP($B33,$A$13:$AG$24,5,FALSE)-VLOOKUP(E$27,$A$13:$AG$24,5,FALSE)) -> 6.195 | F33: =ABS(VLOOKUP($B33,$A$13:$AG$24,5,FALSE)-VLOOKUP(F$27,$A$13:$AG$24,5,FALSE)) -> 13.217 | G33: =ABS(VLOOKUP($B33,$A$13:$AG$24,5,FALSE)-VLOOKUP(G$27,$A$13:$AG$24,5,FALSE)) -> 13.1045 | H33: =ABS(VLOOKUP($B33,$A$13:$AG$24,5,FALSE)-VLOOKUP(H$27,$A$13:$AG$24,5,FALSE)) -> 0 | I33: =ABS(VLOOKUP($B33,$A$13:$AG$24,5,FALSE)-VLOOKUP(I$27,$A$13:$AG$24,5,FALSE)) -> 6.515 | J33: =ABS(VLOOKUP($B33,$A$13:$AG$24,5,FALSE)-VLOOKUP(J$27,$A$13:$AG$24,5,FALSE)) -> 6.35 | ... N33: =ABS(VLOOKUP($B33,$A$13:$AG$24,5,FALSE)-VLOOKUP(N$27,$A$13:$AG$24,5,FALSE)) -> 6.515
B34: 7 | C34: =ABS(VLOOKUP($B34,$A$13:$AG$24,5,FALSE)-VLOOKUP(C$27,$A$13:$AG$24,5,FALSE)) -> 6.745 | D34: =ABS(VLOOKUP($B34,$A$13:$AG$24,5,FALSE)-VLOOKUP(D$27,$A$13:$AG$24,5,FALSE)) -> 6.745 | E34: =ABS(VLOOKUP($B34,$A$13:$AG$24,5,FALSE)-VLOOKUP(E$27,$A$13:$AG$24,5,FALSE)) -> 0.32 | F34: =ABS(VLOOKUP($B34,$A$13:$AG$24,5,FALSE)-VLOOKUP(F$27,$A$13:$AG$24,5,FALSE)) -> 6.702 | G34: =ABS(VLOOKUP($B34,$A$13:$AG$24,5,FALSE)-VLOOKUP(G$27,$A$13:$AG$24,5,FALSE)) -> 6.5895 | H34: =ABS(VLOOKUP($B34,$A$13:$AG$24,5,FALSE)-VLOOKUP(H$27,$A$13:$AG$24,5,FALSE)) -> 6.515 | I34: =ABS(VLOOKUP($B34,$A$13:$AG$24,5,FALSE)-VLOOKUP(I$27,$A$13:$AG$24,5,FALSE)) -> 0 | J34: =ABS(VLOOKUP($B34,$A$13:$AG$24,5,FALSE)-VLOOKUP(J$27,$A$13:$AG$24,5,FALSE)) -> 12.865 | ... N34: =ABS(VLOOKUP($B34,$A$13:$AG$24,5,FALSE)-VLOOKUP(N$27,$A$13:$AG$24,5,FALSE)) -> 0
B35: 8 | C35: =ABS(VLOOKUP($B35,$A$13:$AG$24,5,FALSE)-VLOOKUP(C$27,$A$13:$AG$24,5,FALSE)) -> 19.61 | D35: =ABS(VLOOKUP($B35,$A$13:$AG$24,5,FALSE)-VLOOKUP(D$27,$A$13:$AG$24,5,FALSE)) -> 19.61 | E35: =ABS(VLOOKUP($B35,$A$13:$AG$24,5,FALSE)-VLOOKUP(E$27,$A$13:$AG$24,5,FALSE)) -> 12.545 | F35: =ABS(VLOOKUP($B35,$A$13:$AG$24,5,FALSE)-VLOOKUP(F$27,$A$13:$AG$24,5,FALSE)) -> 19.567 | G35: =ABS(VLOOKUP($B35,$A$13:$AG$24,5,FALSE)-VLOOKUP(G$27,$A$13:$AG$24,5,FALSE)) -> 19.4545 | H35: =ABS(VLOOKUP($B35,$A$13:$AG$24,5,FALSE)-VLOOKUP(H$27,$A$13:$AG$24,5,FALSE)) -> 6.35 | I35: =ABS(VLOOKUP($B35,$A$13:$AG$24,5,FALSE)-VLOOKUP(I$27,$A$13:$AG$24,5,FALSE)) -> 12.865 | J35: =ABS(VLOOKUP($B35,$A$13:$AG$24,5,FALSE)-VLOOKUP(J$27,$A$13:$AG$24,5,FALSE)) -> 0 | ... N35: =ABS(VLOOKUP($B35,$A$13:$AG$24,5,FALSE)-VLOOKUP(N$27,$A$13:$AG$24,5,FALSE)) -> 12.865
B36: 9 | C36: =ABS(VLOOKUP($B36,$A$13:$AG$24,5,FALSE)-VLOOKUP(C$27,$A$13:$AG$24,5,FALSE)) -> 26.66 | D36: =ABS(VLOOKUP($B36,$A$13:$AG$24,5,FALSE)-VLOOKUP(D$27,$A$13:$AG$24,5,FALSE)) -> 26.66 | E36: =ABS(VLOOKUP($B36,$A$13:$AG$24,5,FALSE)-VLOOKUP(E$27,$A$13:$AG$24,5,FALSE)) -> 19.595 | F36: =ABS(VLOOKUP($B36,$A$13:$AG$24,5,FALSE)-VLOOKUP(F$27,$A$13:$AG$24,5,FALSE)) -> 26.617 | G36: =ABS(VLOOKUP($B36,$A$13:$AG$24,5,FALSE)-VLOOKUP(G$27,$A$13:$AG$24,5,FALSE)) -> 26.5045 | H36: =ABS(VLOOKUP($B36,$A$13:$AG$24,5,FALSE)-VLOOKUP(H$27,$A$13:$AG$24,5,FALSE)) -> 13.4 | I36: =ABS(VLOOKUP($B36,$A$13:$AG$24,5,FALSE)-VLOOKUP(I$27,$A$13:$AG$24,5,FALSE)) -> 19.915 | J36: =ABS(VLOOKUP($B36,$A$13:$AG$24,5,FALSE)-VLOOKUP(J$27,$A$13:$AG$24,5,FALSE)) -> 7.05 | ... N36: =ABS(VLOOKUP($B36,$A$13:$AG$24,5,FALSE)-VLOOKUP(N$27,$A$13:$AG$24,5,FALSE)) -> 19.915
B37: 10 | C37: =ABS(VLOOKUP($B37,$A$13:$AG$24,5,FALSE)-VLOOKUP(C$27,$A$13:$AG$24,5,FALSE)) -> 26.66 | D37: =ABS(VLOOKUP($B37,$A$13:$AG$24,5,FALSE)-VLOOKUP(D$27,$A$13:$AG$24,5,FALSE)) -> 26.66 | E37: =ABS(VLOOKUP($B37,$A$13:$AG$24,5,FALSE)-VLOOKUP(E$27,$A$13:$AG$24,5,FALSE)) -> 19.595 | F37: =ABS(VLOOKUP($B37,$A$13:$AG$24,5,FALSE)-VLOOKUP(F$27,$A$13:$AG$24,5,FALSE)) -> 26.617 | G37: =ABS(VLOOKUP($B37,$A$13:$AG$24,5,FALSE)-VLOOKUP(G$27,$A$13:$AG$24,5,FALSE)) -> 26.5045 | H37: =ABS(VLOOKUP($B37,$A$13:$AG$24,5,FALSE)-VLOOKUP(H$27,$A$13:$AG$24,5,FALSE)) -> 13.4 | I37: =ABS(VLOOKUP($B37,$A$13:$AG$24,5,FALSE)-VLOOKUP(I$27,$A$13:$AG$24,5,FALSE)) -> 19.915 | J37: =ABS(VLOOKUP($B37,$A$13:$AG$24,5,FALSE)-VLOOKUP(J$27,$A$13:$AG$24,5,FALSE)) -> 7.05 | ... N37: =ABS(VLOOKUP($B37,$A$13:$AG$24,5,FALSE)-VLOOKUP(N$27,$A$13:$AG$24,5,FALSE)) -> 19.915
B38: 11 | C38: =ABS(VLOOKUP($B38,$A$13:$AG$24,5,FALSE)-VLOOKUP(C$27,$A$13:$AG$24,5,FALSE)) -> 19.135 | D38: =ABS(VLOOKUP($B38,$A$13:$AG$24,5,FALSE)-VLOOKUP(D$27,$A$13:$AG$24,5,FALSE)) -> 19.135 | E38: =ABS(VLOOKUP($B38,$A$13:$AG$24,5,FALSE)-VLOOKUP(E$27,$A$13:$AG$24,5,FALSE)) -> 12.07 | F38: =ABS(VLOOKUP($B38,$A$13:$AG$24,5,FALSE)-VLOOKUP(F$27,$A$13:$AG$24,5,FALSE)) -> 19.092 | G38: =ABS(VLOOKUP($B38,$A$13:$AG$24,5,FALSE)-VLOOKUP(G$27,$A$13:$AG$24,5,FALSE)) -> 18.9795 | H38: =ABS(VLOOKUP($B38,$A$13:$AG$24,5,FALSE)-VLOOKUP(H$27,$A$13:$AG$24,5,FALSE)) -> 5.875 | I38: =ABS(VLOOKUP($B38,$A$13:$AG$24,5,FALSE)-VLOOKUP(I$27,$A$13:$AG$24,5,FALSE)) -> 12.39 | J38: =ABS(VLOOKUP($B38,$A$13:$AG$24,5,FALSE)-VLOOKUP(J$27,$A$13:$AG$24,5,FALSE)) -> 0.475 | ... N38: =ABS(VLOOKUP($B38,$A$13:$AG$24,5,FALSE)-VLOOKUP(N$27,$A$13:$AG$24,5,FALSE)) -> 12.39
B39: 12 | C39: =ABS(VLOOKUP($B39,$A$13:$AG$24,5,FALSE)-VLOOKUP(C$27,$A$13:$AG$24,5,FALSE)) -> 6.745 | D39: =ABS(VLOOKUP($B39,$A$13:$AG$24,5,FALSE)-VLOOKUP(D$27,$A$13:$AG$24,5,FALSE)) -> 6.745 | E39: =ABS(VLOOKUP($B39,$A$13:$AG$24,5,FALSE)-VLOOKUP(E$27,$A$13:$AG$24,5,FALSE)) -> 0.32 | F39: =ABS(VLOOKUP($B39,$A$13:$AG$24,5,FALSE)-VLOOKUP(F$27,$A$13:$AG$24,5,FALSE)) -> 6.702 | G39: =ABS(VLOOKUP($B39,$A$13:$AG$24,5,FALSE)-VLOOKUP(G$27,$A$13:$AG$24,5,FALSE)) -> 6.5895 | H39: =ABS(VLOOKUP($B39,$A$13:$AG$24,5,FALSE)-VLOOKUP(H$27,$A$13:$AG$24,5,FALSE)) -> 6.515 | I39: =ABS(VLOOKUP($B39,$A$13:$AG$24,5,FALSE)-VLOOKUP(I$27,$A$13:$AG$24,5,FALSE)) -> 0 | J39: =ABS(VLOOKUP($B39,$A$13:$AG$24,5,FALSE)-VLOOKUP(J$27,$A$13:$AG$24,5,FALSE)) -> 12.865 | ... N39: =ABS(VLOOKUP($B39,$A$13:$AG$24,5,FALSE)-VLOOKUP(N$27,$A$13:$AG$24,5,FALSE)) -> 0
A42: dYmn | B42: n | C42: 1 | D42: 2 | E42: 3 | F42: 4 | G42: 5 | H42: 6 | I42: 7 | J42: 8 | K42: 9 | L42: 10 | M42: 11 | N42: 12
A43: m | B43: 1 | C43: =ABS(VLOOKUP($B43,$A$13:$AG$24,6,FALSE)-VLOOKUP(C$42,$A$13:$AG$24,6,FALSE)) -> 0 | D43: =ABS(VLOOKUP($B43,$A$13:$AG$24,6,FALSE)-VLOOKUP(D$42,$A$13:$AG$24,6,FALSE)) -> 7.605 | E43: =ABS(VLOOKUP($B43,$A$13:$AG$24,6,FALSE)-VLOOKUP(E$42,$A$13:$AG$24,6,FALSE)) -> 6.19 | F43: =ABS(VLOOKUP($B43,$A$13:$AG$24,6,FALSE)-VLOOKUP(F$42,$A$13:$AG$24,6,FALSE)) -> 14.2 | G43: =ABS(VLOOKUP($B43,$A$13:$AG$24,6,FALSE)-VLOOKUP(G$42,$A$13:$AG$24,6,FALSE)) -> 20.43 | H43: =ABS(VLOOKUP($B43,$A$13:$AG$24,6,FALSE)-VLOOKUP(H$42,$A$13:$AG$24,6,FALSE)) -> 11.375 | I43: =ABS(VLOOKUP($B43,$A$13:$AG$24,6,FALSE)-VLOOKUP(I$42,$A$13:$AG$24,6,FALSE)) -> 15.17 | J43: =ABS(VLOOKUP($B43,$A$13:$AG$24,6,FALSE)-VLOOKUP(J$42,$A$13:$AG$24,6,FALSE)) -> 14.2 | ... N43: =ABS(VLOOKUP($B43,$A$13:$AG$24,6,FALSE)-VLOOKUP(N$42,$A$13:$AG$24,6,FALSE)) -> 1.495
B44: 2 | C44: =ABS(VLOOKUP($B44,$A$13:$AG$24,6,FALSE)-VLOOKUP(C$42,$A$13:$AG$24,6,FALSE)) -> 7.605 | D44: =ABS(VLOOKUP($B44,$A$13:$AG$24,6,FALSE)-VLOOKUP(D$42,$A$13:$AG$24,6,FALSE)) -> 0 | E44: =ABS(VLOOKUP($B44,$A$13:$AG$24,6,FALSE)-VLOOKUP(E$42,$A$13:$AG$24,6,FALSE)) -> 1.415 | F44: =ABS(VLOOKUP($B44,$A$13:$AG$24,6,FALSE)-VLOOKUP(F$42,$A$13:$AG$24,6,FALSE)) -> 6.595 | G44: =ABS(VLOOKUP($B44,$A$13:$AG$24,6,FALSE)-VLOOKUP(G$42,$A$13:$AG$24,6,FALSE)) -> 12.825 | H44: =ABS(VLOOKUP($B44,$A$13:$AG$24,6,FALSE)-VLOOKUP(H$42,$A$13:$AG$24,6,FALSE)) -> 3.77 | I44: =ABS(VLOOKUP($B44,$A$13:$AG$24,6,FALSE)-VLOOKUP(I$42,$A$13:$AG$24,6,FALSE)) -> 7.565 | J44: =ABS(VLOOKUP($B44,$A$13:$AG$24,6,FALSE)-VLOOKUP(J$42,$A$13:$AG$24,6,FALSE)) -> 6.595 | ... N44: =ABS(VLOOKUP($B44,$A$13:$AG$24,6,FALSE)-VLOOKUP(N$42,$A$13:$AG$24,6,FALSE)) -> 9.1
B45: 3 | C45: =ABS(VLOOKUP($B45,$A$13:$AG$24,6,FALSE)-VLOOKUP(C$42,$A$13:$AG$24,6,FALSE)) -> 6.19 | D45: =ABS(VLOOKUP($B45,$A$13:$AG$24,6,FALSE)-VLOOKUP(D$42,$A$13:$AG$24,6,FALSE)) -> 1.415 | E45: =ABS(VLOOKUP($B45,$A$13:$AG$24,6,FALSE)-VLOOKUP(E$42,$A$13:$AG$24,6,FALSE)) -> 0 | F45: =ABS(VLOOKUP($B45,$A$13:$AG$24,6,FALSE)-VLOOKUP(F$42,$A$13:$AG$24,6,FALSE)) -> 8.01 | G45: =ABS(VLOOKUP($B45,$A$13:$AG$24,6,FALSE)-VLOOKUP(G$42,$A$13:$AG$24,6,FALSE)) -> 14.24 | H45: =ABS(VLOOKUP($B45,$A$13:$AG$24,6,FALSE)-VLOOKUP(H$42,$A$13:$AG$24,6,FALSE)) -> 5.185 | I45: =ABS(VLOOKUP($B45,$A$13:$AG$24,6,FALSE)-VLOOKUP(I$42,$A$13:$AG$24,6,FALSE)) -> 8.98 | J45: =ABS(VLOOKUP($B45,$A$13:$AG$24,6,FALSE)-VLOOKUP(J$42,$A$13:$AG$24,6,FALSE)) -> 8.01 | ... N45: =ABS(VLOOKUP($B45,$A$13:$AG$24,6,FALSE)-VLOOKUP(N$42,$A$13:$AG$24,6,FALSE)) -> 7.685
B46: 4 | C46: =ABS(VLOOKUP($B46,$A$13:$AG$24,6,FALSE)-VLOOKUP(C$42,$A$13:$AG$24,6,FALSE)) -> 14.2 | D46: =ABS(VLOOKUP($B46,$A$13:$AG$24,6,FALSE)-VLOOKUP(D$42,$A$13:$AG$24,6,FALSE)) -> 6.595 | E46: =ABS(VLOOKUP($B46,$A$13:$AG$24,6,FALSE)-VLOOKUP(E$42,$A$13:$AG$24,6,FALSE)) -> 8.01 | F46: =ABS(VLOOKUP($B46,$A$13:$AG$24,6,FALSE)-VLOOKUP(F$42,$A$13:$AG$24,6,FALSE)) -> 0 | G46: =ABS(VLOOKUP($B46,$A$13:$AG$24,6,FALSE)-VLOOKUP(G$42,$A$13:$AG$24,6,FALSE)) -> 6.23 | H46: =ABS(VLOOKUP($B46,$A$13:$AG$24,6,FALSE)-VLOOKUP(H$42,$A$13:$AG$24,6,FALSE)) -> 2.825 | I46: =ABS(VLOOKUP($B46,$A$13:$AG$24,6,FALSE)-VLOOKUP(I$42,$A$13:$AG$24,6,FALSE)) -> 0.97 | J46: =ABS(VLOOKUP($B46,$A$13:$AG$24,6,FALSE)-VLOOKUP(J$42,$A$13:$AG$24,6,FALSE)) -> 0 | ... N46: =ABS(VLOOKUP($B46,$A$13:$AG$24,6,FALSE)-VLOOKUP(N$42,$A$13:$AG$24,6,FALSE)) -> 15.695
B47: 5 | C47: =ABS(VLOOKUP($B47,$A$13:$AG$24,6,FALSE)-VLOOKUP(C$42,$A$13:$AG$24,6,FALSE)) -> 20.43 | D47: =ABS(VLOOKUP($B47,$A$13:$AG$24,6,FALSE)-VLOOKUP(D$42,$A$13:$AG$24,6,FALSE)) -> 12.825 | E47: =ABS(VLOOKUP($B47,$A$13:$AG$24,6,FALSE)-VLOOKUP(E$42,$A$13:$AG$24,6,FALSE)) -> 14.24 | F47: =ABS(VLOOKUP($B47,$A$13:$AG$24,6,FALSE)-VLOOKUP(F$42,$A$13:$AG$24,6,FALSE)) -> 6.23 | G47: =ABS(VLOOKUP($B47,$A$13:$AG$24,6,FALSE)-VLOOKUP(G$42,$A$13:$AG$24,6,FALSE)) -> 0 | H47: =ABS(VLOOKUP($B47,$A$13:$AG$24,6,FALSE)-VLOOKUP(H$42,$A$13:$AG$24,6,FALSE)) -> 9.055 | I47: =ABS(VLOOKUP($B47,$A$13:$AG$24,6,FALSE)-VLOOKUP(I$42,$A$13:$AG$24,6,FALSE)) -> 5.26 | J47: =ABS(VLOOKUP($B47,$A$13:$AG$24,6,FALSE)-VLOOKUP(J$42,$A$13:$AG$24,6,FALSE)) -> 6.23 | ... N47: =ABS(VLOOKUP($B47,$A$13:$AG$24,6,FALSE)-VLOOKUP(N$42,$A$13:$AG$24,6,FALSE)) -> 21.925
...

Sheet Color
