Workbook

Sheet Perhitungan FD
A1: Perhitungan Jarak Flow Diagram
B4: ANALISIS PERBANDINGAN PERHITUNGAN JARAK FLOW DIAGRAM
B5: Berdasarkan hasil perbandingan perhitungan jarak transportasi pada flow diagram proses Turning, diketahui bahwa rancangan usulan memiliki total jarak sebesar 27,76 meter, sedangkan kondisi eksisting mencapai 33,88 meter. Hal ini menunjukkan adanya pengurangan jarak transportasi sebesar 6,12 meter atau sekitar 18,06%. Pengurangan ini mencerminkan efisiensi dalam penataan tata letak proses, yang ditunjukkan oleh distribusi jarak yang lebih merata pada rancangan usulan, khususnya pada proses T-3 hingga T-5 yang masing-masing berjarak 2,16 meter. Dengan penataan yang lebih ringkas dan terfokus, aliran material menjadi lebih lancar, waktu tempuh antar proses dapat dipersingkat, dan potensi peningkatan produktivitas pun meningkat. Oleh karena itu, rancangan usulan dapat dianggap lebih optimal dan layak untuk diterapkan guna mendukung efisiensi operasional di lantai produksi.
B11: Proses
B12: Turning
B14: Perhitungan Jarak Transportasi Eksisting | F14: Perhitungan Jarak Transportasi Usulan
B15: No Proses | C15: Jarak (m) | F15: No Proses | G15: Jarak (m)
B16: T-1 | C16: 20.48 | F16: T-1 | G16: =3.08+13.88+0.51+1.44 -> 18.91
B17: T-2 | C17: 1.95 | F17: T-2 | G17: 1.12
B18: T-3 | C18: 3.03 | F18: T-3 | G18: 2.16
B19: T-4 | C19: 2.86 | F19: T-4 | G19: 2.16
B20: T-5 | C20: 3.01 | F20: T-5 | G20: 2.16
B21: T-6 | C21: 2.55 | F21: T-6 | G21: 1.25
B32: Total | C32: =SUM(C16:C31) -> 33.88 | F32: Total | G32: =SUM(G16:G31) -> 27.76

Sheet PPM Eksisting
A1: PETA PEKERJA DAN MESIN
A3: Pekerjaan | C3: : Turning
A4: Nama Mesin | C4: : Mesin Turning
A5: Pekerja
A7: SEKARANG | D7: USULAN | M7: DIPETAKAN OLEH | O7: : Kelompok C08
M8: TANGGAL | O8: :14 Mei 2025
A10: NO | B10: ORANG | L10: MESIN
B11: ASISTEN OPERATOR | E11: Waktu (det) | G11: OPERATOR | J11: Waktu (det) | L11: MESIN TURNING | O11: Waktu (det) | Q11: Jenis Setup
E12: Operasi | F12: Lambang | J12: Operasi | K12: Lambang | O12: Operasi | P12: Lambang | Q12: Internal/Eksternal | R12: Lambang | S12: Lambang
A13: 1 | B13: Berjalan menuju rak material | E13: 13.4 | G13: Menunggu | J13: =E13 -> 13.4 | L13: Mesin dalam keadaan mati | O13: =J13 -> 13.4 | Q13: Internal | R13: SH | S13: UD | T13: =SUM(O13:O42) -> 97.76
A14: 2 | B14: Meraih material | E14: 0.6 | G14: Menunggu | J14: =E14 -> 0.6 | L14: Mesin dalam keadaan mati | O14: =E14 -> 0.6 | Q14: Internal | R14: RE | S14: UD
A15: 3 | B15: Membawa material ke meja kerja | E15: 2.5 | G15: Menunggu | J15: =E15 -> 2.5 | L15: Mesin dalam keadaan mati | O15: =E15 -> 2.5 | Q15: Internal | R15: M | S15: UD
A16: 4 | B16: Melepas material | E16: 0.6 | G16: Menunggu | J16: =E16 -> 0.6 | L16: Mesin dalam keadaan mati | O16: =E16 -> 0.6 | Q16: Internal | R16: RL | S16: UD
A17: 5 | B17: Menunggu | E17: 0.7 | G17: Meraih material | J17: =E17 -> 0.7 | L17: Mesin dalam keadaan mati | O17: =E17 -> 0.7 | Q17: Internal | R17: UD | S17: RE
A18: 6 | B18: Menunggu | E18: 0.2 | G18: Memegang material | J18: =E18 -> 0.2 | L18: Mesin dalam keadaan mati | O18: =E18 -> 0.2 | Q18: Internal | R18: UD | S18: G
A19: 7 | B19: Menunggu | E19: 0.7 | G19: Membawa material | J19: =E19 -> 0.7 | L19: Mesin dalam keadaan mati | O19: =E19 -> 0.7 | Q19: Internal | R19: UD | S19: M
A20: 8 | B20: Menunggu | E20: =J20 -> 6.27 | G20: Memeriksa ukuran material | J20: 6.27 | L20: Mesin dalam keadaan mati | O20: =J20 -> 6.27 | Q20: Internal | R20: UD | S20: I
B21: Menunggu | E21: =J21 -> 4.22 | G21: Membawa material dan gamtek ke mesin | J21: 4.22 | L21: Mesin dalam keadaan mati | O21: =J21 -> 4.22 | Q21: Internal | R21: UD | S21: M
B22: Menunggu | E22: =J22 -> 4.18 | G22: Memasang gamtek ke tempatnya | J22: 4.18 | L22: Mesin dalam keadaan mati | O22: =J22 -> 4.18 | Q22: Internal | R22: UD | S22: P
B23: Menunggu | E23: =J23 -> 1.03 | G23: Menjangkau material | J23: 1.03 | L23: Mesin dalam keadaan mati | O23: =J23 -> 1.03 | Q23: Internal | R23: UD | S23: RE
B24: Menunggu | E24: =J24 -> 0.11 | G24: Menjangkau alat ukur | J24: 0.11 | L24: Mesin dalam keadaan mati | O24: =J24 -> 0.11 | Q24: Internal | R24: UD | S24: H
B25: Menunggu | E25: =J25 -> 1.09 | G25: Membawa alat ukur | J25: 1.09 | L25: Mesin dalam keadaan mati | O25: =J25 -> 1.09 | Q25: Internal | R25: UD | S25: M
B26: Menunggu | E26: =J26 -> 3.13 | G26: Memeriksa ukuran material | J26: 3.13 | L26: Mesin dalam keadaan mati | O26: =J26 -> 3.13 | Q26: Internal | R26: UD | S26: I
B27: Menunggu | E27: =J27 -> 2.22 | G27: Menaruh HP ke tas | J27: 2.22 | L27: Mesin dalam keadaan mati | O27: =J27 -> 2.22 | Q27: Internal | R27: AD | S27: AD
B28: Menunggu | E28: =J28 -> 6.22 | G28: Menjangkau spidol | J28: 6.22 | L28: Mesin dalam keadaan mati | O28: =J28 -> 6.22 | Q28: Internal | R28: UD | S28: RE
B29: Menunggu | E29: =J29 -> 3.21 | G29: Memberi tanda dengan spidol | J29: 3.21 | L29: Mesin dalam keadaan mati | O29: =J29 -> 3.21 | Q29: Internal | R29: UD | S29: U
B30: Menunggu | E30: =J30 -> 1.1 | G30: Menaruh spidol | J30: 1.1 | L30: Mesin dalam keadaan mati | O30: =J30 -> 1.1 | Q30: Internal | R30: UD | S30: RL
B31: Menunggu | E31: =J31 -> 1.08 | G31: Menaruh alat ukur | J31: 1.08 | L31: Mesin dalam keadaan mati | O31: =J31 -> 1.08 | Q31: Internal | R31: UD | S31: RL
B32: Menunggu | E32: =J32 -> 3.03 | G32: Mengarahkan material ke mesin | J32: 3.03 | L32: Mesin dalam keadaan mati | O32: =J32 -> 3.03 | Q32: Internal | R32: UD | S32: p
... B44: Menunggu | E44: =J44 -> 56.81 | G44: Memposisikan mesin agar sesuai dengan material | J44: 56.81 | L44: Mesin dalam keadaan menyala | O44: =J44 -> 56.81 | Q44: Eksternal | R44: UD | S44: P
B45: Menunggu | E45: =J45 -> 2.01 | G45: Mengambil spidol | J45: 2.01 | L45: Mesin dalam keadaan menyala | O45: =J45 -> 2.01 | Q45: Internal | R45: UD | S45: RE | T45: =SUM(O45:O47) -> 7.24
B46: Menunggu | E46: =J46 -> 3.08 | G46: Memberi tanda dengan spidol | J46: 3.08 | L46: Mesin dalam keadaan menyala | O46: =J46 -> 3.08 | Q46: Internal | R46: UD | S46: U
B47: Menunggu | E47: =J47 -> 2.15 | G47: Menaruh spidol | J47: 2.15 | L47: Mesin dalam keadaan menyala | O47: =J47 -> 2.15 | Q47: Internal | R47: UD | S47: RL
B48: Menunggu | E48: =J48 -> 16.15 | G48: Memutar handle untuk mengarahkan posisi mesin | J48: 16.15 | L48: Mesin dalam keadaan menyala | O48: =J48 -> 16.15 | Q48: Eksternal | R48: UD | S48: P
B49: Menunggu | E49: =J49 -> 2.19 | G49: Memeriksa monitor | J49: 2.19 | L49: Mesin dalam keadaan menyala | O49: =J49 -> 2.19 | Q49: Eksternal | R49: UD | S49: I
B50: Menunggu | E50: =J50 -> 11 | G50: Memutar handle untuk mengarahkan posisi mesin | J50: 11 | L50: Mesin dalam keadaan menyala | O50: =J50 -> 11 | Q50: Eksternal | R50: UD | S50: P
B51: Menunggu | E51: =J51 -> 5.01 | G51: Mengamati mesin | J51: 5.01 | L51: Mesin dalam keadaan menyala | O51: =J51 -> 5.01 | Q51: Eksternal | R51: UD | S51: I
B52: Menunggu | E52: =J52 -> 41.34 | G52: Memutar handle untuk mengarahkan posisi mesin | J52: 41.34 | L52: Mesin dalam keadaan menyala | O52: =J52 -> 41.34 | Q52: Eksternal | R52: UD | S52: P
B53: Menunggu | E53: =J53 -> 2.06 | G53: Mengamati mesin | J53: 2.06 | L53: Mesin dalam keadaan menyala | O53: =J53 -> 2.06 | Q53: Eksternal | R53: UD | S53: I
B54: Menunggu | E54: =J54 -> 2.08 | G54: Membuang benang yang tidak terkait | J54: 2.08 | L54: Mesin dalam keadaan menyala | O54: =J54 -> 2.08 | Q54: Internal | R54: UD | S54: RL | T54: =O54 -> 2.08
...

Sheet PPM Usulan
A1: PETA PEKERJA DAN MESIN
A3: Pekerjaan | C3: Turning
A4: Nama Mesin | C4: Mesin Turning
A5: Pekerja
A7: SEKARANG | D7: USULAN | M7: DIPETAKAN OLEH | O7: : Kelompok C08
M8: TANGGAL | O8: :14 Mei 2025
A10: NO | B10: ORANG | G10: MESIN
B11: OPERATOR 1 | E11: Waktu (det) | G11: MESIN TURNING | J11: Waktu (det) | L11: Jenis Setup
E12: Operasi | F12: Lambang | J12: Operasi | K12: Lambang | L12: Internal/Eksternal
A13: 1 | B13: Menunggu | E13: 13.4 | G13: Mesin dalam keadaan mati | J13: =E13 -> 13.4 | L13: Internal | M13: =SUM(J13:J41) -> 85.41
A14: 2 | B14: Menunggu | E14: 0.6 | G14: Mesin dalam keadaan mati | J14: =E14 -> 0.6 | L14: Internal
A15: 3 | B15: Menunggu | E15: 2.5 | G15: Mesin dalam keadaan mati | J15: =E15 -> 2.5 | L15: Internal
A16: 4 | B16: Menunggu | E16: 0.6 | G16: Mesin dalam keadaan mati | J16: =E16 -> 0.6 | L16: Internal
A17: 5 | B17: Meraih material | E17: 0.7 | G17: Mesin dalam keadaan mati | J17: =E17 -> 0.7 | L17: Internal
A18: 6 | B18: Memegang material | E18: 0.2 | G18: Mesin dalam keadaan mati | J18: =E18 -> 0.2 | L18: Internal
A19: 7 | B19: Membawa material | E19: 0.7 | G19: Mesin dalam keadaan mati | J19: =E19 -> 0.7 | L19: Internal
A20: 8 | B20: Memeriksa ukuran material | E20: 6.27 | G20: Mesin dalam keadaan mati | J20: 6.27 | L20: Internal
B21: Membawa material dan gamtek ke mesin | E21: 4.22 | G21: Mesin dalam keadaan mati | J21: 4.22 | L21: Internal
B22: Memasang gamtek ke tempatnya | E22: 4.18 | G22: Mesin dalam keadaan mati | J22: 4.18 | L22: Internal
B23: Menjangkau material | E23: 1.03 | G23: Mesin dalam keadaan mati | J23: 1.03 | L23: Internal
B24: Menjangkau alat ukur | E24: 0.11 | G24: Mesin dalam keadaan mati | J24: 0.11 | L24: Internal
B25: Membawa alat ukur | E25: 1.09 | G25: Mesin dalam keadaan mati | J25: 1.09 | L25: Internal
B26: Memeriksa ukuran material | E26: 3.13 | G26: Mesin dalam keadaan mati | J26: 3.13 | L26: Internal
B27: Menjangkau spidol | E27: 0.5 | G27: Mesin dalam keadaan mati | J27: 0.5 | L27: Internal
B28: Memberi tanda dengan spidol | E28: 3.21 | G28: Mesin dalam keadaan mati | J28: 3.21 | L28: Internal
B29: Menaruh spidol | E29: 0.5 | G29: Mesin dalam keadaan mati | J29: 0.5 | L29: Internal
B30: Menaruh alat ukur | E30: 0.5 | G30: Mesin dalam keadaan mati | J30: 0.5 | L30: Internal
B31: Mengarahkan material ke mesin | E31: 3.03 | G31: Mesin dalam keadaan mati | J31: 3.03 | L31: Internal
B32: Mempersiapkan susunan material dan mesin | E32: 12.1 | G32: Mesin dalam keadaan mati | J32: 12.1 | L32: Internal
... B43: Memposisikan mesin agar sesuai dengan material | E43: 56.81 | G43: Mesin dalam keadaan menyala | J43: 56.81 | L43: Eksternal
B44: Mengambil spidol | E44: 0.5 | G44: Mesin dalam keadaan menyala | J44: 0.5 | L44: Internal | M44: =SUM(J44:J46) -> 4.08
B45: Memberi tanda dengan spidol | E45: 3.08 | G45: Mesin dalam keadaan menyala | J45: 3.08 | L45: Internal
B46: Menaruh spidol | E46: 0.5 | G46: Mesin dalam keadaan menyala | J46: 0.5 | L46: Internal
B47: Memutar handle untuk mengarahkan posisi mesin | E47: 16.15 | G47: Mesin dalam keadaan menyala | J47: 16.15 | L47: Eksternal
B48: Memeriksa monitor | E48: 2.19 | G48: Mesin dalam keadaan menyala | J48: 2.19 | L48: Eksternal
B49: Memutar handle untuk mengarahkan posisi mesin | E49: 11 | G49: Mesin dalam keadaan menyala | J49: 11 | L49: Eksternal
B50: Mengamati mesin | E50: 5.01 | G50: Mesin dalam keadaan menyala | J50: 5.01 | L50: Eksternal
B51: Memutar handle untuk mengarahkan posisi mesin | E51: 41.34 | G51: Mesin dalam keadaan menyala | J51: 41.34 | L51: Eksternal
B52: Mengamati mesin | E52: 2.06 | G52: Mesin dalam keadaan menyala | J52: 2.06 | L52: Eksternal
B53: Mengamati mesin | E53: 7.09 | G53: Mesin dalam keadaan menyala | J53: 7.09 | L53: Eksternal
...

Sheet Tabel Gerakan Therblig PPM
A1: Gerakan Therblig - Material Handler | F1: Gerakan Therblig - Operator 1
A2: Jenis Gerakan | B2: Lambang | C2: Turus | D2: Frekuensi | F2: Jenis Gerakan | G2: Lambang | H2: Turus | I2: Frekuensi
A3: Mencari | B3: SH | C3: =REPT("I",D3) -> I | D3: =COUNTIF('PPM Eksisting'!$R$13:$R$266,'Tabel Gerakan Therblig PPM'!B3) -> 1 | F3: Mencari | G3: SH | H3: =REPT("I",I3) | I3: =COUNTIF('PPM Eksisting'!$S$13:$S$22,'Tabel Gerakan Therblig PPM'!G3) -> 0
A4: Memilih | B4: ST | C4: =REPT("I",D4) | D4: =COUNTIF('PPM Eksisting'!$R$13:$R$266,'Tabel Gerakan Therblig PPM'!B4) -> 0 | F4: Memilih | G4: ST | H4: =REPT("I",I4) | I4: =COUNTIF('PPM Eksisting'!$S$13:$S$266,'Tabel Gerakan Therblig PPM'!G4) -> 0
A5: Memegang | B5: G | C5: =REPT("I",D5) -> I | D5: =COUNTIF('PPM Eksisting'!$R$13:$R$266,'Tabel Gerakan Therblig PPM'!B5) -> 1 | F5: Memegang | G5: G | H5: =REPT("I",I5) -> IIIIII | I5: =COUNTIF('PPM Eksisting'!$S$13:$S$266,'Tabel Gerakan Therblig PPM'!G5) -> 6
A6: Menjangkau | B6: RE | C6: =REPT("I",D6) -> II | D6: =COUNTIF('PPM Eksisting'!$R$13:$R$266,'Tabel Gerakan Therblig PPM'!B6) -> 2 | F6: Menjangkau | G6: RE | H6: =REPT("I",I6) -> IIIIIIIIIIIIIIIIIIIIIIIIIIIIIIIIIII | I6: =COUNTIF('PPM Eksisting'!$S$13:$S$266,'Tabel Gerakan Therblig PPM'!G6) -> 35
A7: Membawa | B7: M | C7: =REPT("I",D7) -> II | D7: =COUNTIF('PPM Eksisting'!$R$13:$R$266,'Tabel Gerakan Therblig PPM'!B7) -> 2 | F7: Membawa | G7: M | H7: =REPT("I",I7) -> IIIIIIIIII | I7: =COUNTIF('PPM Eksisting'!$S$13:$S$266,'Tabel Gerakan Therblig PPM'!G7) -> 10
A8: Memegang untuk memakai | B8: H | C8: =REPT("I",D8) | D8: =COUNTIF('PPM Eksisting'!$R$13:$R$266,'Tabel Gerakan Therblig PPM'!B8) -> 0 | F8: Memegang untuk memakai | G8: H | H8: =REPT("I",I8) -> IIIIIIIIIIII | I8: =COUNTIF('PPM Eksisting'!$S$13:$S$266,'Tabel Gerakan Therblig PPM'!G8) -> 12
A9: Melepas | B9: RL | C9: =REPT("I",D9) -> II | D9: =COUNTIF('PPM Eksisting'!$R$13:$R$266,'Tabel Gerakan Therblig PPM'!B9) -> 2 | F9: Melepas | G9: RL | H9: =REPT("I",I9) -> IIIIIIIIIIIIIIIIIIIIII | I9: =COUNTIF('PPM Eksisting'!$S$13:$S$266,'Tabel Gerakan Therblig PPM'!G9) -> 22
A10: Mengarahkan | B10: P | C10: =REPT("I",D10) | D10: =COUNTIF('PPM Eksisting'!$R$13:$R$266,'Tabel Gerakan Therblig PPM'!B10) -> 0 | F10: Mengarahkan | G10: P | H10: =REPT("I",I10) -> IIIIIIIIIIIIIIIIIIIIIIIIIIIIIIIIII | I10: =COUNTIF('PPM Eksisting'!$S$13:$S$266,'Tabel Gerakan Therblig PPM'!G10) -> 34
A11: Mengarahkan sementara | B11: PP | C11: =REPT("I",D11) | D11: =COUNTIF('PPM Eksisting'!$R$13:$R$266,'Tabel Gerakan Therblig PPM'!B11) -> 0 | F11: Mengarahkan sementara | G11: PP | H11: =REPT("I",I11) | I11: =COUNTIF('PPM Eksisting'!$S$13:$S$266,'Tabel Gerakan Therblig PPM'!G11) -> 0
A12: Memeriksa | B12: I | C12: =REPT("I",D12) | D12: =COUNTIF('PPM Eksisting'!$R$13:$R$266,'Tabel Gerakan Therblig PPM'!B12) -> 0 | F12: Memeriksa | G12: I | H12: =REPT("I",I12) -> IIIIIIIIIIIIIIIIIIIIIIIIIIIIIIIIIIIIIIIIIIIII | I12: =COUNTIF('PPM Eksisting'!$S$13:$S$266,'Tabel Gerakan Therblig PPM'!G12) -> 45
A13: Merakit | B13: A | C13: =REPT("I",D13) | D13: =COUNTIF('PPM Eksisting'!$R$13:$R$266,'Tabel Gerakan Therblig PPM'!B13) -> 0 | F13: Merakit | G13: A | H13: =REPT("I",I13) -> I | I13: =COUNTIF('PPM Eksisting'!$S$13:$S$266,'Tabel Gerakan Therblig PPM'!G13) -> 1
A14: Melepas rakitan | B14: DA | C14: =REPT("I",D14) | D14: =COUNTIF('PPM Eksisting'!$R$13:$R$266,'Tabel Gerakan Therblig PPM'!B14) -> 0 | F14: Melepas rakitan | G14: DA | H14: =REPT("I",I14) | I14: =COUNTIF('PPM Eksisting'!$S$13:$S$266,'Tabel Gerakan Therblig PPM'!G14) -> 0
A15: Memakai | B15: U | C15: =REPT("I",D15) | D15: =COUNTIF('PPM Eksisting'!$R$13:$R$266,'Tabel Gerakan Therblig PPM'!B15) -> 0 | F15: Memakai | G15: U | H15: =REPT("I",I15) -> IIIIIIIIIIIIIIIIIIIIIIIIIIIIIIIIIIIIIIIIIIIIIIIIIIIIIIIIIIIIIIIIIIIIIIIIIIIII | I15: =COUNTIF('PPM Eksisting'!$S$13:$S$266,'Tabel Gerakan Therblig PPM'!G15) -> 77
... A19: Istirahat | B19: R | C19: =REPT("I",D19) | D19: =COUNTIF('PPM Eksisting'!$R$13:$R$266,'Tabel Gerakan Therblig PPM'!B19) -> 0 | F19: Istirahat | G19: R | H19: =REPT("I",I19) -> IIIIIII | I19: =COUNTIF('PPM Eksisting'!$S$13:$S$266,'Tabel Gerakan Therblig PPM'!G19) -> 7
A20: Total | D20: =SUM(D3:D19) -> 254 | F20: Total | I20: =SUM(I3:I19) -> 254
A22: YANG JADI PROBLEM TUH GERAKAN TAMBAHAN DAN LUAR YANG KURANG BENEFICIAL DAN BISA DIHILANGKAN

Sheet Tabel Pemborosan Kerja PPM
A1: TABEL PEMBOROSAN PADA OPERASI
A3: Asisten Operator | G3: Operator
A4: Nama Pemborosan | B4: Jenis Pemborosan | C4: Turus | D4: Frekuensi | E4: Persentase | F4: Persentase Kumulatif | G4: Nama Pemborosan | H4: Jenis Pemborosan | I4: Turus | J4: Frekuensi | K4: Persentase | L4: Persentase Kumulatif
A5: Keterlambatan yang tidak dapat dihindari | B5: Non-added value motion | C5: IIIIIIIIIIIIIIIIIIIIIIIIIIIIIIIIIIIIIIIIIIIIIIIIIIIIIIIIIIIIIIIIIIIIIIIIIIIIIIIIIIIIIIIIIIIIIIIIIIIIIIIIIIIIIIIIIIIIIIIIIIIIIIIIIIIIIIIIIIIIIIIIIIIIIIIIIIIIIIIIIIIIIIIIIIIIIIIIIIIIIIIIIIIIIIIIIIIIIIIIIIIIIIIIIIIIIIIIIIIIIIIIIIIIIIIIIIIIIIIIIII | D5: 243 | E5: =D5/$D$19 -> 1 | F5: =E5 -> 1 | G5: Menjangkau | H5: Non-added value motion | I5: IIIIIIIIIIIIIIIIIIIIIIIIIIIIIIIIIII | J5: 35 | K5: =J5/$J$19 -> 0.21212121 | L5: =K5 -> 0.21212121
G6: Membawa | H6: Non-added value motion | I6: IIIIIIIIII | J6: 10 | K6: =J6/$J$19 -> 0.060606061 | L6: =K6 -> 0.060606061
G7: Memegang untuk memakai | H7: Non-added value motion | I7: IIIIIIIIIIII | J7: 12 | K7: =J7/$J$19 -> 0.072727273 | L7: =K7 -> 0.072727273
G8: Melepas | H8: Non-added value motion | I8: IIIIIIIIIIIIIIIIIIIIII | J8: 22 | K8: =J8/$J$19 -> 0.13333333 | L8: =K8 -> 0.13333333
G9: Mengarahkan | H9: Non-added value motion | I9: IIIIIIIIIIIIIIIIIIIIIIIIIIIIIIIIII | J9: 34 | K9: =J9/$J$19 -> 0.20606061 | L9: =K9 -> 0.20606061
G10: Memeriksa | H10: Non-added value motion | I10: IIIIIIIIIIIIIIIIIIIIIIIIIIIIIIIIIIIIIIIIIIIII | J10: 45 | K10: =J10/$J$19 -> 0.27272727 | L10: =K10 -> 0.27272727
G11: Istirahat | H11: Non-added value motion | I11: IIIIIII | J11: 7 | K11: =J11/$J$19 -> 0.042424242 | L11: =K11 -> 0.042424242
E13: =D13/$D$19 -> 0 | F13: =F12+E13 -> 0 | K13: =J13/$D$19 -> 0 | L13: =L12+K13 -> 0
E14: =D14/$D$19 -> 0 | F14: =F13+E14 -> 0 | K14: =J14/$D$19 -> 0 | L14: =L13+K14 -> 0
E15: =D15/$D$19 -> 0 | F15: =F14+E15 -> 0 | K15: =J15/$D$19 -> 0 | L15: =L14+K15 -> 0
E16: =D16/$D$19 -> 0 | F16: =F15+E16 -> 0 | K16: =J16/$D$19 -> 0 | L16: =L15+K16 -> 0
E17: =D17/$D$19 -> 0 | F17: =F16+E17 -> 0 | K17: =J17/$D$19 -> 0 | L17: =L16+K17 -> 0
E18: =D18/$D$19 -> 0 | F18: =F17+E18 -> 0 | K18: =J18/$D$19 -> 0 | L18: =L17+K18 -> 0
C19: Total | D19: =SUM(D5:D18) -> 243 | I19: Total | J19: =SUM(J5:J18) -> 165
A40: Usulan pada keseluruhan sistem kerja
A41: Pada asisten operator dapat dilihat bahwa keterlambatan yang tidak bisa dihindari memakan waktu yang banyak dalam pemborosan.
A42: Dalam data pemborosan operator dapat dilihat bahwa gerakan yang paling banyak memakan waktu adalah memeriksa, mengarahkan, menjangkau.
A43: Sehingga, usulan yang dapat kami berikan adalah
A44: mengurangi tenaga kerja dengan menghapus keberadaan asisten operator,
A45: dan menempatkan alat sesuai tempat yang disediakan untuk membantu operator mengurangi waktu menjangkau dan mengarahkan, serta '
A46: menyediakan kertas dan pulpen ataupun sejenisnya untuk membantu operator menuliskan hasil perhitungan agar inspeksi tidak dilakukan berulang dan memakan waktu berlebih
C54: Pada asisten operator dapat dilihat bahwa keterlambatan yang tidak bisa dihindari memakan waktu yang banyak dalam pemborosan.Dalam data pemborosan operator dapat dilihat bahwa gerakan yang paling banyak memakan waktu adalah memeriksa, mengarahkan, menjangkau. Sehingga, usulan yang dapat kami berikan adalah mengurangi tenaga kerja dengan menghapus keberadaan asisten operator, dan menempatkan alat sesuai tempat yang disediakan untuk membantu operator mengurangi waktu menjangkau dan mengarahkan, serta ' menyediakan kertas dan pulpen ataupun sejenisnya untuk membantu operator menuliskan hasil perhitungan agar inspeksi tidak dilakukan berulang dan memakan waktu berlebih
