Workbook

Sheet Format LRP
A1: LEMBAR RENCANA PROSES | K1: GAMBAR PART
A3: No . | E3: Halaman ke-
A4: No . Part | E4: File Gambar
A5: Nama Part | E5: Material
E6: Ukuran | F6: Panjang | I6: mm
A7: Dibuat oleh | F7: Lebar/Diameter | I7: mm
A8: Tanggal | F8: Tinggi | I8: mm
A10: No. Proses | B10: Urutan Operasi | C10: Stasiun Kerja | D10: Setup | F10: Tools | G10: Waktu Setup (detik) | H10: Waktu Proses (detik) | I10: Waktu Total (detik)
D11: n | E11: alat bantu | K11: SERACHING MATERIAL AWAL
A12: 1 | K12: MASUKIN KE DIMENSI AWAL
A13: 2
H32: Total

Sheet Perhitungan LRP
A1: PERHITUNGAN LEMBAR RENCANA PROSES | T1: DRILLING | AE1: TURNING
A5: MILLING
A6: No. Proses | B6: Nama Proses | C6: D (mm) | D6: d (mm) | E6: L (mm) | F6: v (mm/min) | G6: N (rev/min) | H6: fr (mm/min) | I6: w (mm) | J6: A (mm) | K6: Tm (min) | L6: Tm (sekon) | M6: MRR (mm3/min) | N6: Volume Awal (mm3) | O6: Scrap | P6: %Scrap | Q6: Volume Akhir (mm3)
A7: 1 | B7: Shell-End Milling Roughing (L=5, d=5) w=5 (Top Side) 2x | D7: 5 | E7: 5
A8: 3
A11: TURNING
A12: No. Proses | B12: Nama Proses | C12: Do (mm) | D12: Df (mm) | E12: d (mm) | F12: d maks (mm) | G12: L (mm) | H12: f (mm/rev) | I12: v (mm/min) | J12: N (rev/min) | K12: fr (mm/min) | L12: Tm (min) | M12: Tm (sekon) | N12: MRR (mm3/min) | O12: Volume Awal (mm3) | P12: Scrap | Q12: % Scrap | R12: Volume Akhir (mm3)
A34: DRILLING (TERMASUK TAPPING DAN BORING)
A35: No. Proses | B35: Nama Proses | C35: D (mm) | D35: d (mm) | E35: f (mm/rev) | F35: v(mm/min) | G35: N (rev/min) | H35: fr (mm/min) | I35: Tm (min) | J35: Tm (sekon) | K35: MRR (mm3/min) | L35: Volume Awal (mm3) | M35: Scrap | N35: % Scrap | O35: Volume Akhir (mm3)
A40: PRESSING (BLANKING, PUNCHING, EMBOSS, DEBOSS)
A41: No. Proses | B41: Nama Proses | C41: TS(MPa) | D41: t (mm) | E41: L (mm) | F41: Volume Awal (mm3) | G41: SPM | H41: Tm (min) | I41: Tm (s) | J41: Scrap | K41: %Scrap | L41: Volume Akhir (mm3)
A42: 2 | B42: Blanking (L=278.71mm, t=40mm, TS=401.8MPa) | T42: MILLING | AE42: BENDING
P44: =POWER(3,2) -> 9
A46: PRESSING (BENDING)
A47: No. Proses | B47: Nama Proses | C47: Kbf | D47: w (mm) | E47: TS (Mpa) | F47: t (mm) | G47: D (mm) | H47: F (N) | I47: SPM | J47: Tm (min) | K47: Tm (s) | L47: Scrap (mm3)
A51: CUTTING (TERMASUK CHAMFERING LINEAR)
A52: No. Proses | B52: Nama Proses | C52: A (mm) | D52: t (mm) | E52: θ | F52: Volume Awal | G52: Scrap | H52: % Scrap | I52: Volume Akhir (mm3)
A53: 5 | B53: Chamfering (A=2mm, t=2mm, θ = 45˚) (All Side) 8x
A57: LANGKAH MEMBACA REFERENSI KALPAKJIAN - MILLING
A60: 1. Operasi yang ingin digunakan?
A62: 2. Untuk operasi tersebut, perhatikan diameter tools (maximum width of cut) yang digunakan -> untuk pengulangan proses
A64: 3. Proses roughing atau finishing? Ingat semua milling harus ada proses finishing (kecuali dinyatakan sebaliknya).
A66: 4. Untuk operasi tersebut, perhatikan maksimum depth of cut -> untuk pengulangan proses
A68: 5. Material apa yang digunakan? Untuk stainless steel, gunakan 'Carbon steel up to 63 kgf/mm2'
A70: 6. Lihat cutting speed dan feed rate yang direkomendasikan.
U79: PUNCHING/BLANKING
A96: LANGKAH MEMBACA REFERENSI KALPAKJIAN - DRILLING
A98: 1. Berapa diameter drilling yang diinginkan?
A100: 2. Material apa yang digunakan?
A102: 3. Lihat cutting speed dan feed yang direkomendasikan (feed, bukan feed rate)
A103: (cutting speed > feed)
A105: 4. Gunakan interpolasi apabila diperlukan (misal: ketika diameter drill 8 mm)
A107: 5. Lihat cooling/lubricant agents yang direkomendasikan bila diperlukan
A133: LANGKAH MEMBACA REFERENSI KALPAKJIAN - TURNING
A134: 1. Berapa feed yang ingin digunakan? (Pertimbangkan trade off-nya)
A136: 2. Material apa yang digunakan?
A138: 3. Cutting tool apa yang digunakan? (Pertimbangkan trade off HSS dan TCT)
A140: 4. Lihat cutting speed yang direkomendasikan

Sheet Perhitungan LRP Bottom Base 1
A1: PERHITUNGAN LEMBAR RENCANA PROSES | T1: DRILLING | AE1: TURNING
A5: MILLING
A6: No. Proses | B6: Nama Proses | C6: D (mm) | D6: d (mm) | E6: L (mm) | F6: v (mm/min) | G6: N (rev/min) | H6: fr (mm/min) | I6: w (mm) | J6: A (mm) | K6: Tm (min) | L6: Tm (sekon) | M6: MRR (mm3/min) | N6: Volume Awal (mm3) | O6: Scrap | P6: %Scrap | Q6: Volume Akhir (mm3)
A7: 23 | B7: Shell-end Milling Roughing (L=26 mm, d=5 mm, w=17 mm) (left side) 3x | C7: 17 | D7: 5 | E7: 26 | F7: 8500 | G7: =F7/(3.14*C7) -> 159.23567 | H7: 1050 | I7: 17 | J7: =C7/2 -> 8.5 | K7: =(E7+J7)/H7 -> 0.032857143 | L7: =K7*60 -> 1.9714286 | M7: =H7*I7*D7 -> 89250 | N7: =O25 -> 183118.72 | O7: =(E7*I7*D7)*3 -> 6630 | P7: =(O7/N7)*100 -> 3.6206021 | Q7: =N7-O7 -> 176488.72
A8: 28 | B8: Shell-end Milling Finishing (L=26 mm, d=1 mm, w=13 mm) (left side) 3x | C8: 17 | D8: 1 | E8: 26 | F8: 8500 | G8: =F8/(3.14*C8) -> 159.23567 | H8: 1050 | I8: 13 | J8: =SQRT(I8*(C8-I8)) -> 7.2111026 | K8: =(E8+J8)/H8 -> 0.031629621 | L8: =K8*60 -> 1.8977773 | M8: =H8*I8*D8 -> 13650 | N8: =Q7 -> 176488.72 | O8: =(E8*I8*D8)*3 -> 1014 | P8: =(O8/N8)*100 -> 0.57454098 | Q8: =N8-O8 -> 175474.72
A9: 29 | B9: Shell-end Milling Roughing (L=17 mm, d=4 mm, w=8 mm) (left side) 3x | C9: 8 | D9: 4 | E9: 17 | F9: 8500 | G9: =F9/(3.14*C9) -> 338.3758 | H9: 1050 | I9: 8 | J9: =C9/2 -> 4 | K9: =(E9+J9)/H9 -> 0.02 | L9: =K9*60 -> 1.2 | M9: =H9*I9*D9 -> 33600 | N9: =Q8 -> 175474.72 | O9: =(E9*I9*D9)*3 -> 1632 | P9: =(O9/N9)*100 -> 0.93004852 | Q9: =N9-O9 -> 173842.72
A10: 38 | B10: Shell-end Milling Finishing (L=17 mm, d=0,5 mm, w=8 mm) (left side) 3x | C10: 8 | D10: 0.5 | E10: 17 | F10: 8500 | G10: =F10/(3.14*C10) -> 338.3758 | H10: 1050 | I10: 8 | J10: =C10/2 -> 4 | K10: =(E10+J10)/H10 -> 0.02 | L10: =K10*60 -> 1.2 | M10: =H10*I10*D10 -> 4200 | N10: =Q9 -> 173842.72 | O10: =(E10*I10*D10)*3 -> 204 | P10: =(O10/N10)*100 -> 0.11734745 | Q10: =N10-O10 -> 173638.72
A12: TURNING
A13: No. Proses | B13: Nama Proses | C13: Do (mm) | D13: Df (mm) | E13: d (mm) | F13: d maks (mm) | G13: L (mm) | H13: f (mm/rev) | I13: v (mm/min) | J13: N (rev/min) | K13: fr (mm/min) | L13: Tm (min) | M13: Tm (sekon) | N13: MRR (mm3/min) | O13: Volume Awal (mm3) | P13: Scrap | Q13: % Scrap | R13: Volume Akhir (mm3)
A14: 2 | B14: Face Turning (L=70 mm, Do=70 mm, Df=70 mm) (right side) | C14: 70 | D14: 70 | E14: 0 | F14: 2 | G14: 70 | H14: 0.1 | I14: 360000 | J14: =I14/(3.14*C14) -> 1637.8526 | K14: =J14*H14 -> 163.78526 | L14: =G14/K14 -> 0.42738889 | M14: =L14*60 -> 25.643333 | N14: =3.14*((C14+D14)/2)*E14*K14 -> 0 | O14: =3.14*(C14/2)^2*G14 -> 269255 | P14: =3.14*((C14^2-D14^2)/4)*G14 -> 0 | Q14: =(P14/O14)*100 -> 0 | R14: =O14-P14 -> 269255
A15: 3 | B15: Face Turning (L=39 mm, Do=70 mm, Df=66 mm) (right side) | C15: 70 | D15: 66 | E15: 2 | F15: 2 | G15: 39 | H15: 0.1 | I15: 360000 | J15: =I15/(3.14*C15) -> 1637.8526 | K15: =J15*H15 -> 163.78526 | L15: =G15/K15 -> 0.23811667 | M15: =L15*60 -> 14.287 | N15: =3.14*((C15+D15)/2)*E15*K15 -> 69942.857 | O15: =R14 -> 269255 | P15: =3.14*((C15^2-D15^2)/4)*G15 -> 16654.56 | Q15: =(P15/O15)*100 -> 6.1854227 | R15: =O15-P15 -> 252600.44
A16: 4 | B16: Face Turning (L=39 mm, Do=66 mm, Df=62 mm) (right side) | C16: 66 | D16: 62 | E16: 2 | F16: 2 | G16: 39 | H16: 0.1 | I16: 360000 | J16: =I16/(3.14*C16) -> 1737.1164 | K16: =J16*H16 -> 173.71164 | L16: =G16/K16 -> 0.22451 | M16: =L16*60 -> 13.4706 | N16: =3.14*((C16+D16)/2)*E16*K16 -> 69818.182 | O16: =R15 -> 252600.44 | P16: =3.14*((C16^2-D16^2)/4)*G16 -> 15674.88 | Q16: =(P16/O16)*100 -> 6.2054049 | R16: =O16-P16 -> 236925.56
A17: 5 | B17: Face Turning (L=39 mm, Do=62 mm, Df=60 mm) (right side) | C17: 62 | D17: 60 | E17: 1 | F17: 2 | G17: 39 | H17: 0.1 | I17: 360000 | J17: =I17/(3.14*C17) -> 1849.1884 | K17: =J17*H17 -> 184.91884 | L17: =G17/K17 -> 0.21090333 | M17: =L17*60 -> 12.6542 | N17: =3.14*((C17+D17)/2)*E17*K17 -> 35419.355 | O17: =R16 -> 236925.56 | P17: =3.14*((C17^2-D17^2)/4)*G17 -> 7470.06 | Q17: =(P17/O17)*100 -> 3.1529144 | R17: =O17-P17 -> 229455.5
A18: 9 | B18: Chamfer Turning (L=10 mm, Do=40 mm, Df=40 mm, θ=40°) (right side) | C18: 60 | D18: 40 | E18: 0 | F18: 2 | G18: 10 | H18: 0.1 | I18: 360000 | J18: =I18/(3.14*C18) -> 1910.828 | K18: =J18*H18 -> 191.0828 | L18: =G18/K18 -> 0.052333333 | M18: =L18*60 -> 3.14 | N18: =3.14*((C18+D18)/2)*E18*K18 -> 0 | O18: =R17 -> 229455.5 | P18: =3.14*((C18^2-D18^2)/4)*G18 -> 15700 | Q18: =(P18/O18)*100 -> 6.8422853 | R18: =O18-P18 -> 213755.5
A20: DRILLING (TERMASUK TAPPING DAN BORING)
A21: No. Proses | B21: Nama Proses | C21: D (mm) | D21: d (mm) | E21: f (mm/rev) | F21: v(mm/min) | G21: N (rev/min) | H21: fr (mm/min) | I21: Tm (min) | J21: Tm (sekon) | K21: MRR (mm3/min) | L21: Volume Awal (mm3) | M21: Scrap | N21: % Scrap | O21: Volume Akhir (mm3)
A22: 10 | B22: Drilling (D=10 mm, d=15 mm) (center) | C22: 10 | D22: 15 | E22: 0.04 | F22: 500 | G22: =F22/(3.14*C22) -> 15.923567 | H22: =G22*E22 -> 0.63694268 | I22: =D22/H22 -> 23.55 | J22: =D22/H22 -> 23.55 | K22: =H22*3.14*(C22/2)^2 -> 50 | L22: =R18 -> 213755.5 | M22: =3.14*(C22/2)^2*D22 -> 1177.5 | N22: =(M22/L22)*100 -> 0.55086302 | O22: =L22-M22 -> 212578
A23: 13 | B23: Boring (L=26 mm, Do=10 mm, Df=38 mm) (left side) | C23: 38 | D23: 26 | E23: 0.1 | F23: 360000 | G23: =F23/(3.14*C23) -> 3017.0969 | H23: =G23*E23 -> 301.70969 | I23: =D23/H23 -> 0.086175556 | J23: =D23/H23 -> 0.086175556 | K23: =3.14*((10+C23)/2)*D23*H23 -> 591157.89 | L23: =O22 -> 212578 | M23: =3.14*((C23^2-10^2)/4)*D23 -> 27431.04 | N23: =(M23/L23)*100 -> 12.903988 | O23: =L23-M23 -> 185146.96
A24: 19 | B24: Drilling (D=8,5 mm, d=15 mm) (center) | C24: 8.5 | D24: 15 | E24: 0.04 | F24: 500 | G24: =F24/(3.14*C24) -> 18.733608 | H24: =G24*E24 -> 0.74934432 | I24: =D24/H24 -> 20.0175 | J24: =D24/H24 -> 20.0175 | K24: =H24*3.14*(C24/2)^2 -> 42.5 | L24: =O23 -> 185146.96 | M24: =3.14*(C24/2)^2*D24 -> 850.74375 | N24: =(M24/L24)*100 -> 0.45949647 | O24: =L24-M24 -> 184296.22
A25: 22 | B25: Tapping (M10, d=15 mm) (center) | C25: 10 | D25: 15 | E25: 0.04 | F25: 500 | G25: =F25/(3.14*C25) -> 15.923567 | H25: =G25*E25 -> 0.63694268 | I25: =D25/H25 -> 23.55 | J25: =D25/H25 -> 23.55 | K25: =H25*((3.14*C25^2)/4) -> 50 | L25: =O24 -> 184296.22 | M25: =(3.14*C25^2)/4*D25 -> 1177.5 | N25: =(M25/L25)*100 -> 0.63891708 | O25: =L25-M25 -> 183118.72
A29: LANGKAH MEMBACA REFERENSI KALPAKJIAN - MILLING
A32: 1. Operasi yang ingin digunakan?
A34: 2. Untuk operasi tersebut, perhatikan diameter tools (maximum width of cut) yang digunakan -> untuk pengulangan proses
A36: 3. Proses roughing atau finishing? Ingat semua milling harus ada proses finishing (kecuali dinyatakan sebaliknya).
A38: 4. Untuk operasi tersebut, perhatikan maksimum depth of cut -> untuk pengulangan proses
A40: 5. Material apa yang digunakan? Untuk stainless steel, gunakan 'Carbon steel up to 63 kgf/mm2'
A42: 6. Lihat cutting speed dan feed rate yang direkomendasikan.
U51: PUNCHING/BLANKING
A68: LANGKAH MEMBACA REFERENSI KALPAKJIAN - DRILLING
A70: 1. Berapa diameter drilling yang diinginkan?
A72: 2. Material apa yang digunakan?
A74: 3. Lihat cutting speed dan feed yang direkomendasikan (feed, bukan feed rate)
A75: (cutting speed > feed)
A77: 4. Gunakan interpolasi apabila diperlukan (misal: ketika diameter drill 8 mm)
A79: 5. Lihat cooling/lubricant agents yang direkomendasikan bila diperlukan
A105: LANGKAH MEMBACA REFERENSI KALPAKJIAN - TURNING
A106: 1. Berapa feed yang ingin digunakan? (Pertimbangkan trade off-nya)
A108: 2. Material apa yang digunakan?
A110: 3. Cutting tool apa yang digunakan? (Pertimbangkan trade off HSS dan TCT)
A112: 4. Lihat cutting speed yang direkomendasikan

Sheet LRP Bottom Base 1
A1: LEMBAR RENCANA PROSES | K1: GAMBAR PART
A3: No . | B3: 1 | E3: Halaman ke- | F3: 1
A4: No . Part | B4: 1 | E4: File Gambar | F4: Tripod-R-01-Bottom Base 1
A5: Nama Part | B5: Bottom Base 1 | E5: Material | F5: Al Alloy
E6: Ukuran | F6: Panjang | I6: mm
A7: Dibuat oleh | B7: Asisten PPST IV | F7: Lebar/Diameter | G7: 70 | I7: mm
A8: Tanggal | B8: 3 Maret 2026 | F8: Tinggi | G8: 39 | I8: mm
A10: No. Proses | B10: Urutan Operasi | C10: Stasiun Kerja | D10: Setup | F10: Tools | G10: Waktu Setup (detik) | H10: Waktu Proses (detik) | I10: Waktu Total (detik)
D11: n | E11: alat bantu
A12: 1 | B12: Pengukuran | C12: Kerja Bangku | D12: - | F12: Jangka Sorong | G12: 0 | H12: 0 | I12: =G12+H12 -> 0
A13: 2 | B13: Face Turning (L=70 mm, Do=70 mm, Df=70 mm) (right side) | C13: Mesin Bubut | D13: 1 | E13: Three Jaw Chuck | F13: HSS Turning Tool | G13: 203.4 | H13: ='[1]Perhitungan LRP Bottom Base 1'!M14 -> 25.643333 | I13: =G13+H13 -> 229.04333
A14: 3 | B14: Face Turning (L=39 mm, Do=70 mm, Df=66 mm) (right side) | C14: Mesin Bubut | D14: 4 | E14: Three Jaw Chuck | F14: HSS Turning Tool | G14: 203.4 | H14: ='[1]Perhitungan LRP Bottom Base 1'!M15 -> 14.287 | I14: =G14+H14 -> 217.687
A15: 4 | B15: Face Turning (L=39 mm, Do=66 mm, Df=62 mm) (right side) | C15: Mesin Bubut | D15: 5 | E15: Three Jaw Chuck | F15: HSS Turning Tool | G15: 203.4 | H15: ='[1]Perhitungan LRP Bottom Base 1'!M16 -> 13.4706 | I15: =G15+H15 -> 216.8706
A16: 5 | B16: Face Turning (L=39 mm, Do=62 mm, Df=60 mm) (right side) | C16: Mesin Bubut | D16: 8 | E16: Three Jaw Chuck | F16: HSS Turning Tool | G16: 203.4 | H16: ='[1]Perhitungan LRP Bottom Base 1'!M17 -> 12.6542 | I16: =G16+H16 -> 216.0542
A17: 9 | B17: Chamfer Turning (L=10 mm, Do=60 mm, Df=40 mm, θ=40°) (right side) | C17: Mesin Bubut | D17: 9 | E17: Three Jaw Chuck | F17: HSS Turning Tool | G17: 203.4 | H17: ='[1]Perhitungan LRP Bottom Base 1'!M18 -> 3.14 | I17: =G17+H17 -> 206.54
A18: 10 | B18: Drilling (D=10 mm, d=15 mm) (center) | C18: Mesin Bubut | D18: 12 | E18: Three Jaw Chuck | F18: HSS Drill 10 mm | G18: 192 | H18: ='[1]Perhitungan LRP Bottom Base 1'!J22 -> 23.55 | I18: =G18+H18 -> 215.55
A19: 13 | B19: Boring (L=26 mm, Do=10 mm, Df=38 mm) (left side) | C19: Mesin Bubut | D19: 15 | E19: Three Jaw Chuck | F19: HSS Boring Tool | G19: 192 | H19: ='[1]Perhitungan LRP Bottom Base 1'!J23 -> 0.086175556 | I19: =G19+H19 -> 192.08618
A20: 19 | B20: Drilling (D=8,5 mm, d=15 mm) (center) | C20: Mesin Drilling | D20: 18 | E20: Ragum | F20: HSS Drill 8,5 mm | G20: 192 | H20: ='[1]Perhitungan LRP Bottom Base 1'!J24 -> 20.0175 | I20: =G20+H20 -> 212.0175
A21: 22 | B21: Tapping (M10, d=15 mm) (center) | C21: Mesin Drilling | D21: 21 | E21: Ragum | F21: Tap M10 | G21: 192 | H21: ='[1]Perhitungan LRP Bottom Base 1'!J25 -> 23.55 | I21: =G21+H21 -> 215.55
A22: 23 | B22: Shell-end Milling Roughing (L=26 mm, d=5 mm, w=17 mm) (left side) 3x | C22: Mesin Milling | D22: 22 | E22: Ragum | F22: HSS Endmill 17 mm | G22: 553.2 | H22: ='[1]Perhitungan LRP Bottom Base 1'!L7 -> 1.9714286 | I22: =G22+H22 -> 555.17143
A23: 28 | B23: Shell-end Milling Finishing (L=26 mm, d=1 mm, w=13 mm) (left side) 3x | C23: Mesin Milling | D23: 27 | E23: Ragum | F23: HSS Endmill 17 mm | G23: 553.2 | H23: ='[1]Perhitungan LRP Bottom Base 1'!L8 -> 1.8977773 | I23: =G23+H23 -> 555.09778
A24: 29 | B24: Shell-end Milling Roughing (L=17 mm, d=4 mm, w=8 mm) (left side) 3x | C24: Mesin Milling | D24: 28 | E24: Ragum | F24: HSS Endmill 8 mm | G24: 553.2 | H24: ='[1]Perhitungan LRP Bottom Base 1'!L9 -> 1.2 | I24: =G24+H24 -> 554.4
A25: 38 | B25: Shell-end Milling Finishing (L=17 mm, d=0,5 mm, w=8 mm) (left side) 3x | C25: Mesin Milling | D25: 37 | E25: Ragum | F25: HSS Endmill 8 mm | G25: 553.2 | H25: ='[1]Perhitungan LRP Bottom Base 1'!L10 -> 1.2 | I25: =G25+H25 -> 554.4
A26: 39 | B26: Deburring | C26: Kerja Bangku | F26: Hand Tool | G26: 0 | H26: 120 | I26: =G26+H26 -> 120
A27: 40 | B27: Inspeksi | C27: Kerja Bangku | D27: - | F27: Jangka Sorong | G27: 0 | H27: 0 | I27: =G27+H27 -> 0
H28: Total | I28: =SUM(I12:I27) -> 4260.468

Sheet LRP Bush
A1: LEMBAR RENCANA PROSES | K1: GAMBAR PART
A3: No . | B3: 1 | E3: Halaman ke- | F3: 1
A4: No . Part | B4: 1 | E4: File Gambar | F4: Tripod-R-01-Bottom Base 1
A5: Nama Part | B5: Bush | E5: Material | F5: Al Alloy
E6: Ukuran | F6: Panjang | I6: mm
A7: Dibuat oleh | B7: Asisten PPST IV | F7: Lebar/Diameter | G7: 6.5 | I7: mm
A8: Tanggal | B8: 4 Maret 2026 | F8: Tinggi | G8: 15 | I8: mm
A10: No. Proses | B10: Urutan Operasi | C10: Stasiun Kerja | D10: Setup | F10: Tools | G10: Waktu Setup (detik) | H10: Waktu Proses (detik) | I10: Waktu Total (detik)
D11: n | E11: alat bantu
A12: 1 | B12: Pengukuran | C12: Kerja Bangku | D12: - | E12: Jangka Sorong | F12: Jangka Sorong | G12: 0 | H12: 0 | I12: =G12+H12 -> 0
A13: 2 | B13: Center Drill (D=4,5 mm, d=3,689 mm) (center) | C13: Mesin Drilling | D13: 1 | E13: Ragum | F13: HSS Center Drill 5 mm | G13: 180 | H13: ='Perhitungan LRP Bush'!J22 -> 0.32550003 | I13: =G13+H13 -> 180.3255
A14: 3 | B14: Drilling (D=4,5 mm, d=15 mm) (center) | C14: Mesin Drilling | D14: 1 | E14: Ragum | F14: HSS Drill 5 mm | G14: 60 | H14: ='Perhitungan LRP Bush'!J23 -> 0.24606299 | I14: =G14+H14 -> 60.246063
A15: 4 | B15: Deburring | C15: Kerja Bangku | F15: Hand Tool | G15: 0 | H15: 120 | I15: =G15+H15 -> 120
A16: 5 | B16: Inspeksi | C16: Kerja Bangku | F16: Jangka Sorong | G16: 0 | H16: 0 | I16: =G16+H16 -> 0
H17: Total | I17: =SUM(I12:I16) -> 360.57156

Sheet Perhitungan LRP Bush
A1: PERHITUNGAN LEMBAR RENCANA PROSES | T1: DRILLING | AE1: TURNING
A5: MILLING
A6: No. Proses | B6: Nama Proses | C6: D (mm) | D6: d (mm) | E6: L (mm) | F6: v (mm/min) | G6: N (rev/min) | H6: fr (mm/min) | I6: w (mm) | J6: A (mm) | K6: Tm (min) | L6: Tm (sekon) | M6: MRR (mm3/min) | N6: Volume Awal (mm3) | O6: Scrap | P6: %Scrap | Q6: Volume Akhir (mm3)
A12: TURNING
A13: No. Proses | B13: Nama Proses | C13: Do (mm) | D13: Df (mm) | E13: d (mm) | F13: d maks (mm) | G13: L (mm) | H13: f (mm/rev) | I13: v (mm/min) | J13: N (rev/min) | K13: fr (mm/min) | L13: Tm (min) | M13: Tm (sekon) | N13: MRR (mm3/min) | O13: Volume Awal (mm3) | P13: Scrap | Q13: % Scrap | R13: Volume Akhir (mm3)
A20: DRILLING (TERMASUK TAPPING DAN BORING)
A21: No. Proses | B21: Nama Proses | C21: D (mm) | D21: d (mm) | E21: f (mm/rev) | F21: v(mm/min) | G21: N (rev/min) | H21: fr (mm/min) | I21: Tm (min) | J21: Tm (sekon) | K21: MRR (mm3/min) | L21: Volume Awal (mm3) | M21: Scrap | N21: % Scrap | O21: Volume Akhir (mm3)
A22: 2 | B22: ='LRP Bush'!B13 -> Center Drill (D=4,5 mm, d=3,689 mm) (center) | C22: 4.5 | D22: 3.689 | E22: =F22/G22 -> 0.086360541 | F22: 829.493 | G22: 9605 | H22: 829.493 | I22: =C22/F22 -> 0.0054250006 | J22: =I22*60 -> 0.32550003 | K22: =(((22/7)*(C22)^2)/4)*F22 -> 13197.826 | L22: =3.14*(6.5/2)^2*15 -> 497.49375 | M22: =I22*K22 -> 71.598214 | N22: =M22/L22 -> 0.14391782 | O22: =L22-M22 -> 425.89554
A23: 3 | B23: ='LRP Bush'!B14 -> Drilling (D=4,5 mm, d=15 mm) (center) | C23: 4.5 | D23: 15 | E23: =F23/G23 -> 0.09144 | F23: 1097.28 | G23: 12000 | H23: 1097.28 | I23: =C23/F23 -> 0.0041010499 | J23: =I23*60 -> 0.24606299 | K23: =(((22/7)*(C23)^2)/4)*F23 -> 17458.509 | L23: =O22 -> 425.89554 | M23: =I23*K23 -> 71.598214 | N23: =M23/L23 -> 0.16811215 | O23: =L23-M23 -> 354.29732
A25: CUTTING (TERMASUK CHAMFERING LINEAR)
A26: No. Proses | B26: Nama Proses | C26: A (mm) | D26: t (mm) | E26: θ | F26: Volume Awal | G26: Scrap | H26: % Scrap | I26: Volume Akhir (mm3)
A29: LANGKAH MEMBACA REFERENSI KALPAKJIAN - MILLING
A32: 1. Operasi yang ingin digunakan?
A34: 2. Untuk operasi tersebut, perhatikan diameter tools (maximum width of cut) yang digunakan -> untuk pengulangan proses
A36: 3. Proses roughing atau finishing? Ingat semua milling harus ada proses finishing (kecuali dinyatakan sebaliknya).
A38: 4. Untuk operasi tersebut, perhatikan maksimum depth of cut -> untuk pengulangan proses
A40: 5. Material apa yang digunakan? Untuk stainless steel, gunakan 'Carbon steel up to 63 kgf/mm2'
A42: 6. Lihat cutting speed dan feed rate yang direkomendasikan.
U51: PUNCHING/BLANKING
A68: LANGKAH MEMBACA REFERENSI KALPAKJIAN - DRILLING
A70: 1. Berapa diameter drilling yang diinginkan?
A72: 2. Material apa yang digunakan?
A74: 3. Lihat cutting speed dan feed yang direkomendasikan (feed, bukan feed rate)
A75: (cutting speed > feed)
A77: 4. Gunakan interpolasi apabila diperlukan (misal: ketika diameter drill 8 mm)
A79: 5. Lihat cooling/lubricant agents yang direkomendasikan bila diperlukan
A105: LANGKAH MEMBACA REFERENSI KALPAKJIAN - TURNING
A106: 1. Berapa feed yang ingin digunakan? (Pertimbangkan trade off-nya)
A108: 2. Material apa yang digunakan?
A110: 3. Cutting tool apa yang digunakan? (Pertimbangkan trade off HSS dan TCT)
A112: 4. Lihat cutting speed yang direkomendasikan

Sheet LRP Rib
A1: LEMBAR RENCANA PROSES | K1: GAMBAR PART
A3: No . | B3: 1 | E3: Halaman ke- | F3: 1
A4: No . Part | B4: 1 | E4: File Gambar | F4: Tripod-R-01-Bottom Base 1
A5: Nama Part | B5: Rib | E5: Material | F5: Al Alloy
E6: Ukuran | F6: Panjang | G6: 92 | I6: mm
A7: Dibuat oleh | B7: Asisten PPST IV | F7: Lebar/Diameter | G7: 12 | I7: mm
A8: Tanggal | B8: 4 Maret 2026 | F8: Tinggi | G8: 3 | I8: mm
A10: No. Proses | B10: Urutan Operasi | C10: Stasiun Kerja | D10: Setup | F10: Tools | G10: Waktu Setup (detik) | H10: Waktu Proses (detik) | I10: Waktu Total (detik)
D11: n | E11: alat bantu
A12: 1 | B12: Pengukuran | C12: Kerja Bangku | D12: - | E12: Jangka Sorong | F12: Jangka Sorong | G12: 0 | H12: 0 | I12: =G12+H12 -> 0
A13: 2 | B13: Spot Drill (D=10 mm, d=3 mm, ϑ= 90°) (top side) 2x | C13: Mesin Drilling | D13: 1 | E13: Ragum | F13: HSS Drill 10 mm | G13: 180 | H13: ='Perhitungan LRP Rib'!J13*2 -> 0.70068901 | I13: =G13+H13 -> 180.70069
A14: 4 | B14: Drill (D=7 mm, d=5 mm) (top side) 2x | C14: Mesin Drilling | D14: 1 | E14: Ragum | F14: HSS Drill 5 mm | G14: 180 | H14: ='Perhitungan LRP Rib'!J14*2 -> 0.65414091 | I14: =G14+H14 -> 180.65414
A15: 6 | B15: Spot Drill (D=10 mm, d=6 mm, ϑ= 90°) (top side) 2x | C15: Mesin Drilling | D15: 1 | E15: Ragum | F15: HSS Drill 10 mm | G15: 180 | H15: ='Perhitungan LRP Rib'!J15*2 -> 0.70068901 | I15: =G15+H15 -> 180.70069
A16: 8 | B16: Drill (D=7 mm, d=7 mm) (top side) 2x | C16: Mesin Drilling | D16: 1 | E16: Ragum | F16: HSS Drill 5 mm | G16: 180 | H16: ='Perhitungan LRP Rib'!J16*2 -> 0.65414091 | I16: =G16+H16 -> 180.65414
A17: 10 | B17: Shell End Milling Roughing (L=90 mm, d=3 mm, w=5 mm) 2x | C17: Mesin Milling | D17: 1 | E17: Ragum | F17: HSS Milling Tool 5 mm | G17: 180 | H17: ='Perhitungan LRP Rib'!L7*2 -> 113.04 | I17: =G17+H17 -> 293.04
A18: 12 | B18: Shell End Milling Finishing (L=90 mm, d=0.5 mm, w=5 mm) 2x | C18: Mesin Milling | D18: 1 | E18: Ragum | F18: HSS Milling Tool 5 mm | G18: 180 | H18: ='Perhitungan LRP Rib'!L8*2 -> 113.04 | I18: =G18+H18 -> 293.04
A19: 13 | B19: Deburring | C19: Kerja Bangku | F19: Hand Tool | G19: 0 | H19: 120 | I19: =G19+H19 -> 120
A20: 14 | B20: Inspeksi | C20: Kerja Bangku | F20: Jangka Sorong | G20: 0 | H20: 0 | I20: =G20+H20 -> 0
H21: Total | I21: =SUM(I12:I20) -> 1428.7897

Sheet Perhitungan LRP Rib
A1: PERHITUNGAN LEMBAR RENCANA PROSES | T1: DRILLING | AE1: TURNING
A5: MILLING
A6: No. Proses | B6: Nama Proses | C6: D (mm) | D6: d (mm) | E6: L (mm) | F6: v (mm/min) | G6: N (rev/min) | H6: fr (mm/min) | I6: w (mm) | J6: A (mm) | K6: Tm (min) | L6: Tm (sekon) | M6: MRR (mm3/min) | N6: Volume Awal (mm3) | O6: Scrap | P6: %Scrap | Q6: Volume Akhir (mm3)
A7: 10 | B7: ='LRP Rib'!B17 -> Shell End Milling Roughing (L=90 mm, d=3 mm, w=5 mm) 2x | C7: 5 | D7: 3 | E7: 90 | F7: 30 | G7: =(1000*F7)/(3.14*10) -> 955.41401 | H7: =0.1*G7 -> 95.541401 | I7: 5 | J7: =I7*D7 -> 15 | K7: =E7/H7 -> 0.942 | L7: =K7*60 -> 56.52 | M7: =J7*H7 -> 1433.121 | N7: =92*12*3 -> 3312 | O7: =K7*M7 -> 1350 | P7: =O7/N7 -> 0.4076087 | Q7: =N7-O7 -> 1962
A8: 12 | B8: ='LRP Rib'!B18 -> Shell End Milling Finishing (L=90 mm, d=0.5 mm, w=5 mm) 2x | C8: 5 | D8: 0.5 | E8: 90 | F8: 30 | G8: =(1000*F8)/(3.14*10) -> 955.41401 | H8: =0.1*G8 -> 95.541401 | I8: 5 | J8: =I8*D8 -> 2.5 | K8: =E8/H8 -> 0.942 | L8: =K8*60 -> 56.52 | M8: =J8*H8 -> 238.8535 | N8: =92*12*3 -> 3312 | O8: =K8*M8 -> 225 | P8: =O8/N8 -> 0.067934783 | Q8: =N8-O8 -> 3087
A11: DRILLING (TERMASUK TAPPING DAN BORING)
A12: No. Proses | B12: Nama Proses | C12: D (mm) | D12: d (mm) | E12: f (mm/rev) | F12: v(mm/min) | G12: N (rev/min) | H12: fr (mm/min) | I12: Tm (min) | J12: Tm (sekon) | K12: MRR (mm3/min) | L12: Volume Awal (mm3) | M12: Scrap | N12: % Scrap | O12: Volume Akhir (mm3)
A13: 2 | B13: ='LRP Rib'!B13 -> Spot Drill (D=10 mm, d=3 mm, ϑ= 90°) (top side) 2x | C13: 10 | D13: 3 | E13: =H13/G13 -> 0.17272819 | F13: 1712.6 | G13: 9915 | H13: 1712.6 | I13: =C13/F13 -> 0.0058390751 | J13: =I13*60 -> 0.35034451 | K13: =(((22/7)*(C13)^2)/4)*H13 -> 134561.43 | L13: =92*12*3 -> 3312 | M13: =I13*K13 -> 785.71429 | N13: =M13/L13 -> 0.23723257 | O13: =L13-M13 -> 2526.2857
A14: 4 | B14: ='LRP Rib'!B14 -> Drill (D=7 mm, d=5 mm) (top side) 2x | C14: 7 | D14: 5 | E14: =H14/G14 -> 0.1117604 | F14: 1284.127 | G14: 11490 | H14: 1284.127 | I14: =C14/F14 -> 0.0054511742 | J14: =I14*60 -> 0.32707045 | K14: =(((22/7)*(C14)^2)/4)*H14 -> 49438.889 | L14: =O13 -> 2526.2857 | M14: =I14*K14 -> 269.5 | N14: =M14/L14 -> 0.10667835 | O14: =L14-M14 -> 2256.7857
A15: 6 | B15: ='LRP Rib'!B15 -> Spot Drill (D=10 mm, d=6 mm, ϑ= 90°) (top side) 2x | C15: 10 | D15: 6 | E15: =H15/G15 -> 0.17272819 | F15: 1712.6 | G15: 9915 | H15: 1712.6 | I15: =C15/F15 -> 0.0058390751 | J15: =I15*60 -> 0.35034451 | K15: =(((22/7)*(C15)^2)/4)*H15 -> 134561.43 | L15: =O14 -> 2256.7857 | M15: =I15*K15 -> 785.71429 | N15: =M15/L15 -> 0.34815635 | O15: =L15-M15 -> 1471.0714
A16: 8 | B16: ='LRP Rib'!B16 -> Drill (D=7 mm, d=7 mm) (top side) 2x | C16: 7 | D16: 7 | E16: =H16/G16 -> 0.1117604 | F16: 1284.127 | G16: 11490 | H16: 1284.127 | I16: =C16/F16 -> 0.0054511742 | J16: =I16*60 -> 0.32707045 | K16: =(((22/7)*(C16)^2)/4)*H16 -> 49438.889 | L16: =O15 -> 1471.0714 | M16: =I16*K16 -> 269.5 | N16: =M16/L16 -> 0.18319981 | O16: =L16-M16 -> 1201.5714
A18: CUTTING (TERMASUK CHAMFERING LINEAR)
A19: No. Proses | B19: Nama Proses | C19: A (mm) | D19: t (mm) | E19: θ | F19: Volume Awal | G19: Scrap | H19: % Scrap | I19: Volume Akhir (mm3)
A24: 1. Operasi yang ingin digunakan?
A26: 2. Untuk operasi tersebut, perhatikan diameter tools (maximum width of cut) yang digunakan -> untuk pengulangan proses
A28: 3. Proses roughing atau finishing? Ingat semua milling harus ada proses finishing (kecuali dinyatakan sebaliknya).
T29: MILLING | AE29: BENDING
A30: 4. Untuk operasi tersebut, perhatikan maksimum depth of cut -> untuk pengulangan proses
A32: 5. Material apa yang digunakan? Untuk stainless steel, gunakan 'Carbon steel up to 63 kgf/mm2'
A34: 6. Lihat cutting speed dan feed rate yang direkomendasikan.
A60: LANGKAH MEMBACA REFERENSI KALPAKJIAN - DRILLING
A62: 1. Berapa diameter drilling yang diinginkan?
A64: 2. Material apa yang digunakan?
A66: 3. Lihat cutting speed dan feed yang direkomendasikan (feed, bukan feed rate) | U66: PUNCHING/BLANKING
A67: (cutting speed > feed)
A69: 4. Gunakan interpolasi apabila diperlukan (misal: ketika diameter drill 8 mm)
A71: 5. Lihat cooling/lubricant agents yang direkomendasikan bila diperlukan
A97: LANGKAH MEMBACA REFERENSI KALPAKJIAN - TURNING
A98: 1. Berapa feed yang ingin digunakan? (Pertimbangkan trade off-nya)
A100: 2. Material apa yang digunakan?
A102: 3. Cutting tool apa yang digunakan? (Pertimbangkan trade off HSS dan TCT)
A104: 4. Lihat cutting speed yang direkomendasikan

Sheet LRP Pivot Holder
A1: LEMBAR RENCANA PROSES | K1: GAMBAR PART
A3: No . | B3: 1 | E3: Halaman ke- | F3: 1
A4: No . Part | B4: 1 | E4: File Gambar | F4: Tripod-R-01-Bottom Base 1
A5: Nama Part | B5: Pivot Holder | E5: Material | F5: Al Alloy
E6: Ukuran | F6: Panjang | I6: mm
A7: Dibuat oleh | B7: Asisten PPST IV | F7: Lebar/Diameter | G7: 20 | I7: mm
A8: Tanggal | B8: 4 Maret 2026 | F8: Tinggi | G8: 75 | I8: mm
A10: No. Proses | B10: Urutan Operasi | C10: Stasiun Kerja | D10: Setup | F10: Tools | G10: Waktu Setup (detik) | H10: Waktu Proses (detik) | I10: Waktu Total (detik)
D11: n | E11: alat bantu
A12: 1 | B12: Pengukuran | C12: Kerja Bangku | D12: - | E12: Jangka Sorong | F12: Jangka Sorong | G12: 0 | H12: 0 | I12: =G12+H12 -> 0
A13: 2 | B13: End Mill Pocket Roughing (L=75 mm, d=2,7 mm, w=6 mm) (top side) 10x | C13: Mesin Milling | D13: 1 | E13: Ragum | F13: HSS Milling Tool 6 mm | G13: 180 | H13: ='Perhitungan LRP Pivot Holder'!K7*10 -> 3.3174098 | I13: =G13+H13 -> 183.31741
A14: 12 | B14: End Mill Pocket Finishing (L=75 mm, d=0,5 mm, w=6 mm) (top side) | C14: Mesin Milling | D14: 1 | E14: Ragum | F14: HSS Milling Tool 6 mm | G14: 60 | H14: ='Perhitungan LRP Pivot Holder'!K8 -> 0.33174098 | I14: =G14+H14 -> 60.331741
A15: 13 | B15: End Mill Circular Pocket Roughing (L=22.6 mm, d=1 mm, w=6 mm) (top side) | C15: Mesin Milling | D15: 1 | E15: Ragum | F15: HSS Milling Tool 6 mm | G15: 60 | H15: ='Perhitungan LRP Pivot Holder'!K9 -> 0.099964614 | I15: =G15+H15 -> 60.099965
A16: 14 | B16: End Mill Circular Pocket Finishing (L=22.6 mm, d=0,5 mm, w=6 mm) (top side) | C16: Mesin Milling | D16: 1 | E16: Ragum | F16: HSS Milling Tool 6 mm | G16: 60 | H16: ='Perhitungan LRP Pivot Holder'!K10 -> 0.099964614 | I16: =G16+H16 -> 60.099965
A17: 15 | B17: End Mill Contour Roughing (L=44 mm, d=2.75 mm, w=6 mm) (top side) 9x | C17: Mesin Milling | D17: 1 | E17: Ragum | F17: HSS Milling Tool 6 mm | G17: 60 | H17: ='Perhitungan LRP Pivot Holder'!K11*9 -> 1.7515924 | I17: =G17+H17 -> 61.751592
A18: 24 | B18: End Mill Contour Finishing (L=44 mm, d=2.75 mm, w=6 mm) (top side) | C18: Mesin Milling | D18: 1 | E18: Ragum | F18: HSS Milling Tool 6 mm | G18: 60 | H18: ='Perhitungan LRP Pivot Holder'!K12 -> 0.19462137 | I18: =G18+H18 -> 60.194621
A19: 25 | B19: Deburring | C19: Kerja Bangku | F19: Hand Tool | G19: 0 | H19: 120 | I19: =G19+H19 -> 120
A20: 26 | B20: Inspeksi | C20: Kerja Bangku | F20: Jangka Sorong | G20: 0 | H20: 0 | I20: =G20+H20 -> 0
H21: Total | I21: =SUM(I12:I20) -> 605.79529

Sheet Perhitungan LRP Pivot Holder
A1: PERHITUNGAN LEMBAR RENCANA PROSES | T1: DRILLING | AE1: TURNING
A5: MILLING
A6: No. Proses | B6: Nama Proses | C6: D (mm) | D6: d (mm) | E6: L (mm) | F6: v (mm/min) | G6: N (rev/min) | H6: fr (mm/min) | I6: w (mm) | J6: A (mm) | K6: Tm (min) | L6: Tm (sekon) | M6: MRR (mm3/min) | N6: Volume Awal (mm3) | O6: Scrap | P6: %Scrap | Q6: Volume Akhir (mm3)
A7: ='LRP Pivot Holder'!A13 -> 2 | B7: ='LRP Pivot Holder'!B13 -> End Mill Pocket Roughing (L=75 mm, d=2,7 mm, w=6 mm) (top side) 10x | C7: 6 | D7: 2.7 | E7: 75 | F7: =(3.14*C7*G7)/1000 -> 226.08 | G7: 12000 | H7: =F7 -> 226.08 | I7: 6 | J7: =I7*D7 -> 16.2 | K7: =E7/H7 -> 0.33174098 | L7: =K7*60 -> 19.904459 | M7: =J7*H7 -> 3662.496 | N7: =3.14*(10)^2*75 -> 23550 | O7: =K7*M7 -> 1215 | P7: =(O7/N7)*100% -> 0.051592357 | Q7: =N7-O7 -> 22335
A8: ='LRP Pivot Holder'!A14 -> 12 | B8: ='LRP Pivot Holder'!B14 -> End Mill Pocket Finishing (L=75 mm, d=0,5 mm, w=6 mm) (top side) | C8: 6 | D8: 0.5 | E8: 75 | F8: =(3.14*C8*G8)/1000 -> 226.08 | G8: 12000 | H8: =F8 -> 226.08 | I8: 6 | J8: =I8*D8 -> 3 | K8: =E8/H8 -> 0.33174098 | L8: =K8*60 -> 19.904459 | M8: =J8*H8 -> 678.24 | N8: =3.14*(10)^2*75 -> 23550 | O8: =K8*M8 -> 225 | P8: =(O8/N8)*100% -> 0.0095541401 | Q8: =N8-O8 -> 23325
A9: ='LRP Pivot Holder'!A15 -> 13 | B9: ='LRP Pivot Holder'!B15 -> End Mill Circular Pocket Roughing (L=22.6 mm, d=1 mm, w=6 mm) (top side) | C9: 6 | D9: 1 | E9: 22.6 | F9: =(3.14*C9*G9)/1000 -> 226.08 | G9: 12000 | H9: =F9 -> 226.08 | I9: 6 | J9: =I9*D9 -> 6 | K9: =E9/H9 -> 0.099964614 | L9: =K9*60 -> 5.9978769 | M9: =J9*H9 -> 1356.48 | N9: =3.14*(10)^2*75 -> 23550 | O9: =K9*M9 -> 135.6 | P9: =(O9/N9)*100% -> 0.0057579618 | Q9: =N9-O9 -> 23414.4
A10: ='LRP Pivot Holder'!A16 -> 14 | B10: ='LRP Pivot Holder'!B16 -> End Mill Circular Pocket Finishing (L=22.6 mm, d=0,5 mm, w=6 mm) (top side) | C10: 6 | D10: 0.5 | E10: 22.6 | F10: =(3.14*C10*G10)/1000 -> 226.08 | G10: 12000 | H10: =F10 -> 226.08 | I10: 6 | J10: =I10*D10 -> 3 | K10: =E10/H10 -> 0.099964614 | L10: =K10*60 -> 5.9978769 | M10: =J10*H10 -> 678.24 | N10: =3.14*(10)^2*75 -> 23550 | O10: =K10*M10 -> 67.8 | P10: =(O10/N10)*100% -> 0.0028789809 | Q10: =N10-O10 -> 23482.2
A11: ='LRP Pivot Holder'!A17 -> 15 | B11: ='LRP Pivot Holder'!B17 -> End Mill Contour Roughing (L=44 mm, d=2.75 mm, w=6 mm) (top side) 9x | C11: 6 | D11: 2.75 | E11: 44 | F11: =(3.14*C11*G11)/1000 -> 226.08 | G11: 12000 | H11: =F11 -> 226.08 | I11: 6 | J11: =I11*D11 -> 16.5 | K11: =E11/H11 -> 0.19462137 | L11: =K11*60 -> 11.677282 | M11: =J11*H11 -> 3730.32 | N11: =3.14*(10)^2*75 -> 23550 | O11: =K11*M11 -> 726 | P11: =(O11/N11)*100% -> 0.030828025 | Q11: =N11-O11 -> 22824
A12: ='LRP Pivot Holder'!A18 -> 24 | B12: ='LRP Pivot Holder'!B18 -> End Mill Contour Finishing (L=44 mm, d=2.75 mm, w=6 mm) (top side) | C12: 6 | D12: 0.5 | E12: 44 | F12: =(3.14*C12*G12)/1000 -> 226.08 | G12: 12000 | H12: =F12 -> 226.08 | I12: 6 | J12: =I12*D12 -> 3 | K12: =E12/H12 -> 0.19462137 | L12: =K12*60 -> 11.677282 | M12: =J12*H12 -> 678.24 | N12: =3.14*(10)^2*75 -> 23550 | O12: =K12*M12 -> 132 | P12: =(O12/N12)*100% -> 0.0056050955 | Q12: =N12-O12 -> 23418
A15: DRILLING (TERMASUK TAPPING DAN BORING)
A16: No. Proses | B16: Nama Proses | C16: D (mm) | D16: d (mm) | E16: f (mm/rev) | F16: v(mm/min) | G16: N (rev/min) | H16: fr (mm/min) | I16: Tm (min) | J16: Tm (sekon) | K16: MRR (mm3/min) | L16: Volume Awal (mm3) | M16: Scrap | N16: % Scrap | O16: Volume Akhir (mm3)
A22: CUTTING (TERMASUK CHAMFERING LINEAR)
A23: No. Proses | B23: Nama Proses | C23: A (mm) | D23: t (mm) | E23: θ | F23: Volume Awal | G23: Scrap | H23: % Scrap | I23: Volume Akhir (mm3)
A28: 1. Operasi yang ingin digunakan?
A30: 2. Untuk operasi tersebut, perhatikan diameter tools (maximum width of cut) yang digunakan -> untuk pengulangan proses
A32: 3. Proses roughing atau finishing? Ingat semua milling harus ada proses finishing (kecuali dinyatakan sebaliknya).
T33: MILLING | AE33: BENDING
A34: 4. Untuk operasi tersebut, perhatikan maksimum depth of cut -> untuk pengulangan proses
A36: 5. Material apa yang digunakan? Untuk stainless steel, gunakan 'Carbon steel up to 63 kgf/mm2'
A38: 6. Lihat cutting speed dan feed rate yang direkomendasikan.
A64: LANGKAH MEMBACA REFERENSI KALPAKJIAN - DRILLING
A66: 1. Berapa diameter drilling yang diinginkan?
A68: 2. Material apa yang digunakan?
A70: 3. Lihat cutting speed dan feed yang direkomendasikan (feed, bukan feed rate) | U70: PUNCHING/BLANKING
A71: (cutting speed > feed)
A73: 4. Gunakan interpolasi apabila diperlukan (misal: ketika diameter drill 8 mm)
A75: 5. Lihat cooling/lubricant agents yang direkomendasikan bila diperlukan
A101: LANGKAH MEMBACA REFERENSI KALPAKJIAN - TURNING
A102: 1. Berapa feed yang ingin digunakan? (Pertimbangkan trade off-nya)
A104: 2. Material apa yang digunakan?
A106: 3. Cutting tool apa yang digunakan? (Pertimbangkan trade off HSS dan TCT)
A108: 4. Lihat cutting speed yang direkomendasikan

Sheet LRP Guide Male
A1: LEMBAR RENCANA PROSES | K1: GAMBAR PART
A3: No . | B3: 2 | E3: Halaman ke- | F3: 1
A4: No . Part | B4: 2 | E4: File Gambar | F4: Tripod-R-02-Bottom Base 2
A5: Nama Part | B5: Guide male | E5: Material | F5: Al Alloy
E6: Ukuran | F6: Panjang | I6: mm
A7: Dibuat oleh | B7: Asisten PPST IV | F7: Lebar/Diameter | G7: 20 | I7: mm
A8: Tanggal | B8: 3 Maret 2026 | F8: Tinggi | G8: 75 | I8: mm
A10: No. Proses | B10: Urutan Operasi | C10: Stasiun Kerja | D10: Setup | F10: Tools | G10: Waktu Setup (detik) | H10: Waktu Proses (detik) | I10: Waktu Total (detik)
D11: n | E11: alat bantu
A12: 1 | B12: Pengukuran | C12: Kerja Bangku | D12: - | F12: Jangka Sorong | G12: 0 | H12: 0 | I12: 0
A13: 2 | B13: Face Turning (L=160 mm, Do=16 mm, Df=14 mm) | C13: Mesin Turning | D13: 1 | E13: Three Jaw Chuck | F13: HSS Turning Tool | G13: 180 | H13: ='Perhitungan LRP Guide Male'!M17 -> 24 | I13: =G13+H13 -> 204
A14: 3 | B14: Face Turning (L=30 mm, Do=14 mm, Df=10 mm) | C14: Mesin Turning | D14: 1 | E14: Three Jaw Chuck | F14: HSS Turning Tool | G14: 120 | H14: ='Perhitungan LRP Guide Male'!M18 -> 4.5 | I14: =G14+H14 -> 124.5
A15: 4 | B15: Chamfering (d=2 mm, ϑ= 45°) | C15: Mesin Turning | D15: 1 | E15: Three Jaw Chuck | F15: HSS Turning Tool | G15: 120 | H15: ='Perhitungan LRP Guide Male'!M19 -> 3.75 | I15: =G15+H15 -> 123.75
A16: 5 | B16: Thread Turning (L=25 mm, M10 x 1.5) | C16: Mesin Turning | D16: 1 | E16: Three Jaw Chuck | F16: HSS Turning Tool | G16: 120 | H16: 60 | I16: =G16+H16 -> 180
A17: 6 | B17: Chamfering (d=1 mm, ϑ= 45°) | C17: Mesin Turning | D17: 1 | E17: Three Jaw Chuck | F17: HSS Turning Tool | G17: 120 | H17: 60 | I17: =G17+H17 -> 180
A18: 7 | B18: Filetting (R=5 mm) | C18: Kerja Bangku | D18: 1 | E18: Ragum | F18: HSS Turning Tool | G18: 120 | H18: 60 | I18: =G18+H18 -> 180
A19: 8 | B19: Deburring | C19: Kerja Bangku | F19: Hand Tool | G19: 0 | H19: 0 | I19: =G19+H19 -> 0
A20: 9 | B20: Inspeksi | C20: Kerja Bangku | F20: Jangka Sorong | G20: 0 | H20: 120 | I20: =G20+H20 -> 120
H21: Total | I21: =SUM(I12:I20) -> 1112.25

Sheet Perhitungan LRP Guide Male
A1: PERHITUNGAN LEMBAR RENCANA PROSES | T1: DRILLING | AE1: TURNING
A5: MILLING
A6: No. Proses | B6: Nama Proses | C6: D (mm) | D6: d (mm) | E6: L (mm) | F6: v (mm/min) | G6: N (rev/min) | H6: fr (mm/min) | I6: w (mm) | J6: A (mm) | K6: Tm (min) | L6: Tm (sekon) | M6: MRR (mm3/min) | N6: Volume Awal (mm3) | O6: Scrap | P6: %Scrap | Q6: Volume Akhir (mm3)
A15: TURNING
A16: No. Proses | B16: Nama Proses | C16: Do (mm) | D16: Df (mm) | E16: d (mm) | F16: d maks (mm) | G16: L (mm) | H16: f (mm/rev) | I16: v (mm/min) | J16: N (rev/min) | K16: fr (mm/min) | L16: Tm (min) | M16: Tm (sekon) | N16: MRR (mm3/min) | O16: Volume Awal (mm3) | P16: Scrap | Q16: % Scrap | R16: Volume Akhir (mm3)
A17: 2 | B17: ='LRP Guide Male'!B13 -> Face Turning (L=160 mm, Do=16 mm, Df=14 mm) | C17: 16 | D17: 14 | E17: =(C17-D17)/2 -> 1 | F17: =5*H17 -> 0.5 | G17: 160 | H17: 0.1 | I17: 400 | J17: =(1000*I17)/(3.14*AVERAGE(C17:D17)) -> 8492.569 | K17: =I17 -> 400 | L17: =G17/K17 -> 0.4 | M17: =L17*60 -> 24 | N17: =I17*H17*E17 -> 40 | O17: =3.14*(75/2)^2*20 -> 88312.5 | P17: =M17*N17 -> 960 | Q17: =(O17-P17)*100% -> 87352.5 | R17: =O17-P17 -> 87352.5
A18: 3 | B18: ='LRP Guide Male'!B14 -> Face Turning (L=30 mm, Do=14 mm, Df=10 mm) | C18: 14 | D18: 10 | E18: =(C18-D18)/2 -> 2 | F18: =5*H18 -> 0.5 | G18: 30 | H18: 0.1 | I18: 400 | J18: =(1000*I18)/(3.14*AVERAGE(C18:D18)) -> 10615.711 | K18: =I18 -> 400 | L18: =G18/K18 -> 0.075 | M18: =L18*60 -> 4.5 | N18: =I18*H18*E18 -> 80 | O18: =R17 -> 87352.5 | P18: =M18*N18 -> 360 | Q18: =(O18-P18)*100% -> 86992.5 | R18: =O18-P18 -> 86992.5
A19: 5 | B19: ='LRP Guide Male'!B16 -> Thread Turning (L=25 mm, M10 x 1.5) | C19: 10 | D19: 10 | E19: 0 | F19: =5*H19 -> 0.5 | G19: 25 | H19: 0.1 | I19: 400 | J19: =(1000*I19)/(3.14*AVERAGE(C19:D19)) -> 12738.854 | K19: =I19 -> 400 | L19: =G19/K19 -> 0.0625 | M19: =L19*60 -> 3.75 | N19: =I19*H19*E19 -> 0 | O19: =R18 -> 86992.5 | P19: =M19*N19 -> 0 | Q19: =(O19-P19)*100% -> 86992.5 | R19: =O19-P19 -> 86992.5
A22: DRILLING (TERMASUK TAPPING DAN BORING)
A23: No. Proses | B23: Nama Proses | C23: D (mm) | D23: d (mm) | E23: f (mm/rev) | F23: v(mm/min) | G23: N (rev/min) | H23: fr (mm/min) | I23: Tm (min) | J23: Tm (sekon) | K23: MRR (mm3/min) | L23: Volume Awal (mm3) | M23: Scrap | N23: % Scrap | O23: Volume Akhir (mm3)
A29: CUTTING (TERMASUK CHAMFERING LINEAR)
A30: No. Proses | B30: Nama Proses | C30: A (mm) | D30: t (mm) | E30: θ | F30: Volume Awal | G30: Scrap | H30: % Scrap | I30: Volume Akhir (mm3)
B31: ='LRP Guide Male'!B15 -> Chamfering (d=2 mm, ϑ= 45°) | D31: 2 | E31: 45 | F31: =R19 -> 86992.5 | G31: =(1/3)*3.14*D31^3 -> 8.3733333 | H31: =(G31/F31) -> 9.6253508e-05 | I31: =F31-G31 -> 86984.127
B32: ='LRP Guide Male'!B17 -> Chamfering (d=1 mm, ϑ= 45°) | D32: 1 | E32: 45 | F32: =I31 -> 86984.127 | G32: =(1/3)*3.14*D32^3 -> 1.0466667 | H32: =(G32/F32) -> 1.2032847e-05 | I32: =F32-G32 -> 86983.08
B33: ='LRP Guide Male'!B18 -> Filetting (R=5 mm) | D33: 5 | F33: =I32 -> 86983.08 | G33: =(1/3)*3.14*D33^3 -> 130.83333 | H33: =(G33/F33) -> 0.0015041239 | I33: =F33-G33 -> 86852.247
A36: LANGKAH MEMBACA REFERENSI KALPAKJIAN - MILLING
A39: 1. Operasi yang ingin digunakan?
A41: 2. Untuk operasi tersebut, perhatikan diameter tools (maximum width of cut) yang digunakan -> untuk pengulangan proses
A43: 3. Proses roughing atau finishing? Ingat semua milling harus ada proses finishing (kecuali dinyatakan sebaliknya).
A45: 4. Untuk operasi tersebut, perhatikan maksimum depth of cut -> untuk pengulangan proses
A47: 5. Material apa yang digunakan? Untuk stainless steel, gunakan 'Carbon steel up to 63 kgf/mm2'
A49: 6. Lihat cutting speed dan feed rate yang direkomendasikan.
U58: PUNCHING/BLANKING
A75: LANGKAH MEMBACA REFERENSI KALPAKJIAN - DRILLING
A77: 1. Berapa diameter drilling yang diinginkan?
A79: 2. Material apa yang digunakan?
A81: 3. Lihat cutting speed dan feed yang direkomendasikan (feed, bukan feed rate)
A82: (cutting speed > feed)
A84: 4. Gunakan interpolasi apabila diperlukan (misal: ketika diameter drill 8 mm)
A86: 5. Lihat cooling/lubricant agents yang direkomendasikan bila diperlukan
A112: LANGKAH MEMBACA REFERENSI KALPAKJIAN - TURNING
A113: 1. Berapa feed yang ingin digunakan? (Pertimbangkan trade off-nya)
A115: 2. Material apa yang digunakan? | Y115: Ringkasan
Y116: Kegiatan | Z116: Jumlah | AA116: Waktu
A117: 3. Cutting tool apa yang digunakan? (Pertimbangkan trade off HSS dan TCT) | Y117: Operasi | Z117: 142 | AA117: 2559.35
Y118: Inspeksi | Z118: 1 | AA118: 0
A119: 4. Lihat cutting speed yang direkomendasikan | Y119: Total | Z119: 143 | AA119: =AA117+0 -> 2559.35

Sheet LRP Bottom Base 2
A1: LEMBAR RENCANA PROSES | K1: GAMBAR PART
A3: No . | B3: 2 | E3: Halaman ke- | F3: 1
A4: No . Part | B4: 2 | E4: File Gambar | F4: Tripod-R-02-Bottom Base 2
A5: Nama Part | B5: Bottom Base 2 | E5: Material | F5: Al Alloy
E6: Ukuran | F6: Panjang | I6: mm
A7: Dibuat oleh | B7: Asisten PPST IV | F7: Lebar/Diameter | G7: 70 | I7: mm
A8: Tanggal | B8: 3 Maret 2026 | F8: Tinggi | G8: 10 | I8: mm
A10: No. Proses | B10: Urutan Operasi | C10: Stasiun Kerja | D10: Setup | F10: Tools | G10: Waktu Setup (detik) | H10: Waktu Proses (detik) | I10: Waktu Total (detik)
D11: n | E11: alat bantu
A12: 1 | B12: Pengukuran | C12: Kerja Bangku | D12: - | F12: Jangka Sorong | G12: 0 | H12: 0 | I12: 0
A13: 2 | B13: Shell End Milling Roughing (L=198.28mm, d=4.5mm, w=5mm) (top side)3x | C13: Mesin Milling | D13: 1 | E13: Ragum | F13: HSS Milling Tool 5 mm | G13: 180 | H13: ='Perhitungan LRP Bottom Base 2'!L7 -> 146.3616 | I13: =G13+H13 -> 326.3616
A14: 5 | B14: Shell End Milling Roughing (L=207.24mm, d=4.5mm, w=5mm) (top side) | C14: Mesin Milling | D14: =A14-1 -> 4 | E14: Ragum | F14: HSS Milling Tool 5 mm | G14: 60 | H14: ='Perhitungan LRP Bottom Base 2'!L8 -> 50.9376 | I14: =G14+H14 -> 110.9376
A15: 6 | B15: Shell End Milling Finishing (L=198.28mm, d=0.5mm, w=5mm) (top side)3x | C15: Mesin Milling | D15: =A15-1 -> 5 | E15: Ragum | F15: HSS Milling Tool 5 mm | G15: 60 | H15: ='Perhitungan LRP Bottom Base 2'!L9 -> 332.64 | I15: =G15+H15 -> 392.64
A16: 9 | B16: Shell End Milling Finishing (L=207.24mm, d=0.5mm, w=5mm) (top side) | C16: Mesin Milling | D16: =A16-1 -> 8 | E16: Ragum | F16: HSS Milling Tool 5 mm | G16: 60 | H16: ='Perhitungan LRP Bottom Base 2'!L10 -> 115.76727 | I16: =G16+H16 -> 175.76727
A17: 10 | B17: Shell End Milling Roughing (L=60mm, d=5mm, w=2.5mm) (top side) 6x | C17: Mesin Milling | D17: =A17-1 -> 9 | E17: Ragum | F17: HSS Milling Tool 2.5 mm | G17: 120 | H17: ='Perhitungan LRP Bottom Base 2'!L11 -> 90 | I17: =G17+H17 -> 210
A18: 16 | B18: Shell End Milling Finishing (L=48mm, d=5mm, w=0.5mm) (top side) 3x | C18: Mesin Milling | D18: =A18-1 -> 15 | E18: Ragum | F18: HSS Milling Tool 2.5 mm | G18: 60 | H18: ='Perhitungan LRP Bottom Base 2'!L12 -> 81.818182 | I18: =G18+H18 -> 141.81818
A19: 19 | B19: Drilling (D=10mm, d=17mm) (left side) 3x | C19: Mesin Drilling | D19: =A19-1 -> 18 | E19: Ragum | F19: HSS Drilling Tool 10 mm | G19: 180 | H19: ='Perhitungan LRP Bottom Base 2'!J17 -> 3.2044245 | I19: =G19+H19 -> 183.20442
A20: 22 | B20: Drilling (D=11mm, d=10mm) (bottom side) | C20: Mesin Drilling | D20: =A20-1 -> 21 | E20: Ragum | F20: HSS Drilling Tool 11 mm | G20: 120 | H20: ='Perhitungan LRP Bottom Base 2'!J18 -> 0.62831853 | I20: =G20+H20 -> 120.62832
A21: 23 | B21: Inspeksi | C21: Kerja Bangku | D21: - | F21: Jangka Sorong | G21: 0 | H21: 0 | I21: =G21+H21 -> 0
H22: Total | I22: =SUM(I12:I21) -> 1661.3574

Sheet Perhitungan LRP Bottom Base 2
A1: PERHITUNGAN LEMBAR RENCANA PROSES | T1: DRILLING | AE1: TURNING
A5: MILLING
A6: No. Proses | B6: Nama Proses | C6: D (mm) | D6: d (mm) | E6: L (mm) | F6: v (mm/min) | G6: N (rev/min) | H6: fr (mm/min) | I6: w (mm) | J6: A (mm) | K6: Tm (min) | L6: Tm (sekon) | M6: MRR (mm3/min) | N6: Volume Awal (mm3) | O6: Scrap | P6: %Scrap | Q6: Volume Akhir (mm3)
A7: ='LRP Bottom Base 2'!A13 -> 2 | B7: ='LRP Bottom Base 2'!B13 -> Shell End Milling Roughing (L=198.28mm, d=4.5mm, w=5mm) (top side)3x | C7: 5 | D7: 4.5 | E7: 198.28 | F7: 200000 | G7: =F7/(PI()*C7) -> 12732.395 | H7: 250 | I7: 5 | J7: =C7/2 -> 2.5 | K7: =(E7+(2*J7))*3/H7 -> 2.43936 | L7: =K7*60 -> 146.3616 | M7: =I7*D7*H7 -> 5625 | N7: =3.14*35*35*10 -> 38465 | O7: =(E7/H7*M7) -> 4461.3 | P7: =(M7*K7)/N7 -> 0.35672429 | Q7: =N7-O7 -> 34003.7
A8: ='LRP Bottom Base 2'!A14 -> 5 | B8: ='LRP Bottom Base 2'!B14 -> Shell End Milling Roughing (L=207.24mm, d=4.5mm, w=5mm) (top side) | C8: 5 | D8: 4.5 | E8: 207.24 | F8: 200000 | G8: =F8/(PI()*C8) -> 12732.395 | H8: 250 | I8: 5 | J8: =C8/2 -> 2.5 | K8: =(E8+(2*J8))/H8 -> 0.84896 | L8: =K8*60 -> 50.9376 | M8: =I8*D8*H8 -> 5625 | N8: =Q7 -> 34003.7 | O8: =(E8/H8*M8) -> 4662.9 | P8: =M8*K8/N8 -> 0.14043766 | Q8: =N8-O8 -> 29340.8
A9: ='LRP Bottom Base 2'!A15 -> 6 | B9: ='LRP Bottom Base 2'!B15 -> Shell End Milling Finishing (L=198.28mm, d=0.5mm, w=5mm) (top side)3x | C9: 5 | D9: 0.5 | E9: 198.28 | F9: 250000 | G9: =F9/(PI()*C9) -> 15915.494 | H9: 110 | I9: 5 | J9: =C9/2 -> 2.5 | K9: =(E9+(2*J9))*3/H9 -> 5.544 | L9: =K9*60 -> 332.64 | M9: =I9*D9*H9 -> 275 | N9: =Q8 -> 29340.8 | O9: =(E9/H9*M9) -> 495.7 | P9: =M9*K9/N9 -> 0.051961773 | Q9: =N9-O9 -> 28845.1
A10: ='LRP Bottom Base 2'!A16 -> 9 | B10: ='LRP Bottom Base 2'!B16 -> Shell End Milling Finishing (L=207.24mm, d=0.5mm, w=5mm) (top side) | C10: 5 | D10: 0.5 | E10: 207.24 | F10: 250000 | G10: =F10/(PI()*C10) -> 15915.494 | H10: 110 | I10: 5 | J10: =C10/2 -> 2.5 | K10: =(E10+(2*J10))/H10 -> 1.9294545 | L10: =K10*60 -> 115.76727 | M10: =I10*D10*H10 -> 275 | N10: =Q9 -> 28845.1 | O10: =(E10/H10*M10) -> 518.1 | P10: =M10*K10/N10 -> 0.018394805 | Q10: =N10-O10 -> 28327
A11: ='LRP Bottom Base 2'!A17 -> 10 | B11: ='LRP Bottom Base 2'!B17 -> Shell End Milling Roughing (L=60mm, d=5mm, w=2.5mm) (top side) 6x | C11: 2.5 | D11: 5 | E11: 60 | F11: 200000 | G11: =F11/(PI()*C11) -> 25464.791 | H11: 250 | I11: 2.5 | J11: =C11/2 -> 1.25 | K11: =(E11+(2*J11))*6/H11 -> 1.5 | L11: =K11*60 -> 90 | M11: =I11*D11*H11 -> 3125 | N11: =Q10 -> 28327 | O11: =(E11/H11*M11) -> 750 | P11: =M11*K11/N11 -> 0.16547817 | Q11: =N11-O11 -> 27577
A12: ='LRP Bottom Base 2'!A18 -> 16 | B12: ='LRP Bottom Base 2'!B18 -> Shell End Milling Finishing (L=48mm, d=5mm, w=0.5mm) (top side) 3x | C12: 2.5 | D12: 5 | E12: 48 | F12: 250000 | G12: =F12/(PI()*C12) -> 31830.989 | H12: 110 | I12: 0.5 | J12: =SQRT(I12*(C12-I12)) -> 1 | K12: =(E12+(2*J12))*3/H12 -> 1.3636364 | L12: =K12*60 -> 81.818182 | M12: =I12*D12*H12 -> 275 | N12: =Q11 -> 27577 | O12: =(E12/H12*M12) -> 120 | P12: =M12*K12/N12 -> 0.013598288 | Q12: =N12-O12 -> 27457
A15: DRILLING (TERMASUK TAPPING DAN BORING)
A16: No. Proses | B16: Nama Proses | C16: D (mm) | D16: d (mm) | E16: f (mm/rev) | F16: v(mm/min) | G16: N (rev/min) | H16: fr (mm/min) | I16: Tm (min) | J16: Tm (sekon) | K16: MRR (mm3/min) | L16: Volume Awal (mm3) | M16: Scrap | N16: % Scrap | O16: Volume Akhir (mm3)
A17: ='LRP Bottom Base 2'!A19 -> 19 | B17: ='LRP Bottom Base 2'!B19 -> Drilling (D=10mm, d=17mm) (left side) 3x | C17: 10 | D17: 17 | E17: 0.2 | F17: 150000 | G17: =F17/(PI()*C17) -> 4774.6483 | H17: =G17*E17 -> 954.92966 | I17: =D17*3/H17 -> 0.053407075 | J17: =I17*60 -> 3.2044245 | K17: =(PI()*C17*C17*H17)/4 -> 75000 | L17: =Q12 -> 27457 | M17: =I17*K17 -> 4005.5306 | N17: =K17*I17/L17 -> 0.14588377 | O17: =L17-M17 -> 23451.469
A18: ='LRP Bottom Base 2'!A20 -> 22 | B18: ='LRP Bottom Base 2'!B20 -> Drilling (D=11mm, d=10mm) (bottom side) | C18: 11 | D18: 10 | E18: =11/10*0.2 -> 0.22 | F18: 150000 | G18: =F18/(PI()*C18) -> 4340.5894 | H18: =G18*E18 -> 954.92966 | I18: =D18/H18 -> 0.010471976 | J18: =I18*60 -> 0.62831853 | K18: =(PI()*C18*C18*H18)/4 -> 90750 | L18: =O17 -> 23451.469 | M18: =I18*K18 -> 950.33178 | N18: =K18*I18/L18 -> 0.040523336 | O18: =L18-M18 -> 22501.138
A20: bik
A21: No. Proses | B21: Nama Proses | C21: A (mm) | D21: t (mm) | E21: θ | F21: Volume Awal | G21: Scrap | H21: % Scrap | I21: Volume Akhir (mm3)
A26: 1. Operasi yang ingin digunakan?
A28: 2. Untuk operasi tersebut, perhatikan diameter tools (maximum width of cut) yang digunakan -> untuk pengulangan proses
A30: 3. Proses roughing atau finishing? Ingat semua milling harus ada proses finishing (kecuali dinyatakan sebaliknya).
T31: MILLING | AE31: BENDING
A32: 4. Untuk operasi tersebut, perhatikan maksimum depth of cut -> untuk pengulangan proses
A34: 5. Material apa yang digunakan? Untuk stainless steel, gunakan 'Carbon steel up to 63 kgf/mm2'
A36: 6. Lihat cutting speed dan feed rate yang direkomendasikan.
A62: LANGKAH MEMBACA REFERENSI KALPAKJIAN - DRILLING
A64: 1. Berapa diameter drilling yang diinginkan?
A66: 2. Material apa yang digunakan?
A68: 3. Lihat cutting speed dan feed yang direkomendasikan (feed, bukan feed rate) | U68: PUNCHING/BLANKING
A69: (cutting speed > feed)
A71: 4. Gunakan interpolasi apabila diperlukan (misal: ketika diameter drill 8 mm)
A73: 5. Lihat cooling/lubricant agents yang direkomendasikan bila diperlukan
A99: LANGKAH MEMBACA REFERENSI KALPAKJIAN - TURNING
A100: 1. Berapa feed yang ingin digunakan? (Pertimbangkan trade off-nya)
A102: 2. Material apa yang digunakan?
A104: 3. Cutting tool apa yang digunakan? (Pertimbangkan trade off HSS dan TCT)
A106: 4. Lihat cutting speed yang direkomendasikan

Sheet LRP Guide Female
A1: LEMBAR RENCANA PROSES | K1: GAMBAR PART
A3: No . | B3: 4 | E3: Halaman ke- | F3: 1
A4: No . Part | B4: 4 | E4: File Gambar | F4: Tripod-R-04-Guide-Female
A5: Nama Part | B5: Guide Female | E5: Material | F5: Al Alloy
E6: Ukuran | F6: Panjang | G6: - | I6: mm
A7: Dibuat oleh | B7: Asisten PPST IV | F7: Lebar/Diameter | G7: 46 | I7: mm
A8: Tanggal | B8: 3 Maret 2026 | F8: Tinggi | G8: 20 | I8: mm
A10: No. Proses | B10: Urutan Operasi | C10: Stasiun Kerja | D10: Setup | F10: Tools | G10: Waktu Setup (detik) | H10: Waktu Proses (detik) | I10: Waktu Total (detik)
D11: n | E11: alat bantu
A12: 1 | B12: Pengukuran | C12: Kerja Bangku | F12: Gerinda | G12: 240 | H12: 0 | I12: =G12+H12 -> 240
A13: 2 | B13: Face Turning (L=20 mm, Do=46 mm, Df=45 mm) (All side) | C13: Mesin Turning | D13: =A13-1 -> 1 | E13: Three Jaw Chuck | F13: HSS Turning Tools | G13: 180 | H13: ='Perhitungan LRP Guide Female'!M38 -> 4.3332 | I13: =G13+H13 -> 184.3332
A14: 3 | B14: Face Turning (L=20 mm, Do=45 mm, Df=44 mm) (All side) | C14: Mesin Turning | D14: =A14-1 -> 2 | E14: Chuck | F14: HSS Turning Tools | G14: 30 | H14: ='Perhitungan LRP Guide Female'!M39 -> 4.239 | I14: =G14+H14 -> 34.239
A15: 4 | B15: Shell-End Milling Roughing (L=38 mm, d=5 mm, w=20 mm)(Right Side) | C15: Mesin Milling | D15: =A15-1 -> 3 | E15: Ragum | F15: HSS Turning Tools | G15: 180 | H15: ='Perhitungan LRP Guide Female'!L7 -> 11.52 | I15: =G15+H15 -> 191.52
A16: 5 | B16: Shell-End Milling Roughing (L=33,74 mm, d=5 mm, w=20 mm)(Right Side) | C16: Mesin Milling | D16: =A16-1 -> 4 | E16: Ragum | F16: HSS Milling Tool 20 mm | G16: 30 | H16: ='Perhitungan LRP Guide Female'!L8 -> 10.4976 | I16: =G16+H16 -> 40.4976
A17: 6 | B17: Shell-End Milling Roughing (L=29,41 mm, d=5 mm, w=20 mm)(Right Side) | C17: Mesin Milling | D17: =A17-1 -> 5 | E17: Ragum | F17: HSS Milling Tool 20 mm | G17: 30 | H17: ='Perhitungan LRP Guide Female'!L9 -> 9.4584 | I17: =G17+H17 -> 39.4584
A18: 7 | B18: Shell-End Milling Roughing (L=25,09 mm, d=5 mm, w=20 mm)(Right Side) | C18: Mesin Milling | D18: =A18-1 -> 6 | E18: Ragum | F18: HSS Milling Tool 20 mm | G18: 30 | H18: ='Perhitungan LRP Guide Female'!L10 -> 8.4216 | I18: =G18+H18 -> 38.4216
A19: 8 | B19: Shell-End Milling Roughing (L=20,76 mm, d=3,5 mm, w=20 mm)(Right Side) | C19: Mesin Milling | D19: =A19-1 -> 7 | E19: Ragum | F19: HSS Milling Tool 20 mm | G19: 30 | H19: ='Perhitungan LRP Guide Female'!L11 -> 7.3824 | I19: =G19+H19 -> 37.3824
A20: 9 | B20: Shell-End Milling Finishing (L=17,73 mm, d=0,5 mm, w=20 mm)(Right Side) | C20: Mesin Milling | D20: =A20-1 -> 8 | E20: Ragum | F20: HSS Milling Tool 20 mm | G20: 30 | H20: ='Perhitungan LRP Guide Female'!L12 -> 15.125455 | I20: =G20+H20 -> 45.125455
A21: 10 | B21: Shell-End Milling Roughing (L=38 mm, d=5 mm, w=20 mm)(Left Side) | C21: Mesin Milling | D21: =A21-1 -> 9 | E21: Ragum | F21: HSS Milling Tool 20 mm | G21: 30 | H21: ='Perhitungan LRP Guide Female'!L13 -> 11.52 | I21: =G21+H21 -> 41.52
A22: 11 | B22: Shell-End Milling Roughing (L=33,74 mm, d=5 mm, w=20 mm)(Left Side) | C22: Mesin Milling | D22: =A22-1 -> 10 | E22: Ragum | F22: HSS Milling Tool 20 mm | G22: 30 | H22: ='Perhitungan LRP Guide Female'!L14 -> 10.4976 | I22: =G22+H22 -> 40.4976
A23: 12 | B23: Shell-End Milling Roughing (L=29,41 mm, d=5 mm, w=20 mm)(Left Side) | C23: Mesin Milling | D23: =A23-1 -> 11 | E23: Ragum | F23: HSS Milling Tool 20 mm | G23: 30 | H23: ='Perhitungan LRP Guide Female'!L15 -> 9.4584 | I23: =G23+H23 -> 39.4584
A24: 13 | B24: Shell-End Milling Roughing (L=25,09 mm, d=5 mm, w=20 mm)(Left Side) | C24: Mesin Milling | D24: =A24-1 -> 12 | E24: Ragum | F24: HSS Milling Tool 20 mm | G24: 30 | H24: ='Perhitungan LRP Guide Female'!L16 -> 8.4216 | I24: =G24+H24 -> 38.4216
A25: 14 | B25: Shell-End Milling Roughing (L=20,76 mm, d=3,5 mm, w=20 mm)(Left Side) | C25: Mesin Milling | D25: =A25-1 -> 13 | E25: Ragum | F25: HSS Milling Tool 20 mm | G25: 30 | H25: ='Perhitungan LRP Guide Female'!L17 -> 7.3824 | I25: =G25+H25 -> 37.3824
A26: 15 | B26: Shell-End Milling Finishing (L=17,73 mm, d=0,5 mm, w=20 mm)(Left Side) | C26: Mesin Milling | D26: =A26-1 -> 14 | E26: Ragum | F26: HSS Milling Tool 20 mm | G26: 30 | H26: ='Perhitungan LRP Guide Female'!L18 -> 15.125455 | I26: =G26+H26 -> 45.125455
... A41: 30 | B41: Shell-End Milling Finishing (L=7 mm, d=0,5 mm, w=20 mm)(Front Side) | C41: Mesin Milling | D41: =A41-1 -> 29 | E41: Ragum | F41: HSS Milling Tool 20 mm | G41: 30 | H41: ='Perhitungan LRP Guide Female'!L33 -> 9.2727273 | I41: =G41+H41 -> 39.272727
A42: 31 | B42: Filleting (L=20 mm, t= 1 mm, ϑ= 45°) x6 (All side) | C42: Kerja Bangku | D42: =A42-1 -> 30 | E42: Ragum | F42: Gerinda | G42: 240 | H42: 0 | I42: =G42+H42 -> 240
A43: 37 | B43: Filleting (L=20 mm, t= 1 mm, ϑ= 45°) x8 (All side) | C43: Kerja Bangku | D43: =A43-1 -> 36 | E43: Ragum | F43: Gerinda | G43: 240 | H43: 0 | I43: =G43+H43 -> 240
A44: 45 | B44: Drilling (D=14 mm, d=20 mm) | C44: Mesin Drilling | D44: =A44-1 -> 44 | E44: Ragum | F44: HSS Drilling Tool 14 mm | G44: 180 | H44: 2.826 | I44: =G44+H44 -> 182.826
A45: 46 | B45: Drilling (D=7 mm, d=8 mm) x3 | C45: Mesin Drilling | D45: =A45-1 -> 45 | E45: Ragum | F45: HSS Drilling Tool 7 mm | G45: 30 | H45: 0.628 | I45: =G45+H45 -> 30.628
A46: 49 | B46: Tapping Drilling (D=6 mm, d=5,46 mm) | C46: Mesin Drilling | D46: =A46-1 -> 48 | E46: Ragum | F46: HSS Drilling Tool 6 mm | G46: 90 | H46: 0.42861 | I46: =G46+H46 -> 90.42861
A47: 50 | B47: Inspeksi | C47: Kerja Bangku | F47: Gerinda | G47: 0 | H47: 0 | I47: =G47+H47 -> 0
H48: Total | I48: =SUM(I12:I47) -> 2416.1334

Sheet Perhitungan LRP Guide Female
A1: PERHITUNGAN LEMBAR RENCANA PROSES | T1: DRILLING | AE1: TURNING
A5: MILLING
A6: No. Proses | B6: Nama Proses | C6: D (mm) | D6: d (mm) | E6: L (mm) | F6: v (mm/min) | G6: N (rev/min) | H6: fr (mm/min) | I6: w (mm) | J6: A (mm) | K6: Tm (min) | L6: Tm (sekon) | M6: MRR (mm3/min) | N6: Volume Awal (mm3) | O6: Scrap | P6: %Scrap | Q6: Volume Akhir (mm3)
A7: 4 | B7: Shell-End Milling Roughing (L=38 mm, d=5 mm, w=20 mm)(Right Side) | C7: 20 | D7: 5 | E7: 38 | F7: 200000 | G7: =F7/3.14/C7 -> 3184.7134 | H7: 250 | I7: 20 | J7: =IF(I7=C7,C7/2,SQRT(I7*(C7-I7))) -> 10 | K7: =((E7+J7)/H7) -> 0.192 | L7: =K7*60 -> 11.52 | M7: =I7*D7*H7 -> 25000 | N7: =R39 -> 30363.8 | O7: =E7/H7*M7 -> 3800 | P7: =(O7/N7)*100 -> 12.514903 | Q7: =N7-O7 -> 26563.8
A8: 5 | B8: Shell-End Milling Roughing (L=33,74 mm, d=5 mm, w=20 mm)(Right Side) | C8: 20 | D8: 5 | E8: 33.74 | F8: 200000 | G8: =F8/3.14/C8 -> 3184.7134 | H8: 250 | I8: 20 | J8: =IF(I8=C8,C8/2,SQRT(I8*(C8-I8))) -> 10 | K8: =((E8+J8)/H8) -> 0.17496 | L8: =K8*60 -> 10.4976 | M8: =I8*D8*H8 -> 25000 | N8: =Q7 -> 26563.8 | O8: =E8/H8*M8 -> 3374 | P8: =(O8/N8)*100 -> 12.701496 | Q8: =N8-O8 -> 23189.8
A9: 6 | B9: Shell-End Milling Roughing (L=29,41 mm, d=5 mm, w=20 mm)(Right Side) | C9: 20 | D9: 5 | E9: 29.41 | F9: 200000 | G9: =F9/3.14/C9 -> 3184.7134 | H9: 250 | I9: 20 | J9: =IF(I9=C9,C9/2,SQRT(I9*(C9-I9))) -> 10 | K9: =((E9+J9)/H9) -> 0.15764 | L9: =K9*60 -> 9.4584 | M9: =I9*D9*H9 -> 25000 | N9: =Q8 -> 23189.8 | O9: =E9/H9*M9 -> 2941 | P9: =(O9/N9)*100 -> 12.6823 | Q9: =N9-O9 -> 20248.8
A10: 7 | B10: Shell-End Milling Roughing (L=25,09 mm, d=5 mm, w=20 mm)(Right Side) | C10: 20 | D10: 5 | E10: 25.09 | F10: 200000 | G10: =F10/3.14/C10 -> 3184.7134 | H10: 250 | I10: 20 | J10: =IF(I10=C10,C10/2,SQRT(I10*(C10-I10))) -> 10 | K10: =((E10+J10)/H10) -> 0.14036 | L10: =K10*60 -> 8.4216 | M10: =I10*D10*H10 -> 25000 | N10: =Q9 -> 20248.8 | O10: =E10/H10*M10 -> 2509 | P10: =(O10/N10)*100 -> 12.390858 | Q10: =N10-O10 -> 17739.8
A11: 8 | B11: Shell-End Milling Roughing (L=20,76 mm, d=3,5 mm, w=20 mm)(Right Side) | C11: 20 | D11: 3.5 | E11: 20.76 | F11: 200000 | G11: =F11/3.14/C11 -> 3184.7134 | H11: 250 | I11: 20 | J11: =IF(I11=C11,C11/2,SQRT(I11*(C11-I11))) -> 10 | K11: =((E11+J11)/H11) -> 0.12304 | L11: =K11*60 -> 7.3824 | M11: =I11*D11*H11 -> 17500 | N11: =Q10 -> 17739.8 | O11: =E11/H11*M11 -> 1453.2 | P11: =(O11/N11)*100 -> 8.1917496 | Q11: =N11-O11 -> 16286.6
A12: 9 | B12: Shell-End Milling Finishing (L=17,73 mm, d=0,5 mm, w=20 mm)(Right Side) | C12: 20 | D12: 0.5 | E12: 17.73 | F12: 250000 | G12: =F12/3.14/C12 -> 3980.8917 | H12: 110 | I12: 20 | J12: =IF(I12=C12,C12/2,SQRT(I12*(C12-I12))) -> 10 | K12: =((E12+J12)/H12) -> 0.25209091 | L12: =K12*60 -> 15.125455 | M12: =I12*D12*H12 -> 1100 | N12: =Q11 -> 16286.6 | O12: =E12/H12*M12 -> 177.3 | P12: =(O12/N12)*100 -> 1.088625 | Q12: =N12-O12 -> 16109.3
A13: 10 | B13: Shell-End Milling Roughing (L=38 mm, d=5 mm, w=20 mm)(Left Side) | C13: 20 | D13: 5 | E13: 38 | F13: 200000 | G13: =F13/3.14/C13 -> 3184.7134 | H13: 250 | I13: 20 | J13: =IF(I13=C13,C13/2,SQRT(I13*(C13-I13))) -> 10 | K13: =((E13+J13)/H13) -> 0.192 | L13: =K13*60 -> 11.52 | M13: =I13*D13*H13 -> 25000 | N13: =Q12 -> 16109.3 | O13: =E13/H13*M13 -> 3800 | P13: =(O13/N13)*100 -> 23.588859 | Q13: =N13-O13 -> 12309.3
A14: 11 | B14: Shell-End Milling Roughing (L=33,74 mm, d=5 mm, w=20 mm)(Left Side) | C14: 20 | D14: 5 | E14: 33.74 | F14: 200000 | G14: =F14/3.14/C14 -> 3184.7134 | H14: 250 | I14: 20 | J14: =IF(I14=C14,C14/2,SQRT(I14*(C14-I14))) -> 10 | K14: =((E14+J14)/H14) -> 0.17496 | L14: =K14*60 -> 10.4976 | M14: =I14*D14*H14 -> 25000 | N14: =Q13 -> 12309.3 | O14: =E14/H14*M14 -> 3374 | P14: =(O14/N14)*100 -> 27.41017 | Q14: =N14-O14 -> 8935.3
A15: 12 | B15: Shell-End Milling Roughing (L=29,41 mm, d=5 mm, w=20 mm)(Left Side) | C15: 20 | D15: 5 | E15: 29.41 | F15: 200000 | G15: =F15/3.14/C15 -> 3184.7134 | H15: 250 | I15: 20 | J15: =IF(I15=C15,C15/2,SQRT(I15*(C15-I15))) -> 10 | K15: =((E15+J15)/H15) -> 0.15764 | L15: =K15*60 -> 9.4584 | M15: =I15*D15*H15 -> 25000 | N15: =Q14 -> 8935.3 | O15: =E15/H15*M15 -> 2941 | P15: =(O15/N15)*100 -> 32.914396 | Q15: =N15-O15 -> 5994.3
