Workbook

Sheet Modul 5
D6: PRAKTIKUM PERANCANGAN SISTEM TERINTEGRASI III
D7: MODUL 1 - Peramalan Permintaan Pasar
K13: PJ Modul
I14: 13422054 - Ohanprada Hebrizky Sitorus
I15: 13422083 - Christopher Nathan Sancoyo
I16: 13422115 - Marella Parahita Dewani
D19: Laboratorium Perencanaan dan Optimasi Sistem Industri
D20: Program Studi Teknik Industri
D21: Fakultas Teknologi Industri
D22: 2025

Sheet Instruksi
B1: Instructions
B2: Worksheet specific notes
B4: Summary
B5: Lembar kerja ini dibuat untuk mengakomodasi pengolahan data PPST III 2025 Modul 1 - Peramalan Permintaan Pasar. Seluruh data yang diperlukan tersedia pada lembar kerja ini.
B6: Keluaran dari lembar kerja ini adalah ramalan permintaan untuk berbagai jenis produk PT PPST Manufacturing.
B8: Formatting guide
B9: Dalam lembar kerja ini, digunakan konvensi penulisan sebagai berikut.
B11: Cells | C11: Sel yang telah dikalkulasikan yang tidak boleh diubah secara manual
C12: Data mentah yang digunakan model
C13: Instruksi, catatan, atau informasi kontekstual lainnya
B15: Tabs | C15: Analysis sheets
C16: Raw data sheets
C17: Output sheets

Sheet Data Awal
B2: Data Awal
B3: Penjualan 40 Bulan Terakhir
B4: Pola Data
B5: Periode | C5: Part_A_Jkt | D5: Part_B_Jkt | E5: Part_C_Jkt | F5: Part_D_Jkt
B6: 2020-03 | C6: 8658 | D6: 4708 | E6: 5114 | F6: 9163
B7: 2020-04 | C7: 8318 | D7: 5518 | E7: 5570 | F7: 3010
B8: 2020-05 | C8: 8781 | D8: 5912 | E8: 5408 | F8: 2018
B9: 2020-06 | C9: 8220 | D9: 5600 | E9: 6816 | F9: 17462
B10: 2020-07 | C10: 8617 | D10: 6417 | E10: 6927 | F10: 17199 | V10: A | W10: Horizontal
B11: 2020-08 | C11: 8938 | D11: 6534 | E11: 7508 | F11: 11400 | V11: b | W11: Tren
B12: 2020-09 | C12: 8302 | D12: 6939 | E12: 7635 | F12: 8070 | V12: c | W12: seasonal
B13: 2020-10 | C13: 8387 | D13: 7543 | E13: 7843 | F13: 2615 | V13: D | W13: random
B14: 2020-11 | C14: 8520 | D14: 7183 | E14: 6991 | F14: 3114
B15: 2020-12 | C15: 8399 | D15: 7312 | E15: 7212 | F15: 8662
B16: 2021-01 | C16: 8190 | D16: 7554 | E16: 7138 | F16: 13586
B17: 2021-02 | C17: 8514 | D17: 7858 | E17: 7150 | F17: 10762
B18: 2021-03 | C18: 8288 | D18: 8361 | E18: 7293 | F18: 14133
B19: 2021-04 | C19: 8595 | D19: 8769 | E19: 7038 | F19: 6048
B20: 2021-05 | C20: 8316 | D20: 9032 | E20: 7304 | F20: 16848
B21: 2021-06 | C21: 8810 | D21: 9479 | E21: 7474 | F21: 12588
B22: 2021-07 | C22: 8343 | D22: 9517 | E22: 7886 | F22: 12281
B23: 2021-08 | C23: 8436 | D23: 10231 | E23: 8688 | F23: 11377
B24: 2021-09 | C24: 8663 | D24: 9998 | E24: 9722 | F24: 7792
B25: 2021-10 | C25: 8254 | D25: 11175 | E25: 9457 | F25: 7507
... B45: 2023-06 | C45: 8631 | D45: 15657 | E45: 15341 | F45: 13099

Sheet A - Forecast
B18: Simple Moving Average | I18: Weighted Moving Average | P18: Single Exponential Smoothing
B20: Parameter Peramalan | C20: N | D20: 3 | I20: Parameter Peramalan | J20: W1 | K20: 1 | P20: Parameter Peramalan | Q20: α | R20: 0.05
J21: W2 | K21: 2
J22: W3 | K22: 3
B23: Ukuran Error | C23: MAD | D23: =AVERAGE(E31:E68) -> 183.43243 | I23: Ukuran Error | J23: MAD | K23: =AVERAGE(L31:L67) -> 206.05856 | P23: Ukuran Error | Q23: MAD | R23: =AVERAGE(S28:S67) -> 172.99732
C24: MSE | D24: =AVERAGE(F31:F67) -> 48517.547 | J24: MSE | K24: =AVERAGE(M31:M67) -> 58259.962 | Q24: MSE | R24: =AVERAGE(T28:T67) -> 46049.013
C25: MAPE | D25: =AVERAGE(G31:G67) -> 0.021636073 | J25: MAPE | K25: =AVERAGE(N31:N67) -> 0.02431058 | Q25: MAPE | R25: =AVERAGE(U28:U67) -> 0.020533796
B27: Periode | C27: Data penjualan Tripod A | D27: Hasil Peramalan pada periode t | E27: Nilai mutlak dari perbedaan antara hasil peramalan & data penjualan | F27: Nilai kuadrat dari perbedaan antara hasil peramalan & data penjualan | G27: Persentase perbedaan nilai hasil peramalan & data penjualan | I27: Periode | J27: Data penjualan Tripod A | K27: Hasil Peramalan pada periode t | L27: Nilai mutlak dari perbedaan antara hasil peramalan & data penjualan | M27: Nilai kuadrat dari perbedaan antara hasil peramalan & data penjualan | N27: Persentase perbedaan nilai hasil peramalan & data penjualan | P27: Periode | Q27: Data penjualan Tripod A | R27: Hasil Peramalan pada periode t | S27: Nilai mutlak dari perbedaan antara hasil peramalan & data penjualan | T27: Nilai kuadrat dari perbedaan antara hasil peramalan & data penjualan | U27: Persentase perbedaan nilai hasil peramalan & data penjualan
B28: 1 | C28: 8658 | I28: 1 | J28: 8658 | P28: 1 | Q28: 8658 | R28: 8658 | S28: =ABS(R28-Q28) -> 0 | T28: =S28^2 -> 0 | U28: =S28/Q28 -> 0
B29: 2 | C29: 8318 | I29: 2 | J29: 8318 | P29: 2 | Q29: 8318 | R29: =R$20*Q28+(1-R$20)*R28 -> 8658 | S29: =ABS(R29-Q29) -> 340 | T29: =S29^2 -> 115600 | U29: =S29/Q29 -> 0.04087521
B30: 3 | C30: 8781 | I30: 3 | J30: 8781 | P30: 3 | Q30: 8781 | R30: =R$20*Q29+(1-R$20)*R29 -> 8641 | S30: =ABS(R30-Q30) -> 140 | T30: =S30^2 -> 19600 | U30: =S30/Q30 -> 0.015943514
B31: 4 | C31: 8220 | D31: =SUM(C28:C30)/$D$20 -> 8585.6667 | E31: =ABS(C31-D31) -> 365.66667 | F31: =E31^2 -> 133712.11 | G31: =E31/C31 -> 0.044484996 | I31: 4 | J31: 8220 | K31: =(1/6)*($K$20*J28+K$21*J29+K$22*J30) -> 8606.1667 | L31: =ABS(J31-K31) -> 386.16667 | M31: =L31^2 -> 149124.69 | N31: =L31/J31 -> 0.046978913 | P31: 4 | Q31: 8220 | R31: =R$20*Q30+(1-R$20)*R30 -> 8648 | S31: =ABS(R31-Q31) -> 428 | T31: =S31^2 -> 183184 | U31: =S31/Q31 -> 0.052068127
B32: 5 | C32: 8617 | D32: =SUM(C29:C31)/$D$20 -> 8439.6667 | E32: =ABS(C32-D32) -> 177.33333 | F32: =E32^2 -> 31447.111 | G32: =E32/C32 -> 0.020579475 | I32: 5 | J32: 8617 | K32: =(1/6)*($K$20*J29+K$21*J30+K$22*J31) -> 8423.3333 | L32: =ABS(J32-K32) -> 193.66667 | M32: =L32^2 -> 37506.778 | N32: =L32/J32 -> 0.022474953 | P32: 5 | Q32: 8617 | R32: =R$20*Q31+(1-R$20)*R31 -> 8626.6 | S32: =ABS(R32-Q32) -> 9.6 | T32: =S32^2 -> 92.16 | U32: =S32/Q32 -> 0.0011140768
B33: 6 | C33: 8938 | D33: =SUM(C30:C32)/$D$20 -> 8539.3333 | E33: =ABS(C33-D33) -> 398.66667 | F33: =E33^2 -> 158935.11 | G33: =E33/C33 -> 0.044603565 | I33: 6 | J33: 8938 | K33: =(1/6)*($K$20*J30+K$21*J31+K$22*J32) -> 8512 | L33: =ABS(J33-K33) -> 426 | M33: =L33^2 -> 181476 | N33: =L33/J33 -> 0.047661669 | P33: 6 | Q33: 8938 | R33: =R$20*Q32+(1-R$20)*R32 -> 8626.12 | S33: =ABS(R33-Q33) -> 311.88 | T33: =S33^2 -> 97269.134 | U33: =S33/Q33 -> 0.034893712
B34: 7 | C34: 8302 | D34: =SUM(C31:C33)/$D$20 -> 8591.6667 | E34: =ABS(C34-D34) -> 289.66667 | F34: =E34^2 -> 83906.778 | G34: =E34/C34 -> 0.034891191 | I34: 7 | J34: 8302 | K34: =(1/6)*($K$20*J31+K$21*J32+K$22*J33) -> 8711.3333 | L34: =ABS(J34-K34) -> 409.33333 | M34: =L34^2 -> 167553.78 | N34: =L34/J34 -> 0.049305388 | P34: 7 | Q34: 8302 | R34: =R$20*Q33+(1-R$20)*R33 -> 8641.714 | S34: =ABS(R34-Q34) -> 339.714 | T34: =S34^2 -> 115405.6 | U34: =S34/Q34 -> 0.040919537
B35: 8 | C35: 8387 | D35: =SUM(C32:C34)/$D$20 -> 8619 | E35: =ABS(C35-D35) -> 232 | F35: =E35^2 -> 53824 | G35: =E35/C35 -> 0.027661858 | I35: 8 | J35: 8387 | K35: =(1/6)*($K$20*J32+K$21*J33+K$22*J34) -> 8566.5 | L35: =ABS(J35-K35) -> 179.5 | M35: =L35^2 -> 32220.25 | N35: =L35/J35 -> 0.02140217 | P35: 8 | Q35: 8387 | R35: =R$20*Q34+(1-R$20)*R34 -> 8624.7283 | S35: =ABS(R35-Q35) -> 237.7283 | T35: =S35^2 -> 56514.745 | U35: =S35/Q35 -> 0.028344855
B36: 9 | C36: 8520 | D36: =SUM(C33:C35)/$D$20 -> 8542.3333 | E36: =ABS(C36-D36) -> 22.333333 | F36: =E36^2 -> 498.77778 | G36: =E36/C36 -> 0.0026212833 | I36: 9 | J36: 8520 | K36: =(1/6)*($K$20*J33+K$21*J34+K$22*J35) -> 8450.5 | L36: =ABS(J36-K36) -> 69.5 | M36: =L36^2 -> 4830.25 | N36: =L36/J36 -> 0.008157277 | P36: 9 | Q36: 8520 | R36: =R$20*Q35+(1-R$20)*R35 -> 8612.8419 | S36: =ABS(R36-Q36) -> 92.841885 | T36: =S36^2 -> 8619.6156 | U36: =S36/Q36 -> 0.010896935
B37: 10 | C37: 8399 | D37: =SUM(C34:C36)/$D$20 -> 8403 | E37: =ABS(C37-D37) -> 4 | F37: =E37^2 -> 16 | G37: =E37/C37 -> 0.00047624717 | I37: 10 | J37: 8399 | K37: =(1/6)*($K$20*J34+K$21*J35+K$22*J36) -> 8439.3333 | L37: =ABS(J37-K37) -> 40.333333 | M37: =L37^2 -> 1626.7778 | N37: =L37/J37 -> 0.004802159 | P37: 10 | Q37: 8399 | R37: =R$20*Q36+(1-R$20)*R36 -> 8608.1998 | S37: =ABS(R37-Q37) -> 209.19979 | T37: =S37^2 -> 43764.552 | U37: =S37/Q37 -> 0.024907702
B38: 11 | C38: 8190 | D38: =SUM(C35:C37)/$D$20 -> 8435.3333 | E38: =ABS(C38-D38) -> 245.33333 | F38: =E38^2 -> 60188.444 | G38: =E38/C38 -> 0.02995523 | I38: 11 | J38: 8190 | K38: =(1/6)*($K$20*J35+K$21*J36+K$22*J37) -> 8437.3333 | L38: =ABS(J38-K38) -> 247.33333 | M38: =L38^2 -> 61173.778 | N38: =L38/J38 -> 0.03019943 | P38: 11 | Q38: 8190 | R38: =R$20*Q37+(1-R$20)*R37 -> 8597.7398 | S38: =ABS(R38-Q38) -> 407.7398 | T38: =S38^2 -> 166251.75 | U38: =S38/Q38 -> 0.04978508
B39: 12 | C39: 8514 | D39: =SUM(C36:C38)/$D$20 -> 8369.6667 | E39: =ABS(C39-D39) -> 144.33333 | F39: =E39^2 -> 20832.111 | G39: =E39/C39 -> 0.01695247 | I39: 12 | J39: 8514 | K39: =(1/6)*($K$20*J36+K$21*J37+K$22*J38) -> 8314.6667 | L39: =ABS(J39-K39) -> 199.33333 | M39: =L39^2 -> 39733.778 | N39: =L39/J39 -> 0.023412419 | P39: 12 | Q39: 8514 | R39: =R$20*Q38+(1-R$20)*R38 -> 8577.3528 | S39: =ABS(R39-Q39) -> 63.352811 | T39: =S39^2 -> 4013.5787 | U39: =S39/Q39 -> 0.0074410161
B40: 13 | C40: 8288 | D40: =SUM(C37:C39)/$D$20 -> 8367.6667 | E40: =ABS(C40-D40) -> 79.666667 | F40: =E40^2 -> 6346.7778 | G40: =E40/C40 -> 0.0096122909 | I40: 13 | J40: 8288 | K40: =(1/6)*($K$20*J37+K$21*J38+K$22*J39) -> 8386.8333 | L40: =ABS(J40-K40) -> 98.833333 | M40: =L40^2 -> 9768.0278 | N40: =L40/J40 -> 0.011924871 | P40: 13 | Q40: 8288 | R40: =R$20*Q39+(1-R$20)*R39 -> 8574.1852 | S40: =ABS(R40-Q40) -> 286.18517 | T40: =S40^2 -> 81901.952 | U40: =S40/Q40 -> 0.034530064
B41: 14 | C41: 8595 | D41: =SUM(C38:C40)/$D$20 -> 8330.6667 | E41: =ABS(C41-D41) -> 264.33333 | F41: =E41^2 -> 69872.111 | G41: =E41/C41 -> 0.030754315 | I41: 14 | J41: 8595 | K41: =(1/6)*($K$20*J38+K$21*J39+K$22*J40) -> 8347 | L41: =ABS(J41-K41) -> 248 | M41: =L41^2 -> 61504 | N41: =L41/J41 -> 0.028853985 | P41: 14 | Q41: 8595 | R41: =R$20*Q40+(1-R$20)*R40 -> 8559.8759 | S41: =ABS(R41-Q41) -> 35.124088 | T41: =S41^2 -> 1233.7016 | U41: =S41/Q41 -> 0.0040865722
B42: 15 | C42: 8316 | D42: =SUM(C39:C41)/$D$20 -> 8465.6667 | E42: =ABS(C42-D42) -> 149.66667 | F42: =E42^2 -> 22400.111 | G42: =E42/C42 -> 0.017997435 | I42: 15 | J42: 8316 | K42: =(1/6)*($K$20*J39+K$21*J40+K$22*J41) -> 8479.1667 | L42: =ABS(J42-K42) -> 163.16667 | M42: =L42^2 -> 26623.361 | N42: =L42/J42 -> 0.019620811 | P42: 15 | Q42: 8316 | R42: =R$20*Q41+(1-R$20)*R41 -> 8561.6321 | S42: =ABS(R42-Q42) -> 245.63212 | T42: =S42^2 -> 60335.137 | U42: =S42/Q42 -> 0.029537292
... B67: 40 | C67: 8631 | D67: =SUM(C64:C66)/$D$20 -> 8576.6667 | E67: =ABS(C67-D67) -> 54.333333 | F67: =E67^2 -> 2952.1111 | G67: =E67/C67 -> 0.0062951377 | I67: 40 | J67: 8631 | K67: =(1/6)*($K$20*J64+K$21*J65+K$22*J66) -> 8474.8333 | L67: =ABS(J67-K67) -> 156.16667 | M67: =L67^2 -> 24388.028 | N67: =L67/J67 -> 0.018093693 | P67: 40 | Q67: 8631 | R67: =R$20*Q66+(1-R$20)*R66 -> 8516.5964 | S67: =ABS(R67-Q67) -> 114.40357 | T67: =S67^2 -> 13088.177 | U67: =S67/Q67 -> 0.013254961
D68: =SUM(C65:C67)/$D$20 -> 8496 | K68: =(1/6)*($K$20*J65+K$21*J66+K$22*J67) -> 8502 | R68: =R$20*Q67+(1-R$20)*R67 -> 8522.3166

Sheet B - Forecast
B18: Linear Regression with Time | I18: Double Exponential Smoothing (Holt's Method)
B20: Parameter Peramalan | C20: Slope | D20: =SLOPE(C29:C68,B29:B68) -> 276.69644 | I20: Parameter Peramalan | J20: α | K20: =_xlfn.FORECAST.ETS.STAT(J29:J68,I29:I68,1,0) -> 0.25
C21: Intercept | D21: =INTERCEPT(C29:C68,B29:B68) -> 4847.7231 | J21: β | K21: =_xlfn.FORECAST.ETS.STAT(J29:J68,I29:I68,2,0) -> 0.001
J22: B(0) | K22: =J29 -> 4708
J23: T(0) | K23: =0 -> 0
B24: Ukuran Error | C24: MAD | D24: =AVERAGE(E29:E74) -> 214.44152 | I24: Ukuran Error | J24: MAD | K24: =AVERAGE(O29:O74) -> 1468.2017
C25: MSE | D25: =AVERAGE(F29:F74) -> 69193.271 | J25: MSE | K25: =AVERAGE(P29:P74) -> 6718376.9
C26: MAPE | D26: =AVERAGE(G29:G68) -> 0.023443914 | J26: MAPE | K26: =AVERAGE(Q29:Q68) -> 0.92353998
B28: Periode | C28: Data penjualan Tripod B | D28: Hasil Peramalan pada periode t | E28: Nilai mutlak dari perbedaan antara hasil peramalan & data penjualan | F28: Nilai kuadrat dari perbedaan antara hasil peramalan & data penjualan | G28: Persentase perbedaan nilai hasil peramalan & data penjualan | I28: Periode | J28: Data penjualan Tripod B | K28: B(t) | L28: T(t) | M28: k | N28: F(t) | O28: Nilai mutlak dari perbedaan antara hasil peramalan & data penjualan | P28: Nilai kuadrat dari perbedaan antara hasil peramalan & data penjualan | Q28: Persentase perbedaan nilai hasil peramalan & data penjualan
B29: 1 | C29: 4708 | D29: =$D$21+$D$20*B29 -> 5124.4195 | E29: =ABS(C29-D29) -> 416.41951 | F29: =E29^2 -> 173405.21 | G29: =E29/C29 -> 0.088449344 | I29: 1 | J29: 4708 | K29: =K20*J29+(1-K20)*(K22+K23) -> 4708 | L29: =K21*(K29-K22)+(1-K21)*K23 -> 0 | M29: 1 | N29: =K29+M29*L29 -> 4708 | O29: =ABS(N29-J29) -> 0 | P29: =O29^2 -> 0 | Q29: =N29/J29 -> 1
B30: 2 | C30: 5518 | D30: =$D$21+$D$20*B30 -> 5401.1159 | E30: =ABS(C30-D30) -> 116.88405 | F30: =E30^2 -> 13661.882 | G30: =E30/C30 -> 0.021182322 | I30: 2 | J30: 5518 | K30: =K$20*J30+(1-K$20)*(K29+L29) -> 4910.5 | L30: =K$21*(K30-K29)+(1-K$21)*L29 -> 0.2025 | M30: 1 | N30: =K30+M30*L30 -> 4910.7025 | O30: =ABS(N30-J30) -> 607.2975 | P30: =O30^2 -> 368810.25 | Q30: =N30/J30 -> 0.88994246
B31: 3 | C31: 5912 | D31: =$D$21+$D$20*B31 -> 5677.8124 | E31: =ABS(C31-D31) -> 234.18762 | F31: =E31^2 -> 54843.84 | G31: =E31/C31 -> 0.039612249 | I31: 3 | J31: 5912 | K31: =K$20*J31+(1-K$20)*(K30+L30) -> 5161.0269 | L31: =K$21*(K31-K30)+(1-K$21)*L30 -> 0.45282438 | M31: 1 | N31: =K31+M31*L31 -> 5161.4797 | O31: =ABS(N31-J31) -> 750.5203 | P31: =O31^2 -> 563280.72 | Q31: =N31/J31 -> 0.87305137
B32: 4 | C32: 5600 | D32: =$D$21+$D$20*B32 -> 5954.5088 | E32: =ABS(C32-D32) -> 354.50882 | F32: =E32^2 -> 125676.5 | G32: =E32/C32 -> 0.063305146 | I32: 4 | J32: 5600 | K32: =K$20*J32+(1-K$20)*(K31+L31) -> 5271.1098 | L32: =K$21*(K32-K31)+(1-K$21)*L31 -> 0.56245445 | M32: 1 | N32: =K32+M32*L32 -> 5271.6722 | O32: =ABS(N32-J32) -> 328.32777 | P32: =O32^2 -> 107799.13 | Q32: =N32/J32 -> 0.94137004
B33: 5 | C33: 6417 | D33: =$D$21+$D$20*B33 -> 6231.2053 | E33: =ABS(C33-D33) -> 185.79475 | F33: =E33^2 -> 34519.688 | G33: =E33/C33 -> 0.028953521 | I33: 5 | J33: 6417 | K33: =K$20*J33+(1-K$20)*(K32+L32) -> 5558.0042 | L33: =K$21*(K33-K32)+(1-K$21)*L32 -> 0.84878639 | M33: 1 | N33: =K33+M33*L33 -> 5558.853 | O33: =ABS(N33-J33) -> 858.14704 | P33: =O33^2 -> 736416.35 | Q33: =N33/J33 -> 0.86626975
B34: 6 | C34: 6534 | D34: =$D$21+$D$20*B34 -> 6507.9017 | E34: =ABS(C34-D34) -> 26.098311 | F34: =E34^2 -> 681.12186 | G34: =E34/C34 -> 0.0039942319 | I34: 6 | J34: 6534 | K34: =K$20*J34+(1-K$20)*(K33+L33) -> 5802.6397 | L34: =K$21*(K34-K33)+(1-K$21)*L33 -> 1.0925732 | M34: 1 | N34: =K34+M34*L34 -> 5803.7323 | O34: =ABS(N34-J34) -> 730.26771 | P34: =O34^2 -> 533290.93 | Q34: =N34/J34 -> 0.88823573
B35: 7 | C35: 6939 | D35: =$D$21+$D$20*B35 -> 6784.5981 | E35: =ABS(C35-D35) -> 154.40188 | F35: =E35^2 -> 23839.939 | G35: =E35/C35 -> 0.022251315 | I35: 7 | J35: 6939 | K35: =K$20*J35+(1-K$20)*(K34+L34) -> 6087.5492 | L35: =K$21*(K35-K34)+(1-K$21)*L34 -> 1.3763901 | M35: 1 | N35: =K35+M35*L35 -> 6088.9256 | O35: =ABS(N35-J35) -> 850.07439 | P35: =O35^2 -> 722626.47 | Q35: =N35/J35 -> 0.87749324
B36: 8 | C36: 7543 | D36: =$D$21+$D$20*B36 -> 7061.2946 | E36: =ABS(C36-D36) -> 481.70544 | F36: =E36^2 -> 232040.13 | G36: =E36/C36 -> 0.063861254 | I36: 8 | J36: 7543 | K36: =K$20*J36+(1-K$20)*(K35+L35) -> 6452.4442 | L36: =K$21*(K36-K35)+(1-K$21)*L35 -> 1.7399087 | M36: 1 | N36: =K36+M36*L36 -> 6454.1841 | O36: =ABS(N36-J36) -> 1088.8159 | P36: =O36^2 -> 1185520 | Q36: =N36/J36 -> 0.85565214
B37: 9 | C37: 7183 | D37: =$D$21+$D$20*B37 -> 7337.991 | E37: =ABS(C37-D37) -> 154.99099 | F37: =E37^2 -> 24022.208 | G37: =E37/C37 -> 0.021577474 | I37: 9 | J37: 7183 | K37: =K$20*J37+(1-K$20)*(K36+L36) -> 6636.3881 | L37: =K$21*(K37-K36)+(1-K$21)*L36 -> 1.9221126 | M37: 1 | N37: =K37+M37*L37 -> 6638.3102 | O37: =ABS(N37-J37) -> 544.6898 | P37: =O37^2 -> 296686.98 | Q37: =N37/J37 -> 0.92416959
B38: 10 | C38: 7312 | D38: =$D$21+$D$20*B38 -> 7614.6874 | E38: =ABS(C38-D38) -> 302.68743 | F38: =E38^2 -> 91619.68 | G38: =E38/C38 -> 0.041395983 | I38: 10 | J38: 7312 | K38: =K$20*J38+(1-K$20)*(K37+L37) -> 6806.7326 | L38: =K$21*(K38-K37)+(1-K$21)*L37 -> 2.0905351 | M38: 1 | N38: =K38+M38*L38 -> 6808.8232 | O38: =ABS(N38-J38) -> 503.17682 | P38: =O38^2 -> 253186.91 | Q38: =N38/J38 -> 0.93118479
B39: 11 | C39: 7554 | D39: =$D$21+$D$20*B39 -> 7891.3839 | E39: =ABS(C39-D39) -> 337.38386 | F39: =E39^2 -> 113827.87 | G39: =E39/C39 -> 0.044662942 | I39: 11 | J39: 7554 | K39: =K$20*J39+(1-K$20)*(K38+L38) -> 6995.1174 | L39: =K$21*(K39-K38)+(1-K$21)*L38 -> 2.2768293 | M39: 1 | N39: =K39+M39*L39 -> 6997.3942 | O39: =ABS(N39-J39) -> 556.60578 | P39: =O39^2 -> 309810 | Q39: =N39/J39 -> 0.92631642
B40: 12 | C40: 7858 | D40: =$D$21+$D$20*B40 -> 8168.0803 | E40: =ABS(C40-D40) -> 310.0803 | F40: =E40^2 -> 96149.793 | G40: =E40/C40 -> 0.039460461 | I40: 12 | J40: 7858 | K40: =K$20*J40+(1-K$20)*(K39+L39) -> 7212.5457 | L40: =K$21*(K40-K39)+(1-K$21)*L39 -> 2.4919807 | M40: 1 | N40: =K40+M40*L40 -> 7215.0376 | O40: =ABS(N40-J40) -> 642.96236 | P40: =O40^2 -> 413400.59 | Q40: =N40/J40 -> 0.91817735
B41: 13 | C41: 8361 | D41: =$D$21+$D$20*B41 -> 8444.7767 | E41: =ABS(C41-D41) -> 83.776735 | F41: =E41^2 -> 7018.5414 | G41: =E41/C41 -> 0.010019942 | I41: 13 | J41: 8361 | K41: =K$20*J41+(1-K$20)*(K40+L40) -> 7501.5282 | L41: =K$21*(K41-K40)+(1-K$21)*L40 -> 2.7784713 | M41: 1 | N41: =K41+M41*L41 -> 7504.3067 | O41: =ABS(N41-J41) -> 856.6933 | P41: =O41^2 -> 733923.4 | Q41: =N41/J41 -> 0.89753698
... B68: 40 | C68: 15657 | D68: =$D$21+$D$20*B68 -> 15915.58 | E68: =ABS(C68-D68) -> 258.58049 | F68: =E68^2 -> 66863.869 | G68: =E68/C68 -> 0.016515328 | I68: 40 | J68: 15657 | K68: =K$20*J68+(1-K$20)*(K67+L67) -> 15071.725 | L68: =K$21*(K68-K67)+(1-K$21)*L67 -> 10.174411 | M68: 1 | N68: =K68+M68*L68 -> 15081.9 | O68: =ABS(N68-J68) -> 575.1001 | P68: =O68^2 -> 330740.12 | Q68: =N68/J68 -> 0.96326882
B69: 41 | D69: =$D$21+$D$20*B69 -> 16192.277 | I69: 41 | K69: =K$20*J69+(1-K$20)*(K68+L68) -> 11311.425 | L69: =K$21*(K69-K68)+(1-K$21)*L68 -> 6.4039365 | M69: 1 | N69: =K69+M69*L69 -> 11317.829 | O69: =ABS(N69-J69) -> 11317.829 | P69: =O69^2 -> 1.2809325e+08
B70: 42 | D70: =$D$21+$D$20*B70 -> 16468.973 | I70: 42 | K70: =K$20*J70+(1-K$20)*(K69+L69) -> 8488.3716 | L70: =K$21*(K70-K69)+(1-K$21)*L69 -> 3.5744792 | M70: 2 | N70: =K70+M70*L70 -> 8495.5206 | O70: =ABS(N70-J70) -> 8495.5206 | P70: =O70^2 -> 72173870
B71: 43 | D71: =$D$21+$D$20*B71 -> 16745.67 | I71: 43 | K71: =K$20*J71+(1-K$20)*(K70+L70) -> 6368.9596 | L71: =K$21*(K71-K70)+(1-K$21)*L70 -> 1.4514927 | M71: 3 | N71: =K71+M71*L71 -> 6373.3141 | O71: =ABS(N71-J71) -> 6373.3141 | P71: =O71^2 -> 40619132
B72: 44 | D72: =$D$21+$D$20*B72 -> 17022.366 | I72: 44 | K72: =K$20*J72+(1-K$20)*(K71+L71) -> 4777.8083 | L72: =K$21*(K72-K71)+(1-K$21)*L71 -> -0.14111006 | M72: 4 | N72: =K72+M72*L72 -> 4777.2439 | O72: =ABS(N72-J72) -> 4777.2439 | P72: =O72^2 -> 22822059
B73: 45 | D73: =$D$21+$D$20*B73 -> 17299.063 | I73: 45 | K73: =K$20*J73+(1-K$20)*(K72+L72) -> 3583.2504 | L73: =K$21*(K73-K72)+(1-K$21)*L72 -> -1.3355269 | M73: 5 | N73: =K73+M73*L73 -> 3576.5728 | O73: =ABS(N73-J73) -> 3576.5728 | P73: =O73^2 -> 12791873
B74: 46 | D74: =$D$21+$D$20*B74 -> 17575.759 | I74: 46 | K74: =K$20*J74+(1-K$20)*(K73+L73) -> 2686.4362 | L74: =K$21*(K74-K73)+(1-K$21)*L73 -> -2.2310056 | M74: 6 | N74: =K74+M74*L74 -> 2673.0501 | O74: =ABS(N74-J74) -> 2673.0501 | P74: =O74^2 -> 7145197

Sheet C - Forecast
C18: Triple Exponential Smoothing (Holt's Winter Method) | P18: Double Exponential Smoothing (Holt's Method)
C20: Parameter Peramalan | D20: α | E20: =_xlfn.FORECAST.ETS.STAT(D33:D72,C33:C72,1,1) -> 0.9 | P20: Parameter Peramalan | Q20: α | R20: =_xlfn.FORECAST.ETS.STAT(Q33:Q72,P33:P72,1,1) -> 0.9
D21: β | E21: =_xlfn.FORECAST.ETS.STAT(D34:D73,C34:C73,2,1) -> 0.001 | Q21: β | R21: =_xlfn.FORECAST.ETS.STAT(Q33:Q72,P33:P72,2,1) -> 0.001
D22: γ | E22: =_xlfn.FORECAST.ETS.STAT(D34:D73,C34:C73,3,1) -> 2.220446e-16
D23: N | E23: 6
D24: V1 | E24: =AVERAGE(D33:D38) -> 6223.8333
D25: V2 | E25: =AVERAGE(D39:D44) -> 7328.1667
D26: T(0) | E26: =(E25-E24)/E23 -> 184.05556
D27: B(0) | E27: =E25+E26*((E23-1)/2) -> 7788.3056
C28: Ukuran Error | D28: MAD | E28: =AVERAGE(J45:J72) -> 178.77638 | P28: Ukuran Error | Q28: MAD | R28: =AVERAGE(S33:S72) -> 976.34719
D29: MSE | E29: =AVERAGE(K45:K72) -> 41161.976 | Q29: MSE | R29: =AVERAGE(T33:T72) -> 1386957.8
D30: MAPE | E30: =AVERAGE(L45:L72) -> 0.016980973 | Q30: MAPE | R30: =AVERAGE(U33:U72) -> 0.10973045
N31: Perhitungan Seasonal Factor
C32: Periode | D32: Data penjualan Tripod C | E32: B(t) | F32: T(t) | G32: S(t) | H32: k | I32: F(t) | J32: Nilai mutlak dari perbedaan antara hasil peramalan & data penjualan | K32: Nilai kuadrat dari perbedaan antara hasil peramalan & data penjualan | L32: Persentase perbedaan nilai hasil peramalan & data penjualan | N32: S-j | P32: Periode | Q32: Data penjualan Tripod C | R32: Hasil Peramalan pada periode t | S32: Nilai mutlak dari perbedaan antara hasil peramalan & data penjualan | T32: Nilai kuadrat dari perbedaan antara hasil peramalan & data penjualan | U32: Persentase perbedaan nilai hasil peramalan & data penjualan
C33: 1 | D33: 5114 | N33: =D33/($E$24-(($E$23+1)/2-C33)*$E$26) -> 0.88727813 | P33: 1 | Q33: 5114 | R33: =_xlfn.FORECAST.ETS(P33,$Q$33:$Q$72,$P$33:$P$72,1) -> 6079.7515 | S33: =ABS(Q33-R33) -> 965.75148 | T33: =S33^2 -> 932675.93 | U33: =S33/Q33 -> 0.18884464
C34: 2 | D34: 5570 | N34: =D34/($E$24-(($E$23+1)/2-C34)*$E$26) -> 0.93648859 | P34: 2 | Q34: 5570 | R34: =_xlfn.FORECAST.ETS(P34,$Q$33:$Q$72,$P$33:$P$72,1) -> 6314.5464 | S34: =ABS(Q34-R34) -> 744.54643 | T34: =S34^2 -> 554349.39 | U34: =S34/Q34 -> 0.13367081
C35: 3 | D35: 5408 | N35: =D35/($E$24-(($E$23+1)/2-C35)*$E$26) -> 0.88195882 | P35: 3 | Q35: 5408 | R35: =_xlfn.FORECAST.ETS(P35,$Q$33:$Q$72,$P$33:$P$72,1) -> 6549.3414 | S35: =ABS(Q35-R35) -> 1141.3414 | T35: =S35^2 -> 1302660.1 | U35: =S35/Q35 -> 0.21104685
C36: 4 | D36: 6816 | N36: =D36/($E$24-(($E$23+1)/2-C36)*$E$26) -> 1.0791878 | P36: 4 | Q36: 6816 | R36: =_xlfn.FORECAST.ETS(P36,$Q$33:$Q$72,$P$33:$P$72,1) -> 6784.1363 | S36: =ABS(Q36-R36) -> 31.863675 | T36: =S36^2 -> 1015.2938 | U36: =S36/Q36 -> 0.004674835
C37: 5 | D37: 6927 | N37: =D37/($E$24-(($E$23+1)/2-C37)*$E$26) -> 1.065706 | P37: 5 | Q37: 6927 | R37: =_xlfn.FORECAST.ETS(P37,$Q$33:$Q$72,$P$33:$P$72,1) -> 7018.9313 | S37: =ABS(Q37-R37) -> 91.931272 | T37: =S37^2 -> 8451.3589 | U37: =S37/Q37 -> 0.013271441
C38: 6 | D38: 7508 | N38: =D38/($E$24-(($E$23+1)/2-C38)*$E$26) -> 1.1232841 | P38: 6 | Q38: 7508 | R38: =_xlfn.FORECAST.ETS(P38,$Q$33:$Q$72,$P$33:$P$72,1) -> 7253.7262 | S38: =ABS(Q38-R38) -> 254.27378 | T38: =S38^2 -> 64655.155 | U38: =S38/Q38 -> 0.033867046
C39: 7 | D39: 7635 | G39: =(N33+N39)/2 -> 0.99947549 | H39: 1 | N39: =D39/($E$24-(($E$23+1)/2-C39)*$E$26) -> 1.1116728 | P39: 7 | Q39: 7635 | R39: =_xlfn.FORECAST.ETS(P39,$Q$33:$Q$72,$P$33:$P$72,1) -> 7488.5212 | S39: =ABS(Q39-R39) -> 146.47883 | T39: =S39^2 -> 21456.048 | U39: =S39/Q39 -> 0.019185178
C40: 8 | D40: 7843 | G40: =(N34+N40)/2 -> 1.0243211 | H40: 1 | N40: =D40/($E$24-(($E$23+1)/2-C40)*$E$26) -> 1.1121536 | P40: 8 | Q40: 7843 | R40: =_xlfn.FORECAST.ETS(P40,$Q$33:$Q$72,$P$33:$P$72,1) -> 7723.3161 | S40: =ABS(Q40-R40) -> 119.68388 | T40: =S40^2 -> 14324.232 | U40: =S40/Q40 -> 0.015259962
C41: 9 | D41: 6991 | G41: =(N35+N41)/2 -> 0.9240409 | H41: 1 | N41: =D41/($E$24-(($E$23+1)/2-C41)*$E$26) -> 0.96612297 | P41: 9 | Q41: 6991 | R41: =_xlfn.FORECAST.ETS(P41,$Q$33:$Q$72,$P$33:$P$72,1) -> 7958.1111 | S41: =ABS(Q41-R41) -> 967.11106 | T41: =S41^2 -> 935303.81 | U41: =S41/Q41 -> 0.13833658
C42: 10 | D42: 7212 | G42: =(N36+N42)/2 -> 1.025565 | H42: 1 | N42: =D42/($E$24-(($E$23+1)/2-C42)*$E$26) -> 0.97194218 | P42: 10 | Q42: 7212 | R42: =_xlfn.FORECAST.ETS(P42,$Q$33:$Q$72,$P$33:$P$72,1) -> 8192.906 | S42: =ABS(Q42-R42) -> 980.90601 | T42: =S42^2 -> 962176.6 | U42: =S42/Q42 -> 0.13601026
C43: 11 | D43: 7138 | G43: =(N37+N43)/2 -> 1.0021958 | H43: 1 | N43: =D43/($E$24-(($E$23+1)/2-C43)*$E$26) -> 0.9386856 | P43: 11 | Q43: 7138 | R43: =_xlfn.FORECAST.ETS(P43,$Q$33:$Q$72,$P$33:$P$72,1) -> 8427.701 | S43: =ABS(Q43-R43) -> 1289.701 | T43: =S43^2 -> 1663328.6 | U43: =S43/Q43 -> 0.180681
C44: 12 | D44: 7150 | G44: =(N38+N44)/2 -> 1.0206636 | H44: 1 | N44: =D44/($E$24-(($E$23+1)/2-C44)*$E$26) -> 0.91804308 | P44: 12 | Q44: 7150 | R44: =_xlfn.FORECAST.ETS(P44,$Q$33:$Q$72,$P$33:$P$72,1) -> 8662.4959 | S44: =ABS(Q44-R44) -> 1512.4959 | T44: =S44^2 -> 2287643.9 | U44: =S44/Q44 -> 0.21153789
C45: 13 | D45: 7293 | E45: =$E$20*D45/(G39/SUM(G39:G44)*$E$23)+(1-$E$20)*(E27+E26) -> 7360.2892 | F45: =$E$21*(E45-E27)+(1-$E$21)*E26 -> 183.44348 | G45: =$E$22*D45/E45+(1-$E$22)*(G39/SUM(G39:G44)*$E$23) -> 1.0000986 | H45: 1 | I45: =(E45+H45*F45)*G45 -> 7544.4763 | J45: =ABS(I45-D45) -> 251.47626 | K45: =J45^2 -> 63240.311 | L45: =J45/E45 -> 0.034166628 | P45: 13 | Q45: 7293 | R45: =_xlfn.FORECAST.ETS(P45,$Q$33:$Q$72,$P$33:$P$72,1) -> 8897.2909 | S45: =ABS(Q45-R45) -> 1604.2909 | T45: =S45^2 -> 2573749.1 | U45: =S45/Q45 -> 0.21997681
C46: 14 | D46: 7038 | E46: =$E$20*D46/(G40/SUM(G40:G45)*$E$23)+(1-$E$20)*(E45+F45) -> 6934.9659 | F46: =$E$21*(E46-E45)+(1-$E$21)*F45 -> 182.83472 | G46: =$E$22*D46/E46+(1-$E$22)*(G40/SUM(G40:G45)*$E$23) -> 1.0248532 | H46: 1 | I46: =(E46+H46*F46)*G46 -> 7294.7006 | J46: =ABS(I46-D46) -> 256.70058 | K46: =J46^2 -> 65895.19 | L46: =J46/E46 -> 0.037015407 | P46: 14 | Q46: 7038 | R46: =_xlfn.FORECAST.ETS(P46,$Q$33:$Q$72,$P$33:$P$72,1) -> 9132.0858 | S46: =ABS(Q46-R46) -> 2094.0858 | T46: =S46^2 -> 4385195.3 | U46: =S46/Q46 -> 0.2975399
C47: 15 | D47: 7304 | E47: =$E$20*D47/(G41/SUM(G41:G46)*$E$23)+(1-$E$20)*(E46+F46) -> 7822.6884 | F47: =$E$21*(E47-E46)+(1-$E$21)*F46 -> 183.5396 | G47: =$E$22*D47/E47+(1-$E$22)*(G41/SUM(G41:G46)*$E$23) -> 0.92443886 | H47: 1 | I47: =(E47+H47*F47)*G47 -> 7401.2683 | J47: =ABS(I47-D47) -> 97.268292 | K47: =J47^2 -> 9461.1206 | L47: =J47/E47 -> 0.012434126 | P47: 15 | Q47: 7304 | R47: =_xlfn.FORECAST.ETS(P47,$Q$33:$Q$72,$P$33:$P$72,1) -> 9366.8807 | S47: =ABS(Q47-R47) -> 2062.8807 | T47: =S47^2 -> 4255477 | U47: =S47/Q47 -> 0.28243165
C48: 16 | D48: 7474 | E48: =$E$20*D48/(G42/SUM(G42:G47)*$E$23)+(1-$E$20)*(E47+F47) -> 7357.1556 | F48: =$E$21*(E48-E47)+(1-$E$21)*F47 -> 182.89053 | G48: =$E$22*D48/E48+(1-$E$22)*(G42/SUM(G42:G47)*$E$23) -> 1.0259386 | H48: 1 | I48: =(E48+H48*F48)*G48 -> 7735.6243 | J48: =ABS(I48-D48) -> 261.62428 | K48: =J48^2 -> 68447.261 | L48: =J48/E48 -> 0.03556052 | P48: 16 | Q48: 7474 | R48: =_xlfn.FORECAST.ETS(P48,$Q$33:$Q$72,$P$33:$P$72,1) -> 9601.6757 | S48: =ABS(Q48-R48) -> 2127.6757 | T48: =S48^2 -> 4527003.9 | U48: =S48/Q48 -> 0.28467697
C49: 17 | D49: 7886 | E49: =$E$20*D49/(G43/SUM(G43:G48)*$E$23)+(1-$E$20)*(E48+F48) -> 7833.7164 | F49: =$E$21*(E49-E48)+(1-$E$21)*F48 -> 183.1842 | G49: =$E$22*D49/E49+(1-$E$22)*(G43/SUM(G43:G48)*$E$23) -> 1.0024984 | H49: 1 | I49: =(E49+H49*F49)*G49 -> 8036.9303 | J49: =ABS(I49-D49) -> 150.93033 | K49: =J49^2 -> 22779.964 | L49: =J49/E49 -> 0.019266759 | P49: 17 | Q49: 7886 | R49: =_xlfn.FORECAST.ETS(P49,$Q$33:$Q$72,$P$33:$P$72,1) -> 9836.4706 | S49: =ABS(Q49-R49) -> 1950.4706 | T49: =S49^2 -> 3804335.7 | U49: =S49/Q49 -> 0.24733333
C50: 18 | D50: 8688 | E50: =$E$20*D50/(G44/SUM(G44:G49)*$E$23)+(1-$E$20)*(E49+F49) -> 8460.6619 | F50: =$E$21*(E50-E49)+(1-$E$21)*F49 -> 183.62796 | G50: =$E$22*D50/E50+(1-$E$22)*(G44/SUM(G44:G49)*$E$23) -> 1.0209203 | H50: 1 | I50: =(E50+H50*F50)*G50 -> 8825.1312 | J50: =ABS(I50-D50) -> 137.1312 | K50: =J50^2 -> 18804.965 | L50: =J50/E50 -> 0.016208093 | P50: 18 | Q50: 8688 | R50: =_xlfn.FORECAST.ETS(P50,$Q$33:$Q$72,$P$33:$P$72,1) -> 10071.266 | S50: =ABS(Q50-R50) -> 1383.2656 | T50: =S50^2 -> 1913423.7 | U50: =S50/Q50 -> 0.15921565
C51: 19 | D51: 9722 | E51: =$E$20*D51/(G45/SUM(G45:G50)*$E$23)+(1-$E$20)*(E50+F50) -> 9611.5409 | F51: =$E$21*(E51-E50)+(1-$E$21)*F50 -> 184.59521 | G51: =$E$22*D51/E51+(1-$E$22)*(G45/SUM(G45:G50)*$E$23) -> 1.0003073 | H51: 1 | I51: =(E51+H51*F51)*G51 -> 9799.1466 | J51: =ABS(I51-D51) -> 77.14657 | K51: =J51^2 -> 5951.5933 | L51: =J51/E51 -> 0.0080264518 | P51: 19 | Q51: 9722 | R51: =_xlfn.FORECAST.ETS(P51,$Q$33:$Q$72,$P$33:$P$72,1) -> 10306.061 | S51: =ABS(Q51-R51) -> 584.06054 | T51: =S51^2 -> 341126.71 | U51: =S51/Q51 -> 0.060076171
C52: 20 | D52: 9457 | E52: =$E$20*D52/(G46/SUM(G46:G51)*$E$23)+(1-$E$20)*(E51+F51) -> 9283.0664 | F52: =$E$21*(E52-E51)+(1-$E$21)*F51 -> 184.08215 | G52: =$E$22*D52/E52+(1-$E$22)*(G46/SUM(G46:G51)*$E$23) -> 1.0250314 | H52: 1 | I52: =(E52+H52*F52)*G52 -> 9704.1247 | J52: =ABS(I52-D52) -> 247.12471 | K52: =J52^2 -> 61070.624 | L52: =J52/E52 -> 0.026621022 | P52: 20 | Q52: 9457 | R52: =_xlfn.FORECAST.ETS(P52,$Q$33:$Q$72,$P$33:$P$72,1) -> 10540.855 | S52: =ABS(Q52-R52) -> 1083.8555 | T52: =S52^2 -> 1174742.7 | U52: =S52/Q52 -> 0.11460881
C53: 21 | D53: 10158 | E53: =$E$20*D53/(G47/SUM(G47:G52)*$E$23)+(1-$E$20)*(E52+F52) -> 10834.748 | F53: =$E$21*(E53-E52)+(1-$E$21)*F52 -> 185.44974 | G53: =$E$22*D53/E53+(1-$E$22)*(G47/SUM(G47:G52)*$E$23) -> 0.92457217 | H53: 1 | I53: =(E53+H53*F53)*G53 -> 10188.968 | J53: =ABS(I53-D53) -> 30.967876 | K53: =J53^2 -> 959.00935 | L53: =J53/E53 -> 0.0028582 | P53: 21 | Q53: 10158 | R53: =_xlfn.FORECAST.ETS(P53,$Q$33:$Q$72,$P$33:$P$72,1) -> 10775.65 | S53: =ABS(Q53-R53) -> 617.65043 | T53: =S53^2 -> 381492.06 | U53: =S53/Q53 -> 0.060804335
C54: 22 | D54: 10921 | E54: =$E$20*D54/(G48/SUM(G48:G53)*$E$23)+(1-$E$20)*(E53+F53) -> 10681.249 | F54: =$E$21*(E54-E53)+(1-$E$21)*F53 -> 185.1108 | G54: =$E$22*D54/E54+(1-$E$22)*(G48/SUM(G48:G53)*$E$23) -> 1.0260637 | H54: 1 | I54: =(E54+H54*F54)*G54 -> 11149.578 | J54: =ABS(I54-D54) -> 228.57796 | K54: =J54^2 -> 52247.886 | L54: =J54/E54 -> 0.021399928 | P54: 22 | Q54: 10921 | R54: =_xlfn.FORECAST.ETS(P54,$Q$33:$Q$72,$P$33:$P$72,1) -> 11010.445 | S54: =ABS(Q54-R54) -> 89.445381 | T54: =S54^2 -> 8000.4762 | U54: =S54/Q54 -> 0.0081902189
C55: 23 | D55: 12035 | E55: =$E$20*D55/(G49/SUM(G49:G54)*$E$23)+(1-$E$20)*(E54+F54) -> 11890.049 | F55: =$E$21*(E55-E54)+(1-$E$21)*F54 -> 186.13449 | G55: =$E$22*D55/E55+(1-$E$22)*(G49/SUM(G49:G54)*$E$23) -> 1.0025998 | H55: 1 | I55: =(E55+H55*F55)*G55 -> 12107.579 | J55: =ABS(I55-D55) -> 72.579457 | K55: =J55^2 -> 5267.7776 | L55: =J55/E55 -> 0.0061042184 | P55: 23 | Q55: 12035 | R55: =_xlfn.FORECAST.ETS(P55,$Q$33:$Q$72,$P$33:$P$72,1) -> 11245.24 | S55: =ABS(Q55-R55) -> 789.75967 | T55: =S55^2 -> 623720.34 | U55: =S55/Q55 -> 0.065621909
C56: 24 | D56: 12118 | E56: =$E$20*D56/(G50/SUM(G50:G55)*$E$23)+(1-$E$20)*(E55+F55) -> 11889.433 | F56: =$E$21*(E56-E55)+(1-$E$21)*F55 -> 185.94773 | G56: =$E$22*D56/E56+(1-$E$22)*(G50/SUM(G50:G55)*$E$23) -> 1.0210063 | H56: 1 | I56: =(E56+H56*F56)*G56 -> 12329.04 | J56: =ABS(I56-D56) -> 211.03978 | K56: =J56^2 -> 44537.789 | L56: =J56/E56 -> 0.017750197 | P56: 24 | Q56: 12118 | R56: =_xlfn.FORECAST.ETS(P56,$Q$33:$Q$72,$P$33:$P$72,1) -> 11480.035 | S56: =ABS(Q56-R56) -> 637.96472 | T56: =S56^2 -> 406998.99 | U56: =S56/Q56 -> 0.052646041
C57: 25 | D57: 13589 | E57: =$E$20*D57/(G51/SUM(G51:G56)*$E$23)+(1-$E$20)*(E56+F56) -> 13433.026 | F57: =$E$21*(E57-E56)+(1-$E$21)*F56 -> 187.30538 | G57: =$E$22*D57/E57+(1-$E$22)*(G51/SUM(G51:G56)*$E$23) -> 1.0003772 | H57: 1 | I57: =(E57+H57*F57)*G57 -> 13625.47 | J57: =ABS(I57-D57) -> 36.469598 | K57: =J57^2 -> 1330.0316 | L57: =J57/E57 -> 0.0027149204 | P57: 25 | Q57: 13589 | R57: =_xlfn.FORECAST.ETS(P57,$Q$33:$Q$72,$P$33:$P$72,1) -> 11714.83 | S57: =ABS(Q57-R57) -> 1874.1698 | T57: =S57^2 -> 3512512.3 | U57: =S57/Q57 -> 0.13791815
... C72: 40 | D72: 15341 | E72: =$E$20*D72/(G66/SUM(G66:G71)*$E$23)+(1-$E$20)*(E71+F71) -> 14980.049 | F72: =$E$21*(E72-E71)+(1-$E$21)*F71 -> 186.07219 | G72: =$E$22*D72/E72+(1-$E$22)*(G66/SUM(G66:G71)*$E$23) -> 1.0261244 | H72: 1 | I72: =(E72+H72*F72)*G72 -> 15562.327 | J72: =ABS(I72-D72) -> 221.3267 | K72: =J72^2 -> 48985.508 | L72: =J72/E72 -> 0.014774765 | P72: 40 | Q72: 15341 | R72: =_xlfn.FORECAST.ETS(P72,$Q$33:$Q$72,$P$33:$P$72,1) -> 15236.754 | S72: =ABS(Q72-R72) -> 104.24556 | T72: =S72^2 -> 10867.137 | U72: =S72/Q72 -> 0.006795226
...

Sheet D - Forecast
C18: Triple Exponential Smoothing (Holt's Winter Method) | J18: Double Exponential Smoothing (Holt's Method) | Q18: Single Exponential Smoothing | X18: Linear Regression with Time | AE18: Weighted Moving Average
C20: Parameter Peramalan | D20: α | E20: =_xlfn.FORECAST.ETS.STAT(D28:D67,C28:C67,1,1) -> 0.002 | J20: Parameter Peramalan | K20: α | L20: =_xlfn.FORECAST.ETS.STAT(K28:K67,J28:J67,1,1) -> 0.002 | Q20: Parameter Peramalan | R20: α | S20: =_xlfn.FORECAST.ETS.STAT(R28:R67,Q28:Q67,1) -> 0.002 | X20: Parameter Peramalan | Y20: Slope | Z20: =SLOPE(Y28:Y67,X28:X67) -> -34.871295 | AE20: Parameter Peramalan | AF20: W1 | AG20: 1
D21: β | E21: =_xlfn.FORECAST.ETS.STAT(D28:D67,C28:C67,2,1) -> 0.001 | K21: β | L21: =_xlfn.FORECAST.ETS.STAT(K28:K67,J28:J67,2,1) -> 0.001 | Y21: Intercept | Z21: =INTERCEPT(Y28:Y67,X28:X67) -> 9569.5115 | AF21: W2 | AG21: 2
D22: γ | E22: =_xlfn.FORECAST.ETS.STAT(D28:D67,C28:C67,3,1) -> 2.220446e-16 | AF22: W3 | AG22: 3
C23: Ukuran Error | D23: MAD | E23: =AVERAGE(F28:F67) -> 3829.5691 | J23: Ukuran Error | K23: MAD | L23: =AVERAGE(M28:M67) -> 3829.5691 | Q23: Ukuran Error | R23: MAD | S23: =AVERAGE(T28:T67) -> 3895.2513 | X23: Ukuran Error | Y23: MAD | Z23: =AVERAGE(AA28:AA67) -> 3846.0078 | AE23: Ukuran Error | AF23: MAD | AG23: =AVERAGE(AH31:AH67) -> 4484.3829
D24: MSE | E24: =AVERAGE(G28:G67) -> 21460112 | K24: MSE | L24: =AVERAGE(N28:N67) -> 21460112 | R24: MSE | S24: =AVERAGE(U28:U67) -> 21650151 | Y24: MSE | Z24: =AVERAGE(AB28:AB67) -> 21354093 | AF24: MSE | AG24: =AVERAGE(AI31:AI67) -> 32075170
D25: MAPE | E25: =AVERAGE(H28:H67) -> 0.74294045 | K25: MAPE | L25: =AVERAGE(O28:O67) -> 0.74294045 | R25: MAPE | S25: =AVERAGE(V28:V67) -> 0.8003573 | Y25: MAPE | Z25: =AVERAGE(AC28:AC67) -> 0.77203616 | AF25: MAPE | AG25: =AVERAGE(AJ31:AJ67) -> 0.73448915
C27: Periode | D27: Data penjualan Tripod D | E27: Hasil Peramalan pada periode t | F27: Nilai mutlak dari perbedaan antara hasil peramalan & data penjualan | G27: Nilai kuadrat dari perbedaan antara hasil peramalan & data penjualan | H27: Persentase perbedaan nilai hasil peramalan & data penjualan | J27: Periode | K27: Data penjualan Tripod D | L27: Hasil Peramalan pada periode t | M27: Nilai mutlak dari perbedaan antara hasil peramalan & data penjualan | N27: Nilai kuadrat dari perbedaan antara hasil peramalan & data penjualan | O27: Persentase perbedaan nilai hasil peramalan & data penjualan | Q27: Periode | R27: Data penjualan Tripod D | S27: Hasil Peramalan pada periode t | T27: Nilai mutlak dari perbedaan antara hasil peramalan & data penjualan | U27: Nilai kuadrat dari perbedaan antara hasil peramalan & data penjualan | V27: Persentase perbedaan nilai hasil peramalan & data penjualan | X27: Periode | Y27: Data penjualan Tripod D | Z27: Hasil Peramalan pada periode t | AA27: Nilai mutlak dari perbedaan antara hasil peramalan & data penjualan | AB27: Nilai kuadrat dari perbedaan antara hasil peramalan & data penjualan | AC27: Persentase perbedaan nilai hasil peramalan & data penjualan | AE27: Periode | AF27: Data penjualan Tripod D | AG27: Hasil Peramalan pada periode t | AH27: Nilai mutlak dari perbedaan antara hasil peramalan & data penjualan | AI27: Nilai kuadrat dari perbedaan antara hasil peramalan & data penjualan | AJ27: Persentase perbedaan nilai hasil peramalan & data penjualan
C28: 1 | D28: 9163 | E28: =_xlfn.FORECAST.ETS(C28,$D$28:$D$67,$C$28:$C$67,1) -> 9024.4711 | F28: =ABS(E28-D28) -> 138.52892 | G28: =F28^2 -> 19190.261 | H28: =F28/D28 -> 0.015118293 | J28: 1 | K28: 9163 | L28: =_xlfn.FORECAST.ETS(J28,$K$28:$K$67,$J$28:$J$67,0) -> 9024.4711 | M28: =ABS(K28-L28) -> 138.52892 | N28: =M28^2 -> 19190.261 | O28: =M28/K28 -> 0.015118293 | Q28: 1 | R28: 9163 | S28: =R28 -> 9163 | T28: =ABS(Y28-Z28) -> 371.64024 | U28: =T28^2 -> 138116.47 | V28: =T28/R28 -> 0.040558796 | X28: 1 | Y28: 9163 | Z28: =$Z$21+$Z$20*X28 -> 9534.6402 | AA28: =ABS(Y28-Z28) -> 371.64024 | AB28: =AA28^2 -> 138116.47 | AC28: =AA28/Y28 -> 0.040558796 | AE28: 1 | AF28: 9163
C29: 2 | D29: 3010 | E29: =_xlfn.FORECAST.ETS(C29,$D$28:$D$67,$C$28:$C$67,1) -> 9000.3166 | F29: =ABS(E29-D29) -> 5990.3166 | G29: =F29^2 -> 35883893 | H29: =F29/D29 -> 1.9901384 | J29: 2 | K29: 3010 | L29: =_xlfn.FORECAST.ETS(J29,$K$28:$K$67,$J$28:$J$67,0) -> 9000.3166 | M29: =ABS(K29-L29) -> 5990.3166 | N29: =M29^2 -> 35883893 | O29: =M29/K29 -> 1.9901384 | Q29: 2 | R29: 3010 | S29: =$S$20*R28+(1-$S$20)*S28 -> 9163 | T29: =ABS(S29-R29) -> 6153 | U29: =T29^2 -> 37859409 | V29: =T29/R29 -> 2.044186 | X29: 2 | Y29: 3010 | Z29: =$Z$21+$Z$20*X29 -> 9499.7689 | AA29: =ABS(Y29-Z29) -> 6489.7689 | AB29: =AA29^2 -> 42117101 | AC29: =AA29/Y29 -> 2.1560694 | AE29: 2 | AF29: 3010
C30: 3 | D30: 2018 | E30: =_xlfn.FORECAST.ETS(C30,$D$28:$D$67,$C$28:$C$67,1) -> 8976.1622 | F30: =ABS(E30-D30) -> 6958.1622 | G30: =F30^2 -> 48416021 | H30: =F30/D30 -> 3.4480486 | J30: 3 | K30: 2018 | L30: =_xlfn.FORECAST.ETS(J30,$K$28:$K$67,$J$28:$J$67,0) -> 8976.1622 | M30: =ABS(K30-L30) -> 6958.1622 | N30: =M30^2 -> 48416021 | O30: =M30/K30 -> 3.4480486 | Q30: 3 | R30: 2018 | S30: =$S$20*R29+(1-$S$20)*S29 -> 9150.694 | T30: =ABS(S30-R30) -> 7132.694 | U30: =T30^2 -> 50875324 | V30: =T30/R30 -> 3.5345362 | X30: 3 | Y30: 2018 | Z30: =$Z$21+$Z$20*X30 -> 9464.8977 | AA30: =ABS(Y30-Z30) -> 7446.8977 | AB30: =AA30^2 -> 55456285 | AC30: =AA30/Y30 -> 3.6902367 | AE30: 3 | AF30: 2018
C31: 4 | D31: 17462 | E31: =_xlfn.FORECAST.ETS(C31,$D$28:$D$67,$C$28:$C$67,1) -> 8952.0077 | F31: =ABS(E31-D31) -> 8509.9923 | G31: =F31^2 -> 72419969 | H31: =F31/D31 -> 0.48734351 | J31: 4 | K31: 17462 | L31: =_xlfn.FORECAST.ETS(J31,$K$28:$K$67,$J$28:$J$67,0) -> 8952.0077 | M31: =ABS(K31-L31) -> 8509.9923 | N31: =M31^2 -> 72419969 | O31: =M31/K31 -> 0.48734351 | Q31: 4 | R31: 17462 | S31: =$S$20*R30+(1-$S$20)*S30 -> 9136.4286 | T31: =ABS(S31-R31) -> 8325.5714 | U31: =T31^2 -> 69315139 | V31: =T31/R31 -> 0.47678224 | X31: 4 | Y31: 17462 | Z31: =$Z$21+$Z$20*X31 -> 9430.0264 | AA31: =ABS(Y31-Z31) -> 8031.9736 | AB31: =AA31^2 -> 64512601 | AC31: =AA31/Y31 -> 0.45996871 | AE31: 4 | AF31: 17462 | AG31: =(1/6)*(AF28*$AG$20+AF29*$AG$21+AF30*$AG$22) -> 3539.5 | AH31: =ABS(AF31-AG31) -> 13922.5 | AI31: =AH31^2 -> 1.9383601e+08 | AJ31: =AH31/AF31 -> 0.79730271
C32: 5 | D32: 17199 | E32: =_xlfn.FORECAST.ETS(C32,$D$28:$D$67,$C$28:$C$67,1) -> 8927.8533 | F32: =ABS(E32-D32) -> 8271.1467 | G32: =F32^2 -> 68411869 | H32: =F32/D32 -> 0.48090858 | J32: 5 | K32: 17199 | L32: =_xlfn.FORECAST.ETS(J32,$K$28:$K$67,$J$28:$J$67,0) -> 8927.8533 | M32: =ABS(K32-L32) -> 8271.1467 | N32: =M32^2 -> 68411869 | O32: =M32/K32 -> 0.48090858 | Q32: 5 | R32: 17199 | S32: =$S$20*R31+(1-$S$20)*S31 -> 9153.0798 | T32: =ABS(S32-R32) -> 8045.9202 | U32: =T32^2 -> 64736833 | V32: =T32/R32 -> 0.46781326 | X32: 5 | Y32: 17199 | Z32: =$Z$21+$Z$20*X32 -> 9395.1551 | AA32: =ABS(Y32-Z32) -> 7803.8449 | AB32: =AA32^2 -> 60899996 | AC32: =AA32/Y32 -> 0.45373829 | AE32: 5 | AF32: 17199 | AG32: =(1/6)*(AF29*$AG$20+AF30*$AG$21+AF31*$AG$22) -> 9905.3333 | AH32: =ABS(AF32-AG32) -> 7293.6667 | AI32: =AH32^2 -> 53197573 | AJ32: =AH32/AF32 -> 0.42407504
C33: 6 | D33: 11400 | E33: =_xlfn.FORECAST.ETS(C33,$D$28:$D$67,$C$28:$C$67,1) -> 8903.6988 | F33: =ABS(E33-D33) -> 2496.3012 | G33: =F33^2 -> 6231519.7 | H33: =F33/D33 -> 0.21897379 | J33: 6 | K33: 11400 | L33: =_xlfn.FORECAST.ETS(J33,$K$28:$K$67,$J$28:$J$67,0) -> 8903.6988 | M33: =ABS(K33-L33) -> 2496.3012 | N33: =M33^2 -> 6231519.7 | O33: =M33/K33 -> 0.21897379 | Q33: 6 | R33: 11400 | S33: =$S$20*R32+(1-$S$20)*S32 -> 9169.1716 | T33: =ABS(S33-R33) -> 2230.8284 | U33: =T33^2 -> 4976595.4 | V33: =T33/R33 -> 0.1956867 | X33: 6 | Y33: 11400 | Z33: =$Z$21+$Z$20*X33 -> 9360.2838 | AA33: =ABS(Y33-Z33) -> 2039.7162 | AB33: =AA33^2 -> 4160442.3 | AC33: =AA33/Y33 -> 0.17892248 | AE33: 6 | AF33: 11400 | AG33: =(1/6)*(AF30*$AG$20+AF31*$AG$21+AF32*$AG$22) -> 14756.5 | AH33: =ABS(AF33-AG33) -> 3356.5 | AI33: =AH33^2 -> 11266092 | AJ33: =AH33/AF33 -> 0.29442982
C34: 7 | D34: 8070 | E34: =_xlfn.FORECAST.ETS(C34,$D$28:$D$67,$C$28:$C$67,1) -> 8879.5443 | F34: =ABS(E34-D34) -> 809.54434 | G34: =F34^2 -> 655362.03 | H34: =F34/D34 -> 0.10031528 | J34: 7 | K34: 8070 | L34: =_xlfn.FORECAST.ETS(J34,$K$28:$K$67,$J$28:$J$67,0) -> 8879.5443 | M34: =ABS(K34-L34) -> 809.54434 | N34: =M34^2 -> 655362.03 | O34: =M34/K34 -> 0.10031528 | Q34: 7 | R34: 8070 | S34: =$S$20*R33+(1-$S$20)*S33 -> 9173.6333 | T34: =ABS(S34-R34) -> 1103.6333 | U34: =T34^2 -> 1218006.4 | V34: =T34/R34 -> 0.13675753 | X34: 7 | Y34: 8070 | Z34: =$Z$21+$Z$20*X34 -> 9325.4125 | AA34: =ABS(Y34-Z34) -> 1255.4125 | AB34: =AA34^2 -> 1576060.5 | AC34: =AA34/Y34 -> 0.15556536 | AE34: 7 | AF34: 8070 | AG34: =(1/6)*(AF31*$AG$20+AF32*$AG$21+AF33*$AG$22) -> 14343.333 | AH34: =ABS(AF34-AG34) -> 6273.3333 | AI34: =AH34^2 -> 39354711 | AJ34: =AH34/AF34 -> 0.77736473
C35: 8 | D35: 2615 | E35: =_xlfn.FORECAST.ETS(C35,$D$28:$D$67,$C$28:$C$67,1) -> 8855.3899 | F35: =ABS(E35-D35) -> 6240.3899 | G35: =F35^2 -> 38942466 | H35: =F35/D35 -> 2.3863824 | J35: 8 | K35: 2615 | L35: =_xlfn.FORECAST.ETS(J35,$K$28:$K$67,$J$28:$J$67,0) -> 8855.3899 | M35: =ABS(K35-L35) -> 6240.3899 | N35: =M35^2 -> 38942466 | O35: =M35/K35 -> 2.3863824 | Q35: 8 | R35: 2615 | S35: =$S$20*R34+(1-$S$20)*S34 -> 9171.426 | T35: =ABS(S35-R35) -> 6556.426 | U35: =T35^2 -> 42986722 | V35: =T35/R35 -> 2.5072375 | X35: 8 | Y35: 2615 | Z35: =$Z$21+$Z$20*X35 -> 9290.5412 | AA35: =ABS(Y35-Z35) -> 6675.5412 | AB35: =AA35^2 -> 44562850 | AC35: =AA35/Y35 -> 2.5527882 | AE35: 8 | AF35: 2615 | AG35: =(1/6)*(AF32*$AG$20+AF33*$AG$21+AF34*$AG$22) -> 10701.5 | AH35: =ABS(AF35-AG35) -> 8086.5 | AI35: =AH35^2 -> 65391482 | AJ35: =AH35/AF35 -> 3.0923518
C36: 9 | D36: 3114 | E36: =_xlfn.FORECAST.ETS(C36,$D$28:$D$67,$C$28:$C$67,1) -> 8831.2354 | F36: =ABS(E36-D36) -> 5717.2354 | G36: =F36^2 -> 32686781 | H36: =F36/D36 -> 1.835978 | J36: 9 | K36: 3114 | L36: =_xlfn.FORECAST.ETS(J36,$K$28:$K$67,$J$28:$J$67,0) -> 8831.2354 | M36: =ABS(K36-L36) -> 5717.2354 | N36: =M36^2 -> 32686781 | O36: =M36/K36 -> 1.835978 | Q36: 9 | R36: 3114 | S36: =$S$20*R35+(1-$S$20)*S35 -> 9158.3131 | T36: =ABS(S36-R36) -> 6044.3131 | U36: =T36^2 -> 36533721 | V36: =T36/R36 -> 1.9410126 | X36: 9 | Y36: 3114 | Z36: =$Z$21+$Z$20*X36 -> 9255.6699 | AA36: =ABS(Y36-Z36) -> 6141.6699 | AB36: =AA36^2 -> 37720109 | AC36: =AA36/Y36 -> 1.9722768 | AE36: 9 | AF36: 3114 | AG36: =(1/6)*(AF33*$AG$20+AF34*$AG$21+AF35*$AG$22) -> 5897.5 | AH36: =ABS(AF36-AG36) -> 2783.5 | AI36: =AH36^2 -> 7747872.2 | AJ36: =AH36/AF36 -> 0.89386641
C37: 10 | D37: 8662 | E37: =_xlfn.FORECAST.ETS(C37,$D$28:$D$67,$C$28:$C$67,1) -> 8807.081 | F37: =ABS(E37-D37) -> 145.08096 | G37: =F37^2 -> 21048.486 | H37: =F37/D37 -> 0.01674913 | J37: 10 | K37: 8662 | L37: =_xlfn.FORECAST.ETS(J37,$K$28:$K$67,$J$28:$J$67,0) -> 8807.081 | M37: =ABS(K37-L37) -> 145.08096 | N37: =M37^2 -> 21048.486 | O37: =M37/K37 -> 0.01674913 | Q37: 10 | R37: 8662 | S37: =$S$20*R36+(1-$S$20)*S36 -> 9146.2245 | T37: =ABS(S37-R37) -> 484.22451 | U37: =T37^2 -> 234473.37 | V37: =T37/R37 -> 0.05590216 | X37: 10 | Y37: 8662 | Z37: =$Z$21+$Z$20*X37 -> 9220.7986 | AA37: =ABS(Y37-Z37) -> 558.79859 | AB37: =AA37^2 -> 312255.87 | AC37: =AA37/Y37 -> 0.064511498 | AE37: 10 | AF37: 8662 | AG37: =(1/6)*(AF34*$AG$20+AF35*$AG$21+AF36*$AG$22) -> 3773.6667 | AH37: =ABS(AF37-AG37) -> 4888.3333 | AI37: =AH37^2 -> 23895803 | AJ37: =AH37/AF37 -> 0.56434234
C38: 11 | D38: 13586 | E38: =_xlfn.FORECAST.ETS(C38,$D$28:$D$67,$C$28:$C$67,1) -> 8782.9265 | F38: =ABS(E38-D38) -> 4803.0735 | G38: =F38^2 -> 23069515 | H38: =F38/D38 -> 0.3535311 | J38: 11 | K38: 13586 | L38: =_xlfn.FORECAST.ETS(J38,$K$28:$K$67,$J$28:$J$67,0) -> 8782.9265 | M38: =ABS(K38-L38) -> 4803.0735 | N38: =M38^2 -> 23069515 | O38: =M38/K38 -> 0.3535311 | Q38: 11 | R38: 13586 | S38: =$S$20*R37+(1-$S$20)*S37 -> 9145.2561 | T38: =ABS(S38-R38) -> 4440.7439 | U38: =T38^2 -> 19720207 | V38: =T38/R38 -> 0.32686177 | X38: 11 | Y38: 13586 | Z38: =$Z$21+$Z$20*X38 -> 9185.9273 | AA38: =ABS(Y38-Z38) -> 4400.0727 | AB38: =AA38^2 -> 19360640 | AC38: =AA38/Y38 -> 0.32386815 | AE38: 11 | AF38: 13586 | AG38: =(1/6)*(AF35*$AG$20+AF36*$AG$21+AF37*$AG$22) -> 5804.8333 | AH38: =ABS(AF38-AG38) -> 7781.1667 | AI38: =AH38^2 -> 60546555 | AJ38: =AH38/AF38 -> 0.57273419
C39: 12 | D39: 10762 | E39: =_xlfn.FORECAST.ETS(C39,$D$28:$D$67,$C$28:$C$67,1) -> 8758.772 | F39: =ABS(E39-D39) -> 2003.228 | G39: =F39^2 -> 4012922.2 | H39: =F39/D39 -> 0.186139 | J39: 12 | K39: 10762 | L39: =_xlfn.FORECAST.ETS(J39,$K$28:$K$67,$J$28:$J$67,0) -> 8758.772 | M39: =ABS(K39-L39) -> 2003.228 | N39: =M39^2 -> 4012922.2 | O39: =M39/K39 -> 0.186139 | Q39: 12 | R39: 10762 | S39: =$S$20*R38+(1-$S$20)*S38 -> 9154.1375 | T39: =ABS(S39-R39) -> 1607.8625 | U39: =T39^2 -> 2585221.7 | V39: =T39/R39 -> 0.14940183 | X39: 12 | Y39: 10762 | Z39: =$Z$21+$Z$20*X39 -> 9151.056 | AA39: =ABS(Y39-Z39) -> 1610.944 | AB39: =AA39^2 -> 2595140.6 | AC39: =AA39/Y39 -> 0.14968816 | AE39: 12 | AF39: 10762 | AG39: =(1/6)*(AF36*$AG$20+AF37*$AG$21+AF38*$AG$22) -> 10199.333 | AH39: =ABS(AF39-AG39) -> 562.66667 | AI39: =AH39^2 -> 316593.78 | AJ39: =AH39/AF39 -> 0.052282723
C40: 13 | D40: 14133 | E40: =_xlfn.FORECAST.ETS(C40,$D$28:$D$67,$C$28:$C$67,1) -> 8734.6176 | F40: =ABS(E40-D40) -> 5398.3824 | G40: =F40^2 -> 29142533 | H40: =F40/D40 -> 0.38197003 | J40: 13 | K40: 14133 | L40: =_xlfn.FORECAST.ETS(J40,$K$28:$K$67,$J$28:$J$67,0) -> 8734.6176 | M40: =ABS(K40-L40) -> 5398.3824 | N40: =M40^2 -> 29142533 | O40: =M40/K40 -> 0.38197003 | Q40: 13 | R40: 14133 | S40: =$S$20*R39+(1-$S$20)*S39 -> 9157.3533 | T40: =ABS(S40-R40) -> 4975.6467 | U40: =T40^2 -> 24757060 | V40: =T40/R40 -> 0.35205878 | X40: 13 | Y40: 14133 | Z40: =$Z$21+$Z$20*X40 -> 9116.1847 | AA40: =ABS(Y40-Z40) -> 5016.8153 | AB40: =AA40^2 -> 25168436 | AC40: =AA40/Y40 -> 0.35497172 | AE40: 13 | AF40: 14133 | AG40: =(1/6)*(AF37*$AG$20+AF38*$AG$21+AF39*$AG$22) -> 11353.333 | AH40: =ABS(AF40-AG40) -> 2779.6667 | AI40: =AH40^2 -> 7726546.8 | AJ40: =AH40/AF40 -> 0.19667917
C41: 14 | D41: 6048 | E41: =_xlfn.FORECAST.ETS(C41,$D$28:$D$67,$C$28:$C$67,1) -> 8710.4631 | F41: =ABS(E41-D41) -> 2662.4631 | G41: =F41^2 -> 7088709.9 | H41: =F41/D41 -> 0.44022208 | J41: 14 | K41: 6048 | L41: =_xlfn.FORECAST.ETS(J41,$K$28:$K$67,$J$28:$J$67,0) -> 8710.4631 | M41: =ABS(K41-L41) -> 2662.4631 | N41: =M41^2 -> 7088709.9 | O41: =M41/K41 -> 0.44022208 | Q41: 14 | R41: 6048 | S41: =$S$20*R40+(1-$S$20)*S40 -> 9167.3046 | T41: =ABS(S41-R41) -> 3119.3046 | U41: =T41^2 -> 9730061 | V41: =T41/R41 -> 0.51575803 | X41: 14 | Y41: 6048 | Z41: =$Z$21+$Z$20*X41 -> 9081.3134 | AA41: =ABS(Y41-Z41) -> 3033.3134 | AB41: =AA41^2 -> 9200990.3 | AC41: =AA41/Y41 -> 0.50153992 | AE41: 14 | AF41: 6048 | AG41: =(1/6)*(AF38*$AG$20+AF39*$AG$21+AF40*$AG$22) -> 12918.167 | AH41: =ABS(AF41-AG41) -> 6870.1667 | AI41: =AH41^2 -> 47199190 | AJ41: =AH41/AF41 -> 1.1359403
C42: 15 | D42: 16848 | E42: =_xlfn.FORECAST.ETS(C42,$D$28:$D$67,$C$28:$C$67,1) -> 8686.3087 | F42: =ABS(E42-D42) -> 8161.6913 | G42: =F42^2 -> 66613205 | H42: =F42/D42 -> 0.48443087 | J42: 15 | K42: 16848 | L42: =_xlfn.FORECAST.ETS(J42,$K$28:$K$67,$J$28:$J$67,0) -> 8686.3087 | M42: =ABS(K42-L42) -> 8161.6913 | N42: =M42^2 -> 66613205 | O42: =M42/K42 -> 0.48443087 | Q42: 15 | R42: 16848 | S42: =$S$20*R41+(1-$S$20)*S41 -> 9161.066 | T42: =ABS(S42-R42) -> 7686.934 | U42: =T42^2 -> 59088955 | V42: =T42/R42 -> 0.45625202 | X42: 15 | Y42: 16848 | Z42: =$Z$21+$Z$20*X42 -> 9046.4421 | AA42: =ABS(Y42-Z42) -> 7801.5579 | AB42: =AA42^2 -> 60864305 | AC42: =AA42/Y42 -> 0.46305543 | AE42: 15 | AF42: 16848 | AG42: =(1/6)*(AF39*$AG$20+AF40*$AG$21+AF41*$AG$22) -> 9528.6667 | AH42: =ABS(AF42-AG42) -> 7319.3333 | AI42: =AH42^2 -> 53572640 | AJ42: =AH42/AF42 -> 0.43443336
... C67: 40 | D67: 13099 | E67: =_xlfn.FORECAST.ETS(C67,$D$28:$D$67,$C$28:$C$67,1) -> 8082.4472 | F67: =ABS(E67-D67) -> 5016.5528 | G67: =F67^2 -> 25165802 | H67: =F67/D67 -> 0.38297219 | J67: 40 | K67: 13099 | L67: =_xlfn.FORECAST.ETS(J67,$K$28:$K$67,$J$28:$J$67,0) -> 8082.4472 | M67: =ABS(K67-L67) -> 5016.5528 | N67: =M67^2 -> 25165802 | O67: =M67/K67 -> 0.38297219 | Q67: 40 | R67: 13099 | S67: =$S$20*R66+(1-$S$20)*S66 -> 9130.6163 | T67: =ABS(S67-R67) -> 3968.3837 | U67: =T67^2 -> 15748069 | V67: =T67/R67 -> 0.30295318 | X67: 40 | Y67: 13099 | Z67: =$Z$21+$Z$20*X67 -> 8174.6598 | AA67: =ABS(Y67-Z67) -> 4924.3402 | AB67: =AA67^2 -> 24249127 | AC67: =AA67/Y67 -> 0.37593253 | AE67: 40 | AF67: 13099 | AG67: =(1/6)*(AF64*$AG$20+AF65*$AG$21+AF66*$AG$22) -> 6914.8333 | AH67: =ABS(AF67-AG67) -> 6184.1667 | AI67: =AH67^2 -> 38243917 | AJ67: =AH67/AF67 -> 0.47210983
C68: 41 | E68: =_xlfn.FORECAST.ETS(C68,$D$28:$D$67,$C$28:$C$67,1) -> 8058.2928 | J68: 41 | L68: =_xlfn.FORECAST.ETS(J68,$K$28:$K$67,$J$28:$J$67,0) -> 8058.2928 | S68: =$S$20*R67+(1-$S$20)*S67 -> 9138.5531 | X68: 41 | Z68: =$Z$21+$Z$20*X68 -> 8139.7885 | AG68: =(1/6)*(AF65*$AG$20+AF66*$AG$21+AF67*$AG$22) -> 9609.8333
C69: 42 | E69: =_xlfn.FORECAST.ETS(C69,$D$28:$D$67,$C$28:$C$67,1) -> 8034.1383 | J69: 42 | L69: =_xlfn.FORECAST.ETS(J69,$K$28:$K$67,$J$28:$J$67,0) -> 8034.1383 | X69: 42
C70: 43 | E70: =_xlfn.FORECAST.ETS(C70,$D$28:$D$67,$C$28:$C$67,1) -> 8009.9839 | J70: 43 | L70: =_xlfn.FORECAST.ETS(J70,$K$28:$K$67,$J$28:$J$67,0) -> 8009.9839 | X70: 43
C71: 44 | E71: =_xlfn.FORECAST.ETS(C71,$D$28:$D$67,$C$28:$C$67,1) -> 7985.8294 | J71: 44 | L71: =_xlfn.FORECAST.ETS(J71,$K$28:$K$67,$J$28:$J$67,0) -> 7985.8294 | X71: 44
C72: 45 | E72: =_xlfn.FORECAST.ETS(C72,$D$28:$D$67,$C$28:$C$67,1) -> 7961.6749 | J72: 45 | L72: =_xlfn.FORECAST.ETS(J72,$K$28:$K$67,$J$28:$J$67,0) -> 7961.6749 | X72: 45
C73: 46 | E73: =_xlfn.FORECAST.ETS(C73,$D$28:$D$67,$C$28:$C$67,1) -> 7937.5205 | J73: 46 | L73: =_xlfn.FORECAST.ETS(J73,$K$28:$K$67,$J$28:$J$67,0) -> 7937.5205 | X73: 46

Sheet Verifikasi Hasil Forecast
B1: Moving Range Control Chart
B19: Pemeriksaan Kondisi Abnormalitas
B20: Tidak ada 1 atau lebih titik yang melewati UCL | O20: Tidak ada 1 atau lebih titik yang melewati UCL | AB20: Tidak ada 1 atau lebih titik yang melewati UCL | AO20: Tidak ada 1 atau lebih titik yang melewati UCL
B21: Tidak konsisten berada di bawah CL/dekat dengan LCL | O21: Tidak konsisten berada di bawah CL/dekat dengan LCL | AB21: Tidak konsisten berada di bawah CL/dekat dengan LCL | AO21: Tidak konsisten berada di bawah CL/dekat dengan LCL
B23: Individuals Control Chart
B41: Pemeriksaan Kondisi Abnormalitas | O41: Pemeriksaan Kondisi Abnormalitas | AB41: Pemeriksaan Kondisi Abnormalitas | AO41: Pemeriksaan Kondisi Abnormalitas
B42: Tidak ada 1 atau lebih titik yang melewati UCL atau LCL | O42: Tidak ada 1 atau lebih titik yang melewati UCL atau LCL | AB42: Tidak ada 1 atau lebih titik yang melewati UCL atau LCL | AO42: Tidak ada 1 atau lebih titik yang melewati UCL atau LCL
B43: Tidak ada 2 atau lebih titik dari 3 titik berurutan yang melewati 2 sigma | O43: Tidak ada 2 atau lebih titik dari 3 titik berurutan yang melewati 2 sigma | AB43: Tidak ada 2 atau lebih titik dari 3 titik berurutan yang melewati 2 sigma | AO43: Tidak ada 2 atau lebih titik dari 3 titik berurutan yang melewati 2 sigma
B44: Tidak ada 4 atau lebih titik dari 5 titik berurutan yang melewati 1 sigma | O44: Tidak ada 4 atau lebih titik dari 5 titik berurutan yang melewati 1 sigma | AB44: Tidak ada 4 atau lebih titik dari 5 titik berurutan yang melewati 1 sigma | AO44: Tidak ada 4 atau lebih titik dari 5 titik berurutan yang melewati 1 sigma
B45: Tidak ada 8 atau lebih titik yang berurutan berada di salah satu sisi CL | O45: Tidak ada 8 atau lebih titik yang berurutan berada di salah satu sisi CL | AB45: Tidak ada 8 atau lebih titik yang berurutan berada di salah satu sisi CL | AO45: Tidak ada 8 atau lebih titik yang berurutan berada di salah satu sisi CL
B46: A - Single Exponential Smoothing | O46: B - Linear Regression | AB46: C - Triple Exponential Smoothing | AO46: D - Triple Exponential Smoothing
B48: Parameter Control Chart | C48: Xbar | D48: =AVERAGE(C54:C93) -> -67.841696 | N48: 209 | O48: Parameter Control Chart | P48: Xbar | Q48: =AVERAGE(P54:P93) -> 2.2737368e-14 | AB48: Parameter Control Chart | AC48: Xbar | AD48: =AVERAGE(AC54:AC81) -> -14.966255 | AO48: Parameter Control Chart | AP48: Xbar | AQ48: =AVERAGE(AP54:AP91) -> 73.587719
C49: MR Bar | D49: =AVERAGE(D55:D93) -> 279.01984 | N49: 260.15 | P49: MR Bar | Q49: =AVERAGE(Q55:Q93) -> 295.20742 | AC49: MR Bar | AD49: =AVERAGE(AD55:AD81) -> 485.351 | AP49: MR Bar | AQ49: =AVERAGE(AQ55:AQ92) -> 6006.3816
C50: d2 | D50: 1.128 | N50: 1.128 | P50: d2 | Q50: 1.128 | AC50: d2 | AD50: 1.128 | AP50: d2 | AQ50: 1.128
C51: D4 | D51: 3.267 | N51: 3.267 | P51: D4 | Q51: 3.267 | AC51: D4 | AD51: 3.267 | AP51: D4 | AQ51: 3.267
B53: Periode | C53: Error | D53: Moving Range | E53: Xbar | F53: UCL 3sigma | G53: LCL 3sigma | H53: UCL 2sigma | I53: LCL 2sigma | J53: UCL 1sigma | K53: LCL1sigma | L53: MRbar | M53: UCL | O53: Periode | P53: Error | Q53: Moving Range | R53: Xbar | S53: UCL 3sigma | T53: LCL 3sigma | U53: UCL 2sigma | V53: LCL 2sigma | W53: UCL 1sigma | X53: LCL1sigma | Y53: MRbar | Z53: UCL | AB53: Periode | AC53: Error | AD53: Moving Range | AE53: Xbar | AF53: UCL 3sigma | AG53: LCL 3sigma | AH53: UCL 2sigma | AI53: LCL 2sigma | AJ53: UCL 1sigma | AK53: LCL1sigma | AL53: MRbar | AM53: UCL | AO53: Periode | AP53: Error | AQ53: Moving Range | AR53: Xbar | AS53: UCL 3sigma | AT53: LCL 3sigma | AU53: UCL 2sigma | AV53: LCL 2sigma | AW53: UCL 1sigma | AX53: LCL1sigma | AY53: MRbar | AZ53: UCL
B54: 1 | C54: 0 | E54: =D48 -> -67.841696 | F54: =$D$48 + 3*($D$49/$D$50) -> 674.23235 | G54: =$D$48 - 3*($D$49/$D$50) -> -809.91575 | H54: =$D$48 + 2*($D$49/$D$50) -> 426.87434 | I54: =$D$48 - 2*($D$49/$D$50) -> -562.55773 | J54: =$D$48 + 1*($D$49/$D$50) -> 179.51632 | K54: =$D$48 - 1*($D$49/$D$50) -> -315.19971 | O54: 1 | P54: ='B - Forecast'!C29-'B - Forecast'!D29 -> -416.41951 | R54: =Q48 -> 2.2737368e-14 | S54: =$Q$48 + 3*($Q$49/$Q$50) -> 785.12611 | T54: =$Q$48 - 3*($Q$49/$Q$50) -> -785.12611 | U54: =$Q$48 + 2*($Q$49/$Q$50) -> 523.41741 | V54: =$Q$48 - 2*($Q$49/$Q$50) -> -523.41741 | W54: =$Q$48 + 1*($Q$49/$Q$50) -> 261.7087 | X54: =$Q$48 - 1*($Q$49/$Q$50) -> -261.7087 | AB54: 1 | AC54: ='C - Forecast'!D45-'C - Forecast'!E45 -> -67.289177 | AE54: =AD$48 -> -14.966255 | AF54: =$AD$48+3*$AD$49/$AD$50 -> 1275.8609 | AG54: =$AD$48-3*$AD$49/$AD$50 -> -1305.7934 | AH54: =$AD$48+2*$AD$49/$AD$50 -> 845.58517 | AI54: =$AD$48-2*$AD$49/$AD$50 -> -875.51768 | AJ54: =$AD$48+1*$AD$49/$AD$50 -> 415.30946 | AK54: =$AD$48-1*$AD$49/$AD$50 -> -445.24197 | AO54: 1 | AP54: ='D - Forecast'!AF31-'D - Forecast'!AG31 -> 13922.5 | AR54: =AQ$48 -> 73.587719 | AS54: =$AQ$48+3*$AQ$49/$AQ$50 -> 16048.007 | AT54: =$AQ$48-3*$AQ$49/$AQ$50 -> -15900.831 | AU54: =$AQ$48+2*$AQ$49/$AQ$50 -> 10723.2 | AV54: =$AQ$48-2*$AQ$49/$AQ$50 -> -10576.025 | AW54: =$AQ$48+1*$AQ$49/$AQ$50 -> 5398.3941 | AX54: =$AQ$48-1*$AQ$49/$AQ$50 -> -5251.2186
B55: 2 | C55: ='A - Forecast'!Q29-'A - Forecast'!R29 -> -340 | D55: =ABS(C55-C54) -> 340 | E55: =$D$48 -> -67.841696 | F55: =$D$48 + 3*($D$49/$D$50) -> 674.23235 | G55: =$D$48 - 3*($D$49/$D$50) -> -809.91575 | H55: =$D$48 + 2*($D$49/$D$50) -> 426.87434 | I55: =$D$48 - 2*($D$49/$D$50) -> -562.55773 | J55: =$D$48 + 1*($D$49/$D$50) -> 179.51632 | K55: =$D$48 - 1*($D$49/$D$50) -> -315.19971 | L55: =$D$49 -> 279.01984 | M55: =$D$49*$D$51 -> 911.55783 | O55: 2 | P55: ='B - Forecast'!C30-'B - Forecast'!D30 -> 116.88405 | Q55: =ABS(P55-P54) -> 533.30356 | R55: =$Q$48 -> 2.2737368e-14 | S55: =$Q$48 + 3*($Q$49/$Q$50) -> 785.12611 | T55: =$Q$48 - 3*($Q$49/$Q$50) -> -785.12611 | U55: =$Q$48 + 2*($Q$49/$Q$50) -> 523.41741 | V55: =$Q$48 - 2*($Q$49/$Q$50) -> -523.41741 | W55: =$Q$48 + 1*($Q$49/$Q$50) -> 261.7087 | X55: =$Q$48 - 1*($Q$49/$Q$50) -> -261.7087 | Y55: =$Q$49 -> 295.20742 | Z55: =$Q$49*$Q$51 -> 964.44263 | AB55: 2 | AC55: ='C - Forecast'!D46-'C - Forecast'!E46 -> 103.03413 | AD55: =ABS(AC55-AC54) -> 170.32331 | AE55: =AD$48 -> -14.966255 | AF55: =$AD$48+3*$AD$49/$AD$50 -> 1275.8609 | AG55: =$AD$48-3*$AD$49/$AD$50 -> -1305.7934 | AH55: =$AD$48+2*$AD$49/$AD$50 -> 845.58517 | AI55: =$AD$48-2*$AD$49/$AD$50 -> -875.51768 | AJ55: =$AD$48+1*$AD$49/$AD$50 -> 415.30946 | AK55: =$AD$48-1*$AD$49/$AD$50 -> -445.24197 | AL55: =$AD$49 -> 485.351 | AM55: =$AD$49*$AD$51 -> 1585.6417 | AO55: 2 | AP55: ='D - Forecast'!AF32-'D - Forecast'!AG32 -> 7293.6667 | AQ55: =ABS(AP54-AP55) -> 6628.8333 | AR55: =AQ$48 -> 73.587719 | AS55: =$AQ$48+3*$AQ$49/$AQ$50 -> 16048.007 | AT55: =$AQ$48-3*$AQ$49/$AQ$50 -> -15900.831 | AU55: =$AQ$48+2*$AQ$49/$AQ$50 -> 10723.2 | AV55: =$AQ$48-2*$AQ$49/$AQ$50 -> -10576.025 | AW55: =$AQ$48+1*$AQ$49/$AQ$50 -> 5398.3941 | AX55: =$AQ$48-1*$AQ$49/$AQ$50 -> -5251.2186 | AY55: =$AQ$49 -> 6006.3816 | AZ55: =$AQ$49*$AQ$51 -> 19622.849
B56: 3 | C56: ='A - Forecast'!Q30-'A - Forecast'!R30 -> 140 | D56: =ABS(C56-C55) -> 480 | E56: =$D$48 -> -67.841696 | F56: =$D$48 + 3*($D$49/$D$50) -> 674.23235 | G56: =$D$48 - 3*($D$49/$D$50) -> -809.91575 | H56: =$D$48 + 2*($D$49/$D$50) -> 426.87434 | I56: =$D$48 - 2*($D$49/$D$50) -> -562.55773 | J56: =$D$48 + 1*($D$49/$D$50) -> 179.51632 | K56: =$D$48 - 1*($D$49/$D$50) -> -315.19971 | L56: =$D$49 -> 279.01984 | M56: =$D$49*$D$51 -> 911.55783 | O56: 3 | P56: ='B - Forecast'!C31-'B - Forecast'!D31 -> 234.18762 | Q56: =ABS(P56-P55) -> 117.30356 | R56: =$Q$48 -> 2.2737368e-14 | S56: =$Q$48 + 3*($Q$49/$Q$50) -> 785.12611 | T56: =$Q$48 - 3*($Q$49/$Q$50) -> -785.12611 | U56: =$Q$48 + 2*($Q$49/$Q$50) -> 523.41741 | V56: =$Q$48 - 2*($Q$49/$Q$50) -> -523.41741 | W56: =$Q$48 + 1*($Q$49/$Q$50) -> 261.7087 | X56: =$Q$48 - 1*($Q$49/$Q$50) -> -261.7087 | Y56: =$Q$49 -> 295.20742 | Z56: =$Q$49*$Q$51 -> 964.44263 | AB56: 3 | AC56: ='C - Forecast'!D47-'C - Forecast'!E47 -> -518.68837 | AD56: =ABS(AC56-AC55) -> 621.7225 | AE56: =AD$48 -> -14.966255 | AF56: =$AD$48+3*$AD$49/$AD$50 -> 1275.8609 | AG56: =$AD$48-3*$AD$49/$AD$50 -> -1305.7934 | AH56: =$AD$48+2*$AD$49/$AD$50 -> 845.58517 | AI56: =$AD$48-2*$AD$49/$AD$50 -> -875.51768 | AJ56: =$AD$48+1*$AD$49/$AD$50 -> 415.30946 | AK56: =$AD$48-1*$AD$49/$AD$50 -> -445.24197 | AL56: =$AD$49 -> 485.351 | AM56: =$AD$49*$AD$51 -> 1585.6417 | AO56: 3 | AP56: ='D - Forecast'!AF33-'D - Forecast'!AG33 -> -3356.5 | AQ56: =ABS(AP55-AP56) -> 10650.167 | AR56: =AQ$48 -> 73.587719 | AS56: =$AQ$48+3*$AQ$49/$AQ$50 -> 16048.007 | AT56: =$AQ$48-3*$AQ$49/$AQ$50 -> -15900.831 | AU56: =$AQ$48+2*$AQ$49/$AQ$50 -> 10723.2 | AV56: =$AQ$48-2*$AQ$49/$AQ$50 -> -10576.025 | AW56: =$AQ$48+1*$AQ$49/$AQ$50 -> 5398.3941 | AX56: =$AQ$48-1*$AQ$49/$AQ$50 -> -5251.2186 | AY56: =$AQ$49 -> 6006.3816 | AZ56: =$AQ$49*$AQ$51 -> 19622.849
