Workbook

Sheet Modul 1
D6: PRAKTIKUM PERANCANGAN SISTEM TERINTEGRASI III
D7: MODUL 3 - Pengendalian Kualitas Secara Statistika
K13: PJ Modul
I14: 13422005 Naufal Vitoperisa Oktora 13422068 Daniel Febrian Parhusip 13422126 Nadya Farah Iresqa
D19: Laboratorium Perencanaan dan Optimasi Sistem Industri
D20: Program Studi Teknik Industri
D21: Fakultas Teknologi Industri
D22: 2025

Sheet Skenario
A1: No | B1: Informasi
A2: 1 | B2: PT PPST Manufacturing memproduksi 4 jenis tripod dengan dua ukuran (tripod kecil dan besar), yaitu Tripod A, B, C, dan D. Dari berbagai macam part yang dibutuhkan untuk membuat tripod, terdapat 3 part yang dibuat sendiri dari bahan baku mentah, yaitu bottom base 2, leg, dan pivot. Untuk part pivot, akan dilakukan pengendalian kualitas pada diameter lubang horizontal. Sampel diambil dengan ukuran banyak. PT PPST Manufacturing ingin melihat kurva OC, ARL, dan kapabilitas dari proses tersebut. PT PPST Manufacturing juga ingin melihat implementasi dari penggunaan peta kendali ini. | E2: Pivot (diameter lubang horizontal)
A3: 2 | B3: Untuk part bottom base 2, akan dilakukan pengendalian kualitas pada diameter half cylinder dari bottom base 2. Sampel diambil dengan ukuran 1 karena waktu proses yang relatif lebih lama.
A4: 3 | B4: Pada tahap perakitan S3A1, perakitan yang menggabungkan S4A1 (assembly bottom base 1 dengan leg dan bottom base 2) dengan S5A2 (assembly guide male dan guide female), akan dihitung jumlah cacat berupa bercak atau goresan yang muncul pada tiap unit S3A1 ketika perakitan berlangsung. Pengendalian kualitas dilakukan per satu unit inspeksi.
A5: 4 | B5: Pada tahap akhir perakitan akan dilakukan inspeksi secara menyeluruh untuk mengecek apakah ada tripod yang rusak (nonconforming).
A6: 5 | B6: Perbedaan dari keempat jenis tripod adalah pada tinggi dari tripod itu sendiri. Oleh karena itu, akan ada perbedaan dimensi panjang pada part Leg di setiap jenis tripod. Pengendalian kualitas secara statistika menggunakan peta kendali diinginkan yang bisa mengakomodasi seluruh jenis tripod. | E6: Bottom base 2 (diameter half cylinder)
A7: 6 | B7: Setelah barang selesai dirakit, akan dilakukan proses pengiriman barang kepada konsumen. Selanjutnya, PT X akan memberikan invoice dan dokumen lain kepada konsumen. Disebabkan oleh penyatuan lini produksi beberapa tripod karena kesamaan alur produksi, beberapa pekerja masih belum terbiasa dengan pembuatan dokumen hasil produksi yang baru sehingga dapat terjadi kesalahan dalam pembuatan dokumen, seperti pencatatan jenis tripod yang salah, invoice yang salah penempatan, dan sebagainya. Oleh karena itu, akan dilakukan pengendalian kualitas untuk dokumen yang akan diberikan kepada konsumen dengan ketentuan unit inspeksi lebih dari satu.
A8: 7 | B8: Disebabkan oleh efisiensi yang berhasil dilakukan pada lini produksi tripod dan tingginya permintaan yang masuk, PT X menerima pesanan pembuatan part XYZ 1 dan XYZ 2. a. Part XYZ 1 adalah part yang perlu diinspeksi dengan teknologi tinggi sehingga ukuran sampel untuk inspeksi hanya satu (pengukuran individual). Dimensi yang diukur adalah panjang. Agar tidak mengecewakan konsumen, peta kendali harus mampu mendeteksi pergeseran kecil.
A9: 8 | B9: b. Dimensi yang ingin dikendalikan kualitasnya untuk part XYZ 2 adalah diameter dalam dan diameter luar secara bersamaan.
E10: Leg (panjang)

Sheet Data Awal
B2: Data Awal | I2: Data untuk Implementasi | S2: Data Awal | V2: Data Awal | Y2: Data Awal | AB2: Data Awal | AK2: Data Awal | AN2: Data Awal | AT2: Data Awal
B3: Diameter Lubang Horizontal part pivot (mm) | I3: Diameter Lubang Horizontal part pivot (mm) | S3: Diameter Half cylinder bottom base 2 (mm) | V3: Jumlah nonconformity assembly S3A1 | Y3: Jumlah nonconforming (cacat) Tripod | AB3: Panjang Leg Tripod (mm) | AK3: Jumlah saltik (typo) pada dokumen (1 inspeksi unit = 1 dokumen) | AN3: Panjang Part XYZ 1 | AT3: Diameter dalam dan luar Part XYZ 2
B4: Sample Number (i) | C4: Observasi | I4: Sample Number (i) | J4: Observasi | P4: Spesifikasi Diameter Lubang Horizontal Tripod | S4: Sample Number (i) | T4: Observasi | V4: Sample Number (i) | W4: Observasi per 1 unit inspeksi | Y4: Sample Number (i) | Z4: Observasi per 50 unit Tripod | AB4: Sample Number (i) | AC4: Jenis Tripod | AD4: Observasi | AH4: Spesifikasi Target Panjang Leg Tripod (mm) | AK4: Sample Number (i) | AL4: Observasi per 100 dokumen | AN4: Sample Number (i) | AO4: Observasi | AQ4: Parameter untuk peta cusum dan EWMA part XYZ 1 | AT4: Sample Number (i) | AU4: Observasi diameter dalam (mm) | AY4: Observasi diameter luar (mm)
B5: 1 | C5: 9.976 | D5: 10.694 | E5: 10.368 | F5: 10.503 | G5: 10.323 | I5: 26 | J5: 10.477 | K5: 10.499 | L5: 10.577 | M5: 10.654 | N5: 10.455 | P5: USL | Q5: 12 | S5: 1 | T5: 3.7664858 | V5: 1 | W5: 5 | Y5: 1 | Z5: 7 | AB5: 1 | AC5: A | AD5: 2.637 | AE5: 2.641 | AF5: 2.639 | AH5: A | AI5: 264 | AK5: 1 | AL5: 12 | AN5: 1 | AO5: 8 | AQ5: K | AR5: 1/2 sigma | AT5: 1 | AU5: 10.036 | AV5: 10.068 | AW5: 10.014 | AX5: 9.963 | AY5: 11.998 | AZ5: 11.885 | BA5: 12.011 | BB5: 11.914
B6: 2 | C6: 10.626 | D6: 10.424 | E6: 11.109 | F6: 1.057 | G6: 10.133 | I6: 27 | J6: 10.299 | K6: 10.321 | L6: 10.343 | M6: 10.266 | N6: 10.543 | P6: LSL | Q6: 10 | S6: 2 | T6: 3.6069998 | V6: 2 | W6: 6 | Y6: 2 | Z6: 15 | AB6: 2 | AC6: A | AD6: 2.639 | AE6: 2.639 | AF6: 2.641 | AH6: B | AI6: 284 | AK6: 2 | AL6: 7 | AN6: 2 | AO6: 9 | AQ6: H | AR6: 5 sigma | AT6: 2 | AU6: 10.045 | AV6: 10.203 | AW6: 10.149 | AX6: 10.199 | AY6: 1.191 | AZ6: 11.784 | BA6: 11.924 | BB6: 11.838
B7: 3 | C7: 10.458 | D7: 10.548 | E7: 10.761 | F7: 10.301 | G7: 10.043 | I7: 28 | J7: 10.532 | K7: 10.643 | L7: 10.221 | M7: 1.021 | N7: 1.041 | S7: 3 | T7: 3.1533437 | V7: 3 | W7: 10 | Y7: 3 | Z7: 7 | AB7: 3 | AC7: A | AD7: 2.638 | AE7: 2.639 | AF7: 2.641 | AH7: C | AI7: 304 | AK7: 3 | AL7: 5 | AN7: 3 | AO7: 1 | AQ7: Lambda | AR7: 0.01 | AT7: 3 | AU7: 9.864 | AV7: 10.257 | AW7: 10.085 | AX7: 10.158 | AY7: 11.866 | AZ7: 12.068 | BA7: 12.063 | BB7: 11.969
B8: 4 | C8: 10.649 | D8: 10.727 | E8: 10.424 | F8: 10.604 | G8: 10.604 | I8: 29 | J8: 10.466 | K8: 10.266 | L8: 10.243 | M8: 10.366 | N8: 1.041 | S8: 4 | T8: 3.8022472 | V8: 4 | W8: 8 | Y8: 4 | Z8: 8 | AB8: 4 | AC8: A | AD8: 2.641 | AE8: 2.639 | AF8: 2.641 | AH8: D | AI8: 324 | AK8: 4 | AL8: 12 | AN8: 4 | AO8: 9 | AQ8: L | AR8: 2.7 | AT8: 4 | AU8: 10.085 | AV8: 10.022 | AW8: 10.063 | AX8: 10.238 | AY8: 11.875 | AZ8: 11.985 | BA8: 12.043 | BB8: 11.688
B9: 5 | C9: 10.581 | D9: 10.918 | E9: 10.402 | F9: 10.481 | G9: 10.795 | I9: 30 | J9: 10.666 | K9: 10.532 | L9: 10.399 | M9: 10.477 | N9: 10.388 | S9: 5 | T9: 3.8057884 | V9: 5 | W9: 8 | Y9: 5 | Z9: 15 | AB9: 5 | AC9: A | AD9: =0.264*10 -> 2.64 | AE9: 2.639 | AF9: =0.264*10 -> 2.64 | AK9: 5 | AL9: 4 | AN9: 5 | AO9: 12 | AQ9: miu0 target | AR9: 1 | AT9: 5 | AU9: 10.445 | AV9: 0.102 | AW9: 10.153 | AX9: 10.097 | AY9: 11.754 | AZ9: 11.888 | BA9: 11.817 | BB9: 12.243
B10: 6 | C10: 10.436 | D10: 10.503 | E10: 10.907 | F10: 10.458 | G10: 9.807 | I10: 31 | J10: 10.343 | K10: 10.588 | L10: 10.277 | M10: 10.388 | N10: 10.399 | S10: 6 | T10: 3.0967304 | V10: 6 | W10: 5 | Y10: 6 | Z10: 9 | AB10: 6 | AC10: B | AD10: 0.284 | AE10: 0.284 | AF10: 2.841 | AK10: 6 | AL10: 3 | AN10: 6 | AO10: 8 | AQ10: sigma target | AR10: 0.1 | AT10: 6 | AU10: 9.993 | AV10: 9.974 | AW10: 10.051 | AX10: 10.434 | AY10: 11.844 | AZ10: 11.979 | BA10: 12.063 | BB10: 11.893
B11: 7 | C11: 10.682 | D11: 10.447 | E11: 10.323 | F11: 10.312 | G11: 10.806 | I11: 32 | J11: 1.051 | K11: 10.421 | L11: 10.221 | M11: 10.555 | N11: 10.555 | S11: 7 | T11: 3.3090724 | V11: 7 | W11: 7 | Y11: 7 | Z11: 9 | AB11: 7 | AC11: B | AD11: 0.284 | AE11: 2.841 | AF11: 0.284 | AK11: 7 | AL11: 12 | AN11: 7 | AO11: 12 | AT11: 7 | AU11: 1.024 | AV11: 10.021 | AW11: 10.297 | AX11: 9.801 | AY11: 11.751 | AZ11: 11.963 | BA11: 11.902 | BB11: 11.883
B12: 8 | C12: 10.357 | D12: 10.481 | E12: 10.447 | F12: 10.469 | G12: 10.638 | I12: 33 | J12: 10.232 | K12: 10.477 | L12: 1.041 | M12: 10.543 | N12: 10.532 | S12: 8 | T12: 3.7744093 | V12: 8 | W12: 12 | Y12: 8 | Z12: 5 | AB12: 8 | AC12: B | AD12: 2.839 | AE12: 0.284 | AF12: 2.839 | AK12: 8 | AL12: 12 | AN12: 8 | AO12: 12 | AT12: 8 | AU12: 10.256 | AV12: 10.139 | AW12: 10.089 | AX12: 10.072 | AY12: 11.962 | AZ12: 11.658 | BA12: 11.757 | BB12: 11.932
B13: 9 | C13: 10.682 | D13: 10.907 | E13: 10.402 | F13: 1.029 | G13: 10.581 | I13: 34 | J13: 10.566 | K13: 10.332 | L13: 10.332 | M13: 10.332 | N13: 10.632 | S13: 9 | T13: 3.6511427 | V13: 9 | W13: 8 | Y13: 9 | Z13: 6 | AB13: 9 | AC13: B | AD13: 2.839 | AE13: 2.841 | AF13: 2.841 | AK13: 9 | AL13: 12 | AN13: 9 | AO13: 9 | AT13: 9 | AU13: 9.983 | AV13: 10.128 | AW13: 10.221 | AX13: 10.043 | AY13: 11.691 | AZ13: 0.121 | BA13: 12.004 | BB13: 0.118
B14: 10 | C14: 10.525 | D14: 10.682 | E14: 10.581 | F14: 1.066 | G14: 10.817 | I14: 35 | J14: 10.343 | K14: 10.455 | L14: 10.588 | M14: 1.041 | N14: 1.021 | S14: 10 | T14: 3.1736182 | V14: 10 | W14: 7 | Y14: 10 | Z14: 11 | AB14: 10 | AC14: B | AD14: 2.839 | AE14: 2.842 | AF14: 0.284 | AK14: 10 | AL14: 5 | AN14: 10 | AO14: 8 | AT14: 10 | AU14: 10.093 | AV14: 10.125 | AW14: 10.116 | AX14: 10.071 | AY14: 11.876 | AZ14: 12.006 | BA14: 12.065 | BB14: 11.847
B15: 11 | C15: 10.795 | D15: 10.424 | E15: 10.638 | F15: 11.109 | G15: 11.109 | I15: 36 | J15: 10.432 | K15: 10.577 | L15: 10.255 | M15: 10.421 | N15: 10.477 | S15: 11 | T15: 3.3752294 | V15: 11 | W15: 5 | Y15: 11 | Z15: 6 | AB15: 11 | AC15: C | AD15: 3.041 | AE15: 3.041 | AF15: 3.039 | AK15: 11 | AL15: 4 | AN15: 11 | AO15: 8 | AT15: 11 | AU15: 10.194 | AV15: 10.329 | AW15: 10.041 | AX15: 10.362 | AY15: 12.067 | AZ15: 11.922 | BA15: 12.123 | BB15: 11.791
B16: 12 | C16: 10.581 | D16: 10.503 | E16: 10.436 | F16: 1.038 | G16: 10.952 | I16: 37 | J16: 10.455 | K16: 1.061 | L16: 10.654 | M16: 10.477 | N16: 10.399 | S16: 12 | T16: 3.7174377 | V16: 12 | W16: 15 | Y16: 12 | Z16: 8 | AB16: 12 | AC16: C | AD16: 3.039 | AE16: 3.041 | AF16: 0.304 | AK16: 12 | AL16: 7 | AN16: 12 | AO16: 1 | AT16: 12 | AU16: 10.195 | AV16: 9.918 | AW16: 10.229 | AX16: 10.141 | AY16: 12.045 | AZ16: 11.985 | BA16: 12.015 | BB16: 11.845
B17: 13 | C17: 10.705 | D17: 10.357 | E17: 10.357 | F17: 10.537 | G17: 10.514 | I17: 38 | J17: 10.455 | K17: 10.455 | L17: 10.432 | M17: 10.299 | N17: 10.232 | S17: 13 | T17: 3.5066225 | V17: 13 | W17: 5 | Y17: 13 | Z17: 5 | AB17: 13 | AC17: C | AD17: 0.304 | AE17: 0.304 | AF17: 3.042 | AK17: 13 | AL17: 9 | AN17: 13 | AO17: 13 | AT17: 13 | AU17: 10.131 | AV17: 0.995 | AW17: 9.815 | AX17: 10.229 | AY17: 11.873 | AZ17: 12.047 | BA17: 11.648 | BB17: 12.033
B18: 14 | C18: 10.413 | D18: 10.335 | E18: 10.469 | F18: 10.424 | G18: 10.559 | I18: 39 | J18: 10.588 | K18: 10.677 | L18: 10.232 | M18: 1.051 | N18: 10.632 | S18: 14 | T18: 3.744536 | V18: 14 | W18: 14 | Y18: 14 | Z18: 5 | AB18: 14 | AC18: C | AD18: 3.041 | AE18: 0.304 | AF18: 3.039 | AK18: 14 | AL18: 12 | AN18: 14 | AO18: 12 | AT18: 14 | AU18: 10.168 | AV18: 9.757 | AW18: 9.969 | AX18: 10.198 | AY18: 1.188 | AZ18: 11.909 | BA18: 11.923 | BB18: 11.895
B19: 15 | C19: 1.011 | D19: 10.604 | E19: 10.514 | F19: 1.057 | G19: 10.503 | I19: 40 | J19: 10.399 | K19: 10.443 | L19: 10.532 | M19: 1.061 | N19: 10.266 | S19: 15 | T19: 3.0840297 | V19: 15 | W19: 11 | Y19: 15 | Z19: 12 | AB19: 15 | AC19: C | AD19: 3.039 | AE19: 3.038 | AF19: 0.304 | AK19: 15 | AL19: 7 | AN19: 15 | AO19: 8 | AT19: 15 | AU19: 10.278 | AV19: 1.033 | AW19: 9.944 | AX19: 10.301 | AY19: 12.037 | AZ19: 11.786 | BA19: 12.062 | BB19: 11.969
B20: 16 | C20: 1.057 | D20: 10.626 | E20: 10.368 | F20: 10.671 | G20: 10.705 | I20: 41 | J20: 10.666 | K20: 10.599 | L20: 10.466 | M20: 10.321 | N20: 10.466 | S20: 16 | T20: 3.6532833 | V20: 16 | W20: 11 | Y20: 16 | Z20: 6 | AB20: 16 | AC20: D | AD20: 3.239 | AE20: 3.239 | AF20: 3.241 | AK20: 16 | AL20: 11 | AN20: 16 | AO20: 11 | AT20: 16 | AU20: 10.025 | AV20: 1.018 | AW20: 10.218 | AX20: 1.004 | AY20: 12.091 | AZ20: 11.915 | BA20: 12.005 | BB20: 11.861
B21: 17 | C21: 10.727 | D21: 10.458 | E21: 9.706 | F21: 10.346 | G21: 10.604 | I21: 42 | J21: 10.555 | K21: 10.288 | L21: 10.466 | M21: 10.421 | N21: 10.266 | S21: 17 | T21: 3.3985718 | V21: 17 | W21: 5 | Y21: 17 | Z21: 13 | AB21: 17 | AC21: D | AD21: 3.241 | AE21: 3.242 | AF21: 3.241 | AK21: 17 | AL21: 8 | AN21: 17 | AO21: 7 | AT21: 17 | AU21: 10.082 | AV21: 10.245 | AW21: 9.965 | AX21: 10.063 | AY21: 11.618 | AZ21: 12.058 | BA21: 11.795 | BB21: 0.12
B22: 18 | C22: 10.705 | D22: 11.053 | E22: 10.548 | F22: 10.346 | G22: 9.886 | I22: 43 | J22: 10.232 | K22: 10.332 | L22: 10.377 | M22: 10.421 | N22: 10.266 | S22: 18 | T22: 3.4784714 | V22: 18 | W22: 7 | Y22: 18 | Z22: 5 | AB22: 18 | AC22: D | AD22: 3.238 | AE22: 3.239 | AF22: 0.324 | AK22: 18 | AL22: 5 | AN22: 18 | AO22: 9 | AT22: 18 | AU22: 10.304 | AV22: 9.798 | AW22: 10.145 | AX22: 10.342 | AY22: 0.121 | AZ22: 11.853 | BA22: 1.221 | BB22: 11.761
... B24: 20 | C24: 10.806 | D24: 10.772 | E24: 1.075 | F24: 10.503 | G24: 10.896 | I24: 45 | J24: 10.388 | K24: 10.421 | L24: 1.061 | M24: 10.221 | N24: 10.288 | S24: 20 | T24: 3.4005051 | V24: 20 | W24: 5 | Y24: 20 | Z24: 10 | AB24: 20 | AC24: D | AD24: 0.324 | AE24: 0.324 | AF24: 3.241 | AK24: 20 | AL24: 11 | AN24: 20 | AO24: 1 | AT24: 20 | AU24: 10.013 | AV24: 10.293 | AW24: 10.101 | AX24: 9.977 | AY24: 12.006 | AZ24: 11.744 | BA24: 11.583 | BB24: 12.022
B25: 21 | C25: 10.279 | D25: 10.716 | E25: 1.057 | F25: 10.705 | G25: 10.335 | I25: 46 | J25: 10.621 | K25: 10.288 | L25: 10.399 | M25: 10.466 | N25: 10.343 | S25: 21 | T25: 3.4304236 | V25: 21 | W25: 6 | Y25: 21 | Z25: 7 | AK25: 21 | AL25: 7 | AN25: 21 | AO25: 11
B26: 22 | C26: 1.075 | D26: 10.593 | E26: 10.402 | F26: 1.038 | G26: 9.886 | I26: 47 | J26: 10.677 | K26: 10.443 | L26: 10.588 | M26: 10.366 | N26: 10.421 | S26: 22 | T26: 3.5846108 | V26: 22 | W26: 15 | Y26: 22 | Z26: 8 | AK26: 22 | AL26: 14 | AN26: 22 | AO26: 7
B27: 23 | C27: 11.776 | D27: 10.469 | E27: 1095618.2 | F27: 1076273.7 | G27: 1079306 | I27: 48 | J27: 10.666 | K27: 10.366 | L27: 10.343 | M27: 1.021 | N27: 10.566 | S27: 23 | T27: 3.6765189 | V27: 23 | W27: 6 | Y27: 23 | Z27: 14 | AK27: 23 | AL27: 8 | AN27: 23 | AO27: 11
B28: 24 | C28: 10.705 | D28: 10.761 | E28: 10.436 | F28: 10.548 | G28: 9.897 | I28: 49 | J28: 1.041 | K28: 10.677 | L28: 10.321 | M28: 10.588 | N28: 10.499 | S28: 24 | T28: 3.5462192 | V28: 24 | W28: 12 | Y28: 24 | Z28: 7 | AK28: 24 | AL28: 12 | AN28: 24 | AO28: 1
B29: 25 | C29: 10.245 | D29: 10.525 | E29: 10.436 | F29: 10.525 | G29: 10.346 | I29: 50 | J29: 10.443 | K29: 1.031 | L29: 10.377 | M29: 10.688 | N29: 10.477 | S29: 25 | T29: 3.2133604 | V29: 25 | W29: 8 | Y29: 25 | Z29: 10 | AK29: 25 | AL29: 15 | AN29: 25 | AO29: 9
AN30: 26 | AO30: 9
AN31: 27 | AO31: 7
AN32: 28 | AO32: 6
AN33: 29 | AO33: 9
AN34: 30 | AO34: 7

Sheet Tabel Faktor
A1: n | B1: A | C1: A2 | D1: A3 | E1: c4 | F1: 1/c4 | G1: B3 | H1: B4 | I1: B5 | J1: B6 | K1: d2 | L1: 1/d2 | M1: d_3 | N1: D1 | O1: D2 | P1: D3 | Q1: D4
A2: 2 | B2: 2.121 | C2: 1.88 | D2: 2.659 | E2: 0.7979 | F2: 1.2533 | G2: 0 | H2: 3.267 | I2: 0 | J2: 2.606 | K2: 1.128 | L2: 0.8865 | M2: 0.853 | N2: 0 | O2: 3.686 | P2: 0 | Q2: 3.267
A3: 3 | B3: 1.732 | C3: 1.023 | D3: 1.954 | E3: 0.8862 | F3: 1.1284 | G3: 0 | H3: 2.568 | I3: 0 | J3: 2.276 | K3: 1.693 | L3: 0.5907 | M3: 0.888 | N3: 0 | O3: 4.358 | P3: 0 | Q3: 2.574
A4: 4 | B4: 1.5 | C4: 0.729 | D4: 1.628 | E4: 0.9213 | F4: 1.0854 | G4: 0 | H4: 2.266 | I4: 0 | J4: 2.088 | K4: 2.059 | L4: 0.4857 | M4: 0.88 | N4: 0 | O4: 4.698 | P4: 0 | Q4: 2.282
A5: 5 | B5: 1.342 | C5: 0.577 | D5: 1.427 | E5: 0.94 | F5: 1.0638 | G5: 0 | H5: 2.089 | I5: 0 | J5: 1.964 | K5: 2.326 | L5: 0.4299 | M5: 0.864 | N5: 0 | O5: 4.918 | P5: 0 | Q5: 2.114
A6: 6 | B6: 1.225 | C6: 0.483 | D6: 1.287 | E6: 0.9515 | F6: 1.051 | G6: 0.03 | H6: 1.97 | I6: 0.029 | J6: 1.874 | K6: 2.534 | L6: 0.3946 | M6: 0.848 | N6: 0 | O6: 5.078 | P6: 0 | Q6: 2.004
A7: 7 | B7: 1.134 | C7: 0.419 | D7: 1.182 | E7: 0.9594 | F7: 1.0423 | G7: 0.118 | H7: 1.882 | I7: 0.113 | J7: 1.806 | K7: 2.704 | L7: 0.3698 | M7: 0.833 | N7: 0.204 | O7: 5.204 | P7: 0.076 | Q7: 1.924
A8: 8 | B8: 1.061 | C8: 0.373 | D8: 1.099 | E8: 0.965 | F8: 1.0363 | G8: 0.185 | H8: 1.815 | I8: 0.179 | J8: 1.751 | K8: 2.847 | L8: 0.3512 | M8: 0.82 | N8: 0.388 | O8: 5.306 | P8: 0.136 | Q8: 1.864
A9: 9 | B9: 1 | C9: 0.337 | D9: 1.032 | E9: 0.9693 | F9: 1.0317 | G9: 0.239 | H9: 1.761 | I9: 0.232 | J9: 1.707 | K9: 2.97 | L9: 0.3367 | M9: 0.808 | N9: 0.547 | O9: 5.393 | P9: 0.184 | Q9: 1.816
A10: 10 | B10: 0.949 | C10: 0.308 | D10: 0.975 | E10: 0.9727 | F10: 1.0281 | G10: 0.284 | H10: 1.716 | I10: 0.276 | J10: 1.669 | K10: 3.078 | L10: 0.3249 | M10: 0.797 | N10: 0.687 | O10: 5.469 | P10: 0.223 | Q10: 1.777
A11: 11 | B11: 0.905 | C11: 0.285 | D11: 0.927 | E11: 0.9754 | F11: 1.0252 | G11: 0.321 | H11: 1.679 | I11: 0.313 | J11: 1.637 | K11: 3.173 | L11: 0.3152 | M11: 0.787 | N11: 0.811 | O11: 5.535 | P11: 0.256 | Q11: 1.744
A12: 12 | B12: 0.866 | C12: 0.266 | D12: 0.886 | E12: 0.9776 | F12: 1.0229 | G12: 0.354 | H12: 1.646 | I12: 0.346 | J12: 1.61 | K12: 3.258 | L12: 0.3069 | M12: 0.778 | N12: 0.922 | O12: 5.594 | P12: 0.283 | Q12: 1.717
A13: 13 | B13: 0.832 | C13: 0.249 | D13: 0.85 | E13: 0.9794 | F13: 1.021 | G13: 0.382 | H13: 1.618 | I13: 0.374 | J13: 1.585 | K13: 3.336 | L13: 0.2998 | M13: 0.77 | N13: 1.025 | O13: 5.647 | P13: 0.307 | Q13: 1.693
... A25: 25 | B25: 0.6 | C25: 0.153 | D25: 0.606 | E25: 0.9896 | F25: 1.0105 | G25: 0.565 | H25: 1.435 | I25: 0.559 | J25: 1.42 | K25: 3.931 | L25: 0.2544 | M25: 0.708 | N25: 1.806 | O25: 6.056 | P25: 0.459 | Q25: 1.541

Sheet Instruksi
B1: Instructions
B2: Worksheet specific notes
B4: Summary
B5: Lembar kerja ini dibuat untuk mengakomodasi pengolahan data PPST III 2025/2025 Modul 3 - Pengendalian Kualitas Secara Statistika. Seluruh data yang diperlukan tersedia pada lembar kerja ini.
B6: Keluaran dari lembar kerja ini adalah peta kendali, kurva OC, ARL, dan kapabilitas proses.
B8: Formatting guide
B10: Dalam lembar kerja ini, digunakan konvensi penulisan sebagai berikut.
B12: Cells | C12: Sel yang telah dikalkulasikan yang tidak boleh diubah secara manual
C13: Data mentah yang digunakan model
C14: Instruksi, catatan, atau informasi kontekstual lainnya
B16: Tabs | C16: Analysis sheets
C17: Raw data sheets

Sheet Pemilihan Peta Kendali
A1: Part | B1: Peta Kendali
A2: Pivot | E2: xbar-R atau xbar-s
A3: Bottom Base 2 | E3: MR
A4: Pan Assembly | E4: p atau np
A5: Tripod | E5: c
A6: Leg | E6: u
A7: Dokumen | E7: cusum atau EWMA
A8: XYZ 1 | E8: Short Production Run xbar-R
A9: XYZ 2 | E9: T^2

Sheet Peta Kendali xbar-R
B2: Part
B3: Iterasi 1 | Q3: Iterasi 2
B4: Pemeriksaan Kondisi Abnormalitas Peta R | I4: Pemeriksaan Kondisi Abnormalitas Peta xbar | Q4: Pemeriksaan Kondisi Abnormalitas Peta R | X4: Pemeriksaan Kondisi Abnormalitas Peta xbar
B5: Run | I5: Run | Q5: Run | X5: Run
B6: Trend | I6: Trend | Q6: Trend | X6: Trend
B7: Pengulangan Secara Periodik | I7: Pengulangan Secara Periodik | Q7: Pengulangan Secara Periodik | X7: Pengulangan Secara Periodik
B8: Hugging pada garis tengah | I8: Hugging pada garis tengah | Q8: Hugging pada garis tengah | X8: Hugging pada garis tengah
B9: Hugging dekat garis batas kendali | I9: Hugging dekat garis batas kendali | Q9: Hugging dekat garis batas kendali | X9: Hugging dekat garis batas kendali
B27: Peta xbar-R | Q27: Peta xbar-R
B29: Parameter Peta Kendali | C29: m | Q29: Parameter Peta Kendali | R29: m
C30: n | R30: n
C31: xbarbar | R31: xbarbar
C32: Rbar | R32: Rbar
C33: BKA R | R33: BKA R
C34: BKB R | R34: BKB R
C35: BKA Xbar | R35: BKA Xbar
C36: BKB Xbar | R36: BKB Xbar
C37: A2 | D37: =INDEX('Tabel Faktor'!$A$1:$Q$25,MATCH(D30,'Tabel Faktor'!$A$1:$A$25,0),MATCH(C37,'Tabel Faktor'!$A$1:$Q$1,0)) -> #N/A | R37: A2 | S37: {=D37:D39} -> #N/A
C38: D4 | D38: {=INDEX('Tabel Faktor'!$A$1:$Q$25,MATCH(D30,'Tabel Faktor'!$A$1:$A$25,0),MATCH(C38,'Tabel Faktor'!$A$1:$Q$1,0))} -> #N/A | R38: D4 | S38: #N/A
C39: D3 | D39: {=INDEX('Tabel Faktor'!$A$1:$Q$25,MATCH(D30,'Tabel Faktor'!$A$1:$A$25,0),MATCH(C39,'Tabel Faktor'!$A$1:$Q$1,0))} -> #N/A | R39: D3 | S39: #N/A
B41: Sample Number (i) | C41: Observasi | H41: Rata-rata (xi bar) | I41: Range (Ri) | J41: GT R | K41: BKA R | L41: BKB R | M41: GT xbar | N41: BKA xbar | O41: BKB xbar | Q41: Sample Number (i) | R41: Observasi | W41: Rata-rata (xi bar) | X41: Range (Ri) | Y41: GT R | Z41: BKA R | AA41: BKB R | AB41: GT xbar | AC41: BKA xbar | AD41: BKB xbar
B42: 1 | J42: =$D$32 -> 0 | K42: =$D$33 -> 0 | L42: =$D$34 -> 0 | M42: =$D$31 -> 0 | N42: =$D$35 -> 0 | O42: =$D$36 -> 0 | Q42: 1 | Y42: =$S$32 -> 0 | Z42: =$S$33 -> 0 | AA42: =$S$34 -> 0 | AB42: =$S$31 -> 0 | AC42: =$S$35 -> 0 | AD42: =$S$36 -> 0
B43: 2 | J43: =$D$32 -> 0 | K43: =$D$33 -> 0 | L43: =$D$34 -> 0 | M43: =$D$31 -> 0 | N43: =$D$35 -> 0 | O43: =$D$36 -> 0 | Q43: 2 | Y43: =$S$32 -> 0 | Z43: =$S$33 -> 0 | AA43: =$S$34 -> 0 | AB43: =$S$31 -> 0 | AC43: =$S$35 -> 0 | AD43: =$S$36 -> 0
B44: 3 | J44: =$D$32 -> 0 | K44: =$D$33 -> 0 | L44: =$D$34 -> 0 | M44: =$D$31 -> 0 | N44: =$D$35 -> 0 | O44: =$D$36 -> 0 | Q44: 3 | Y44: =$S$32 -> 0 | Z44: =$S$33 -> 0 | AA44: =$S$34 -> 0 | AB44: =$S$31 -> 0 | AC44: =$S$35 -> 0 | AD44: =$S$36 -> 0
B45: 4 | J45: =$D$32 -> 0 | K45: =$D$33 -> 0 | L45: =$D$34 -> 0 | M45: =$D$31 -> 0 | N45: =$D$35 -> 0 | O45: =$D$36 -> 0 | Q45: 4 | Y45: =$S$32 -> 0 | Z45: =$S$33 -> 0 | AA45: =$S$34 -> 0 | AB45: =$S$31 -> 0 | AC45: =$S$35 -> 0 | AD45: =$S$36 -> 0
B46: 5 | J46: =$D$32 -> 0 | K46: =$D$33 -> 0 | L46: =$D$34 -> 0 | M46: =$D$31 -> 0 | N46: =$D$35 -> 0 | O46: =$D$36 -> 0 | Q46: 5 | Y46: =$S$32 -> 0 | Z46: =$S$33 -> 0 | AA46: =$S$34 -> 0 | AB46: =$S$31 -> 0 | AC46: =$S$35 -> 0 | AD46: =$S$36 -> 0
B47: 6 | J47: =$D$32 -> 0 | K47: =$D$33 -> 0 | L47: =$D$34 -> 0 | M47: =$D$31 -> 0 | N47: =$D$35 -> 0 | O47: =$D$36 -> 0 | Q47: 6 | Y47: =$S$32 -> 0 | Z47: =$S$33 -> 0 | AA47: =$S$34 -> 0 | AB47: =$S$31 -> 0 | AC47: =$S$35 -> 0 | AD47: =$S$36 -> 0
B48: 7 | J48: =$D$32 -> 0 | K48: =$D$33 -> 0 | L48: =$D$34 -> 0 | M48: =$D$31 -> 0 | N48: =$D$35 -> 0 | O48: =$D$36 -> 0 | Q48: 7 | Y48: =$S$32 -> 0 | Z48: =$S$33 -> 0 | AA48: =$S$34 -> 0 | AB48: =$S$31 -> 0 | AC48: =$S$35 -> 0 | AD48: =$S$36 -> 0
B49: 8 | J49: =$D$32 -> 0 | K49: =$D$33 -> 0 | L49: =$D$34 -> 0 | M49: =$D$31 -> 0 | N49: =$D$35 -> 0 | O49: =$D$36 -> 0 | Q49: 8 | Y49: =$S$32 -> 0 | Z49: =$S$33 -> 0 | AA49: =$S$34 -> 0 | AB49: =$S$31 -> 0 | AC49: =$S$35 -> 0 | AD49: =$S$36 -> 0
B50: 9 | J50: =$D$32 -> 0 | K50: =$D$33 -> 0 | L50: =$D$34 -> 0 | M50: =$D$31 -> 0 | N50: =$D$35 -> 0 | O50: =$D$36 -> 0 | Q50: 9 | Y50: =$S$32 -> 0 | Z50: =$S$33 -> 0 | AA50: =$S$34 -> 0 | AB50: =$S$31 -> 0 | AC50: =$S$35 -> 0 | AD50: =$S$36 -> 0
B51: 10 | J51: =$D$32 -> 0 | K51: =$D$33 -> 0 | L51: =$D$34 -> 0 | M51: =$D$31 -> 0 | N51: =$D$35 -> 0 | O51: =$D$36 -> 0 | Q51: 10 | Y51: =$S$32 -> 0 | Z51: =$S$33 -> 0 | AA51: =$S$34 -> 0 | AB51: =$S$31 -> 0 | AC51: =$S$35 -> 0 | AD51: =$S$36 -> 0
B52: 11 | J52: =$D$32 -> 0 | K52: =$D$33 -> 0 | L52: =$D$34 -> 0 | M52: =$D$31 -> 0 | N52: =$D$35 -> 0 | O52: =$D$36 -> 0 | Q52: 11 | Y52: =$S$32 -> 0 | Z52: =$S$33 -> 0 | AA52: =$S$34 -> 0 | AB52: =$S$31 -> 0 | AC52: =$S$35 -> 0 | AD52: =$S$36 -> 0
B53: 12 | J53: =$D$32 -> 0 | K53: =$D$33 -> 0 | L53: =$D$34 -> 0 | M53: =$D$31 -> 0 | N53: =$D$35 -> 0 | O53: =$D$36 -> 0 | Q53: 12 | Y53: =$S$32 -> 0 | Z53: =$S$33 -> 0 | AA53: =$S$34 -> 0 | AB53: =$S$31 -> 0 | AC53: =$S$35 -> 0 | AD53: =$S$36 -> 0
... B65: 24 | J65: =$D$32 -> 0 | K65: =$D$33 -> 0 | L65: =$D$34 -> 0 | M65: =$D$31 -> 0 | N65: =$D$35 -> 0 | O65: =$D$36 -> 0 | Q65: 25 | Y65: =$S$32 -> 0 | Z65: =$S$33 -> 0 | AA65: =$S$34 -> 0 | AB65: =$S$31 -> 0 | AC65: =$S$35 -> 0 | AD65: =$S$36 -> 0
B66: 25 | J66: =$D$32 -> 0 | K66: =$D$33 -> 0 | L66: =$D$34 -> 0 | M66: =$D$31 -> 0 | N66: =$D$35 -> 0 | O66: =$D$36 -> 0

Sheet Peta Kendali xbar-s
B2: Part | R2: Part
B3: Iterasi 1 | R3: Iterasi 2
B4: Pemeriksaan Kondisi Abnormalitas Peta s | I4: Pemeriksaan Kondisi Abnormalitas Peta xbar | R4: Pemeriksaan Kondisi Abnormalitas Peta s | Y4: Pemeriksaan Kondisi Abnormalitas Peta xbar
B5: Run | I5: Run | R5: Run | Y5: Run
B6: Trend | I6: Trend | R6: Trend | Y6: Trend
B7: Pengulangan Secara Periodik | I7: Pengulangan Secara Periodik | R7: Pengulangan Secara Periodik | Y7: Pengulangan Secara Periodik
B8: Hugging pada garis tengah | I8: Hugging pada garis tengah | R8: Hugging pada garis tengah | Y8: Hugging pada garis tengah
B9: Hugging dekat garis batas kendali | I9: Hugging dekat garis batas kendali | R9: Hugging dekat garis batas kendali | Y9: Hugging dekat garis batas kendali
B27: Peta xbar-s | R27: Peta xbar-s
B29: Parameter Peta Kendali | C29: m | R29: Parameter Peta Kendali | S29: m
C30: n | S30: n
C31: xbarbar | S31: xbarbar
C32: sbar | S32: sbar
C33: BKA s | S33: BKA s
C34: BKB s | S34: BKB s
C35: BKA Xbar | S35: BKA Xbar
C36: BKB Xbar | S36: BKB Xbar
C37: A3 | D37: =INDEX('Tabel Faktor'!$A$1:$Q$25,MATCH(D30,'Tabel Faktor'!$A$1:$A$25,0),MATCH(C37,'Tabel Faktor'!$A$1:$Q$1,0)) -> #N/A | S37: A3 | T37: {=INDEX('Tabel Faktor'!$A$1:$Q$25,MATCH(T30,'Tabel Faktor'!$A$1:$A$25,0),MATCH(S37,'Tabel Faktor'!$A$1:$Q$1,0))} -> #N/A
C38: B4 | D38: {=INDEX('Tabel Faktor'!$A$1:$Q$25,MATCH(D30,'Tabel Faktor'!$A$1:$A$25,0),MATCH(C38,'Tabel Faktor'!$A$1:$Q$1,0))} -> #N/A | S38: B4 | T38: {=INDEX('Tabel Faktor'!$A$1:$Q$25,MATCH(T30,'Tabel Faktor'!$A$1:$A$25,0),MATCH(S38,'Tabel Faktor'!$A$1:$Q$1,0))} -> #N/A
C39: B3 | D39: {=INDEX('Tabel Faktor'!$A$1:$Q$25,MATCH(D30,'Tabel Faktor'!$A$1:$A$25,0),MATCH(C39,'Tabel Faktor'!$A$1:$Q$1,0))} -> #N/A | S39: B3 | T39: {=INDEX('Tabel Faktor'!$A$1:$Q$25,MATCH(T30,'Tabel Faktor'!$A$1:$A$25,0),MATCH(S39,'Tabel Faktor'!$A$1:$Q$1,0))} -> #N/A
B41: Sample Number (i) | C41: Observasi | H41: Rata-rata (xi bar) | I41: Standar Deviasi (si) | J41: GT s | K41: BKA s | L41: BKB s | M41: GT xbar | N41: BKA xbar | O41: BKB xbar | R41: Sample Number (i) | S41: Observasi | X41: Rata-rata (xi bar) | Y41: Standar Deviasi (si) | Z41: GT s | AA41: BKA s | AB41: BKB s | AC41: GT xbar | AD41: BKA xbar | AE41: BKB xbar
B42: 1 | H42: =AVERAGE(C42:G42) -> #DIV/0! | I42: =STDEV(C42:G42) -> #DIV/0! | J42: =$D$32 -> 0 | K42: =$D$33 -> 0 | L42: =$D$34 -> 0 | M42: =$D$31 -> 0 | N42: =$D$35 -> 0 | O42: =$D$36 -> 0 | R42: 1 | X42: =AVERAGE(S42:W42) -> #DIV/0! | Y42: =STDEV(S42:W42) -> #DIV/0! | Z42: =$T$32 -> 0 | AA42: =$T$33 -> 0 | AB42: =$T$34 -> 0 | AC42: =$T$31 -> 0 | AD42: =$T$35 -> 0 | AE42: =$T$36 -> 0
B43: 2 | H43: =AVERAGE(C43:G43) -> #DIV/0! | I43: =STDEV(C43:G43) -> #DIV/0! | J43: =$D$32 -> 0 | K43: =$D$33 -> 0 | L43: =$D$34 -> 0 | M43: =$D$31 -> 0 | N43: =$D$35 -> 0 | O43: =$D$36 -> 0 | R43: 2 | X43: =AVERAGE(S43:W43) -> #DIV/0! | Y43: =STDEV(S43:W43) -> #DIV/0! | Z43: =$T$32 -> 0 | AA43: =$T$33 -> 0 | AB43: =$T$34 -> 0 | AC43: =$T$31 -> 0 | AD43: =$T$35 -> 0 | AE43: =$T$36 -> 0
B44: 3 | H44: =AVERAGE(C44:G44) -> #DIV/0! | I44: =STDEV(C44:G44) -> #DIV/0! | J44: =$D$32 -> 0 | K44: =$D$33 -> 0 | L44: =$D$34 -> 0 | M44: =$D$31 -> 0 | N44: =$D$35 -> 0 | O44: =$D$36 -> 0 | R44: 3 | X44: =AVERAGE(S44:W44) -> #DIV/0! | Y44: =STDEV(S44:W44) -> #DIV/0! | Z44: =$T$32 -> 0 | AA44: =$T$33 -> 0 | AB44: =$T$34 -> 0 | AC44: =$T$31 -> 0 | AD44: =$T$35 -> 0 | AE44: =$T$36 -> 0
B45: 4 | H45: =AVERAGE(C45:G45) -> #DIV/0! | I45: =STDEV(C45:G45) -> #DIV/0! | J45: =$D$32 -> 0 | K45: =$D$33 -> 0 | L45: =$D$34 -> 0 | M45: =$D$31 -> 0 | N45: =$D$35 -> 0 | O45: =$D$36 -> 0 | R45: 4 | X45: =AVERAGE(S45:W45) -> #DIV/0! | Y45: =STDEV(S45:W45) -> #DIV/0! | Z45: =$T$32 -> 0 | AA45: =$T$33 -> 0 | AB45: =$T$34 -> 0 | AC45: =$T$31 -> 0 | AD45: =$T$35 -> 0 | AE45: =$T$36 -> 0
B46: 5 | H46: =AVERAGE(C46:G46) -> #DIV/0! | I46: =STDEV(C46:G46) -> #DIV/0! | J46: =$D$32 -> 0 | K46: =$D$33 -> 0 | L46: =$D$34 -> 0 | M46: =$D$31 -> 0 | N46: =$D$35 -> 0 | O46: =$D$36 -> 0 | R46: 5 | X46: =AVERAGE(S46:W46) -> #DIV/0! | Y46: =STDEV(S46:W46) -> #DIV/0! | Z46: =$T$32 -> 0 | AA46: =$T$33 -> 0 | AB46: =$T$34 -> 0 | AC46: =$T$31 -> 0 | AD46: =$T$35 -> 0 | AE46: =$T$36 -> 0
B47: 6 | H47: =AVERAGE(C47:G47) -> #DIV/0! | I47: =STDEV(C47:G47) -> #DIV/0! | J47: =$D$32 -> 0 | K47: =$D$33 -> 0 | L47: =$D$34 -> 0 | M47: =$D$31 -> 0 | N47: =$D$35 -> 0 | O47: =$D$36 -> 0 | R47: 6 | X47: =AVERAGE(S47:W47) -> #DIV/0! | Y47: =STDEV(S47:W47) -> #DIV/0! | Z47: =$T$32 -> 0 | AA47: =$T$33 -> 0 | AB47: =$T$34 -> 0 | AC47: =$T$31 -> 0 | AD47: =$T$35 -> 0 | AE47: =$T$36 -> 0
B48: 7 | H48: =AVERAGE(C48:G48) -> #DIV/0! | I48: =STDEV(C48:G48) -> #DIV/0! | J48: =$D$32 -> 0 | K48: =$D$33 -> 0 | L48: =$D$34 -> 0 | M48: =$D$31 -> 0 | N48: =$D$35 -> 0 | O48: =$D$36 -> 0 | R48: 7 | X48: =AVERAGE(S48:W48) -> #DIV/0! | Y48: =STDEV(S48:W48) -> #DIV/0! | Z48: =$T$32 -> 0 | AA48: =$T$33 -> 0 | AB48: =$T$34 -> 0 | AC48: =$T$31 -> 0 | AD48: =$T$35 -> 0 | AE48: =$T$36 -> 0
B49: 8 | H49: =AVERAGE(C49:G49) -> #DIV/0! | I49: =STDEV(C49:G49) -> #DIV/0! | J49: =$D$32 -> 0 | K49: =$D$33 -> 0 | L49: =$D$34 -> 0 | M49: =$D$31 -> 0 | N49: =$D$35 -> 0 | O49: =$D$36 -> 0 | R49: 8 | X49: =AVERAGE(S49:W49) -> #DIV/0! | Y49: =STDEV(S49:W49) -> #DIV/0! | Z49: =$T$32 -> 0 | AA49: =$T$33 -> 0 | AB49: =$T$34 -> 0 | AC49: =$T$31 -> 0 | AD49: =$T$35 -> 0 | AE49: =$T$36 -> 0
B50: 9 | H50: =AVERAGE(C50:G50) -> #DIV/0! | I50: =STDEV(C50:G50) -> #DIV/0! | J50: =$D$32 -> 0 | K50: =$D$33 -> 0 | L50: =$D$34 -> 0 | M50: =$D$31 -> 0 | N50: =$D$35 -> 0 | O50: =$D$36 -> 0 | R50: 9 | X50: =AVERAGE(S50:W50) -> #DIV/0! | Y50: =STDEV(S50:W50) -> #DIV/0! | Z50: =$T$32 -> 0 | AA50: =$T$33 -> 0 | AB50: =$T$34 -> 0 | AC50: =$T$31 -> 0 | AD50: =$T$35 -> 0 | AE50: =$T$36 -> 0
B51: 10 | H51: =AVERAGE(C51:G51) -> #DIV/0! | I51: =STDEV(C51:G51) -> #DIV/0! | J51: =$D$32 -> 0 | K51: =$D$33 -> 0 | L51: =$D$34 -> 0 | M51: =$D$31 -> 0 | N51: =$D$35 -> 0 | O51: =$D$36 -> 0 | R51: 10 | X51: =AVERAGE(S51:W51) -> #DIV/0! | Y51: =STDEV(S51:W51) -> #DIV/0! | Z51: =$T$32 -> 0 | AA51: =$T$33 -> 0 | AB51: =$T$34 -> 0 | AC51: =$T$31 -> 0 | AD51: =$T$35 -> 0 | AE51: =$T$36 -> 0
B52: 11 | H52: =AVERAGE(C52:G52) -> #DIV/0! | I52: =STDEV(C52:G52) -> #DIV/0! | J52: =$D$32 -> 0 | K52: =$D$33 -> 0 | L52: =$D$34 -> 0 | M52: =$D$31 -> 0 | N52: =$D$35 -> 0 | O52: =$D$36 -> 0 | R52: 11 | X52: =AVERAGE(S52:W52) -> #DIV/0! | Y52: =STDEV(S52:W52) -> #DIV/0! | Z52: =$T$32 -> 0 | AA52: =$T$33 -> 0 | AB52: =$T$34 -> 0 | AC52: =$T$31 -> 0 | AD52: =$T$35 -> 0 | AE52: =$T$36 -> 0
B53: 12 | H53: =AVERAGE(C53:G53) -> #DIV/0! | I53: =STDEV(C53:G53) -> #DIV/0! | J53: =$D$32 -> 0 | K53: =$D$33 -> 0 | L53: =$D$34 -> 0 | M53: =$D$31 -> 0 | N53: =$D$35 -> 0 | O53: =$D$36 -> 0 | R53: 12 | X53: =AVERAGE(S53:W53) -> #DIV/0! | Y53: =STDEV(S53:W53) -> #DIV/0! | Z53: =$T$32 -> 0 | AA53: =$T$33 -> 0 | AB53: =$T$34 -> 0 | AC53: =$T$31 -> 0 | AD53: =$T$35 -> 0 | AE53: =$T$36 -> 0
... B65: 24 | H65: =AVERAGE(C65:G65) -> #DIV/0! | I65: =STDEV(C65:G65) -> #DIV/0! | J65: =$D$32 -> 0 | K65: =$D$33 -> 0 | L65: =$D$34 -> 0 | M65: =$D$31 -> 0 | N65: =$D$35 -> 0 | O65: =$D$36 -> 0 | R65: 24 | X65: =AVERAGE(S65:W65) -> #DIV/0! | Y65: =STDEV(S65:W65) -> #DIV/0! | Z65: =$T$32 -> 0 | AA65: =$T$33 -> 0 | AB65: =$T$34 -> 0 | AC65: =$T$31 -> 0 | AD65: =$T$35 -> 0 | AE65: =$T$36 -> 0
B66: 25 | H66: =AVERAGE(C66:G66) -> #DIV/0! | I66: =STDEV(C66:G66) -> #DIV/0! | J66: =$D$32 -> 0 | K66: =$D$33 -> 0 | L66: =$D$34 -> 0 | M66: =$D$31 -> 0 | N66: =$D$35 -> 0 | O66: =$D$36 -> 0 | R66: 25

Sheet OC Curve ARL xbar-R
B2: Part
B4: OC Curve dan ARL
B6: Parameter kurva OC | C6: R
C7: d2 | D7: =INDEX('Tabel Faktor'!$A$1:$Q$25,MATCH(D10,'Tabel Faktor'!$A$1:$A$25,0),MATCH(C7,'Tabel Faktor'!$A$1:$Q$1,0)) -> #N/A
C8: sigma | D8: =D6/D7 -> #N/A
C9: L | D9: 3
C10: n
B12: ksigma | C12: k | D12: Beta | E12: ARL
B13: 0 | C13: =B13/$D$8 -> #N/A | D13: =_xlfn.NORM.S.DIST($D$9-C13*SQRT($D$10),TRUE)-_xlfn.NORM.S.DIST(-$D$9-C13*SQRT($D$10),TRUE) -> #N/A | E13: =1/(1-D13) -> #N/A
B14: 0.01 | C14: =B14/$D$8 -> #N/A | D14: =_xlfn.NORM.S.DIST($D$9-C14*SQRT($D$10),TRUE)-_xlfn.NORM.S.DIST(-$D$9-C14*SQRT($D$10),TRUE) -> #N/A | E14: =1/(1-D14) -> #N/A
B15: 0.02 | C15: =B15/$D$8 -> #N/A | D15: =_xlfn.NORM.S.DIST($D$9-C15*SQRT($D$10),TRUE)-_xlfn.NORM.S.DIST(-$D$9-C15*SQRT($D$10),TRUE) -> #N/A | E15: =1/(1-D15) -> #N/A
B16: 0.03 | C16: =B16/$D$8 -> #N/A | D16: =_xlfn.NORM.S.DIST($D$9-C16*SQRT($D$10),TRUE)-_xlfn.NORM.S.DIST(-$D$9-C16*SQRT($D$10),TRUE) -> #N/A | E16: =1/(1-D16) -> #N/A
B17: 0.04 | C17: =B17/$D$8 -> #N/A | D17: =_xlfn.NORM.S.DIST($D$9-C17*SQRT($D$10),TRUE)-_xlfn.NORM.S.DIST(-$D$9-C17*SQRT($D$10),TRUE) -> #N/A | E17: =1/(1-D17) -> #N/A
B18: 0.05 | C18: =B18/$D$8 -> #N/A | D18: =_xlfn.NORM.S.DIST($D$9-C18*SQRT($D$10),TRUE)-_xlfn.NORM.S.DIST(-$D$9-C18*SQRT($D$10),TRUE) -> #N/A | E18: =1/(1-D18) -> #N/A
B19: 0.06 | C19: =B19/$D$8 -> #N/A | D19: =_xlfn.NORM.S.DIST($D$9-C19*SQRT($D$10),TRUE)-_xlfn.NORM.S.DIST(-$D$9-C19*SQRT($D$10),TRUE) -> #N/A | E19: =1/(1-D19) -> #N/A
B20: 0.07 | C20: =B20/$D$8 -> #N/A | D20: =_xlfn.NORM.S.DIST($D$9-C20*SQRT($D$10),TRUE)-_xlfn.NORM.S.DIST(-$D$9-C20*SQRT($D$10),TRUE) -> #N/A | E20: =1/(1-D20) -> #N/A
B21: 0.08 | C21: =B21/$D$8 -> #N/A | D21: =_xlfn.NORM.S.DIST($D$9-C21*SQRT($D$10),TRUE)-_xlfn.NORM.S.DIST(-$D$9-C21*SQRT($D$10),TRUE) -> #N/A | E21: =1/(1-D21) -> #N/A
B22: 0.09 | C22: =B22/$D$8 -> #N/A | D22: =_xlfn.NORM.S.DIST($D$9-C22*SQRT($D$10),TRUE)-_xlfn.NORM.S.DIST(-$D$9-C22*SQRT($D$10),TRUE) -> #N/A | E22: =1/(1-D22) -> #N/A
B23: 0.1 | C23: =B23/$D$8 -> #N/A | D23: =_xlfn.NORM.S.DIST($D$9-C23*SQRT($D$10),TRUE)-_xlfn.NORM.S.DIST(-$D$9-C23*SQRT($D$10),TRUE) -> #N/A | E23: =1/(1-D23) -> #N/A
B24: 0.11 | C24: =B24/$D$8 -> #N/A | D24: =_xlfn.NORM.S.DIST($D$9-C24*SQRT($D$10),TRUE)-_xlfn.NORM.S.DIST(-$D$9-C24*SQRT($D$10),TRUE) -> #N/A | E24: =1/(1-D24) -> #N/A
... B57: 1 | C57: =B57/$D$8 -> #N/A | D57: =_xlfn.NORM.S.DIST($D$9-C57*SQRT($D$10),TRUE)-_xlfn.NORM.S.DIST(-$D$9-C57*SQRT($D$10),TRUE) -> #N/A | E57: =1/(1-D57) -> #N/A

Sheet Kapabilitas Proses xbar-R
B2: Part
B3: Kesimpulan
B19: Kapabilitas Proses
B21: Parameter Proses | C21: Mean
C22: R
C23: n
C24: d2 | D24: {=INDEX('Tabel Faktor'!$A$1:$Q$25,MATCH(D23,'Tabel Faktor'!$A$1:$A$25,0),MATCH(C24,'Tabel Faktor'!$A$1:$Q$1,0))} -> #N/A
C25: sigma | D25: =D22/D24 -> #N/A
B26: Spesifikasi | C26: USL
C27: LSL
C28: Sigma | D28: =(D29-D27)/3 -> #DIV/0!
C29: Mean | D29: =AVERAGE(D26:D27) -> #DIV/0!
B30: Kapabilitas Proses | C30: Cp | D30: =(D26-D27)/(6*D25) -> #N/A
C31: Cpl | D31: =(D21-D27)/(3*D25) -> #N/A
C32: Cpu | D32: =(D26-D21)/(3*D25) -> #N/A
C33: Cpk | D33: =MIN(D31:D32) -> #N/A
C34: Persentase Cacat | D34: =1-(_xlfn.NORM.DIST(D26,D21,D25,TRUE)-_xlfn.NORM.DIST(D27,D21,D25,TRUE)) -> #N/A
B35: z | C35: x proses | D35: f(x) proses | E35: x spesifikasi | F35: f(x) spesifikasi | G35: USL | H35: LSL
B36: -3 | C36: =$D$21+B36*$D$25 -> #N/A | D36: =_xlfn.NORM.DIST($D$21+B36*$D$25,$D$21,$D$25,FALSE) -> #N/A | E36: =$D$29+B36*$D$28 -> #DIV/0! | F36: =_xlfn.NORM.DIST(E36,$D$29,$D$28,TRUE) -> #DIV/0! | G36: =$D$26 -> 0 | H36: =$D$27 -> 0
B37: =B36+0.03 -> -2.97 | C37: =$D$21+B37*$D$25 -> #N/A | D37: =_xlfn.NORM.DIST($D$21+B37*$D$25,$D$21,$D$25,FALSE) -> #N/A | E37: =$D$29+B37*$D$28 -> #DIV/0! | F37: =_xlfn.NORM.DIST(E37,$D$29,$D$28,TRUE) -> #DIV/0! | G37: =$D$26 -> 0 | H37: =$D$27 -> 0
B38: =B37+0.03 -> -2.94 | C38: =$D$21+B38*$D$25 -> #N/A | D38: =_xlfn.NORM.DIST($D$21+B38*$D$25,$D$21,$D$25,FALSE) -> #N/A | E38: =$D$29+B38*$D$28 -> #DIV/0! | F38: =_xlfn.NORM.DIST(E38,$D$29,$D$28,TRUE) -> #DIV/0! | G38: =$D$26 -> 0 | H38: =$D$27 -> 0
B39: =B38+0.03 -> -2.91 | C39: =$D$21+B39*$D$25 -> #N/A | D39: =_xlfn.NORM.DIST($D$21+B39*$D$25,$D$21,$D$25,FALSE) -> #N/A | E39: =$D$29+B39*$D$28 -> #DIV/0! | F39: =_xlfn.NORM.DIST(E39,$D$29,$D$28,TRUE) -> #DIV/0! | G39: =$D$26 -> 0 | H39: =$D$27 -> 0
B40: =B39+0.03 -> -2.88 | C40: =$D$21+B40*$D$25 -> #N/A | D40: =_xlfn.NORM.DIST($D$21+B40*$D$25,$D$21,$D$25,FALSE) -> #N/A | E40: =$D$29+B40*$D$28 -> #DIV/0! | F40: =_xlfn.NORM.DIST(E40,$D$29,$D$28,TRUE) -> #DIV/0! | G40: =$D$26 -> 0 | H40: =$D$27 -> 0
B41: =B40+0.03 -> -2.85 | C41: =$D$21+B41*$D$25 -> #N/A | D41: =_xlfn.NORM.DIST($D$21+B41*$D$25,$D$21,$D$25,FALSE) -> #N/A | E41: =$D$29+B41*$D$28 -> #DIV/0! | F41: =_xlfn.NORM.DIST(E41,$D$29,$D$28,TRUE) -> #DIV/0! | G41: =$D$26 -> 0 | H41: =$D$27 -> 0
B42: =B41+0.03 -> -2.82 | C42: =$D$21+B42*$D$25 -> #N/A | D42: =_xlfn.NORM.DIST($D$21+B42*$D$25,$D$21,$D$25,FALSE) -> #N/A | E42: =$D$29+B42*$D$28 -> #DIV/0! | F42: =_xlfn.NORM.DIST(E42,$D$29,$D$28,TRUE) -> #DIV/0! | G42: =$D$26 -> 0 | H42: =$D$27 -> 0
B43: =B42+0.03 -> -2.79 | C43: =$D$21+B43*$D$25 -> #N/A | D43: =_xlfn.NORM.DIST($D$21+B43*$D$25,$D$21,$D$25,FALSE) -> #N/A | E43: =$D$29+B43*$D$28 -> #DIV/0! | F43: =_xlfn.NORM.DIST(E43,$D$29,$D$28,TRUE) -> #DIV/0! | G43: =$D$26 -> 0 | H43: =$D$27 -> 0
B44: =B43+0.03 -> -2.76 | C44: =$D$21+B44*$D$25 -> #N/A | D44: =_xlfn.NORM.DIST($D$21+B44*$D$25,$D$21,$D$25,FALSE) -> #N/A | E44: =$D$29+B44*$D$28 -> #DIV/0! | F44: =_xlfn.NORM.DIST(E44,$D$29,$D$28,TRUE) -> #DIV/0! | G44: =$D$26 -> 0 | H44: =$D$27 -> 0
B45: =B44+0.03 -> -2.73 | C45: =$D$21+B45*$D$25 -> #N/A | D45: =_xlfn.NORM.DIST($D$21+B45*$D$25,$D$21,$D$25,FALSE) -> #N/A | E45: =$D$29+B45*$D$28 -> #DIV/0! | F45: =_xlfn.NORM.DIST(E45,$D$29,$D$28,TRUE) -> #DIV/0! | G45: =$D$26 -> 0 | H45: =$D$27 -> 0
B46: =B45+0.03 -> -2.7 | C46: =$D$21+B46*$D$25 -> #N/A | D46: =_xlfn.NORM.DIST($D$21+B46*$D$25,$D$21,$D$25,FALSE) -> #N/A | E46: =$D$29+B46*$D$28 -> #DIV/0! | F46: =_xlfn.NORM.DIST(E46,$D$29,$D$28,TRUE) -> #DIV/0! | G46: =$D$26 -> 0 | H46: =$D$27 -> 0
B47: =B46+0.03 -> -2.67 | C47: =$D$21+B47*$D$25 -> #N/A | D47: =_xlfn.NORM.DIST($D$21+B47*$D$25,$D$21,$D$25,FALSE) -> #N/A | E47: =$D$29+B47*$D$28 -> #DIV/0! | F47: =_xlfn.NORM.DIST(E47,$D$29,$D$28,TRUE) -> #DIV/0! | G47: =$D$26 -> 0 | H47: =$D$27 -> 0
B48: =B47+0.03 -> -2.64 | C48: =$D$21+B48*$D$25 -> #N/A | D48: =_xlfn.NORM.DIST($D$21+B48*$D$25,$D$21,$D$25,FALSE) -> #N/A | E48: =$D$29+B48*$D$28 -> #DIV/0! | F48: =_xlfn.NORM.DIST(E48,$D$29,$D$28,TRUE) -> #DIV/0! | G48: =$D$26 -> 0 | H48: =$D$27 -> 0
... B236: =B235+0.03 -> 3 | C236: =$D$21+B236*$D$25 -> #N/A | D236: =_xlfn.NORM.DIST($D$21+B236*$D$25,$D$21,$D$25,FALSE) -> #N/A | E236: =$D$29+B236*$D$28 -> #DIV/0! | F236: =_xlfn.NORM.DIST(E236,$D$29,$D$28,TRUE) -> #DIV/0! | G236: =$D$26 -> 0 | H236: =$D$27 -> 0

Sheet Implementasi xbar-R
B2: Part
B3: Kesimpulan
B21: Peta xbar-R
B23: Parameter Peta Kendali | C23: m | D23: =COUNT(B33:B57) -> 25
C24: n | D24: =COUNT(C33:G33) -> 0
C25: GT xbar | D25: =AVERAGE(H33:H57) -> #DIV/0!
C26: GT R | D26: =AVERAGE(I33:I57) -> 0
C27: BKA R | D27: {='Peta Kendali xbar-R'!D33:D36} -> 0
C28: BKB R | D28: 0
C29: BKA Xbar | D29: 0
C30: BKB Xbar | D30: 0
B32: Sample Number (i) | C32: Observasi | H32: Rata-rata (xi bar) | I32: Range (Ri) | J32: GT R | K32: BKA R | L32: BKB R | M32: GT xbar | N32: BKA xbar | O32: BKB xbar
B33: 26 | H33: =AVERAGE(C33:G33) -> #DIV/0! | I33: =MAX(C33:G33)-MIN(C33:G33) -> 0 | J33: =$D$26 -> 0 | K33: =$D$27 -> 0 | L33: =$D$28 -> 0 | M33: =$D$25 -> #DIV/0! | N33: =$D$29 -> 0 | O33: =$D$30 -> 0
B34: 27 | H34: =AVERAGE(C34:G34) -> #DIV/0! | I34: =MAX(C34:G34)-MIN(C34:G34) -> 0 | J34: =$D$26 -> 0 | K34: =$D$27 -> 0 | L34: =$D$28 -> 0 | M34: =$D$25 -> #DIV/0! | N34: =$D$29 -> 0 | O34: =$D$30 -> 0
B35: 28 | H35: =AVERAGE(C35:G35) -> #DIV/0! | I35: =MAX(C35:G35)-MIN(C35:G35) -> 0 | J35: =$D$26 -> 0 | K35: =$D$27 -> 0 | L35: =$D$28 -> 0 | M35: =$D$25 -> #DIV/0! | N35: =$D$29 -> 0 | O35: =$D$30 -> 0
B36: 29 | H36: =AVERAGE(C36:G36) -> #DIV/0! | I36: =MAX(C36:G36)-MIN(C36:G36) -> 0 | J36: =$D$26 -> 0 | K36: =$D$27 -> 0 | L36: =$D$28 -> 0 | M36: =$D$25 -> #DIV/0! | N36: =$D$29 -> 0 | O36: =$D$30 -> 0
B37: 30 | H37: =AVERAGE(C37:G37) -> #DIV/0! | I37: =MAX(C37:G37)-MIN(C37:G37) -> 0 | J37: =$D$26 -> 0 | K37: =$D$27 -> 0 | L37: =$D$28 -> 0 | M37: =$D$25 -> #DIV/0! | N37: =$D$29 -> 0 | O37: =$D$30 -> 0
B38: 31 | H38: =AVERAGE(C38:G38) -> #DIV/0! | I38: =MAX(C38:G38)-MIN(C38:G38) -> 0 | J38: =$D$26 -> 0 | K38: =$D$27 -> 0 | L38: =$D$28 -> 0 | M38: =$D$25 -> #DIV/0! | N38: =$D$29 -> 0 | O38: =$D$30 -> 0
B39: 32 | H39: =AVERAGE(C39:G39) -> #DIV/0! | I39: =MAX(C39:G39)-MIN(C39:G39) -> 0 | J39: =$D$26 -> 0 | K39: =$D$27 -> 0 | L39: =$D$28 -> 0 | M39: =$D$25 -> #DIV/0! | N39: =$D$29 -> 0 | O39: =$D$30 -> 0
B40: 33 | H40: =AVERAGE(C40:G40) -> #DIV/0! | I40: =MAX(C40:G40)-MIN(C40:G40) -> 0 | J40: =$D$26 -> 0 | K40: =$D$27 -> 0 | L40: =$D$28 -> 0 | M40: =$D$25 -> #DIV/0! | N40: =$D$29 -> 0 | O40: =$D$30 -> 0
B41: 34 | H41: =AVERAGE(C41:G41) -> #DIV/0! | I41: =MAX(C41:G41)-MIN(C41:G41) -> 0 | J41: =$D$26 -> 0 | K41: =$D$27 -> 0 | L41: =$D$28 -> 0 | M41: =$D$25 -> #DIV/0! | N41: =$D$29 -> 0 | O41: =$D$30 -> 0
B42: 35 | H42: =AVERAGE(C42:G42) -> #DIV/0! | I42: =MAX(C42:G42)-MIN(C42:G42) -> 0 | J42: =$D$26 -> 0 | K42: =$D$27 -> 0 | L42: =$D$28 -> 0 | M42: =$D$25 -> #DIV/0! | N42: =$D$29 -> 0 | O42: =$D$30 -> 0
B43: 36 | H43: =AVERAGE(C43:G43) -> #DIV/0! | I43: =MAX(C43:G43)-MIN(C43:G43) -> 0 | J43: =$D$26 -> 0 | K43: =$D$27 -> 0 | L43: =$D$28 -> 0 | M43: =$D$25 -> #DIV/0! | N43: =$D$29 -> 0 | O43: =$D$30 -> 0
B44: 37 | H44: =AVERAGE(C44:G44) -> #DIV/0! | I44: =MAX(C44:G44)-MIN(C44:G44) -> 0 | J44: =$D$26 -> 0 | K44: =$D$27 -> 0 | L44: =$D$28 -> 0 | M44: =$D$25 -> #DIV/0! | N44: =$D$29 -> 0 | O44: =$D$30 -> 0
... B57: 50 | H57: =AVERAGE(C57:G57) -> #DIV/0! | I57: =MAX(C57:G57)-MIN(C57:G57) -> 0 | J57: =$D$26 -> 0 | K57: =$D$27 -> 0 | L57: =$D$28 -> 0 | M57: =$D$25 -> #DIV/0! | N57: =$D$29 -> 0 | O57: =$D$30 -> 0

Sheet Peta Kendali MR
B2: Part
B3: Iterasi 1
B4: Pemeriksaan Kondisi Abnormalitas Peta MR | G4: Pemeriksaan Kondisi Abnormalitas Peta xindv
B5: Run | G5: Run
B6: Trend | G6: Trend
B7: Pengulangan Secara Periodik | G7: Pengulangan Secara Periodik
B8: Hugging pada garis tengah | G8: Hugging pada garis tengah
B9: Hugging dekat garis batas kendali | G9: Hugging dekat garis batas kendali
B27: Peta xindv-MR
B29: Parameter Peta Kendali | C29: m
C30: n | D30: 2
C31: xbar | D31: =AVERAGE(C42:C66) -> #DIV/0!
C32: MRbar | D32: =AVERAGE(E43:E66) -> #DIV/0!
C33: BKA MR | D33: =D38*D32 -> #DIV/0!
C34: BKB MR | D34: =D39*D32 -> #DIV/0!
C35: BKA xindv | D35: =D31+(3*D32/D37) -> #DIV/0!
C36: BKB xindv | D36: =D31-(3*D32/D37) -> #DIV/0!
C37: d2 | D37: {=INDEX('Tabel Faktor'!$A$1:$Q$25,MATCH(D30,'Tabel Faktor'!$A$1:$A$25,0),MATCH(C37,'Tabel Faktor'!$A$1:$Q$1,0))} -> 1.128
C38: D4 | D38: {=INDEX('Tabel Faktor'!$A$1:$Q$25,MATCH(D30,'Tabel Faktor'!$A$1:$A$25,0),MATCH(C38,'Tabel Faktor'!$A$1:$Q$1,0))} -> 3.267
C39: D3 | D39: {=INDEX('Tabel Faktor'!$A$1:$Q$25,MATCH(D30,'Tabel Faktor'!$A$1:$A$25,0),MATCH(C39,'Tabel Faktor'!$A$1:$Q$1,0))} -> 0
B41: Sample Number (i) | C41: Observasi | D41: x individual | E41: MR | F41: GT MR | G41: BKA MR | H41: BKB MR | I41: GT xindv | J41: BKA xindv | K41: BKB xindv | L41: 1/2 UCLx | M41: 1/2 LCLx
B42: 1 | D42: =C42 -> 0 | F42: =$D$32 -> #DIV/0! | G42: =$D$33 -> #DIV/0! | H42: =$D$34 -> #DIV/0! | I42: =$D$31 -> #DIV/0! | J42: =$D$35 -> #DIV/0! | K42: =$D$36 -> #DIV/0! | L42: =I42+(J42-I42)/2 -> #DIV/0! | M42: =I42-(I42-K42)/2 -> #DIV/0!
B43: 2 | D43: =C43 -> 0 | F43: =$D$32 -> #DIV/0! | G43: =$D$33 -> #DIV/0! | H43: =$D$34 -> #DIV/0! | I43: =$D$31 -> #DIV/0! | J43: =$D$35 -> #DIV/0! | K43: =$D$36 -> #DIV/0! | L43: =L42 -> #DIV/0! | M43: =M42 -> #DIV/0!
B44: 3 | D44: =C44 -> 0 | F44: =$D$32 -> #DIV/0! | G44: =$D$33 -> #DIV/0! | H44: =$D$34 -> #DIV/0! | I44: =$D$31 -> #DIV/0! | J44: =$D$35 -> #DIV/0! | K44: =$D$36 -> #DIV/0! | L44: =L43 -> #DIV/0! | M44: =M43 -> #DIV/0!
B45: 4 | D45: =C45 -> 0 | F45: =$D$32 -> #DIV/0! | G45: =$D$33 -> #DIV/0! | H45: =$D$34 -> #DIV/0! | I45: =$D$31 -> #DIV/0! | J45: =$D$35 -> #DIV/0! | K45: =$D$36 -> #DIV/0! | L45: =L44 -> #DIV/0! | M45: =M44 -> #DIV/0!
B46: 5 | D46: =C46 -> 0 | F46: =$D$32 -> #DIV/0! | G46: =$D$33 -> #DIV/0! | H46: =$D$34 -> #DIV/0! | I46: =$D$31 -> #DIV/0! | J46: =$D$35 -> #DIV/0! | K46: =$D$36 -> #DIV/0! | L46: =L45 -> #DIV/0! | M46: =M45 -> #DIV/0!
B47: 6 | D47: =C47 -> 0 | F47: =$D$32 -> #DIV/0! | G47: =$D$33 -> #DIV/0! | H47: =$D$34 -> #DIV/0! | I47: =$D$31 -> #DIV/0! | J47: =$D$35 -> #DIV/0! | K47: =$D$36 -> #DIV/0! | L47: =L46 -> #DIV/0! | M47: =M46 -> #DIV/0!
B48: 7 | D48: =C48 -> 0 | F48: =$D$32 -> #DIV/0! | G48: =$D$33 -> #DIV/0! | H48: =$D$34 -> #DIV/0! | I48: =$D$31 -> #DIV/0! | J48: =$D$35 -> #DIV/0! | K48: =$D$36 -> #DIV/0! | L48: =L47 -> #DIV/0! | M48: =M47 -> #DIV/0!
B49: 8 | D49: =C49 -> 0 | F49: =$D$32 -> #DIV/0! | G49: =$D$33 -> #DIV/0! | H49: =$D$34 -> #DIV/0! | I49: =$D$31 -> #DIV/0! | J49: =$D$35 -> #DIV/0! | K49: =$D$36 -> #DIV/0! | L49: =L48 -> #DIV/0! | M49: =M48 -> #DIV/0!
B50: 9 | D50: =C50 -> 0 | F50: =$D$32 -> #DIV/0! | G50: =$D$33 -> #DIV/0! | H50: =$D$34 -> #DIV/0! | I50: =$D$31 -> #DIV/0! | J50: =$D$35 -> #DIV/0! | K50: =$D$36 -> #DIV/0! | L50: =L49 -> #DIV/0! | M50: =M49 -> #DIV/0!
B51: 10 | D51: =C51 -> 0 | F51: =$D$32 -> #DIV/0! | G51: =$D$33 -> #DIV/0! | H51: =$D$34 -> #DIV/0! | I51: =$D$31 -> #DIV/0! | J51: =$D$35 -> #DIV/0! | K51: =$D$36 -> #DIV/0! | L51: =L50 -> #DIV/0! | M51: =M50 -> #DIV/0!
B52: 11 | D52: =C52 -> 0 | F52: =$D$32 -> #DIV/0! | G52: =$D$33 -> #DIV/0! | H52: =$D$34 -> #DIV/0! | I52: =$D$31 -> #DIV/0! | J52: =$D$35 -> #DIV/0! | K52: =$D$36 -> #DIV/0! | L52: =L51 -> #DIV/0! | M52: =M51 -> #DIV/0!
B53: 12 | D53: =C53 -> 0 | F53: =$D$32 -> #DIV/0! | G53: =$D$33 -> #DIV/0! | H53: =$D$34 -> #DIV/0! | I53: =$D$31 -> #DIV/0! | J53: =$D$35 -> #DIV/0! | K53: =$D$36 -> #DIV/0! | L53: =L52 -> #DIV/0! | M53: =M52 -> #DIV/0!
B54: 13 | D54: =C54 -> 0 | F54: =$D$32 -> #DIV/0! | G54: =$D$33 -> #DIV/0! | H54: =$D$34 -> #DIV/0! | I54: =$D$31 -> #DIV/0! | J54: =$D$35 -> #DIV/0! | K54: =$D$36 -> #DIV/0! | L54: =L53 -> #DIV/0! | M54: =M53 -> #DIV/0!
... B66: 25 | D66: =C66 -> 0 | F66: =$D$32 -> #DIV/0! | G66: =$D$33 -> #DIV/0! | H66: =$D$34 -> #DIV/0! | I66: =$D$31 -> #DIV/0! | J66: =$D$35 -> #DIV/0! | K66: =$D$36 -> #DIV/0! | L66: =L65 -> #DIV/0! | M66: =M65 -> #DIV/0!

Sheet Peta Kendali p dan np
B2: Part
B4: Pemeriksaan Kondisi Abnormalitas Peta p | G4: Pemeriksaan Kondisi Abnormalitas Peta np
B5: Run | G5: Run
B6: Trend | G6: Trend
B7: Pengulangan Secara Periodik | G7: Pengulangan Secara Periodik
B8: Hugging pada garis tengah | G8: Hugging pada garis tengah
B9: Hugging dekat garis batas kendali | G9: Hugging dekat garis batas kendali
B27: Peta p dan np
B29: Parameter Peta Kendali | C29: m | D29: 1
C30: n | D30: 20
C31: pbar
C32: npbar
C33: BKA p
C34: BKB p
C35: BKA np
C36: BKB np
B38: Sample Number (i) | C38: Jumlah Item Cacat | D38: Fraksi Item Cacat (p) | E38: Jumlah Item Cacat (np) | F38: GT p | G38: BKA p | H38: BKB p | I38: GT np | J38: BKA np | K38: BKB np
B39: 1 | D39: =C39/$D$30 -> 0 | E39: =D39*$D$30 -> 0 | F39: =$D$31 -> 0 | G39: =$D$33 -> 0 | H39: =$D$34 -> 0 | I39: =$D$32 -> 0 | J39: =$D$35 -> 0 | K39: =$D$36 -> 0
B40: 2 | D40: =C40/$D$30 -> 0 | E40: =D40*$D$30 -> 0 | F40: =$D$31 -> 0 | G40: =$D$33 -> 0 | H40: =$D$34 -> 0 | I40: =$D$32 -> 0 | J40: =$D$35 -> 0 | K40: =$D$36 -> 0
B41: 3 | D41: =C41/$D$30 -> 0 | E41: =D41*$D$30 -> 0 | F41: =$D$31 -> 0 | G41: =$D$33 -> 0 | H41: =$D$34 -> 0 | I41: =$D$32 -> 0 | J41: =$D$35 -> 0 | K41: =$D$36 -> 0
B42: 4 | D42: =C42/$D$30 -> 0 | E42: =D42*$D$30 -> 0 | F42: =$D$31 -> 0 | G42: =$D$33 -> 0 | H42: =$D$34 -> 0 | I42: =$D$32 -> 0 | J42: =$D$35 -> 0 | K42: =$D$36 -> 0
B43: 5 | D43: =C43/$D$30 -> 0 | E43: =D43*$D$30 -> 0 | F43: =$D$31 -> 0 | G43: =$D$33 -> 0 | H43: =$D$34 -> 0 | I43: =$D$32 -> 0 | J43: =$D$35 -> 0 | K43: =$D$36 -> 0
B44: 6 | D44: =C44/$D$30 -> 0 | E44: =D44*$D$30 -> 0 | F44: =$D$31 -> 0 | G44: =$D$33 -> 0 | H44: =$D$34 -> 0 | I44: =$D$32 -> 0 | J44: =$D$35 -> 0 | K44: =$D$36 -> 0
B45: 7 | D45: =C45/$D$30 -> 0 | E45: =D45*$D$30 -> 0 | F45: =$D$31 -> 0 | G45: =$D$33 -> 0 | H45: =$D$34 -> 0 | I45: =$D$32 -> 0 | J45: =$D$35 -> 0 | K45: =$D$36 -> 0
B46: 8 | D46: =C46/$D$30 -> 0 | E46: =D46*$D$30 -> 0 | F46: =$D$31 -> 0 | G46: =$D$33 -> 0 | H46: =$D$34 -> 0 | I46: =$D$32 -> 0 | J46: =$D$35 -> 0 | K46: =$D$36 -> 0
B47: 9 | D47: =C47/$D$30 -> 0 | E47: =D47*$D$30 -> 0 | F47: =$D$31 -> 0 | G47: =$D$33 -> 0 | H47: =$D$34 -> 0 | I47: =$D$32 -> 0 | J47: =$D$35 -> 0 | K47: =$D$36 -> 0
B48: 10 | D48: =C48/$D$30 -> 0 | E48: =D48*$D$30 -> 0 | F48: =$D$31 -> 0 | G48: =$D$33 -> 0 | H48: =$D$34 -> 0 | I48: =$D$32 -> 0 | J48: =$D$35 -> 0 | K48: =$D$36 -> 0
B49: 11 | D49: =C49/$D$30 -> 0 | E49: =D49*$D$30 -> 0 | F49: =$D$31 -> 0 | G49: =$D$33 -> 0 | H49: =$D$34 -> 0 | I49: =$D$32 -> 0 | J49: =$D$35 -> 0 | K49: =$D$36 -> 0
B50: 12 | D50: =C50/$D$30 -> 0 | E50: =D50*$D$30 -> 0 | F50: =$D$31 -> 0 | G50: =$D$33 -> 0 | H50: =$D$34 -> 0 | I50: =$D$32 -> 0 | J50: =$D$35 -> 0 | K50: =$D$36 -> 0
... B63: 25 | D63: =C63/$D$30 -> 0 | E63: =D63*$D$30 -> 0 | F63: =$D$31 -> 0 | G63: =$D$33 -> 0 | H63: =$D$34 -> 0 | I63: =$D$32 -> 0 | J63: =$D$35 -> 0 | K63: =$D$36 -> 0

Sheet Peta Kendali c
B2: Part
B3: Iterasi 1
B4: Pemeriksaan Kondisi Abnormalitas Peta c
B5: Run
B6: Trend
B7: Pengulangan Secara Periodik
B8: Hugging pada garis tengah
B9: Hugging dekat garis batas kendali
B27: Peta c
B29: Parameter Peta Kendali | C29: m
C30: n
C31: cbar
C32: BKA c
C33: BKB c
B35: Sample Number (i) | C35: Jumlah Cacat (c) | D35: GT c | E35: BKA c | F35: BKB c
B36: 1 | D36: =$D$31 -> 0 | E36: =$D$32 -> 0 | F36: =$D$33 -> 0
B37: 2 | D37: =$D$31 -> 0 | E37: =$D$32 -> 0 | F37: =$D$33 -> 0
B38: 3 | D38: =$D$31 -> 0 | E38: =$D$32 -> 0 | F38: =$D$33 -> 0
B39: 4 | D39: =$D$31 -> 0 | E39: =$D$32 -> 0 | F39: =$D$33 -> 0
B40: 5 | D40: =$D$31 -> 0 | E40: =$D$32 -> 0 | F40: =$D$33 -> 0
B41: 6 | D41: =$D$31 -> 0 | E41: =$D$32 -> 0 | F41: =$D$33 -> 0
B42: 7 | D42: =$D$31 -> 0 | E42: =$D$32 -> 0 | F42: =$D$33 -> 0
B43: 8 | D43: =$D$31 -> 0 | E43: =$D$32 -> 0 | F43: =$D$33 -> 0
B44: 9 | D44: =$D$31 -> 0 | E44: =$D$32 -> 0 | F44: =$D$33 -> 0
B45: 10 | D45: =$D$31 -> 0 | E45: =$D$32 -> 0 | F45: =$D$33 -> 0
B46: 11 | D46: =$D$31 -> 0 | E46: =$D$32 -> 0 | F46: =$D$33 -> 0
B47: 12 | D47: =$D$31 -> 0 | E47: =$D$32 -> 0 | F47: =$D$33 -> 0
... B60: 25 | D60: =$D$31 -> 0 | E60: =$D$32 -> 0 | F60: =$D$33 -> 0

Sheet Peta Kendali u
B2: Part
B3: Iterasi 1
B4: Pemeriksaan Kondisi Abnormalitas Peta u
B5: Run
B6: Trend
B7: Pengulangan Secara Periodik
B8: Hugging pada garis tengah
B9: Hugging dekat garis batas kendali
B27: Peta u
B29: Parameter Peta Kendali | C29: m
C30: n
C31: ubar
C32: BKA u
C33: BKB u
B35: Sample Number (i) | C35: Jumlah Cacat | D35: Jumlah Cacat/unit (u) | E35: GT u | F35: BKA u | G35: BKB u
B36: 1 | E36: =$D$31 -> 0 | F36: =$D$32 -> 0 | G36: =$D$33 -> 0
B37: 2 | E37: =$D$31 -> 0 | F37: =$D$32 -> 0 | G37: =$D$33 -> 0
B38: 3 | E38: =$D$31 -> 0 | F38: =$D$32 -> 0 | G38: =$D$33 -> 0
B39: 4 | E39: =$D$31 -> 0 | F39: =$D$32 -> 0 | G39: =$D$33 -> 0
B40: 5 | E40: =$D$31 -> 0 | F40: =$D$32 -> 0 | G40: =$D$33 -> 0
B41: 6 | E41: =$D$31 -> 0 | F41: =$D$32 -> 0 | G41: =$D$33 -> 0
B42: 7 | E42: =$D$31 -> 0 | F42: =$D$32 -> 0 | G42: =$D$33 -> 0
B43: 8 | E43: =$D$31 -> 0 | F43: =$D$32 -> 0 | G43: =$D$33 -> 0
B44: 9 | E44: =$D$31 -> 0 | F44: =$D$32 -> 0 | G44: =$D$33 -> 0
B45: 10 | E45: =$D$31 -> 0 | F45: =$D$32 -> 0 | G45: =$D$33 -> 0
B46: 11 | E46: =$D$31 -> 0 | F46: =$D$32 -> 0 | G46: =$D$33 -> 0
B47: 12 | E47: =$D$31 -> 0 | F47: =$D$32 -> 0 | G47: =$D$33 -> 0
... B60: 25 | E60: =$D$31 -> 0 | F60: =$D$32 -> 0 | G60: =$D$33 -> 0

Sheet Peta Kendali cusum
B2: Part
B20: Peta cusum
B22: Parameter Peta Kendali | C22: K | D22: =0.5*D25 -> 0.05 | G22: Deteksi Pergeseran | H22: i
C23: H | D23: =5*D25 -> 0.5 | H23: Ci
C24: miu0 | D24: 1 | H24: Ni
C25: sigma | D25: 0.1 | H25: miu
B27: Period (i) | C27: Observasi (xi) | D27: xi-(miu0+k) | E27: Ci+ | F27: Ni+ | G27: (miu0-k)-xi | H27: Ci- | I27: Ni- | J27: -Ci- | K27: H | L27: -H
B28: 1 | J28: =-H28 -> 0 | K28: =$D$23 -> 0.5 | L28: =-$D$23 -> -0.5
B29: 2 | J29: =-H29 -> 0 | K29: =$D$23 -> 0.5 | L29: =-$D$23 -> -0.5
B30: 3 | J30: =-H30 -> 0 | K30: =$D$23 -> 0.5 | L30: =-$D$23 -> -0.5
B31: 4 | J31: =-H31 -> 0 | K31: =$D$23 -> 0.5 | L31: =-$D$23 -> -0.5
B32: 5 | J32: =-H32 -> 0 | K32: =$D$23 -> 0.5 | L32: =-$D$23 -> -0.5
B33: 6 | J33: =-H33 -> 0 | K33: =$D$23 -> 0.5 | L33: =-$D$23 -> -0.5
B34: 7 | J34: =-H34 -> 0 | K34: =$D$23 -> 0.5 | L34: =-$D$23 -> -0.5
B35: 8 | J35: =-H35 -> 0 | K35: =$D$23 -> 0.5 | L35: =-$D$23 -> -0.5
B36: 9 | J36: =-H36 -> 0 | K36: =$D$23 -> 0.5 | L36: =-$D$23 -> -0.5
B37: 10 | J37: =-H37 -> 0 | K37: =$D$23 -> 0.5 | L37: =-$D$23 -> -0.5
B38: 11 | J38: =-H38 -> 0 | K38: =$D$23 -> 0.5 | L38: =-$D$23 -> -0.5
B39: 12 | J39: =-H39 -> 0 | K39: =$D$23 -> 0.5 | L39: =-$D$23 -> -0.5
... B57: 30 | J57: =-H57 -> 0 | K57: =$D$23 -> 0.5 | L57: =-$D$23 -> -0.5

Sheet Peta Kendali EWMA
B2: Part
B20: Peta EWMA
B22: Parameter Peta Kendali | C22: Lambda | D22: 0.1
C23: L | D23: 2.7
C24: miu0 | D24: 1
C25: sigma | D25: 0.1
C26: BKA i besar | D26: =$D$24+$D$23*$D$25*SQRT($D$22/(2-$D$22)) -> 1.0619422
C27: BKB i besar | D27: =$D$24-$D$23*$D$25*SQRT($D$22/(2-$D$22)) -> 0.93805775
B29: Period (i) | C29: Observasi (xi) | D29: EWMA, zi | E29: BKA | F29: BKB | G29: Check Luar BK
B30: 1 | E30: =$D$24+$D$23*$D$25*SQRT($D$22/(2-$D$22)*(1-(1-$D$22)^(2*B30))) -> 1.027 | F30: =$D$24-$D$23*$D$25*SQRT($D$22/(2-$D$22)*(1-(1-$D$22)^(2*B30))) -> 0.973 | G30: =IF(OR(D30<F30,D30>E30),"Yes","No") -> Yes
B31: 2 | E31: =$D$24+$D$23*$D$25*SQRT($D$22/(2-$D$22)*(1-(1-$D$22)^(2*B31))) -> 1.0363248 | F31: =$D$24-$D$23*$D$25*SQRT($D$22/(2-$D$22)*(1-(1-$D$22)^(2*B31))) -> 0.96367522 | G31: =IF(OR(D31<F31,D31>E31),"Yes","No") -> Yes
B32: 3 | E32: =$D$24+$D$23*$D$25*SQRT($D$22/(2-$D$22)*(1-(1-$D$22)^(2*B32))) -> 1.0424003 | F32: =$D$24-$D$23*$D$25*SQRT($D$22/(2-$D$22)*(1-(1-$D$22)^(2*B32))) -> 0.95759968 | G32: =IF(OR(D32<F32,D32>E32),"Yes","No") -> Yes
B33: 4 | E33: =$D$24+$D$23*$D$25*SQRT($D$22/(2-$D$22)*(1-(1-$D$22)^(2*B33))) -> 1.0467462 | F33: =$D$24-$D$23*$D$25*SQRT($D$22/(2-$D$22)*(1-(1-$D$22)^(2*B33))) -> 0.9532538 | G33: =IF(OR(D33<F33,D33>E33),"Yes","No") -> Yes
B34: 5 | E34: =$D$24+$D$23*$D$25*SQRT($D$22/(2-$D$22)*(1-(1-$D$22)^(2*B34))) -> 1.0499902 | F34: =$D$24-$D$23*$D$25*SQRT($D$22/(2-$D$22)*(1-(1-$D$22)^(2*B34))) -> 0.95000982 | G34: =IF(OR(D34<F34,D34>E34),"Yes","No") -> Yes
B35: 6 | E35: =$D$24+$D$23*$D$25*SQRT($D$22/(2-$D$22)*(1-(1-$D$22)^(2*B35))) -> 1.052471 | F35: =$D$24-$D$23*$D$25*SQRT($D$22/(2-$D$22)*(1-(1-$D$22)^(2*B35))) -> 0.94752901 | G35: =IF(OR(D35<F35,D35>E35),"Yes","No") -> Yes
B36: 7 | E36: =$D$24+$D$23*$D$25*SQRT($D$22/(2-$D$22)*(1-(1-$D$22)^(2*B36))) -> 1.0543976 | F36: =$D$24-$D$23*$D$25*SQRT($D$22/(2-$D$22)*(1-(1-$D$22)^(2*B36))) -> 0.94560243 | G36: =IF(OR(D36<F36,D36>E36),"Yes","No") -> Yes
B37: 8 | E37: =$D$24+$D$23*$D$25*SQRT($D$22/(2-$D$22)*(1-(1-$D$22)^(2*B37))) -> 1.0559095 | F37: =$D$24-$D$23*$D$25*SQRT($D$22/(2-$D$22)*(1-(1-$D$22)^(2*B37))) -> 0.94409054 | G37: =IF(OR(D37<F37,D37>E37),"Yes","No") -> Yes
B38: 9 | E38: =$D$24+$D$23*$D$25*SQRT($D$22/(2-$D$22)*(1-(1-$D$22)^(2*B38))) -> 1.0571048 | F38: =$D$24-$D$23*$D$25*SQRT($D$22/(2-$D$22)*(1-(1-$D$22)^(2*B38))) -> 0.94289525 | G38: =IF(OR(D38<F38,D38>E38),"Yes","No") -> Yes
B39: 10 | E39: =$D$24+$D$23*$D$25*SQRT($D$22/(2-$D$22)*(1-(1-$D$22)^(2*B39))) -> 1.0580549 | F39: =$D$24-$D$23*$D$25*SQRT($D$22/(2-$D$22)*(1-(1-$D$22)^(2*B39))) -> 0.9419451 | G39: =IF(OR(D39<F39,D39>E39),"Yes","No") -> Yes
B40: 11 | E40: =$D$24+$D$23*$D$25*SQRT($D$22/(2-$D$22)*(1-(1-$D$22)^(2*B40))) -> 1.0588133 | F40: =$D$24-$D$23*$D$25*SQRT($D$22/(2-$D$22)*(1-(1-$D$22)^(2*B40))) -> 0.94118673 | G40: =IF(OR(D40<F40,D40>E40),"Yes","No") -> Yes
B41: 12 | E41: =$D$24+$D$23*$D$25*SQRT($D$22/(2-$D$22)*(1-(1-$D$22)^(2*B41))) -> 1.0594205 | F41: =$D$24-$D$23*$D$25*SQRT($D$22/(2-$D$22)*(1-(1-$D$22)^(2*B41))) -> 0.94057954 | G41: =IF(OR(D41<F41,D41>E41),"Yes","No") -> Yes
... B59: 30 | E59: =$D$24+$D$23*$D$25*SQRT($D$22/(2-$D$22)*(1-(1-$D$22)^(2*B59))) -> 1.0618866 | F59: =$D$24-$D$23*$D$25*SQRT($D$22/(2-$D$22)*(1-(1-$D$22)^(2*B59))) -> 0.93811343 | G59: =IF(OR(D59<F59,D59>E59),"Yes","No") -> Yes

Sheet Peta Kendali xbar-R SPR
B2: Part
B20: Peta xbar-R Short Production Run
B22: Parameter Peta Kendali | C22: m
C23: n
C24: A | D24: ='Data Awal'!AI5 -> 264 | E24: T (Target)
C25: B | D25: ='Data Awal'!AI6 -> 284
C26: C | D26: ='Data Awal'!AI7 -> 304
C27: D | D27: ='Data Awal'!AI8 -> 324
C28: A | E28: R (Range)
C29: B
C30: C
C31: D
C32: GT xbar
C33: GT R
C34: BKA R
C35: BKB R
C36: BKA Xbar
C37: BKB Xbar
C38: A2 | D38: {=INDEX('Tabel Faktor'!$A$1:$Q$25,MATCH('Peta Kendali xbar-R SPR'!D23,'Tabel Faktor'!$A$1:$A$25,0),MATCH('Peta Kendali xbar-R SPR'!C38,'Tabel Faktor'!$A$1:$Q$1,0))} -> #N/A
C39: D4 | D39: {=INDEX('Tabel Faktor'!$A$1:$Q$25,MATCH('Peta Kendali xbar-R SPR'!D23,'Tabel Faktor'!$A$1:$A$25,0),MATCH('Peta Kendali xbar-R SPR'!C39,'Tabel Faktor'!$A$1:$Q$1,0))} -> #N/A
C40: D3 | D40: {=INDEX('Tabel Faktor'!$A$1:$Q$25,MATCH('Peta Kendali xbar-R SPR'!D23,'Tabel Faktor'!$A$1:$A$25,0),MATCH('Peta Kendali xbar-R SPR'!C40,'Tabel Faktor'!$A$1:$Q$1,0))} -> #N/A
B42: Sample Number (i) | C42: Jenis Tripod | D42: Observasi | G42: Rata-rata (xi bar) | H42: Range (Ri) | I42: Target (T) | J42: Avg Range | K42: xbar standardized | L42: R standardized | M42: GT R | N42: BKA R | O42: BKB R | P42: GT xbar | Q42: BKA xbar | R42: BKB xbar
B43: 1 | G43: =AVERAGE(D43:F43) -> #DIV/0! | H43: =MAX(D43:F43)-MIN(D43:F43) -> 0 | I43: =INDEX($D$24:$D$27,MATCH(C43,$C$24:$C$27,0)) -> #N/A | J43: =INDEX($D$28:$D$31,MATCH(C43,$C$28:$C$31,0)) -> #N/A | K43: =(G43-I43)/J43 -> #DIV/0! | L43: =H43/J43 -> #N/A | M43: =$D$33 -> 0 | N43: =$D$34 -> 0 | O43: =$D$35 -> 0 | P43: =$D$32 -> 0 | Q43: =$D$36 -> 0 | R43: =$D$37 -> 0
B44: 2 | G44: =AVERAGE(D44:F44) -> #DIV/0! | H44: =MAX(D44:F44)-MIN(D44:F44) -> 0 | I44: =INDEX($D$24:$D$27,MATCH(C44,$C$24:$C$27,0)) -> #N/A | J44: =INDEX($D$28:$D$31,MATCH(C44,$C$28:$C$31,0)) -> #N/A | K44: =(G44-I44)/J44 -> #DIV/0! | L44: =H44/J44 -> #N/A | M44: =$D$33 -> 0 | N44: =$D$34 -> 0 | O44: =$D$35 -> 0 | P44: =$D$32 -> 0 | Q44: =$D$36 -> 0 | R44: =$D$37 -> 0
B45: 3 | G45: =AVERAGE(D45:F45) -> #DIV/0! | H45: =MAX(D45:F45)-MIN(D45:F45) -> 0 | I45: =INDEX($D$24:$D$27,MATCH(C45,$C$24:$C$27,0)) -> #N/A | J45: =INDEX($D$28:$D$31,MATCH(C45,$C$28:$C$31,0)) -> #N/A | K45: =(G45-I45)/J45 -> #DIV/0! | L45: =H45/J45 -> #N/A | M45: =$D$33 -> 0 | N45: =$D$34 -> 0 | O45: =$D$35 -> 0 | P45: =$D$32 -> 0 | Q45: =$D$36 -> 0 | R45: =$D$37 -> 0
B46: 4 | G46: =AVERAGE(D46:F46) -> #DIV/0! | H46: =MAX(D46:F46)-MIN(D46:F46) -> 0 | I46: =INDEX($D$24:$D$27,MATCH(C46,$C$24:$C$27,0)) -> #N/A | J46: =INDEX($D$28:$D$31,MATCH(C46,$C$28:$C$31,0)) -> #N/A | K46: =(G46-I46)/J46 -> #DIV/0! | L46: =H46/J46 -> #N/A | M46: =$D$33 -> 0 | N46: =$D$34 -> 0 | O46: =$D$35 -> 0 | P46: =$D$32 -> 0 | Q46: =$D$36 -> 0 | R46: =$D$37 -> 0
B47: 5 | G47: =AVERAGE(D47:F47) -> #DIV/0! | H47: =MAX(D47:F47)-MIN(D47:F47) -> 0 | I47: =INDEX($D$24:$D$27,MATCH(C47,$C$24:$C$27,0)) -> #N/A | J47: =INDEX($D$28:$D$31,MATCH(C47,$C$28:$C$31,0)) -> #N/A | K47: =(G47-I47)/J47 -> #DIV/0! | L47: =H47/J47 -> #N/A | M47: =$D$33 -> 0 | N47: =$D$34 -> 0 | O47: =$D$35 -> 0 | P47: =$D$32 -> 0 | Q47: =$D$36 -> 0 | R47: =$D$37 -> 0
B48: 6 | G48: =AVERAGE(D48:F48) -> #DIV/0! | H48: =MAX(D48:F48)-MIN(D48:F48) -> 0 | I48: =INDEX($D$24:$D$27,MATCH(C48,$C$24:$C$27,0)) -> #N/A | J48: =INDEX($D$28:$D$31,MATCH(C48,$C$28:$C$31,0)) -> #N/A | K48: =(G48-I48)/J48 -> #DIV/0! | L48: =H48/J48 -> #N/A | M48: =$D$33 -> 0 | N48: =$D$34 -> 0 | O48: =$D$35 -> 0 | P48: =$D$32 -> 0 | Q48: =$D$36 -> 0 | R48: =$D$37 -> 0
B49: 7 | G49: =AVERAGE(D49:F49) -> #DIV/0! | H49: =MAX(D49:F49)-MIN(D49:F49) -> 0 | I49: =INDEX($D$24:$D$27,MATCH(C49,$C$24:$C$27,0)) -> #N/A | J49: =INDEX($D$28:$D$31,MATCH(C49,$C$28:$C$31,0)) -> #N/A | K49: =(G49-I49)/J49 -> #DIV/0! | L49: =H49/J49 -> #N/A | M49: =$D$33 -> 0 | N49: =$D$34 -> 0 | O49: =$D$35 -> 0 | P49: =$D$32 -> 0 | Q49: =$D$36 -> 0 | R49: =$D$37 -> 0
B50: 8 | G50: =AVERAGE(D50:F50) -> #DIV/0! | H50: =MAX(D50:F50)-MIN(D50:F50) -> 0 | I50: =INDEX($D$24:$D$27,MATCH(C50,$C$24:$C$27,0)) -> #N/A | J50: =INDEX($D$28:$D$31,MATCH(C50,$C$28:$C$31,0)) -> #N/A | K50: =(G50-I50)/J50 -> #DIV/0! | L50: =H50/J50 -> #N/A | M50: =$D$33 -> 0 | N50: =$D$34 -> 0 | O50: =$D$35 -> 0 | P50: =$D$32 -> 0 | Q50: =$D$36 -> 0 | R50: =$D$37 -> 0
